Workbook

Sheet 鹿屋
A1: =SUM(A57,A69,A81,A93,A9,A21,A33,A45,A201,A213,A225,A237,A105,A117,A129,A141,A153,A165,A177,A189,A249,A261) -> 1307300 | B1: 日付 | C1: 46067 | D1: =C1+1 -> 46068 | E1: =D1+1 -> 46069 | F1: =E1+1 -> 46070 | G1: =F1+1 -> 46071 | H1: =G1+1 -> 46072 | I1: =H1+1 -> 46073 | J1: =I1+1 -> 46074 | K1: =J1+1 -> 46075 | ... AS1: =AR1+1 -> 46109
B2: =SUM(C2:AO2) -> 13073 | C2: 0 | D2: =SUM(D58,D70,D82,D94,D10,D22,D34,D46,D202,D214,D226,D238,D190,D178,D166,D154,D142,D130,D118,D106,D250,D262) -> 0 | E2: =SUM(E58,E70,E82,E94,E10,E22,E34,E46,E202,E214,E226,E238,E190,E178,E166,E154,E142,E130,E118,E106,E250,E262) -> 1732 | F2: =SUM(F58,F70,F82,F94,F10,F22,F34,F46,F202,F214,F226,F238,F190,F178,F166,F154,F142,F130,F118,F106,F250,F262) -> 0 | G2: =SUM(G58,G70,G82,G94,G10,G22,G34,G46,G202,G214,G226,G238,G190,G178,G166,G154,G142,G130,G118,G106,G250,G262) -> 0 | H2: =SUM(H58,H70,H82,H94,H10,H22,H34,H46,H202,H214,H226,H238,H190,H178,H166,H154,H142,H130,H118,H106,H250,H262) -> 828 | I2: =SUM(I58,I70,I82,I94,I10,I22,I34,I46,I202,I214,I226,I238,I190,I178,I166,I154,I142,I130,I118,I106,I250,I262) -> 0 | J2: =SUM(J58,J70,J82,J94,J10,J22,J34,J46,J202,J214,J226,J238,J190,J178,J166,J154,J142,J130,J118,J106,J250,J262) -> 0 | K2: =SUM(K58,K70,K82,K94,K10,K22,K34,K46,K202,K214,K226,K238,K190,K178,K166,K154,K142,K130,K118,K106,K250,K262) -> 2045 | ... AS2: =SUM(AS58,AS70,AS82,AS94,AS10,AS22,AS34,AS46,AS202,AS214,AS226,AS238,AS190,AS178,AS166,AS154,AS142,AS130,AS118,AS106,AS250,AS262) -> 0
A3: 鹿屋 | B3: 100円 | C3: 3924 | D3: 3924 | E3: 3943 | F3: 3943 | G3: 3943 | H3: 3948 | I3: 3948 | J3: 3948 | K3: 3987 | L3: 3987 | M3: 3987 | N3: 3987 | O3: 4004 | P3: 4004 | Q3: 4004 | R3: 4018 | S3: 4018 | T3: 4018 | U3: 4018 | V3: 4048 | W3: 4048 | X3: 4048 | Y3: 4108 | Z3: 4108 | AA3: 4108 | AB3: 4108 | AC3: 4136 | AD3: 4136 | AE3: 4136 | AF3: 4177
A4: BUZZ＃１ | B4: プライズ | C4: 285 | D4: =IF(D3="","",C4) -> 285 | E4: 286 | F4: =IF(F3="","",E4) -> 286 | G4: =IF(G3="","",F4) -> 286 | H4: =IF(H3="","",G4) -> 286 | I4: =IF(I3="","",H4) -> 286 | J4: =IF(J3="","",I4) -> 286 | K4: =IF(K3="","",J4) -> 286 | L4: =IF(L3="","",K4) -> 286 | M4: =IF(M3="","",L4) -> 286 | ... Q4: =IF(Q3="","",P4) -> 286 | R4: 287 | S4: =IF(S3="","",R4) -> 287 | T4: =IF(T3="","",S4) -> 287 | U4: =IF(U3="","",T4) -> 287 | V4: 288 | W4: =IF(W3="","",V4) -> 288 | X4: =IF(X3="","",W4) -> 288 | Y4: 290 | Z4: =IF(Z3="","",Y4) -> 290 | AA4: =IF(AA3="","",Z4) -> 290 | AB4: =IF(AB3="","",AA4) -> 290 | AC4: =IF(AC3="","",AB4) -> 290 | AD4: =IF(AD3="","",AC4) -> 290 | AE4: =IF(AE3="","",AD4) -> 290 | AF4: =IF(AF3="","",AE4) -> 290 | AG4: =IF(AG3="","",AF4) | ... AS4: =IF(AS3="","",AR4)
A5: 1 | B5: 投入残 | C5: 6 | D5: =IF(D3="","",(C5+C6)) -> 6 | E5: =IF(E3="","",(D5+D6)) -> 6 | F5: =IF(F3="","",(E5+E6)) -> 4 | G5: =IF(G3="","",(F5+F6)) -> 4 | H5: =IF(H3="","",(G5+G6)) -> 4 | I5: =IF(I3="","",(H5+H6)) -> 4 | J5: =IF(J3="","",(I5+I6)) -> 4 | K5: =IF(K3="","",(J5+J6)) -> 4 | ... Q5: =IF(Q3="","",(P5+P6)) -> 4 | R5: 3 | S5: =IF(S3="","",(R5+R6)) -> 15 | T5: =IF(T3="","",(S5+S6)) -> 15 | U5: =IF(U3="","",(T5+T6)) -> 15 | V5: 14 | W5: =IF(W3="","",(V5+V6)) -> 14 | X5: =IF(X3="","",(W5+W6)) -> 14 | Y5: 12 | Z5: =IF(Z3="","",(Y5+Y6)) -> 12 | AA5: =IF(AA3="","",(Z5+Z6)) -> 12 | AB5: =IF(AB3="","",(AA5+AA6)) -> 12 | AC5: =IF(AC3="","",(AB5+AB6)) -> 12 | AD5: =IF(AD3="","",(AC5+AC6)) -> 12 | AE5: =IF(AE3="","",(AD5+AD6)) -> 12 | AF5: =IF(AF3="","",(AE5+AE6)) -> 12 | AG5: =IF(AG3="","",(AF5+AF6)) | ... AS5: =IF(AS3="","",(AR5+AR6))
A6: 機械合計 | B6: 補充 | E6: -2 | R6: 12
A7: =+(A10+A22+A34+A46)*100 -> 243100 | B7: 単価 | C7: 500 | D7: =IF(D3="","",C7) -> 500 | E7: =IF(E3="","",D7) -> 500 | F7: =IF(F3="","",E7) -> 500 | G7: =IF(G3="","",F7) -> 500 | H7: =IF(H3="","",G7) -> 500 | I7: =IF(I3="","",H7) -> 500 | J7: =IF(J3="","",I7) -> 500 | K7: =IF(K3="","",J7) -> 500 | ... AS7: =IF(AS3="","",AR7)
A8: 月間予想 | B8: 景品名 | C8: サンリオホワイトMC | D8: =IF(D3="","",C8) -> サンリオホワイトMC | E8: ポメラニアン | F8: =IF(F3="","",E8) -> ポメラニアン | G8: =IF(G3="","",F8) -> ポメラニアン | H8: =IF(H3="","",G8) -> ポメラニアン | I8: =IF(I3="","",H8) -> ポメラニアン | J8: =IF(J3="","",I8) -> ポメラニアン | K8: =IF(K3="","",J8) -> ポメラニアン | L8: =IF(L3="","",K8) -> ポメラニアン | M8: =IF(M3="","",L8) -> ポメラニアン | ... Q8: =IF(Q3="","",P8) -> ポメラニアン | R8: 電ブル | S8: =IF(S3="","",R8) -> 電ブル | T8: =IF(T3="","",S8) -> 電ブル | U8: =IF(U3="","",T8) -> 電ブル | V8: =IF(V3="","",U8) -> 電ブル | W8: =IF(W3="","",V8) -> 電ブル | X8: =IF(X3="","",W8) -> 電ブル | Y8: =IF(Y3="","",X8) -> 電ブル | Z8: =IF(Z3="","",Y8) -> 電ブル | ... AS8: =IF(AS3="","",AR8)
A9: =AVERAGE(C10:AS10)*30*100 -> 25300 | B9: 設定
A10: =SUM(C10:AS10) -> 253 | B10: 百差 | C10: 0 | D10: =IF(D3="","",D3-C3) -> 0 | E10: =IF(E3="","",E3-D3) -> 19 | F10: =IF(F3="","",F3-E3) -> 0 | G10: =IF(G3="","",G3-F3) -> 0 | H10: =IF(H3="","",H3-G3) -> 5 | I10: =IF(I3="","",I3-H3) -> 0 | J10: =IF(J3="","",J3-I3) -> 0 | K10: =IF(K3="","",K3-J3) -> 39 | ... AS10: =IF(AS3="","",AS3-AR3)
A11: =SUM(C11:AS11) -> 5 | B11: P差 | C11: 0 | D11: =IF(D4="","",D4-C4) -> 0 | E11: =IF(E4="","",E4-D4) -> 1 | F11: =IF(F4="","",F4-E4) -> 0 | G11: =IF(G4="","",G4-F4) -> 0 | H11: =IF(H4="","",H4-G4) -> 0 | I11: =IF(I4="","",I4-H4) -> 0 | J11: =IF(J4="","",J4-I4) -> 0 | K11: =IF(K4="","",K4-J4) -> 0 | ... AS11: =IF(AS4="","",AS4-AR4)
A12: =SUM(C12:AS12) -> 4 | B12: 払出 | C12: 0 | D12: =IF(D5="","",C5+C6-D5) -> 0 | E12: =IF(E5="","",D5+D6-E5) -> 0 | F12: =IF(F5="","",E5+E6-F5) -> 0 | G12: =IF(G5="","",F5+F6-G5) -> 0 | H12: =IF(H5="","",G5+G6-H5) -> 0 | I12: =IF(I5="","",H5+H6-I5) -> 0 | J12: =IF(J5="","",I5+I6-J5) -> 0 | K12: =IF(K5="","",J5+J6-K5) -> 0 | ... AS12: =IF(AS5="","",AR5+AR6-AS5)
A13: =SUM(C13:AS13) -> 2000 | B13: 払出額 | C13: 0 | D13: =IF(D3="","",D12*D7) -> 0 | E13: =IF(E3="","",E12*E7) -> 0 | F13: =IF(F3="","",F12*F7) -> 0 | G13: =IF(G3="","",G12*G7) -> 0 | H13: =IF(H3="","",H12*H7) -> 0 | I13: =IF(I3="","",I12*I7) -> 0 | J13: =IF(J3="","",J12*J7) -> 0 | K13: =IF(K3="","",K12*K7) -> 0 | ... AS13: =IF(AS3="","",AS12*AS7) | AT13: =
A14: =IF(A13="","",A13/(A10*100)) -> 0.079051383 | B14: 原価率 | D14: =IF(D13="","",IF(D13=0,"",D13/(D10*100))) | E14: =IF(E13="","",IF(E13=0,"",E13/(E10*100))) | F14: =IF(F13="","",IF(F13=0,"",F13/(F10*100))) | G14: =IF(G13="","",IF(G13=0,"",G13/(G10*100))) | H14: =IF(H13="","",IF(H13=0,"",H13/(H10*100))) | I14: =IF(I13="","",IF(I13=0,"",I13/(I10*100))) | J14: =IF(J13="","",IF(J13=0,"",J13/(J10*100))) | K14: =IF(K13="","",IF(K13=0,"",K13/(K10*100))) | ... AS14: =IF(AS13="","",IF(AS13=0,"",AS13/(AS10*100)))
A15: 鹿屋 | B15: 100円 | C15: 6732 | D15: =IF(D3="","",C15) -> 6732 | E15: 6742 | F15: =IF(F3="","",E15) -> 6742 | G15: =IF(G3="","",F15) -> 6742 | H15: 6752 | I15: =IF(I3="","",H15) -> 6752 | J15: =IF(J3="","",I15) -> 6752 | K15: 6761 | L15: =IF(L3="","",K15) -> 6761 | M15: =IF(M3="","",L15) -> 6761 | N15: =IF(N3="","",M15) -> 6761 | O15: 6869 | P15: =IF(P3="","",O15) -> 6869 | Q15: =IF(Q3="","",P15) -> 6869 | R15: 6960 | S15: =IF(S3="","",R15) -> 6960 | T15: =IF(T3="","",S15) -> 6960 | U15: =IF(U3="","",T15) -> 6960 | V15: 7005 | W15: =IF(W3="","",V15) -> 7005 | X15: =IF(X3="","",W15) -> 7005 | Y15: 7076 | Z15: =IF(Z3="","",Y15) -> 7076 | AA15: =IF(AA3="","",Z15) -> 7076 | AB15: =IF(AB3="","",AA15) -> 7076 | AC15: 7148 | AD15: =IF(AD3="","",AC15) -> 7148 | AE15: =IF(AE3="","",AD15) -> 7148 | AF15: 7181 | AG15: =IF(AG3="","",AF15) | AH15: =IF(AH3="","",AG15) | AI15: =IF(AI3="","",AH15) | AJ15: =IF(AJ3="","",AI15) | AK15: =IF(AK3="","",AJ15) | AL15: =IF(AL3="","",AK15) | AM15: =IF(AM3="","",AL15) | AN15: =IF(AN3="","",AM15) | ... AS15: =IF(AS3="","",AR15)
A16: BUZZ＃１ | B16: プライズ | C16: 301 | D16: =IF(D3="","",C16) -> 301 | E16: =IF(E3="","",D16) -> 301 | F16: =IF(F3="","",E16) -> 301 | G16: =IF(G3="","",F16) -> 301 | H16: =IF(H3="","",G16) -> 301 | I16: =IF(I3="","",H16) -> 301 | J16: =IF(J3="","",I16) -> 301 | K16: 302 | L16: =IF(L3="","",K16) -> 302 | M16: =IF(M3="","",L16) -> 302 | N16: =IF(N3="","",M16) -> 302 | O16: 304 | P16: =IF(P3="","",O16) -> 304 | Q16: =IF(Q3="","",P16) -> 304 | R16: 306 | S16: =IF(S3="","",R16) -> 306 | T16: =IF(T3="","",S16) -> 306 | U16: =IF(U3="","",T16) -> 306 | V16: 307 | W16: =IF(W3="","",V16) -> 307 | X16: =IF(X3="","",W16) -> 307 | Y16: 310 | Z16: =IF(Z3="","",Y16) -> 310 | AA16: =IF(AA3="","",Z16) -> 310 | AB16: =IF(AB3="","",AA16) -> 310 | AC16: 311 | AD16: =IF(AD3="","",AC16) -> 311 | AE16: =IF(AE3="","",AD16) -> 311 | AF16: 313 | AG16: =IF(AG3="","",AF16) | AH16: =IF(AH3="","",AG16) | AI16: =IF(AI3="","",AH16) | AJ16: =IF(AJ3="","",AI16) | AK16: =IF(AK3="","",AJ16) | AL16: =IF(AL3="","",AK16) | AM16: =IF(AM3="","",AL16) | AN16: =IF(AN3="","",AM16) | ... AS16: =IF(AS3="","",AR16)
A17: 2 | B17: 投入残 | C17: 4 | D17: =IF(D15="","",(C17+C18)) -> 4 | E17: =IF(E15="","",(D17+D18)) -> 4 | F17: =IF(F15="","",(E17+E18)) -> 5 | G17: =IF(G15="","",(F17+F18)) -> 5 | H17: =IF(H15="","",(G17+G18)) -> 5 | I17: =IF(I15="","",(H17+H18)) -> 5 | J17: =IF(J15="","",(I17+I18)) -> 5 | K17: 3 | L17: =IF(L15="","",(K17+K18)) -> 3 | M17: =IF(M15="","",(L17+L18)) -> 3 | N17: =IF(N15="","",(M17+M18)) -> 3 | O17: 2 | P17: =IF(P15="","",(O17+O18)) -> 2 | Q17: =IF(Q15="","",(P17+P18)) -> 2 | R17: 0 | S17: =IF(S15="","",(R17+R18)) -> 2 | T17: =IF(T15="","",(S17+S18)) -> 2 | U17: =IF(U15="","",(T17+T18)) -> 2 | V17: =IF(V15="","",(U17+U18)) -> 2 | W17: =IF(W15="","",(V17+V18)) -> 2 | X17: =IF(X15="","",(W17+W18)) -> 2 | Y17: 1 | Z17: =IF(Z15="","",(Y17+Y18)) -> 3 | AA17: =IF(AA15="","",(Z17+Z18)) -> 3 | AB17: =IF(AB15="","",(AA17+AA18)) -> 3 | AC17: =IF(AC15="","",(AB17+AB18)) -> 3 | AD17: =IF(AD15="","",(AC17+AC18)) -> 3 | AE17: =IF(AE15="","",(AD17+AD18)) -> 3 | AF17: 1 | AG17: =IF(AG15="","",(AF17+AF18)) | AH17: =IF(AH15="","",(AG17+AG18)) | AI17: =IF(AI15="","",(AH17+AH18)) | AJ17: =IF(AJ15="","",(AI17+AI18)) | AK17: =IF(AK15="","",(AJ17+AJ18)) | AL17: =IF(AL15="","",(AK17+AK18)) | AM17: =IF(AM15="","",(AL17+AL18)) | AN17: =IF(AN15="","",(AM17+AM18)) | ... AS17: =IF(AS15="","",(AR17+AR18))
B18: 補充 | E18: 1 | R18: 2 | Y18: 2 | AF18: 2
B19: 単価 | C19: 750 | D19: =IF(D15="","",C19) -> 750 | E19: =IF(E15="","",D19) -> 750 | F19: =IF(F15="","",E19) -> 750 | G19: =IF(G15="","",F19) -> 750 | H19: =IF(H15="","",G19) -> 750 | I19: =IF(I15="","",H19) -> 750 | J19: =IF(J15="","",I19) -> 750 | K19: =IF(K15="","",J19) -> 750 | ... AS19: =IF(AS15="","",AR19)
A20: 月間予想 | B20: 景品名 | C20: ジャグラーボタン | D20: =IF(D15="","",C20) -> ジャグラーボタン | E20: モンチッチAirPodsケース | F20: =IF(F15="","",E20) -> モンチッチAirPodsケース | G20: =IF(G15="","",F20) -> モンチッチAirPodsケース | H20: =IF(H15="","",G20) -> モンチッチAirPodsケース | I20: =IF(I15="","",H20) -> モンチッチAirPodsケース | J20: =IF(J15="","",I20) -> モンチッチAirPodsケース | K20: スンスンフェイスポーチ | L20: =IF(L15="","",K20) -> スンスンフェイスポーチ | M20: =IF(M15="","",L20) -> スンスンフェイスポーチ | N20: =IF(N15="","",M20) -> スンスンフェイスポーチ | O20: =IF(O15="","",N20) -> スンスンフェイスポーチ | P20: =IF(P15="","",O20) -> スンスンフェイスポーチ | Q20: =IF(Q15="","",P20) -> スンスンフェイスポーチ | R20: =IF(R15="","",Q20) -> スンスンフェイスポーチ | S20: =IF(S15="","",R20) -> スンスンフェイスポーチ | ... AS20: =IF(AS15="","",AR20)
A21: =AVERAGE(C22:AS22)*30*100 -> 44900 | B21: 設定
A22: =SUM(C22:AS22) -> 449 | B22: 百差 | C22: 0 | D22: =IF(D15="","",D15-C15) -> 0 | E22: =IF(E15="","",E15-D15) -> 10 | F22: =IF(F15="","",F15-E15) -> 0 | G22: =IF(G15="","",G15-F15) -> 0 | H22: =IF(H15="","",H15-G15) -> 10 | I22: =IF(I15="","",I15-H15) -> 0 | J22: =IF(J15="","",J15-I15) -> 0 | K22: =IF(K15="","",K15-J15) -> 9 | ... AS22: =IF(AS15="","",AS15-AR15)
A23: =SUM(C23:AS23) -> 12 | B23: P差 | C23: 0 | D23: =IF(D16="","",D16-C16) -> 0 | E23: =IF(E16="","",E16-D16) -> 0 | F23: =IF(F16="","",F16-E16) -> 0 | G23: =IF(G16="","",G16-F16) -> 0 | H23: =IF(H16="","",H16-G16) -> 0 | I23: =IF(I16="","",I16-H16) -> 0 | J23: =IF(J16="","",J16-I16) -> 0 | K23: =IF(K16="","",K16-J16) -> 1 | ... AS23: =IF(AS16="","",AS16-AR16)
A24: =SUM(C24:AS24) -> 8 | B24: 払出 | C24: 0 | D24: =IF(D17="","",C17+C18-D17) -> 0 | E24: =IF(E17="","",D17+D18-E17) -> 0 | F24: =IF(F17="","",E17+E18-F17) -> 0 | G24: =IF(G17="","",F17+F18-G17) -> 0 | H24: =IF(H17="","",G17+G18-H17) -> 0 | I24: =IF(I17="","",H17+H18-I17) -> 0 | J24: =IF(J17="","",I17+I18-J17) -> 0 | K24: =IF(K17="","",J17+J18-K17) -> 2 | ... AS24: =IF(AS17="","",AR17+AR18-AS17)
A25: =SUM(C25:AS25) -> 6000 | B25: 払出額 | C25: 0 | D25: =IF(D15="","",D24*D19) -> 0 | E25: =IF(E15="","",E24*E19) -> 0 | F25: =IF(F15="","",F24*F19) -> 0 | G25: =IF(G15="","",G24*G19) -> 0 | H25: =IF(H15="","",H24*H19) -> 0 | I25: =IF(I15="","",I24*I19) -> 0 | J25: =IF(J15="","",J24*J19) -> 0 | K25: =IF(K15="","",K24*K19) -> 1500 | ... AS25: =IF(AS15="","",AS24*AS19)
A26: =IF(A25="","",A25/(A22*100)) -> 0.13363029 | B26: 原価率 | D26: =IF(D25="","",IF(D25=0,"",D25/(D22*100))) | E26: =IF(E25="","",IF(E25=0,"",E25/(E22*100))) | F26: =IF(F25="","",IF(F25=0,"",F25/(F22*100))) | G26: =IF(G25="","",IF(G25=0,"",G25/(G22*100))) | H26: =IF(H25="","",IF(H25=0,"",H25/(H22*100))) | I26: =IF(I25="","",IF(I25=0,"",I25/(I22*100))) | J26: =IF(J25="","",IF(J25=0,"",J25/(J22*100))) | K26: =IF(K25="","",IF(K25=0,"",K25/(K22*100))) -> 1.6666667 | ... AS26: =IF(AS25="","",IF(AS25=0,"",AS25/(AS22*100)))
A27: 鹿屋 | B27: 100円 | C27: 4029 | D27: =IF(D3="","",C27) -> 4029 | E27: 4043 | F27: =IF(F3="","",E27) -> 4043 | G27: =IF(G3="","",F27) -> 4043 | H27: 4136 | I27: =IF(I3="","",H27) -> 4136 | J27: =IF(J3="","",I27) -> 4136 | K27: 4251 | L27: =IF(L3="","",K27) -> 4251 | M27: =IF(M3="","",L27) -> 4251 | N27: =IF(N3="","",M27) -> 4251 | O27: 4333 | P27: =IF(P3="","",O27) -> 4333 | Q27: =IF(Q3="","",P27) -> 4333 | R27: 4617 | S27: =IF(S3="","",R27) -> 4617 | T27: =IF(T3="","",S27) -> 4617 | U27: =IF(U3="","",T27) -> 4617 | V27: 4698 | W27: =IF(W3="","",V27) -> 4698 | X27: =IF(X3="","",W27) -> 4698 | Y27: 4871 | Z27: =IF(Z3="","",Y27) -> 4871 | AA27: =IF(AA3="","",Z27) -> 4871 | AB27: =IF(AB3="","",AA27) -> 4871 | AC27: 5113 | AD27: =IF(AD3="","",AC27) -> 5113 | AE27: =IF(AE3="","",AD27) -> 5113 | AF27: 5273 | AG27: =IF(AG3="","",AF27) | AH27: =IF(AH3="","",AG27) | AI27: =IF(AI3="","",AH27) | AJ27: =IF(AJ3="","",AI27) | AK27: =IF(AK3="","",AJ27) | AL27: =IF(AL3="","",AK27) | AM27: =IF(AM3="","",AL27) | AN27: =IF(AN3="","",AM27) | ... AS27: =IF(AS3="","",AR27)
A28: BUZZ＃１ | B28: プライズ | C28: 366 | D28: =IF(D3="","",C28) -> 366 | E28: 367 | F28: =IF(F3="","",E28) -> 367 | G28: =IF(G3="","",F28) -> 367 | H28: 369 | I28: =IF(I3="","",H28) -> 369 | J28: =IF(J3="","",I28) -> 369 | K28: 371 | L28: =IF(L3="","",K28) -> 371 | M28: =IF(M3="","",L28) -> 371 | N28: =IF(N3="","",M28) -> 371 | O28: 374 | P28: =IF(P3="","",O28) -> 374 | Q28: =IF(Q3="","",P28) -> 374 | R28: 375 | S28: =IF(S3="","",R28) -> 375 | T28: =IF(T3="","",S28) -> 375 | U28: =IF(U3="","",T28) -> 375 | V28: =IF(V3="","",U28) -> 375 | W28: =IF(W3="","",V28) -> 375 | X28: =IF(X3="","",W28) -> 375 | Y28: 376 | Z28: =IF(Z3="","",Y28) -> 376 | AA28: =IF(AA3="","",Z28) -> 376 | AB28: =IF(AB3="","",AA28) -> 376 | AC28: 377 | AD28: =IF(AD3="","",AC28) -> 377 | AE28: =IF(AE3="","",AD28) -> 377 | AF28: 378 | AG28: =IF(AG3="","",AF28) | AH28: =IF(AH3="","",AG28) | AI28: =IF(AI3="","",AH28) | AJ28: =IF(AJ3="","",AI28) | AK28: =IF(AK3="","",AJ28) | AL28: =IF(AL3="","",AK28) | AM28: =IF(AM3="","",AL28) | AN28: =IF(AN3="","",AM28) | ... AS28: =IF(AS3="","",AR28)
A29: 3 | B29: 投入残 | C29: 29 | D29: =IF(D27="","",(C29+C30)) -> 29 | E29: 28 | F29: =IF(F27="","",(E29+E30)) -> 9 | G29: =IF(G27="","",(F29+F30)) -> 9 | H29: 7 | I29: =IF(I27="","",(H29+H30)) -> 10 | J29: =IF(J27="","",(I29+I30)) -> 10 | K29: 8 | L29: =IF(L27="","",(K29+K30)) -> 10 | M29: =IF(M27="","",(L29+L30)) -> 10 | N29: =IF(N27="","",(M29+M30)) -> 10 | O29: 7 | P29: =IF(P27="","",(O29+O30)) -> 9 | Q29: =IF(Q27="","",(P29+P30)) -> 9 | R29: =IF(R27="","",(Q29+Q30)) -> 9 | S29: =IF(S27="","",(R29+R30)) -> 9 | T29: =IF(T27="","",(S29+S30)) -> 9 | U29: =IF(U27="","",(T29+T30)) -> 9 | V29: =IF(V27="","",(U29+U30)) -> 9 | W29: =IF(W27="","",(V29+V30)) -> 9 | X29: =IF(X27="","",(W29+W30)) -> 9 | Y29: 8 | Z29: =IF(Z27="","",(Y29+Y30)) -> 9 | AA29: =IF(AA27="","",(Z29+Z30)) -> 9 | AB29: =IF(AB27="","",(AA29+AA30)) -> 9 | AC29: 8 | AD29: =IF(AD27="","",(AC29+AC30)) -> 8 | AE29: =IF(AE27="","",(AD29+AD30)) -> 8 | AF29: 7 | AG29: =IF(AG27="","",(AF29+AF30)) | AH29: =IF(AH27="","",(AG29+AG30)) | AI29: =IF(AI27="","",(AH29+AH30)) | AJ29: =IF(AJ27="","",(AI29+AI30)) | AK29: =IF(AK27="","",(AJ29+AJ30)) | AL29: =IF(AL27="","",(AK29+AK30)) | AM29: =IF(AM27="","",(AL29+AL30)) | AN29: =IF(AN27="","",(AM29+AM30)) | ... AS29: =IF(AS27="","",(AR29+AR30))
B30: 補充 | E30: -19 | H30: 3 | K30: 2 | O30: 2 | Y30: 1 | AF30: 1
B31: 単価 | C31: 450 | D31: =IF(D27="","",C31) -> 450 | E31: =IF(E27="","",D31) -> 450 | F31: =IF(F27="","",E31) -> 450 | G31: =IF(G27="","",F31) -> 450 | H31: =IF(H27="","",G31) -> 450 | I31: =IF(I27="","",H31) -> 450 | J31: =IF(J27="","",I31) -> 450 | K31: =IF(K27="","",J31) -> 450 | ... AS31: =IF(AS27="","",AR31)
A32: 月間予想 | B32: 景品名 | C32: アングリー | D32: =IF(D27="","",C32) -> アングリー | E32: たまごっちマスコット | F32: =IF(F27="","",E32) -> たまごっちマスコット | G32: =IF(G27="","",F32) -> たまごっちマスコット | H32: =IF(H27="","",G32) -> たまごっちマスコット | I32: =IF(I27="","",H32) -> たまごっちマスコット | J32: =IF(J27="","",I32) -> たまごっちマスコット | K32: =IF(K27="","",J32) -> たまごっちマスコット | L32: =IF(L27="","",K32) -> たまごっちマスコット | M32: =IF(M27="","",L32) -> たまごっちマスコット | ... AS32: =IF(AS27="","",AR32)
A33: =AVERAGE(C34:AS34)*30*100 -> 124400 | B33: 設定
A34: =SUM(C34:AS34) -> 1244 | B34: 百差 | C34: 0 | D34: =IF(D27="","",D27-C27) -> 0 | E34: =IF(E27="","",E27-D27) -> 14 | F34: =IF(F27="","",F27-E27) -> 0 | G34: =IF(G27="","",G27-F27) -> 0 | H34: =IF(H27="","",H27-G27) -> 93 | I34: =IF(I27="","",I27-H27) -> 0 | J34: =IF(J27="","",J27-I27) -> 0 | K34: =IF(K27="","",K27-J27) -> 115 | ... AS34: =IF(AS27="","",AS27-AR27)
A35: =SUM(C35:AS35) -> 12 | B35: P差 | C35: 0 | D35: =IF(D28="","",D28-C28) -> 0 | E35: =IF(E28="","",E28-D28) -> 1 | F35: =IF(F28="","",F28-E28) -> 0 | G35: =IF(G28="","",G28-F28) -> 0 | H35: =IF(H28="","",H28-G28) -> 2 | I35: =IF(I28="","",I28-H28) -> 0 | J35: =IF(J28="","",J28-I28) -> 0 | K35: =IF(K28="","",K28-J28) -> 2 | ... AS35: =IF(AS28="","",AS28-AR28)
A36: =SUM(C36:AS36) -> 11 | B36: 払出 | C36: 0 | D36: =IF(D29="","",C29+C30-D29) -> 0 | E36: =IF(E29="","",D29+D30-E29) -> 1 | F36: =IF(F29="","",E29+E30-F29) -> 0 | G36: =IF(G29="","",F29+F30-G29) -> 0 | H36: =IF(H29="","",G29+G30-H29) -> 2 | I36: =IF(I29="","",H29+H30-I29) -> 0 | J36: =IF(J29="","",I29+I30-J29) -> 0 | K36: =IF(K29="","",J29+J30-K29) -> 2 | ... AS36: =IF(AS29="","",AR29+AR30-AS29)
A37: =SUM(C37:AS37) -> 4950 | B37: 払出額 | C37: 0 | D37: =IF(D27="","",D36*D31) -> 0 | E37: =IF(E27="","",E36*E31) -> 450 | F37: =IF(F27="","",F36*F31) -> 0 | G37: =IF(G27="","",G36*G31) -> 0 | H37: =IF(H27="","",H36*H31) -> 900 | I37: =IF(I27="","",I36*I31) -> 0 | J37: =IF(J27="","",J36*J31) -> 0 | K37: =IF(K27="","",K36*K31) -> 900 | ... AS37: =IF(AS27="","",AS36*AS31)
A38: =IF(A37="","",A37/(A34*100)) -> 0.039790997 | B38: 原価率 | D38: =IF(D37="","",IF(D37=0,"",D37/(D34*100))) | E38: =IF(E37="","",IF(E37=0,"",E37/(E34*100))) -> 0.32142857 | F38: =IF(F37="","",IF(F37=0,"",F37/(F34*100))) | G38: =IF(G37="","",IF(G37=0,"",G37/(G34*100))) | H38: =IF(H37="","",IF(H37=0,"",H37/(H34*100))) -> 0.096774194 | I38: =IF(I37="","",IF(I37=0,"",I37/(I34*100))) | J38: =IF(J37="","",IF(J37=0,"",J37/(J34*100))) | K38: =IF(K37="","",IF(K37=0,"",K37/(K34*100))) -> 0.07826087 | ... AS38: =IF(AS37="","",IF(AS37=0,"",AS37/(AS34*100)))
A39: 鹿屋 | B39: 100円 | C39: 8984 | D39: =IF(D3="","",C39) -> 8984 | E39: 9026 | F39: =IF(F3="","",E39) -> 9026 | G39: =IF(G3="","",F39) -> 9026 | H39: 9037 | I39: =IF(I3="","",H39) -> 9037 | J39: =IF(J3="","",I39) -> 9037 | K39: 9161 | L39: =IF(L3="","",K39) -> 9161 | M39: =IF(M3="","",L39) -> 9161 | N39: =IF(N3="","",M39) -> 9161 | O39: 9191 | P39: =IF(P3="","",O39) -> 9191 | Q39: =IF(Q3="","",P39) -> 9191 | R39: 9247 | S39: =IF(S3="","",R39) -> 9247 | T39: =IF(T3="","",S39) -> 9247 | U39: =IF(U3="","",T39) -> 9247 | V39: 9261 | W39: =IF(W3="","",V39) -> 9261 | X39: =IF(X3="","",W39) -> 9261 | Y39: 9379 | Z39: =IF(Z3="","",Y39) -> 9379 | AA39: =IF(AA3="","",Z39) -> 9379 | AB39: =IF(AB3="","",AA39) -> 9379 | AC39: 9398 | AD39: =IF(AD3="","",AC39) -> 9398 | AE39: =IF(AE3="","",AD39) -> 9398 | AF39: 9469 | AG39: =IF(AG3="","",AF39) | AH39: =IF(AH3="","",AG39) | AI39: =IF(AI3="","",AH39) | AJ39: =IF(AJ3="","",AI39) | AK39: =IF(AK3="","",AJ39) | AL39: =IF(AL3="","",AK39) | AM39: =IF(AM3="","",AL39) | AN39: =IF(AN3="","",AM39) | ... AS39: =IF(AS3="","",AR39)
A40: BUZZ＃１ | B40: プライズ | C40: 520 | D40: =IF(D3="","",C40) -> 520 | E40: 525 | F40: =IF(F3="","",E40) -> 525 | G40: =IF(G3="","",F40) -> 525 | H40: 526 | I40: =IF(I3="","",H40) -> 526 | J40: =IF(J3="","",I40) -> 526 | K40: 534 | L40: =IF(L3="","",K40) -> 534 | M40: =IF(M3="","",L40) -> 534 | N40: =IF(N3="","",M40) -> 534 | O40: 538 | P40: =IF(P3="","",O40) -> 538 | Q40: =IF(Q3="","",P40) -> 538 | R40: 543 | S40: =IF(S3="","",R40) -> 543 | T40: =IF(T3="","",S40) -> 543 | U40: =IF(U3="","",T40) -> 543 | V40: 547 | W40: =IF(W3="","",V40) -> 547 | X40: =IF(X3="","",W40) -> 547 | Y40: 550 | Z40: =IF(Z3="","",Y40) -> 550 | AA40: =IF(AA3="","",Z40) -> 550 | AB40: =IF(AB3="","",AA40) -> 550 | AC40: 553 | AD40: =IF(AD3="","",AC40) -> 553 | AE40: =IF(AE3="","",AD40) -> 553 | AF40: 556 | AG40: =IF(AG3="","",AF40) | AH40: =IF(AH3="","",AG40) | AI40: =IF(AI3="","",AH40) | AJ40: =IF(AJ3="","",AI40) | AK40: =IF(AK3="","",AJ40) | AL40: =IF(AL3="","",AK40) | AM40: =IF(AM3="","",AL40) | AN40: =IF(AN3="","",AM40) | ... AS40: =IF(AS3="","",AR40)
...

Sheet 都城
A1: =SUM(A57,A69,A81,A93,A9,A21,A33,A45,A201,A213,A225,A237,A105,A117,A129,A141,A153,A165,A177,A189,A249,A261) -> 1286700 | B1: 日付 | C1: 46067 | D1: =C1+1 -> 46068 | E1: =D1+1 -> 46069 | F1: =E1+1 -> 46070 | G1: =F1+1 -> 46071 | H1: =G1+1 -> 46072 | I1: =H1+1 -> 46073 | J1: =I1+1 -> 46074 | K1: =J1+1 -> 46075 | ... AS1: =AR1+1 -> 46109
B2: =SUM(C2:AO2) -> 12867 | C2: 0 | D2: =SUM(D10,D22,D34,D46,D58,D70,D82,D94,D106,D118,D130,D142,D154,D166,D178,D190,D202,D214,D226,D238) -> 0 | E2: =SUM(E10,E22,E34,E46,E58,E70,E82,E94,E106,E118,E130,E142,E154,E166,E178,E190,E202,E214,E226,E238) -> 1637 | F2: =SUM(F10,F22,F34,F46,F58,F70,F82,F94,F106,F118,F130,F142,F154,F166,F178,F190,F202,F214,F226,F238) -> 0 | G2: =SUM(G10,G22,G34,G46,G58,G70,G82,G94,G106,G118,G130,G142,G154,G166,G178,G190,G202,G214,G226,G238) -> 0 | H2: =SUM(H10,H22,H34,H46,H58,H70,H82,H94,H106,H118,H130,H142,H154,H166,H178,H190,H202,H214,H226,H238) -> 1202 | I2: =SUM(I10,I22,I34,I46,I58,I70,I82,I94,I106,I118,I130,I142,I154,I166,I178,I190,I202,I214,I226,I238) -> 0 | J2: =SUM(J10,J22,J34,J46,J58,J70,J82,J94,J106,J118,J130,J142,J154,J166,J178,J190,J202,J214,J226,J238) -> 0 | K2: =SUM(K10,K22,K34,K46,K58,K70,K82,K94,K106,K118,K130,K142,K154,K166,K178,K190,K202,K214,K226,K238) -> 1841 | ... AS2: =SUM(AS10,AS22,AS34,AS46,AS58,AS70,AS82,AS94,AS106,AS118,AS130,AS142,AS154,AS166,AS178,AS190,AS202,AS214,AS226,AS238) -> 0
A3: 都城 | B3: 100円 | C3: 3545 | D3: 3545 | E3: 3590 | F3: 3590 | G3: 3590 | H3: 3618 | I3: 3618 | J3: 3618 | K3: 3631 | L3: 3631 | M3: 3631 | N3: 3631 | O3: 3757 | P3: 3757 | Q3: 3757 | R3: 3771 | S3: 3771 | T3: 3771 | U3: 3771 | V3: 3810 | W3: 3810 | X3: 3810 | Y3: 3819 | Z3: 3819 | AA3: 3819 | AB3: 3819 | AC3: 3874 | AD3: 3874 | AE3: 3874 | AF3: 3917
A4: BUZZ＃１ | B4: プライズ | C4: 81 | D4: =IF(D3="","",C4) -> 81 | E4: 82 | F4: =IF(F3="","",E4) -> 82 | G4: =IF(G3="","",F4) -> 82 | H4: =IF(H3="","",G4) -> 82 | I4: =IF(I3="","",H4) -> 82 | J4: =IF(J3="","",I4) -> 82 | K4: =IF(K3="","",J4) -> 82 | L4: =IF(L3="","",K4) -> 82 | M4: =IF(M3="","",L4) -> 82 | N4: =IF(N3="","",M4) -> 82 | O4: 84 | P4: =IF(P3="","",O4) -> 84 | Q4: =IF(Q3="","",P4) -> 84 | R4: =IF(R3="","",Q4) -> 84 | S4: =IF(S3="","",R4) -> 84 | T4: =IF(T3="","",S4) -> 84 | U4: =IF(U3="","",T4) -> 84 | V4: 85 | W4: =IF(W3="","",V4) -> 85 | X4: =IF(X3="","",W4) -> 85 | Y4: =IF(Y3="","",X4) -> 85 | Z4: =IF(Z3="","",Y4) -> 85 | AA4: =IF(AA3="","",Z4) -> 85 | AB4: =IF(AB3="","",AA4) -> 85 | AC4: 86 | AD4: =IF(AD3="","",AC4) -> 86 | AE4: =IF(AE3="","",AD4) -> 86 | AF4: =IF(AF3="","",AE4) -> 86 | AG4: =IF(AG3="","",AF4) | AH4: =IF(AH3="","",AG4) | AI4: =IF(AI3="","",AH4) | AJ4: =IF(AJ3="","",AI4) | AK4: =IF(AK3="","",AJ4) | ... AS4: =IF(AS3="","",AR4)
A5: 1 | B5: 投入残 | C5: 4 | D5: =IF(D3="","",(C5+C6)) -> 4 | E5: =IF(E3="","",(D5+D6)) -> 4 | F5: =IF(F3="","",(E5+E6)) -> 4 | G5: =IF(G3="","",(F5+F6)) -> 4 | H5: =IF(H3="","",(G5+G6)) -> 4 | I5: =IF(I3="","",(H5+H6)) -> 4 | J5: =IF(J3="","",(I5+I6)) -> 4 | K5: =IF(K3="","",(J5+J6)) -> 4 | ... N5: =IF(N3="","",(M5+M6)) -> 4 | O5: 2 | P5: =IF(P3="","",(O5+O6)) -> 3 | Q5: =IF(Q3="","",(P5+P6)) -> 3 | R5: =IF(R3="","",(Q5+Q6)) -> 3 | S5: =IF(S3="","",(R5+R6)) -> 3 | T5: =IF(T3="","",(S5+S6)) -> 3 | U5: =IF(U3="","",(T5+T6)) -> 3 | V5: =IF(V3="","",(U5+U6)) -> 3 | W5: =IF(W3="","",(V5+V6)) -> 3 | ... AB5: =IF(AB3="","",(AA5+AA6)) -> 3 | AC5: 2 | AD5: =IF(AD3="","",(AC5+AC6)) -> 4 | AE5: =IF(AE3="","",(AD5+AD6)) -> 4 | AF5: =IF(AF3="","",(AE5+AE6)) -> 4 | AG5: =IF(AG3="","",(AF5+AF6)) | AH5: =IF(AH3="","",(AG5+AG6)) | AI5: =IF(AI3="","",(AH5+AH6)) | AJ5: =IF(AJ3="","",(AI5+AI6)) | AK5: =IF(AK3="","",(AJ5+AJ6)) | ... AS5: =IF(AS3="","",(AR5+AR6))
A6: 機械合計 | B6: 補充 | O6: 1 | AC6: 2
A7: =+(A10+A22+A34+A46)*100 -> 176500 | B7: 単価 | C7: 500 | D7: =IF(D3="","",C7) -> 500 | E7: =IF(E3="","",D7) -> 500 | F7: =IF(F3="","",E7) -> 500 | G7: =IF(G3="","",F7) -> 500 | H7: =IF(H3="","",G7) -> 500 | I7: =IF(I3="","",H7) -> 500 | J7: =IF(J3="","",I7) -> 500 | K7: =IF(K3="","",J7) -> 500 | ... AS7: =IF(AS3="","",AR7)
A8: 月間予想 | B8: 景品名 | C8: サンリオフェイスポーチ | D8: =IF(D3="","",C8) -> サンリオフェイスポーチ | E8: =IF(E3="","",D8) -> サンリオフェイスポーチ | F8: =IF(F3="","",E8) -> サンリオフェイスポーチ | G8: =IF(G3="","",F8) -> サンリオフェイスポーチ | H8: =IF(H3="","",G8) -> サンリオフェイスポーチ | I8: =IF(I3="","",H8) -> サンリオフェイスポーチ | J8: =IF(J3="","",I8) -> サンリオフェイスポーチ | K8: =IF(K3="","",J8) -> サンリオフェイスポーチ | ... AS8: =IF(AS3="","",AR8)
A9: =AVERAGE(C10:AS10)*30*100 -> 37200 | B9: 設定
A10: =SUM(C10:AS10) -> 372 | B10: 百差 | C10: 0 | D10: =IF(D3="","",D3-C3) -> 0 | E10: =IF(E3="","",E3-D3) -> 45 | F10: =IF(F3="","",F3-E3) -> 0 | G10: =IF(G3="","",G3-F3) -> 0 | H10: =IF(H3="","",H3-G3) -> 28 | I10: =IF(I3="","",I3-H3) -> 0 | J10: =IF(J3="","",J3-I3) -> 0 | K10: =IF(K3="","",K3-J3) -> 13 | ... AS10: =IF(AS3="","",AS3-AR3)
A11: =SUM(C11:AS11) -> 5 | B11: P差 | C11: 0 | D11: =IF(D4="","",D4-C4) -> 0 | E11: =IF(E4="","",E4-D4) -> 1 | F11: =IF(F4="","",F4-E4) -> 0 | G11: =IF(G4="","",G4-F4) -> 0 | H11: =IF(H4="","",H4-G4) -> 0 | I11: =IF(I4="","",I4-H4) -> 0 | J11: =IF(J4="","",J4-I4) -> 0 | K11: =IF(K4="","",K4-J4) -> 0 | ... AS11: =IF(AS4="","",AS4-AR4)
A12: =SUM(C12:AS12) -> 3 | B12: 払出 | C12: 0 | D12: =IF(D5="","",C5+C6-D5) -> 0 | E12: =IF(E5="","",D5+D6-E5) -> 0 | F12: =IF(F5="","",E5+E6-F5) -> 0 | G12: =IF(G5="","",F5+F6-G5) -> 0 | H12: =IF(H5="","",G5+G6-H5) -> 0 | I12: =IF(I5="","",H5+H6-I5) -> 0 | J12: =IF(J5="","",I5+I6-J5) -> 0 | K12: =IF(K5="","",J5+J6-K5) -> 0 | ... AS12: =IF(AS5="","",AR5+AR6-AS5)
A13: =SUM(C13:AS13) -> 1500 | B13: 払出額 | C13: 0 | D13: =IF(D3="","",D12*D7) -> 0 | E13: =IF(E3="","",E12*E7) -> 0 | F13: =IF(F3="","",F12*F7) -> 0 | G13: =IF(G3="","",G12*G7) -> 0 | H13: =IF(H3="","",H12*H7) -> 0 | I13: =IF(I3="","",I12*I7) -> 0 | J13: =IF(J3="","",J12*J7) -> 0 | K13: =IF(K3="","",K12*K7) -> 0 | ... AS13: =IF(AS3="","",AS12*AS7)
A14: =IF(A13="","",A13/(A10*100)) -> 0.040322581 | B14: 原価率 | D14: =IF(D13="","",IF(D13=0,"",D13/(D10*100))) | E14: =IF(E13="","",IF(E13=0,"",E13/(E10*100))) | F14: =IF(F13="","",IF(F13=0,"",F13/(F10*100))) | G14: =IF(G13="","",IF(G13=0,"",G13/(G10*100))) | H14: =IF(H13="","",IF(H13=0,"",H13/(H10*100))) | I14: =IF(I13="","",IF(I13=0,"",I13/(I10*100))) | J14: =IF(J13="","",IF(J13=0,"",J13/(J10*100))) | K14: =IF(K13="","",IF(K13=0,"",K13/(K10*100))) | ... AS14: =IF(AS13="","",IF(AS13=0,"",AS13/(AS10*100)))
A15: 都城 | B15: 100円 | C15: 5792 | D15: =IF(D3="","",C15) -> 5792 | E15: 5830 | F15: =IF(F3="","",E15) -> 5830 | G15: =IF(G3="","",F15) -> 5830 | H15: 5875 | I15: =IF(I3="","",H15) -> 5875 | J15: =IF(J3="","",I15) -> 5875 | K15: 5966 | L15: =IF(L3="","",K15) -> 5966 | M15: =IF(M3="","",L15) -> 5966 | N15: =IF(N3="","",M15) -> 5966 | O15: 6041 | P15: =IF(P3="","",O15) -> 6041 | Q15: =IF(Q3="","",P15) -> 6041 | R15: 6131 | S15: =IF(S3="","",R15) -> 6131 | T15: =IF(T3="","",S15) -> 6131 | U15: =IF(U3="","",T15) -> 6131 | V15: 6150 | W15: =IF(W3="","",V15) -> 6150 | X15: =IF(X3="","",W15) -> 6150 | Y15: 6230 | Z15: =IF(Z3="","",Y15) -> 6230 | AA15: =IF(AA3="","",Z15) -> 6230 | AB15: =IF(AB3="","",AA15) -> 6230 | AC15: 6317 | AD15: =IF(AD3="","",AC15) -> 6317 | AE15: =IF(AE3="","",AD15) -> 6317 | AF15: 6378 | AG15: =IF(AG3="","",AF15) | AH15: =IF(AH3="","",AG15) | AI15: =IF(AI3="","",AH15) | AJ15: =IF(AJ3="","",AI15) | AK15: =IF(AK3="","",AJ15) | AL15: =IF(AL3="","",AK15) | AM15: =IF(AM3="","",AL15) | AN15: =IF(AN3="","",AM15) | ... AS15: =IF(AS3="","",AR15)
A16: BUZZ＃１ | B16: プライズ | C16: 80 | D16: =IF(D3="","",C16) -> 80 | E16: 81 | F16: =IF(F3="","",E16) -> 81 | G16: =IF(G3="","",F16) -> 81 | H16: 82 | I16: =IF(I3="","",H16) -> 82 | J16: =IF(J3="","",I16) -> 82 | K16: 83 | L16: =IF(L3="","",K16) -> 83 | M16: =IF(M3="","",L16) -> 83 | N16: =IF(N3="","",M16) -> 83 | O16: 84 | P16: =IF(P3="","",O16) -> 84 | Q16: =IF(Q3="","",P16) -> 84 | R16: =IF(R3="","",Q16) -> 84 | S16: =IF(S3="","",R16) -> 84 | T16: =IF(T3="","",S16) -> 84 | U16: =IF(U3="","",T16) -> 84 | V16: =IF(V3="","",U16) -> 84 | W16: =IF(W3="","",V16) -> 84 | X16: =IF(X3="","",W16) -> 84 | Y16: 85 | Z16: =IF(Z3="","",Y16) -> 85 | AA16: =IF(AA3="","",Z16) -> 85 | AB16: =IF(AB3="","",AA16) -> 85 | AC16: 86 | AD16: =IF(AD3="","",AC16) -> 86 | AE16: =IF(AE3="","",AD16) -> 86 | AF16: 87 | AG16: =IF(AG3="","",AF16) | AH16: =IF(AH3="","",AG16) | AI16: =IF(AI3="","",AH16) | AJ16: =IF(AJ3="","",AI16) | AK16: =IF(AK3="","",AJ16) | AL16: =IF(AL3="","",AK16) | AM16: =IF(AM3="","",AL16) | AN16: =IF(AN3="","",AM16) | ... AS16: =IF(AS3="","",AR16)
A17: 2 | B17: 投入残 | C17: 5 | D17: =IF(D15="","",(C17+C18)) -> 5 | E17: =IF(E15="","",(D17+D18)) -> 5 | F17: =IF(F15="","",(E17+E18)) -> 5 | G17: =IF(G15="","",(F17+F18)) -> 5 | H17: 4 | I17: =IF(I15="","",(H17+H18)) -> 5 | J17: =IF(J15="","",(I17+I18)) -> 5 | K17: 4 | L17: =IF(L15="","",(K17+K18)) -> 7 | M17: =IF(M15="","",(L17+L18)) -> 7 | N17: =IF(N15="","",(M17+M18)) -> 7 | O17: 6 | P17: =IF(P15="","",(O17+O18)) -> 7 | Q17: =IF(Q15="","",(P17+P18)) -> 7 | R17: =IF(R15="","",(Q17+Q18)) -> 7 | S17: =IF(S15="","",(R17+R18)) -> 7 | T17: =IF(T15="","",(S17+S18)) -> 7 | U17: =IF(U15="","",(T17+T18)) -> 7 | V17: =IF(V15="","",(U17+U18)) -> 7 | W17: =IF(W15="","",(V17+V18)) -> 7 | ... AE17: =IF(AE15="","",(AD17+AD18)) -> 7 | AF17: 5 | AG17: =IF(AG15="","",(AF17+AF18)) | AH17: =IF(AH15="","",(AG17+AG18)) | AI17: =IF(AI15="","",(AH17+AH18)) | AJ17: =IF(AJ15="","",(AI17+AI18)) | AK17: =IF(AK15="","",(AJ17+AJ18)) | AL17: =IF(AL15="","",(AK17+AK18)) | AM17: =IF(AM15="","",(AL17+AL18)) | AN17: =IF(AN15="","",(AM17+AM18)) | ... AS17: =IF(AS15="","",(AR17+AR18))
B18: 補充 | H18: 1 | K18: 3 | O18: 1
B19: 単価 | C19: 800 | D19: =IF(D15="","",C19) -> 800 | E19: =IF(E15="","",D19) -> 800 | F19: =IF(F15="","",E19) -> 800 | G19: =IF(G15="","",F19) -> 800 | H19: =IF(H15="","",G19) -> 800 | I19: =IF(I15="","",H19) -> 800 | J19: =IF(J15="","",I19) -> 800 | K19: =IF(K15="","",J19) -> 800 | ... AS19: =IF(AS15="","",AR19)
A20: 月間予想 | B20: 景品名 | C20: ミニデジタルカメラ | D20: =IF(D15="","",C20) -> ミニデジタルカメラ | E20: =IF(E15="","",D20) -> ミニデジタルカメラ | F20: =IF(F15="","",E20) -> ミニデジタルカメラ | G20: =IF(G15="","",F20) -> ミニデジタルカメラ | H20: =IF(H15="","",G20) -> ミニデジタルカメラ | I20: =IF(I15="","",H20) -> ミニデジタルカメラ | J20: =IF(J15="","",I20) -> ミニデジタルカメラ | K20: =IF(K15="","",J20) -> ミニデジタルカメラ | ... AS20: =IF(AS15="","",AR20)
A21: =AVERAGE(C22:AS22)*30*100 -> 58600 | B21: 設定
A22: =SUM(C22:AS22) -> 586 | B22: 百差 | C22: 0 | D22: =IF(D15="","",D15-C15) -> 0 | E22: =IF(E15="","",E15-D15) -> 38 | F22: =IF(F15="","",F15-E15) -> 0 | G22: =IF(G15="","",G15-F15) -> 0 | H22: =IF(H15="","",H15-G15) -> 45 | I22: =IF(I15="","",I15-H15) -> 0 | J22: =IF(J15="","",J15-I15) -> 0 | K22: =IF(K15="","",K15-J15) -> 91 | ... AS22: =IF(AS15="","",AS15-AR15)
A23: =SUM(C23:AS23) -> 7 | B23: P差 | C23: 0 | D23: =IF(D16="","",D16-C16) -> 0 | E23: =IF(E16="","",E16-D16) -> 1 | F23: =IF(F16="","",F16-E16) -> 0 | G23: =IF(G16="","",G16-F16) -> 0 | H23: =IF(H16="","",H16-G16) -> 1 | I23: =IF(I16="","",I16-H16) -> 0 | J23: =IF(J16="","",J16-I16) -> 0 | K23: =IF(K16="","",K16-J16) -> 1 | ... AS23: =IF(AS16="","",AS16-AR16)
A24: =SUM(C24:AS24) -> 5 | B24: 払出 | C24: 0 | D24: =IF(D17="","",C17+C18-D17) -> 0 | E24: =IF(E17="","",D17+D18-E17) -> 0 | F24: =IF(F17="","",E17+E18-F17) -> 0 | G24: =IF(G17="","",F17+F18-G17) -> 0 | H24: =IF(H17="","",G17+G18-H17) -> 1 | I24: =IF(I17="","",H17+H18-I17) -> 0 | J24: =IF(J17="","",I17+I18-J17) -> 0 | K24: =IF(K17="","",J17+J18-K17) -> 1 | ... AS24: =IF(AS17="","",AR17+AR18-AS17)
A25: =SUM(C25:AS25) -> 4000 | B25: 払出額 | C25: 0 | D25: =IF(D15="","",D24*D19) -> 0 | E25: =IF(E15="","",E24*E19) -> 0 | F25: =IF(F15="","",F24*F19) -> 0 | G25: =IF(G15="","",G24*G19) -> 0 | H25: =IF(H15="","",H24*H19) -> 800 | I25: =IF(I15="","",I24*I19) -> 0 | J25: =IF(J15="","",J24*J19) -> 0 | K25: =IF(K15="","",K24*K19) -> 800 | ... AS25: =IF(AS15="","",AS24*AS19)
A26: =IF(A25="","",A25/(A22*100)) -> 0.068259386 | B26: 原価率 | D26: =IF(D25="","",IF(D25=0,"",D25/(D22*100))) | E26: =IF(E25="","",IF(E25=0,"",E25/(E22*100))) | F26: =IF(F25="","",IF(F25=0,"",F25/(F22*100))) | G26: =IF(G25="","",IF(G25=0,"",G25/(G22*100))) | H26: =IF(H25="","",IF(H25=0,"",H25/(H22*100))) -> 0.17777778 | I26: =IF(I25="","",IF(I25=0,"",I25/(I22*100))) | J26: =IF(J25="","",IF(J25=0,"",J25/(J22*100))) | K26: =IF(K25="","",IF(K25=0,"",K25/(K22*100))) -> 0.087912088 | ... AS26: =IF(AS25="","",IF(AS25=0,"",AS25/(AS22*100)))
A27: 都城 | B27: 100円 | C27: 6425 | D27: =IF(D3="","",C27) -> 6425 | E27: 6514 | F27: =IF(F3="","",E27) -> 6514 | G27: =IF(G3="","",F27) -> 6514 | H27: 6531 | I27: =IF(I3="","",H27) -> 6531 | J27: =IF(J3="","",I27) -> 6531 | K27: 6601 | L27: =IF(L3="","",K27) -> 6601 | M27: =IF(M3="","",L27) -> 6601 | N27: =IF(N3="","",M27) -> 6601 | O27: 6627 | P27: =IF(P3="","",O27) -> 6627 | Q27: =IF(Q3="","",P27) -> 6627 | R27: 6719 | S27: =IF(S3="","",R27) -> 6719 | T27: =IF(T3="","",S27) -> 6719 | U27: =IF(U3="","",T27) -> 6719 | V27: 6773 | W27: =IF(W3="","",V27) -> 6773 | X27: =IF(X3="","",W27) -> 6773 | Y27: 6803 | Z27: =IF(Z3="","",Y27) -> 6803 | AA27: =IF(AA3="","",Z27) -> 6803 | AB27: =IF(AB3="","",AA27) -> 6803 | AC27: 6840 | AD27: =IF(AD3="","",AC27) -> 6840 | AE27: =IF(AE3="","",AD27) -> 6840 | AF27: 6908 | AG27: =IF(AG3="","",AF27) | AH27: =IF(AH3="","",AG27) | AI27: =IF(AI3="","",AH27) | AJ27: =IF(AJ3="","",AI27) | AK27: =IF(AK3="","",AJ27) | AL27: =IF(AL3="","",AK27) | AM27: =IF(AM3="","",AL27) | AN27: =IF(AN3="","",AM27) | ... AS27: =IF(AS3="","",AR27)
A28: BUZZ＃１ | B28: プライズ | C28: 236 | D28: =IF(D3="","",C28) -> 236 | E28: 237 | F28: =IF(F3="","",E28) -> 237 | G28: =IF(G3="","",F28) -> 237 | H28: =IF(H3="","",G28) -> 237 | I28: =IF(I3="","",H28) -> 237 | J28: =IF(J3="","",I28) -> 237 | K28: 238 | L28: =IF(L3="","",K28) -> 238 | M28: =IF(M3="","",L28) -> 238 | N28: =IF(N3="","",M28) -> 238 | O28: =IF(O3="","",N28) -> 238 | P28: =IF(P3="","",O28) -> 238 | Q28: =IF(Q3="","",P28) -> 238 | R28: 240 | S28: =IF(S3="","",R28) -> 240 | T28: =IF(T3="","",S28) -> 240 | U28: =IF(U3="","",T28) -> 240 | V28: =IF(V3="","",U28) -> 240 | W28: =IF(W3="","",V28) -> 240 | X28: =IF(X3="","",W28) -> 240 | Y28: 241 | Z28: =IF(Z3="","",Y28) -> 241 | AA28: =IF(AA3="","",Z28) -> 241 | AB28: =IF(AB3="","",AA28) -> 241 | AC28: =IF(AC3="","",AB28) -> 241 | AD28: =IF(AD3="","",AC28) -> 241 | AE28: =IF(AE3="","",AD28) -> 241 | AF28: 242 | AG28: =IF(AG3="","",AF28) | AH28: =IF(AH3="","",AG28) | AI28: =IF(AI3="","",AH28) | AJ28: =IF(AJ3="","",AI28) | AK28: =IF(AK3="","",AJ28) | AL28: =IF(AL3="","",AK28) | AM28: =IF(AM3="","",AL28) | AN28: =IF(AN3="","",AM28) | ... AS28: =IF(AS3="","",AR28)
A29: 3 | B29: 投入残 | C29: 11 | D29: =IF(D27="","",(C29+C30)) -> 11 | E29: 10 | F29: =IF(F27="","",(E29+E30)) -> 10 | G29: =IF(G27="","",(F29+F30)) -> 10 | H29: =IF(H27="","",(G29+G30)) -> 10 | I29: =IF(I27="","",(H29+H30)) -> 10 | J29: =IF(J27="","",(I29+I30)) -> 10 | K29: 9 | L29: =IF(L27="","",(K29+K30)) -> 9 | M29: =IF(M27="","",(L29+L30)) -> 9 | N29: =IF(N27="","",(M29+M30)) -> 9 | O29: =IF(O27="","",(N29+N30)) -> 9 | P29: =IF(P27="","",(O29+O30)) -> 9 | Q29: =IF(Q27="","",(P29+P30)) -> 9 | R29: 7 | S29: =IF(S27="","",(R29+R30)) -> 7 | T29: =IF(T27="","",(S29+S30)) -> 7 | U29: =IF(U27="","",(T29+T30)) -> 7 | V29: =IF(V27="","",(U29+U30)) -> 7 | W29: =IF(W27="","",(V29+V30)) -> 8 | X29: =IF(X27="","",(W29+W30)) -> 8 | Y29: =IF(Y27="","",(X29+X30)) -> 8 | Z29: =IF(Z27="","",(Y29+Y30)) -> 8 | ... AE29: =IF(AE27="","",(AD29+AD30)) -> 9 | AF29: 8 | AG29: =IF(AG27="","",(AF29+AF30)) | AH29: =IF(AH27="","",(AG29+AG30)) | AI29: =IF(AI27="","",(AH29+AH30)) | AJ29: =IF(AJ27="","",(AI29+AI30)) | AK29: =IF(AK27="","",(AJ29+AJ30)) | AL29: =IF(AL27="","",(AK29+AK30)) | AM29: =IF(AM27="","",(AL29+AL30)) | AN29: =IF(AN27="","",(AM29+AM30)) | ... AS29: =IF(AS27="","",(AR29+AR30))
B30: 補充 | V30: 1 | AC30: 1
B31: 単価 | C31: 175 | D31: =IF(D27="","",C31) -> 175 | E31: =IF(E27="","",D31) -> 175 | F31: =IF(F27="","",E31) -> 175 | G31: =IF(G27="","",F31) -> 175 | H31: =IF(H27="","",G31) -> 175 | I31: =IF(I27="","",H31) -> 175 | J31: =IF(J27="","",I31) -> 175 | K31: =IF(K27="","",J31) -> 175 | ... AS31: =IF(AS27="","",AR31)
A32: 月間予想 | B32: 景品名 | C32: スライム | D32: =IF(D27="","",C32) -> スライム | E32: =IF(E27="","",D32) -> スライム | F32: =IF(F27="","",E32) -> スライム | G32: =IF(G27="","",F32) -> スライム | H32: =IF(H27="","",G32) -> スライム | I32: =IF(I27="","",H32) -> スライム | J32: =IF(J27="","",I32) -> スライム | K32: =IF(K27="","",J32) -> スライム | ... AS32: =IF(AS27="","",AR32)
A33: =AVERAGE(C34:AS34)*30*100 -> 48300 | B33: 設定
A34: =SUM(C34:AS34) -> 483 | B34: 百差 | C34: 0 | D34: =IF(D27="","",D27-C27) -> 0 | E34: =IF(E27="","",E27-D27) -> 89 | F34: =IF(F27="","",F27-E27) -> 0 | G34: =IF(G27="","",G27-F27) -> 0 | H34: =IF(H27="","",H27-G27) -> 17 | I34: =IF(I27="","",I27-H27) -> 0 | J34: =IF(J27="","",J27-I27) -> 0 | K34: =IF(K27="","",K27-J27) -> 70 | ... AS34: =IF(AS27="","",AS27-AR27)
A35: =SUM(C35:AS35) -> 6 | B35: P差 | C35: 0 | D35: =IF(D28="","",D28-C28) -> 0 | E35: =IF(E28="","",E28-D28) -> 1 | F35: =IF(F28="","",F28-E28) -> 0 | G35: =IF(G28="","",G28-F28) -> 0 | H35: =IF(H28="","",H28-G28) -> 0 | I35: =IF(I28="","",I28-H28) -> 0 | J35: =IF(J28="","",J28-I28) -> 0 | K35: =IF(K28="","",K28-J28) -> 1 | ... AS35: =IF(AS28="","",AS28-AR28)
A36: =SUM(C36:AS36) -> 5 | B36: 払出 | C36: 0 | D36: =IF(D29="","",C29+C30-D29) -> 0 | E36: =IF(E29="","",D29+D30-E29) -> 1 | F36: =IF(F29="","",E29+E30-F29) -> 0 | G36: =IF(G29="","",F29+F30-G29) -> 0 | H36: =IF(H29="","",G29+G30-H29) -> 0 | I36: =IF(I29="","",H29+H30-I29) -> 0 | J36: =IF(J29="","",I29+I30-J29) -> 0 | K36: =IF(K29="","",J29+J30-K29) -> 1 | ... AS36: =IF(AS29="","",AR29+AR30-AS29)
A37: =SUM(C37:AS37) -> 875 | B37: 払出額 | C37: 0 | D37: =IF(D27="","",D36*D31) -> 0 | E37: =IF(E27="","",E36*E31) -> 175 | F37: =IF(F27="","",F36*F31) -> 0 | G37: =IF(G27="","",G36*G31) -> 0 | H37: =IF(H27="","",H36*H31) -> 0 | I37: =IF(I27="","",I36*I31) -> 0 | J37: =IF(J27="","",J36*J31) -> 0 | K37: =IF(K27="","",K36*K31) -> 175 | ... AS37: =IF(AS27="","",AS36*AS31)
A38: =IF(A37="","",A37/(A34*100)) -> 0.018115942 | B38: 原価率 | D38: =IF(D37="","",IF(D37=0,"",D37/(D34*100))) | E38: =IF(E37="","",IF(E37=0,"",E37/(E34*100))) -> 0.019662921 | F38: =IF(F37="","",IF(F37=0,"",F37/(F34*100))) | G38: =IF(G37="","",IF(G37=0,"",G37/(G34*100))) | H38: =IF(H37="","",IF(H37=0,"",H37/(H34*100))) | I38: =IF(I37="","",IF(I37=0,"",I37/(I34*100))) | J38: =IF(J37="","",IF(J37=0,"",J37/(J34*100))) | K38: =IF(K37="","",IF(K37=0,"",K37/(K34*100))) -> 0.025 | ... AS38: =IF(AS37="","",IF(AS37=0,"",AS37/(AS34*100)))
A39: 都城 | B39: 100円 | C39: 3171 | D39: =IF(D3="","",C39) -> 3171 | E39: 3209 | F39: =IF(F3="","",E39) -> 3209 | G39: =IF(G3="","",F39) -> 3209 | H39: 3214 | I39: =IF(I3="","",H39) -> 3214 | J39: =IF(J3="","",I39) -> 3214 | K39: 3244 | L39: =IF(L3="","",K39) -> 3244 | M39: =IF(M3="","",L39) -> 3244 | N39: =IF(N3="","",M39) -> 3244 | O39: 3268 | P39: =IF(P3="","",O39) -> 3268 | Q39: =IF(Q3="","",P39) -> 3268 | R39: 3351 | S39: =IF(S3="","",R39) -> 3351 | T39: =IF(T3="","",S39) -> 3351 | U39: =IF(U3="","",T39) -> 3351 | V39: 3386 | W39: =IF(W3="","",V39) -> 3386 | X39: =IF(X3="","",W39) -> 3386 | Y39: 3413 | Z39: =IF(Z3="","",Y39) -> 3413 | AA39: =IF(AA3="","",Z39) -> 3413 | AB39: =IF(AB3="","",AA39) -> 3413 | AC39: 3452 | AD39: =IF(AD3="","",AC39) -> 3452 | AE39: =IF(AE3="","",AD39) -> 3452 | AF39: 3495 | AG39: =IF(AG3="","",AF39) | AH39: =IF(AH3="","",AG39) | AI39: =IF(AI3="","",AH39) | AJ39: =IF(AJ3="","",AI39) | AK39: =IF(AK3="","",AJ39) | AL39: =IF(AL3="","",AK39) | AM39: =IF(AM3="","",AL39) | AN39: =IF(AN3="","",AM39) | ... AS39: =IF(AS3="","",AR39)
A40: BUZZ＃１ | B40: プライズ | C40: 61 | D40: =IF(D3="","",C40) -> 61 | E40: 64 | F40: =IF(F3="","",E40) -> 64 | G40: =IF(G3="","",F40) -> 64 | H40: =IF(H3="","",G40) -> 64 | I40: =IF(I3="","",H40) -> 64 | J40: =IF(J3="","",I40) -> 64 | K40: 65 | L40: =IF(L3="","",K40) -> 65 | M40: =IF(M3="","",L40) -> 65 | N40: =IF(N3="","",M40) -> 65 | O40: 66 | P40: =IF(P3="","",O40) -> 66 | Q40: =IF(Q3="","",P40) -> 66 | R40: 67 | S40: =IF(S3="","",R40) -> 67 | T40: =IF(T3="","",S40) -> 67 | U40: =IF(U3="","",T40) -> 67 | V40: 68 | W40: =IF(W3="","",V40) -> 68 | X40: =IF(X3="","",W40) -> 68 | Y40: 69 | Z40: =IF(Z3="","",Y40) -> 69 | AA40: =IF(AA3="","",Z40) -> 69 | AB40: =IF(AB3="","",AA40) -> 69 | AC40: 70 | AD40: =IF(AD3="","",AC40) -> 70 | AE40: =IF(AE3="","",AD40) -> 70 | AF40: 73 | AG40: =IF(AG3="","",AF40) | AH40: =IF(AH3="","",AG40) | AI40: =IF(AI3="","",AH40) | AJ40: =IF(AJ3="","",AI40) | AK40: =IF(AK3="","",AJ40) | AL40: =IF(AL3="","",AK40) | AM40: =IF(AM3="","",AL40) | AN40: =IF(AN3="","",AM40) | ... AS40: =IF(AS3="","",AR40)
...

Sheet 霧島
A1: =SUM(A9,A45,A57,A69,A81,A93,A105,A117,A129,A153,A141,A165,A177,A189,A201,A213,A225,A33,A21,A237,A249) -> 1211709.7 | B1: 日付 | C1: 46066 | D1: =C1+1 -> 46067 | E1: =D1+1 -> 46068 | F1: =E1+1 -> 46069 | G1: =F1+1 -> 46070 | H1: =G1+1 -> 46071 | I1: =H1+1 -> 46072 | J1: =I1+1 -> 46073 | K1: =J1+1 -> 46074 | ... AS1: =AR1+1 -> 46108
B2: =SUM(C2:AO2) -> 12521 | C2: 0 | D2: =SUM(D10,D250,D238,D22,D34,D226,D214,D202,D190,D178,D166,D154,D142,D130,D118,,D106,D94,D82,D70,D58,D46) -> 0 | E2: =SUM(E10,E250,E238,E22,E34,E226,E214,E202,E190,E178,E166,E154,E142,E130,E118,,E106,E94,E82,E70,E58,E46) -> 0 | F2: =SUM(F10,F250,F238,F22,F34,F226,F214,F202,F190,F178,F166,F154,F142,F130,F118,,F106,F94,F82,F70,F58,F46) -> 1684 | G2: =SUM(G10,G250,G238,G22,G34,G226,G214,G202,G190,G178,G166,G154,G142,G130,G118,,G106,G94,G82,G70,G58,G46) -> 0 | H2: =SUM(H10,H250,H238,H22,H34,H226,H214,H202,H190,H178,H166,H154,H142,H130,H118,,H106,H94,H82,H70,H58,H46) -> 0 | I2: =SUM(I10,I250,I238,I22,I34,I226,I214,I202,I190,I178,I166,I154,I142,I130,I118,,I106,I94,I82,I70,I58,I46) -> 1003 | J2: =SUM(J10,J250,J238,J22,J34,J226,J214,J202,J190,J178,J166,J154,J142,J130,J118,,J106,J94,J82,J70,J58,J46) -> 0 | K2: =SUM(K10,K250,K238,K22,K34,K226,K214,K202,K190,K178,K166,K154,K142,K130,K118,,K106,K94,K82,K70,K58,K46) -> 0 | ... AS2: =SUM(AS10,AS250,AS238,AS22,AS34,AS226,AS214,AS202,AS190,AS178,AS166,AS154,AS142,AS130,AS118,,AS106,AS94,AS82,AS70,AS58,AS46) -> 0
A3: 霧島 | B3: 100円 | C3: 21752 | D3: 21752 | E3: 21752 | F3: 21846 | G3: 21846 | H3: 21846 | I3: 21903 | J3: 21903 | K3: 21903 | L3: 22061 | M3: 22061 | N3: 22061 | O3: 22061 | P3: 22096 | Q3: 22096 | R3: 22096 | S3: 22229 | T3: 22229 | U3: 22229 | V3: 22229 | W3: 22279 | X3: 22279 | Y3: 22279 | Z3: 22361 | AA3: 22361 | AB3: 22361 | AC3: 22361 | AD3: 22456 | AE3: 22456 | AF3: 22456 | AG3: 22531
A4: BUZZミニ | B4: プライズ | C4: 349 | D4: =IF(D$3="","",C4) -> 349 | E4: =IF(E$3="","",D4) -> 349 | F4: 350 | G4: =IF(G$3="","",F4) -> 350 | H4: =IF(H$3="","",G4) -> 350 | I4: 352 | J4: =IF(J$3="","",I4) -> 352 | K4: =IF(K$3="","",J4) -> 352 | L4: 357 | M4: =IF(M$3="","",L4) -> 357 | N4: =IF(N$3="","",M4) -> 357 | O4: =IF(O$3="","",N4) -> 357 | P4: =IF(P$3="","",O4) -> 357 | Q4: =IF(Q$3="","",P4) -> 357 | R4: =IF(R$3="","",Q4) -> 357 | S4: 360 | T4: =IF(T$3="","",S4) -> 360 | U4: =IF(U$3="","",T4) -> 360 | V4: =IF(V$3="","",U4) -> 360 | W4: 363 | X4: =IF(X$3="","",W4) -> 363 | Y4: =IF(Y$3="","",X4) -> 363 | Z4: 364 | AA4: =IF(AA$3="","",Z4) -> 364 | AB4: =IF(AB$3="","",AA4) -> 364 | AC4: =IF(AC$3="","",AB4) -> 364 | AD4: 365 | AE4: =IF(AE$3="","",AD4) -> 365 | AF4: =IF(AF$3="","",AE4) -> 365 | AG4: 366 | AH4: =IF(AH$3="","",AG4) | AI4: =IF(AI$3="","",AH4) | AJ4: =IF(AJ$3="","",AI4) | AK4: =IF(AK$3="","",AJ4) | AL4: =IF(AL$3="","",AK4) | AM4: =IF(AM$3="","",AL4) | AN4: =IF(AN$3="","",AM4) | AO4: =IF(AO$3="","",AN4) | ... AS4: =IF(AS$3="","",AR4)
B5: 投入残 | C5: 19 | D5: =IF(D3="","",(C5+C6)) -> 19 | E5: =IF(E3="","",(D5+D6)) -> 19 | F5: 18 | G5: =IF(G3="","",(F5+F6)) -> 18 | H5: =IF(H3="","",(G5+G6)) -> 18 | I5: 16 | J5: =IF(J3="","",(I5+I6)) -> 20 | K5: =IF(K3="","",(J5+J6)) -> 20 | L5: 15 | M5: =IF(M3="","",(L5+L6)) -> 21 | N5: =IF(N3="","",(M5+M6)) -> 21 | O5: =IF(O3="","",(N5+N6)) -> 21 | P5: =IF(P3="","",(O5+O6)) -> 21 | Q5: =IF(Q3="","",(P5+P6)) -> 34 | R5: =IF(R3="","",(Q5+Q6)) -> 34 | S5: 31 | T5: =IF(T3="","",(S5+S6)) -> 31 | U5: =IF(U3="","",(T5+T6)) -> 31 | V5: =IF(V3="","",(U5+U6)) -> 31 | W5: 28 | X5: =IF(X3="","",(W5+W6)) -> 28 | Y5: =IF(Y3="","",(X5+X6)) -> 28 | Z5: 27 | AA5: =IF(AA3="","",(Z5+Z6)) -> 27 | AB5: =IF(AB3="","",(AA5+AA6)) -> 27 | AC5: =IF(AC3="","",(AB5+AB6)) -> 27 | AD5: 26 | AE5: =IF(AE3="","",(AD5+AD6)) -> 26 | AF5: =IF(AF3="","",(AE5+AE6)) -> 26 | AG5: 25 | AH5: =IF(AH3="","",(AG5+AG6)) | AI5: =IF(AI3="","",(AH5+AH6)) | AJ5: =IF(AJ3="","",(AI5+AI6)) | AK5: =IF(AK3="","",(AJ5+AJ6)) | AL5: =IF(AL3="","",(AK5+AK6)) | AM5: =IF(AM3="","",(AL5+AL6)) | AN5: =IF(AN3="","",(AM5+AM6)) | AO5: =IF(AO3="","",(AN5+AN6)) | ... AS5: =IF(AS3="","",(AR5+AR6))
B6: 補充 | I6: 4 | L6: 6 | P6: 13
B7: 単価 | C7: 715 | D7: =IF(D3="","",C7) -> 715 | E7: =IF(E3="","",D7) -> 715 | F7: =IF(F3="","",E7) -> 715 | G7: =IF(G3="","",F7) -> 715 | H7: =IF(H3="","",G7) -> 715 | I7: =IF(I3="","",H7) -> 715 | J7: =IF(J3="","",I7) -> 715 | K7: =IF(K3="","",J7) -> 715 | ... AS7: =IF(AS3="","",AR7)
A8: 月間予想 | B8: 景品名 | C8: サムエル（箱無し） | D8: =IF(D3="","",C8) -> サムエル（箱無し） | E8: =IF(E3="","",D8) -> サムエル（箱無し） | F8: =IF(F3="","",E8) -> サムエル（箱無し） | G8: =IF(G3="","",F8) -> サムエル（箱無し） | H8: =IF(H3="","",G8) -> サムエル（箱無し） | I8: =IF(I3="","",H8) -> サムエル（箱無し） | J8: =IF(J3="","",I8) -> サムエル（箱無し） | K8: =IF(K3="","",J8) -> サムエル（箱無し） | ... AS8: =IF(AS3="","",AR8)
A9: =AVERAGE(C10:AS10)*30*100 -> 75387.097 | B9: 設定
A10: =SUM(C10:AS10) -> 779 | B10: 百差 | C10: 0 | D10: =IF(D3="","",D3-C3) -> 0 | E10: =IF(E3="","",E3-D3) -> 0 | F10: =IF(F3="","",F3-E3) -> 94 | G10: =IF(G3="","",G3-F3) -> 0 | H10: =IF(H3="","",H3-G3) -> 0 | I10: =IF(I3="","",I3-H3) -> 57 | J10: =IF(J3="","",J3-I3) -> 0 | K10: =IF(K3="","",K3-J3) -> 0 | ... AS10: =IF(AS3="","",AS3-AR3)
A11: =SUM(C11:AS11) -> 17 | B11: P差 | C11: 0 | D11: =IF(D4="","",D4-C4) -> 0 | E11: =IF(E4="","",E4-D4) -> 0 | F11: =IF(F4="","",F4-E4) -> 1 | G11: =IF(G4="","",G4-F4) -> 0 | H11: =IF(H4="","",H4-G4) -> 0 | I11: =IF(I4="","",I4-H4) -> 2 | J11: =IF(J4="","",J4-I4) -> 0 | K11: =IF(K4="","",K4-J4) -> 0 | ... AS11: =IF(AS4="","",AS4-AR4)
A12: =SUM(C12:AS12) -> 17 | B12: 払出 | C12: 0 | D12: =IF(D5="","",C5+C6-D5) -> 0 | E12: =IF(E5="","",D5+D6-E5) -> 0 | F12: =IF(F5="","",E5+E6-F5) -> 1 | G12: =IF(G5="","",F5+F6-G5) -> 0 | H12: =IF(H5="","",G5+G6-H5) -> 0 | I12: =IF(I5="","",H5+H6-I5) -> 2 | J12: =IF(J5="","",I5+I6-J5) -> 0 | K12: =IF(K5="","",J5+J6-K5) -> 0 | ... AS12: =IF(AS5="","",AR5+AR6-AS5)
A13: =SUM(C13:AS13) -> 12155 | B13: 払出額 | C13: 0 | D13: =IF(D3="","",D12*D7) -> 0 | E13: =IF(E3="","",E12*E7) -> 0 | F13: =IF(F3="","",F12*F7) -> 715 | G13: =IF(G3="","",G12*G7) -> 0 | H13: =IF(H3="","",H12*H7) -> 0 | I13: =IF(I3="","",I12*I7) -> 1430 | J13: =IF(J3="","",J12*J7) -> 0 | K13: =IF(K3="","",K12*K7) -> 0 | ... AS13: =IF(AS3="","",AS12*AS7)
A14: =IF(A13="","",A13/(A10*100)) -> 0.15603338 | B14: 原価率 | D14: =IF(D13="","",IF(D13=0,"",D13/(D10*100))) | E14: =IF(E13="","",IF(E13=0,"",E13/(E10*100))) | F14: =IF(F13="","",IF(F13=0,"",F13/(F10*100))) -> 0.07606383 | G14: =IF(G13="","",IF(G13=0,"",G13/(G10*100))) | H14: =IF(H13="","",IF(H13=0,"",H13/(H10*100))) | I14: =IF(I13="","",IF(I13=0,"",I13/(I10*100))) -> 0.25087719 | J14: =IF(J13="","",IF(J13=0,"",J13/(J10*100))) | K14: =IF(K13="","",IF(K13=0,"",K13/(K10*100))) | ... AS14: =IF(AS13="","",IF(AS13=0,"",AS13/(AS10*100)))
A15: 霧島 | B15: 100円 | C15: 16914 | D15: =IF(D$3="","",C15) -> 16914 | E15: =IF(E$3="","",D15) -> 16914 | F15: 17070 | G15: =IF(G$3="","",F15) -> 17070 | H15: =IF(H$3="","",G15) -> 17070 | I15: 17167 | J15: =IF(J$3="","",I15) -> 17167 | K15: =IF(K$3="","",J15) -> 17167 | L15: 17303 | M15: =IF(M$3="","",L15) -> 17303 | N15: =IF(N$3="","",M15) -> 17303 | O15: =IF(O$3="","",N15) -> 17303 | P15: 17391 | Q15: =IF(Q$3="","",P15) -> 17391 | R15: =IF(R$3="","",Q15) -> 17391 | S15: 17451 | T15: =IF(T$3="","",S15) -> 17451 | U15: =IF(U$3="","",T15) -> 17451 | V15: =IF(V$3="","",U15) -> 17451 | W15: 17497 | X15: =IF(X$3="","",W15) -> 17497 | Y15: =IF(Y$3="","",X15) -> 17497 | Z15: 17590 | AA15: =IF(AA$3="","",Z15) -> 17590 | AB15: =IF(AB$3="","",AA15) -> 17590 | AC15: =IF(AC$3="","",AB15) -> 17590 | AD15: 17664 | AE15: =IF(AE$3="","",AD15) -> 17664 | AF15: =IF(AF$3="","",AE15) -> 17664 | AG15: 17736 | AH15: =IF(AH$3="","",AG15) | AI15: =IF(AI$3="","",AH15) | AJ15: =IF(AJ$3="","",AI15) | AK15: =IF(AK$3="","",AJ15) | AL15: =IF(AL$3="","",AK15) | AM15: =IF(AM$3="","",AL15) | AN15: =IF(AN$3="","",AM15) | AO15: =IF(AO$3="","",AN15) | ... AS15: =IF(AS$3="","",AR15)
A16: BUZZミニ#2 | B16: プライズ | C16: 428 | D16: =IF(D$3="","",C16) -> 428 | E16: =IF(E$3="","",D16) -> 428 | F16: 431 | G16: =IF(G$3="","",F16) -> 431 | H16: =IF(H$3="","",G16) -> 431 | I16: 432 | J16: =IF(J$3="","",I16) -> 432 | K16: =IF(K$3="","",J16) -> 432 | L16: 434 | M16: =IF(M$3="","",L16) -> 434 | N16: =IF(N$3="","",M16) -> 434 | O16: =IF(O$3="","",N16) -> 434 | P16: 437 | Q16: =IF(Q$3="","",P16) -> 437 | R16: =IF(R$3="","",Q16) -> 437 | S16: =IF(S$3="","",R16) -> 437 | T16: =IF(T$3="","",S16) -> 437 | U16: =IF(U$3="","",T16) -> 437 | V16: =IF(V$3="","",U16) -> 437 | W16: 438 | X16: =IF(X$3="","",W16) -> 438 | Y16: =IF(Y$3="","",X16) -> 438 | Z16: 439 | AA16: =IF(AA$3="","",Z16) -> 439 | AB16: =IF(AB$3="","",AA16) -> 439 | AC16: =IF(AC$3="","",AB16) -> 439 | AD16: 441 | AE16: =IF(AE$3="","",AD16) -> 441 | AF16: =IF(AF$3="","",AE16) -> 441 | AG16: 442 | AH16: =IF(AH$3="","",AG16) | AI16: =IF(AI$3="","",AH16) | AJ16: =IF(AJ$3="","",AI16) | AK16: =IF(AK$3="","",AJ16) | AL16: =IF(AL$3="","",AK16) | AM16: =IF(AM$3="","",AL16) | AN16: =IF(AN$3="","",AM16) | AO16: =IF(AO$3="","",AN16) | ... AS16: =IF(AS$3="","",AR16)
B17: 投入残 | C17: 47 | D17: =IF(D15="","",(C17+C18)) -> 47 | E17: =IF(E15="","",(D17+D18)) -> 47 | F17: 44 | G17: =IF(G15="","",(F17+F18)) -> 44 | H17: =IF(H15="","",(G17+G18)) -> 44 | I17: 43 | J17: =IF(J15="","",(I17+I18)) -> 43 | K17: =IF(K15="","",(J17+J18)) -> 43 | L17: 41 | M17: =IF(M15="","",(L17+L18)) -> 41 | N17: =IF(N15="","",(M17+M18)) -> 41 | O17: =IF(O15="","",(N17+N18)) -> 41 | P17: 38 | Q17: =IF(Q15="","",(P17+P18)) -> 38 | R17: =IF(R15="","",(Q17+Q18)) -> 38 | S17: =IF(S15="","",(R17+R18)) -> 38 | T17: =IF(T15="","",(S17+S18)) -> 39 | U17: =IF(U15="","",(T17+T18)) -> 39 | V17: =IF(V15="","",(U17+U18)) -> 39 | W17: 38 | X17: =IF(X15="","",(W17+W18)) -> 38 | Y17: =IF(Y15="","",(X17+X18)) -> 38 | Z17: 37 | AA17: =IF(AA15="","",(Z17+Z18)) -> 37 | AB17: =IF(AB15="","",(AA17+AA18)) -> 37 | AC17: =IF(AC15="","",(AB17+AB18)) -> 37 | AD17: 35 | AE17: =IF(AE15="","",(AD17+AD18)) -> 35 | AF17: =IF(AF15="","",(AE17+AE18)) -> 35 | AG17: 34 | AH17: =IF(AH15="","",(AG17+AG18)) | AI17: =IF(AI15="","",(AH17+AH18)) | AJ17: =IF(AJ15="","",(AI17+AI18)) | AK17: =IF(AK15="","",(AJ17+AJ18)) | AL17: =IF(AL15="","",(AK17+AK18)) | AM17: =IF(AM15="","",(AL17+AL18)) | AN17: =IF(AN15="","",(AM17+AM18)) | AO17: =IF(AO15="","",(AN17+AN18)) | ... AS17: =IF(AS15="","",(AR17+AR18))
B18: 補充 | S18: 1
B19: 単価 | C19: 700 | D19: =IF(D15="","",C19) -> 700 | E19: =IF(E15="","",D19) -> 700 | F19: =IF(F15="","",E19) -> 700 | G19: =IF(G15="","",F19) -> 700 | H19: =IF(H15="","",G19) -> 700 | I19: =IF(I15="","",H19) -> 700 | J19: =IF(J15="","",I19) -> 700 | K19: =IF(K15="","",J19) -> 700 | ... AS19: =IF(AS15="","",AR19)
A20: 月間予想 | B20: 景品名 | C20: サンリオマスコット | D20: =IF(D15="","",C20) -> サンリオマスコット | E20: =IF(E15="","",D20) -> サンリオマスコット | F20: =IF(F15="","",E20) -> サンリオマスコット | G20: =IF(G15="","",F20) -> サンリオマスコット | H20: =IF(H15="","",G20) -> サンリオマスコット | I20: =IF(I15="","",H20) -> サンリオマスコット | J20: =IF(J15="","",I20) -> サンリオマスコット | K20: =IF(K15="","",J20) -> サンリオマスコット | ... AS20: =IF(AS15="","",AR20)
A21: =AVERAGE(C22:AS22)*30*100 -> 79548.387 | B21: 設定
A22: =SUM(C22:AS22) -> 822 | B22: 百差 | C22: 0 | D22: =IF(D15="","",D15-C15) -> 0 | E22: =IF(E15="","",E15-D15) -> 0 | F22: =IF(F15="","",F15-E15) -> 156 | G22: =IF(G15="","",G15-F15) -> 0 | H22: =IF(H15="","",H15-G15) -> 0 | I22: =IF(I15="","",I15-H15) -> 97 | J22: =IF(J15="","",J15-I15) -> 0 | K22: =IF(K15="","",K15-J15) -> 0 | ... AS22: =IF(AS15="","",AS15-AR15)
A23: =SUM(C23:AS23) -> 14 | B23: P差 | C23: 0 | D23: =IF(D16="","",D16-C16) -> 0 | E23: =IF(E16="","",E16-D16) -> 0 | F23: =IF(F16="","",F16-E16) -> 3 | G23: =IF(G16="","",G16-F16) -> 0 | H23: =IF(H16="","",H16-G16) -> 0 | I23: =IF(I16="","",I16-H16) -> 1 | J23: =IF(J16="","",J16-I16) -> 0 | K23: =IF(K16="","",K16-J16) -> 0 | ... AS23: =IF(AS16="","",AS16-AR16)
A24: =SUM(C24:AS24) -> 14 | B24: 払出 | C24: 0 | D24: =IF(D17="","",C17+C18-D17) -> 0 | E24: =IF(E17="","",D17+D18-E17) -> 0 | F24: =IF(F17="","",E17+E18-F17) -> 3 | G24: =IF(G17="","",F17+F18-G17) -> 0 | H24: =IF(H17="","",G17+G18-H17) -> 0 | I24: =IF(I17="","",H17+H18-I17) -> 1 | J24: =IF(J17="","",I17+I18-J17) -> 0 | K24: =IF(K17="","",J17+J18-K17) -> 0 | ... AS24: =IF(AS17="","",AR17+AR18-AS17)
A25: =SUM(C25:AS25) -> 9800 | B25: 払出額 | C25: 0 | D25: =IF(D15="","",D24*D19) -> 0 | E25: =IF(E15="","",E24*E19) -> 0 | F25: =IF(F15="","",F24*F19) -> 2100 | G25: =IF(G15="","",G24*G19) -> 0 | H25: =IF(H15="","",H24*H19) -> 0 | I25: =IF(I15="","",I24*I19) -> 700 | J25: =IF(J15="","",J24*J19) -> 0 | K25: =IF(K15="","",K24*K19) -> 0 | ... AS25: =IF(AS15="","",AS24*AS19)
A26: =IF(A25="","",A25/(A22*100)) -> 0.11922141 | B26: 原価率 | D26: =IF(D25="","",IF(D25=0,"",D25/(D22*100))) | E26: =IF(E25="","",IF(E25=0,"",E25/(E22*100))) | F26: =IF(F25="","",IF(F25=0,"",F25/(F22*100))) -> 0.13461538 | G26: =IF(G25="","",IF(G25=0,"",G25/(G22*100))) | H26: =IF(H25="","",IF(H25=0,"",H25/(H22*100))) | I26: =IF(I25="","",IF(I25=0,"",I25/(I22*100))) -> 0.072164948 | J26: =IF(J25="","",IF(J25=0,"",J25/(J22*100))) | K26: =IF(K25="","",IF(K25=0,"",K25/(K22*100))) | ... AS26: =IF(AS25="","",IF(AS25=0,"",AS25/(AS22*100)))
A27: 霧島 | B27: 100円 | C27: 38243 | D27: =IF(D$3="","",C27) -> 38243 | E27: =IF(E$3="","",D27) -> 38243 | F27: 38290 | G27: =IF(G$3="","",F27) -> 38290 | H27: =IF(H$3="","",G27) -> 38290 | I27: 38334 | J27: =IF(J$3="","",I27) -> 38334 | K27: =IF(K$3="","",J27) -> 38334 | L27: 38422 | M27: =IF(M$3="","",L27) -> 38422 | N27: =IF(N$3="","",M27) -> 38422 | O27: =IF(O$3="","",N27) -> 38422 | P27: 38478 | Q27: =IF(Q$3="","",P27) -> 38478 | R27: =IF(R$3="","",Q27) -> 38478 | S27: 38556 | T27: =IF(T$3="","",S27) -> 38556 | U27: =IF(U$3="","",T27) -> 38556 | V27: =IF(V$3="","",U27) -> 38556 | W27: 38589 | X27: =IF(X$3="","",W27) -> 38589 | Y27: =IF(Y$3="","",X27) -> 38589 | Z27: 38651 | AA27: =IF(AA$3="","",Z27) -> 38651 | AB27: =IF(AB$3="","",AA27) -> 38651 | AC27: =IF(AC$3="","",AB27) -> 38651 | AD27: 38689 | AE27: =IF(AE$3="","",AD27) -> 38689 | AF27: =IF(AF$3="","",AE27) -> 38689 | AG27: 38724 | AH27: =IF(AH$3="","",AG27) | AI27: =IF(AI$3="","",AH27) | AJ27: =IF(AJ$3="","",AI27) | AK27: =IF(AK$3="","",AJ27) | AL27: =IF(AL$3="","",AK27) | AM27: =IF(AM$3="","",AL27) | AN27: =IF(AN$3="","",AM27) | AO27: =IF(AO$3="","",AN27) | ... AS27: =IF(AS$3="","",AR27)
A28: クリスタル | B28: プライズ | C28: 975 | D28: =IF(D$3="","",C28) -> 975 | E28: =IF(E$3="","",D28) -> 975 | F28: 976 | G28: =IF(G$3="","",F28) -> 976 | H28: =IF(H$3="","",G28) -> 976 | I28: 980 | J28: =IF(J$3="","",I28) -> 980 | K28: =IF(K$3="","",J28) -> 980 | L28: 994 | M28: =IF(M$3="","",L28) -> 994 | N28: =IF(N$3="","",M28) -> 994 | O28: =IF(O$3="","",N28) -> 994 | P28: =IF(P$3="","",O28) -> 994 | Q28: =IF(Q$3="","",P28) -> 994 | R28: =IF(R$3="","",Q28) -> 994 | S28: 996 | T28: =IF(T$3="","",S28) -> 996 | U28: =IF(U$3="","",T28) -> 996 | V28: =IF(V$3="","",U28) -> 996 | W28: 999 | X28: =IF(X$3="","",W28) -> 999 | Y28: =IF(Y$3="","",X28) -> 999 | Z28: 1003 | AA28: =IF(AA$3="","",Z28) -> 1003 | AB28: =IF(AB$3="","",AA28) -> 1003 | AC28: =IF(AC$3="","",AB28) -> 1003 | AD28: 1007 | AE28: =IF(AE$3="","",AD28) -> 1007 | AF28: =IF(AF$3="","",AE28) -> 1007 | AG28: 1009 | AH28: =IF(AH$3="","",AG28) | AI28: =IF(AI$3="","",AH28) | AJ28: =IF(AJ$3="","",AI28) | AK28: =IF(AK$3="","",AJ28) | AL28: =IF(AL$3="","",AK28) | AM28: =IF(AM$3="","",AL28) | AN28: =IF(AN$3="","",AM28) | AO28: =IF(AO$3="","",AN28) | ... AS28: =IF(AS$3="","",AR28)
B29: 投入残 | C29: 13 | D29: =IF(D27="","",(C29+C30)) -> 13 | E29: =IF(E27="","",(D29+D30)) -> 13 | F29: 12 | G29: =IF(G27="","",(F29+F30)) -> 12 | H29: =IF(H27="","",(G29+G30)) -> 12 | I29: 8 | J29: =IF(J27="","",(I29+I30)) -> 20 | K29: =IF(K27="","",(J29+J30)) -> 20 | L29: 6 | M29: =IF(M27="","",(L29+L30)) -> 15 | N29: =IF(N27="","",(M29+M30)) -> 15 | O29: =IF(O27="","",(N29+N30)) -> 15 | P29: =IF(P27="","",(O29+O30)) -> 15 | Q29: =IF(Q27="","",(P29+P30)) -> 15 | R29: =IF(R27="","",(Q29+Q30)) -> 15 | S29: 13 | T29: =IF(T27="","",(S29+S30)) -> 13 | U29: =IF(U27="","",(T29+T30)) -> 13 | V29: =IF(V27="","",(U29+U30)) -> 13 | W29: =IF(W27="","",(V29+V30)) -> 13 | X29: =IF(X27="","",(W29+W30)) -> 13 | Y29: =IF(Y27="","",(X29+X30)) -> 13 | Z29: 11 | AA29: =IF(AA27="","",(Z29+Z30)) -> 11 | AB29: =IF(AB27="","",(AA29+AA30)) -> 11 | AC29: =IF(AC27="","",(AB29+AB30)) -> 11 | AD29: 7 | AE29: =IF(AE27="","",(AD29+AD30)) -> 7 | AF29: =IF(AF27="","",(AE29+AE30)) -> 7 | AG29: 4 | AH29: =IF(AH27="","",(AG29+AG30)) | AI29: =IF(AI27="","",(AH29+AH30)) | AJ29: =IF(AJ27="","",(AI29+AI30)) | AK29: =IF(AK27="","",(AJ29+AJ30)) | AL29: =IF(AL27="","",(AK29+AK30)) | AM29: =IF(AM27="","",(AL29+AL30)) | AN29: =IF(AN27="","",(AM29+AM30)) | AO29: =IF(AO27="","",(AN29+AN30)) | ... AS29: =IF(AS27="","",(AR29+AR30))
B30: 補充 | I30: 12 | L30: 9 | AG30: 13
B31: 単価 | C31: 400 | D31: =IF(D27="","",C31) -> 400 | E31: =IF(E27="","",D31) -> 400 | F31: =IF(F27="","",E31) -> 400 | G31: =IF(G27="","",F31) -> 400 | H31: =IF(H27="","",G31) -> 400 | I31: =IF(I27="","",H31) -> 400 | J31: =IF(J27="","",I31) -> 400 | K31: =IF(K27="","",J31) -> 400 | ... AS31: =IF(AS27="","",AR31)
A32: 月間予想 | B32: 景品名 | C32: ラブブMC | D32: =IF(D27="","",C32) -> ラブブMC | E32: =IF(E27="","",D32) -> ラブブMC | F32: =IF(F27="","",E32) -> ラブブMC | G32: =IF(G27="","",F32) -> ラブブMC | H32: =IF(H27="","",G32) -> ラブブMC | I32: ピクミンMC | J32: =IF(J27="","",I32) -> ピクミンMC | K32: =IF(K27="","",J32) -> ピクミンMC | L32: サムエル（箱無し） | M32: =IF(M27="","",L32) -> サムエル（箱無し） | N32: =IF(N27="","",M32) -> サムエル（箱無し） | O32: =IF(O27="","",N32) -> サムエル（箱無し） | P32: =IF(P27="","",O32) -> サムエル（箱無し） | Q32: =IF(Q27="","",P32) -> サムエル（箱無し） | R32: =IF(R27="","",Q32) -> サムエル（箱無し） | S32: =IF(S27="","",R32) -> サムエル（箱無し） | T32: =IF(T27="","",S32) -> サムエル（箱無し） | ... AS32: =IF(AS27="","",AR32)
A33: =AVERAGE(C34:AS34)*30*100 -> 46548.387 | B33: 設定
