Workbook

Sheet 鹿屋
A1: =SUM(A62,A74,A86,A98,A14,A26,A38,A50,A206,A218,A230,A242,A110,A122,A134,A146,A158,A170,A182,A194,A254,A266) -> 1082400 | B1: 日付 | C1: 46157 | D1: 46158 | E1: 46159 | F1: 46160 | G1: 46161 | H1: 46162 | I1: 46163 | J1: =I1+1 -> 46164 | K1: =J1+1 -> 46165 | L1: =K1+1 -> 46166 | M1: =L1+1 -> 46167 | N1: =M1+1 -> 46168 | O1: =N1+1 -> 46169 | P1: =O1+1 -> 46170 | Q1: =P1+1 -> 46171 | ... AS1: =AR1+1 -> 46199
B2: =SUM(C2:AO2) -> 3608 | C2: 0 | D2: 0 | E2: 1432 | F2: 0 | G2: 0 | H2: 0 | I2: 821 | J2: =SUM(J63,J75,J87,J99,J15,J27,J39,J51,J207,J219,J231,J243,J195,J183,J171,J159,J147,J135,J123,J111,J255,J267) -> 0 | K2: =SUM(K63,K75,K87,K99,K15,K27,K39,K51,K207,K219,K231,K243,K195,K183,K171,K159,K147,K135,K123,K111,K255,K267) -> 0 | L2: =SUM(L63,L75,L87,L99,L15,L27,L39,L51,L207,L219,L231,L243,L195,L183,L171,L159,L147,L135,L123,L111,L255,L267) -> 1355 | M2: =SUM(M63,M75,M87,M99,M15,M27,M39,M51,M207,M219,M231,M243,M195,M183,M171,M159,M147,M135,M123,M111,M255,M267) -> 0 | N2: =SUM(N63,N75,N87,N99,N15,N27,N39,N51,N207,N219,N231,N243,N195,N183,N171,N159,N147,N135,N123,N111,N255,N267) -> 0 | O2: =SUM(O63,O75,O87,O99,O15,O27,O39,O51,O207,O219,O231,O243,O195,O183,O171,O159,O147,O135,O123,O111,O255,O267) -> 0 | P2: =SUM(P63,P75,P87,P99,P15,P27,P39,P51,P207,P219,P231,P243,P195,P183,P171,P159,P147,P135,P123,P111,P255,P267) -> 0 | Q2: =SUM(Q63,Q75,Q87,Q99,Q15,Q27,Q39,Q51,Q207,Q219,Q231,Q243,Q195,Q183,Q171,Q159,Q147,Q135,Q123,Q111,Q255,Q267) -> 0 | ... AS2: =SUM(AS63,AS75,AS87,AS99,AS15,AS27,AS39,AS51,AS207,AS219,AS231,AS243,AS195,AS183,AS171,AS159,AS147,AS135,AS123,AS111,AS255,AS267) -> 0
A3: 集金
A4: 両替機
A5: 百出 | E5: 1140 | L5: 2680
A6: 札入 | E6: 91 | L6: 204
A7: 五入 | E7: 46 | L7: 128
A8: 鹿屋 | B8: 100円 | C8: 5280 | D8: 5280 | E8: 5315 | F8: 5315 | G8: 5315 | H8: 5315 | I8: 5335 | J8: 5335 | K8: 5335 | L8: 5396
A9: BUZZ＃１ | B9: プライズ | C9: 351 | D9: 351 | E9: 357 | F9: 357 | G9: 357 | H9: 357 | I9: 359 | J9: =IF(J8="","",I9) -> 359 | K9: =IF(K8="","",J9) -> 359 | L9: 365 | M9: =IF(M8="","",L9) | N9: =IF(N8="","",M9) | O9: =IF(O8="","",N9) | P9: =IF(P8="","",O9) | Q9: =IF(Q8="","",P9) | R9: =IF(R8="","",Q9) | S9: =IF(S8="","",R9) | T9: =IF(T8="","",S9) | ... AS9: =IF(AS8="","",AR9)
A10: 1 | B10: 投入残 | C10: 40 | D10: 40 | E10: 34 | F10: 34 | G10: 34 | H10: 34 | I10: 32 | J10: =IF(J8="","",(I10+I11)) -> 32 | K10: =IF(K8="","",(J10+J11)) -> 32 | L10: 26 | M10: =IF(M8="","",(L10+L11)) | N10: =IF(N8="","",(M10+M11)) | O10: =IF(O8="","",(N10+N11)) | P10: =IF(P8="","",(O10+O11)) | Q10: =IF(Q8="","",(P10+P11)) | R10: =IF(R8="","",(Q10+Q11)) | S10: =IF(S8="","",(R10+R11)) | T10: =IF(T8="","",(S10+S11)) | ... AS10: =IF(AS8="","",(AR10+AR11))
A11: 機械合計 | B11: 補充
A12: =+(A15+A27+A39+A51)*100 -> 49200 | B12: 単価 | C12: 500 | D12: 500 | E12: 500 | F12: 500 | G12: 500 | H12: 500 | I12: 500 | J12: =IF(J8="","",I12) -> 500 | K12: =IF(K8="","",J12) -> 500 | L12: =IF(L8="","",K12) -> 500 | M12: =IF(M8="","",L12) | N12: =IF(N8="","",M12) | O12: =IF(O8="","",N12) | P12: =IF(P8="","",O12) | Q12: =IF(Q8="","",P12) | ... AS12: =IF(AS8="","",AR12)
A13: 月間予想 | B13: 景品名 | C13: 電ブル | D13: 電ブル | E13: 電ブル | F13: 電ブル | G13: 電ブル | H13: 電ブル | I13: 電ブル | J13: =IF(J8="","",I13) -> 電ブル | K13: =IF(K8="","",J13) -> 電ブル | L13: =IF(L8="","",K13) -> 電ブル | M13: =IF(M8="","",L13) | N13: =IF(N8="","",M13) | O13: =IF(O8="","",N13) | P13: =IF(P8="","",O13) | Q13: =IF(Q8="","",P13) | ... AS13: =IF(AS8="","",AR13)
A14: =AVERAGE(C15:AS15)*30*100 -> 34800 | B14: 設定
A15: =SUM(C15:AS15) -> 116 | B15: 百差 | C15: 0 | D15: 0 | E15: 35 | F15: 0 | G15: 0 | H15: 0 | I15: 20 | J15: =IF(J8="","",J8-I8) -> 0 | K15: =IF(K8="","",K8-J8) -> 0 | L15: =IF(L8="","",L8-K8) -> 61 | M15: =IF(M8="","",M8-L8) | N15: =IF(N8="","",N8-M8) | O15: =IF(O8="","",O8-N8) | P15: =IF(P8="","",P8-O8) | Q15: =IF(Q8="","",Q8-P8) | ... AS15: =IF(AS8="","",AS8-AR8)
A16: =SUM(C16:AS16) -> 14 | B16: P差 | C16: 0 | D16: 0 | E16: 6 | F16: 0 | G16: 0 | H16: 0 | I16: 2 | J16: =IF(J9="","",J9-I9) -> 0 | K16: =IF(K9="","",K9-J9) -> 0 | L16: =IF(L9="","",L9-K9) -> 6 | M16: =IF(M9="","",M9-L9) | N16: =IF(N9="","",N9-M9) | O16: =IF(O9="","",O9-N9) | P16: =IF(P9="","",P9-O9) | Q16: =IF(Q9="","",Q9-P9) | ... AS16: =IF(AS9="","",AS9-AR9)
A17: =SUM(C17:AS17) -> 14 | B17: 払出 | C17: 0 | D17: 0 | E17: 6 | F17: 0 | G17: 0 | H17: 0 | I17: 2 | J17: =IF(J10="","",I10+I11-J10) -> 0 | K17: =IF(K10="","",J10+J11-K10) -> 0 | L17: =IF(L10="","",K10+K11-L10) -> 6 | M17: =IF(M10="","",L10+L11-M10) | N17: =IF(N10="","",M10+M11-N10) | O17: =IF(O10="","",N10+N11-O10) | P17: =IF(P10="","",O10+O11-P10) | Q17: =IF(Q10="","",P10+P11-Q10) | ... AS17: =IF(AS10="","",AR10+AR11-AS10)
A18: =SUM(C18:AS18) -> 7000 | B18: 払出額 | C18: 0 | D18: 0 | E18: 3000 | F18: 0 | G18: 0 | H18: 0 | I18: 1000 | J18: =IF(J8="","",J17*J12) -> 0 | K18: =IF(K8="","",K17*K12) -> 0 | L18: =IF(L8="","",L17*L12) -> 3000 | M18: =IF(M8="","",M17*M12) | N18: =IF(N8="","",N17*N12) | O18: =IF(O8="","",O17*O12) | P18: =IF(P8="","",P17*P12) | Q18: =IF(Q8="","",Q17*Q12) | ... AS18: =IF(AS8="","",AS17*AS12) | AT18: =
A19: =IF(A18="","",A18/(A15*100)) -> 0.60344828 | B19: 原価率 | E19: 0.85714286 | I19: 0.5 | J19: =IF(J18="","",IF(J18=0,"",J18/(J15*100))) | K19: =IF(K18="","",IF(K18=0,"",K18/(K15*100))) | L19: =IF(L18="","",IF(L18=0,"",L18/(L15*100))) -> 0.49180328 | M19: =IF(M18="","",IF(M18=0,"",M18/(M15*100))) | N19: =IF(N18="","",IF(N18=0,"",N18/(N15*100))) | O19: =IF(O18="","",IF(O18=0,"",O18/(O15*100))) | P19: =IF(P18="","",IF(P18=0,"",P18/(P15*100))) | Q19: =IF(Q18="","",IF(Q18=0,"",Q18/(Q15*100))) | ... AS19: =IF(AS18="","",IF(AS18=0,"",AS18/(AS15*100)))
A20: 鹿屋 | B20: 100円 | C20: 7899 | D20: 7899 | E20: 7933 | F20: 7933 | G20: 7933 | H20: 7933 | I20: 7964 | J20: =IF(J8="","",I20) -> 7964 | K20: =IF(K8="","",J20) -> 7964 | L20: 7992 | M20: =IF(M8="","",L20) | N20: =IF(N8="","",M20) | O20: =IF(O8="","",N20) | P20: =IF(P8="","",O20) | Q20: =IF(Q8="","",P20) | R20: =IF(R8="","",Q20) | S20: =IF(S8="","",R20) | T20: =IF(T8="","",S20) | ... AS20: =IF(AS8="","",AR20)
A21: BUZZ＃１ | B21: プライズ | C21: 317 | D21: 317 | E21: 317 | F21: 317 | G21: 317 | H21: 317 | I21: 317 | J21: =IF(J8="","",I21) -> 317 | K21: =IF(K8="","",J21) -> 317 | L21: 317 | M21: =IF(M8="","",L21) | N21: =IF(N8="","",M21) | O21: =IF(O8="","",N21) | P21: =IF(P8="","",O21) | Q21: =IF(Q8="","",P21) | R21: =IF(R8="","",Q21) | S21: =IF(S8="","",R21) | T21: =IF(T8="","",S21) | ... AS21: =IF(AS8="","",AR21)
A22: 2 | B22: 投入残 | C22: 3 | D22: 3 | E22: 2 | F22: 2 | G22: 2 | H22: 2 | I22: 2 | J22: =IF(J20="","",(I22+I23)) -> 2 | K22: =IF(K20="","",(J22+J23)) -> 2 | L22: =IF(L20="","",(K22+K23)) -> 2 | M22: =IF(M20="","",(L22+L23)) | N22: =IF(N20="","",(M22+M23)) | O22: =IF(O20="","",(N22+N23)) | P22: =IF(P20="","",(O22+O23)) | Q22: =IF(Q20="","",(P22+P23)) | ... AS22: =IF(AS20="","",(AR22+AR23))
B23: 補充
B24: 単価 | C24: 750 | D24: 750 | E24: 750 | F24: 750 | G24: 750 | H24: 750 | I24: 750 | J24: =IF(J20="","",I24) -> 750 | K24: =IF(K20="","",J24) -> 750 | L24: =IF(L20="","",K24) -> 750 | M24: =IF(M20="","",L24) | N24: =IF(N20="","",M24) | O24: =IF(O20="","",N24) | P24: =IF(P20="","",O24) | Q24: =IF(Q20="","",P24) | ... AS24: =IF(AS20="","",AR24)
A25: 月間予想 | B25: 景品名 | C25: スンスンフェイスポーチ | D25: スンスンフェイスポーチ | E25: スンスンフェイスポーチ | F25: スンスンフェイスポーチ | G25: スンスンフェイスポーチ | H25: スンスンフェイスポーチ | I25: スンスンフェイスポーチ | J25: =IF(J20="","",I25) -> スンスンフェイスポーチ | K25: =IF(K20="","",J25) -> スンスンフェイスポーチ | L25: =IF(L20="","",K25) -> スンスンフェイスポーチ | M25: =IF(M20="","",L25) | N25: =IF(N20="","",M25) | O25: =IF(O20="","",N25) | P25: =IF(P20="","",O25) | Q25: =IF(Q20="","",P25) | ... AS25: =IF(AS20="","",AR25)
A26: =AVERAGE(C27:AS27)*30*100 -> 27900 | B26: 設定
A27: =SUM(C27:AS27) -> 93 | B27: 百差 | C27: 0 | D27: 0 | E27: 34 | F27: 0 | G27: 0 | H27: 0 | I27: 31 | J27: =IF(J20="","",J20-I20) -> 0 | K27: =IF(K20="","",K20-J20) -> 0 | L27: =IF(L20="","",L20-K20) -> 28 | M27: =IF(M20="","",M20-L20) | N27: =IF(N20="","",N20-M20) | O27: =IF(O20="","",O20-N20) | P27: =IF(P20="","",P20-O20) | Q27: =IF(Q20="","",Q20-P20) | ... AS27: =IF(AS20="","",AS20-AR20)
A28: =SUM(C28:AS28) -> 0 | B28: P差 | C28: 0 | D28: 0 | E28: 0 | F28: 0 | G28: 0 | H28: 0 | I28: 0 | J28: =IF(J21="","",J21-I21) -> 0 | K28: =IF(K21="","",K21-J21) -> 0 | L28: =IF(L21="","",L21-K21) -> 0 | M28: =IF(M21="","",M21-L21) | N28: =IF(N21="","",N21-M21) | O28: =IF(O21="","",O21-N21) | P28: =IF(P21="","",P21-O21) | Q28: =IF(Q21="","",Q21-P21) | ... AS28: =IF(AS21="","",AS21-AR21)
A29: =SUM(C29:AS29) -> 1 | B29: 払出 | C29: 0 | D29: 0 | E29: 1 | F29: 0 | G29: 0 | H29: 0 | I29: 0 | J29: =IF(J22="","",I22+I23-J22) -> 0 | K29: =IF(K22="","",J22+J23-K22) -> 0 | L29: =IF(L22="","",K22+K23-L22) -> 0 | M29: =IF(M22="","",L22+L23-M22) | N29: =IF(N22="","",M22+M23-N22) | O29: =IF(O22="","",N22+N23-O22) | P29: =IF(P22="","",O22+O23-P22) | Q29: =IF(Q22="","",P22+P23-Q22) | ... AS29: =IF(AS22="","",AR22+AR23-AS22)
A30: =SUM(C30:AS30) -> 750 | B30: 払出額 | C30: 0 | D30: 0 | E30: 750 | F30: 0 | G30: 0 | H30: 0 | I30: 0 | J30: =IF(J20="","",J29*J24) -> 0 | K30: =IF(K20="","",K29*K24) -> 0 | L30: =IF(L20="","",L29*L24) -> 0 | M30: =IF(M20="","",M29*M24) | N30: =IF(N20="","",N29*N24) | O30: =IF(O20="","",O29*O24) | P30: =IF(P20="","",P29*P24) | Q30: =IF(Q20="","",Q29*Q24) | ... AS30: =IF(AS20="","",AS29*AS24)
A31: =IF(A30="","",A30/(A27*100)) -> 0.080645161 | B31: 原価率 | E31: 0.22058824 | J31: =IF(J30="","",IF(J30=0,"",J30/(J27*100))) | K31: =IF(K30="","",IF(K30=0,"",K30/(K27*100))) | L31: =IF(L30="","",IF(L30=0,"",L30/(L27*100))) | M31: =IF(M30="","",IF(M30=0,"",M30/(M27*100))) | N31: =IF(N30="","",IF(N30=0,"",N30/(N27*100))) | O31: =IF(O30="","",IF(O30=0,"",O30/(O27*100))) | P31: =IF(P30="","",IF(P30=0,"",P30/(P27*100))) | Q31: =IF(Q30="","",IF(Q30=0,"",Q30/(Q27*100))) | ... AS31: =IF(AS30="","",IF(AS30=0,"",AS30/(AS27*100)))
A32: 鹿屋 | B32: 100円 | C32: 6830 | D32: 6830 | E32: 6871 | F32: 6871 | G32: 6871 | H32: 6871 | I32: 6917 | J32: =IF(J8="","",I32) -> 6917 | K32: =IF(K8="","",J32) -> 6917 | L32: 6997 | M32: =IF(M8="","",L32) | N32: =IF(N8="","",M32) | O32: =IF(O8="","",N32) | P32: =IF(P8="","",O32) | Q32: =IF(Q8="","",P32) | R32: =IF(R8="","",Q32) | S32: =IF(S8="","",R32) | T32: =IF(T8="","",S32) | ... AS32: =IF(AS8="","",AR32)
A33: BUZZ＃１ | B33: プライズ | C33: 390 | D33: 390 | E33: 391 | F33: 391 | G33: 391 | H33: 391 | I33: 391 | J33: =IF(J8="","",I33) -> 391 | K33: =IF(K8="","",J33) -> 391 | L33: 392 | M33: =IF(M8="","",L33) | N33: =IF(N8="","",M33) | O33: =IF(O8="","",N33) | P33: =IF(P8="","",O33) | Q33: =IF(Q8="","",P33) | R33: =IF(R8="","",Q33) | S33: =IF(S8="","",R33) | T33: =IF(T8="","",S33) | ... AS33: =IF(AS8="","",AR33)
A34: 3 | B34: 投入残 | C34: 8 | D34: 8 | E34: 7 | F34: 7 | G34: 7 | H34: 7 | I34: 7 | J34: =IF(J32="","",(I34+I35)) -> 7 | K34: =IF(K32="","",(J34+J35)) -> 7 | L34: 6 | M34: =IF(M32="","",(L34+L35)) | N34: =IF(N32="","",(M34+M35)) | O34: =IF(O32="","",(N34+N35)) | P34: =IF(P32="","",(O34+O35)) | Q34: =IF(Q32="","",(P34+P35)) | R34: =IF(R32="","",(Q34+Q35)) | S34: =IF(S32="","",(R34+R35)) | T34: =IF(T32="","",(S34+S35)) | ... AS34: =IF(AS32="","",(AR34+AR35))
B35: 補充
B36: 単価 | C36: 450 | D36: 450 | E36: 450 | F36: 450 | G36: 450 | H36: 450 | I36: 450 | J36: =IF(J32="","",I36) -> 450 | K36: =IF(K32="","",J36) -> 450 | L36: =IF(L32="","",K36) -> 450 | M36: =IF(M32="","",L36) | N36: =IF(N32="","",M36) | O36: =IF(O32="","",N36) | P36: =IF(P32="","",O36) | Q36: =IF(Q32="","",P36) | ... AS36: =IF(AS32="","",AR36)
A37: 月間予想 | B37: 景品名 | C37: たまごっちマスコット | D37: たまごっちマスコット | E37: たまごっちマスコット | F37: たまごっちマスコット | G37: たまごっちマスコット | H37: たまごっちマスコット | I37: たまごっちマスコット | J37: =IF(J32="","",I37) -> たまごっちマスコット | K37: =IF(K32="","",J37) -> たまごっちマスコット | L37: =IF(L32="","",K37) -> たまごっちマスコット | M37: =IF(M32="","",L37) | N37: =IF(N32="","",M37) | O37: =IF(O32="","",N37) | P37: =IF(P32="","",O37) | Q37: =IF(Q32="","",P37) | ... AS37: =IF(AS32="","",AR37)
A38: =AVERAGE(C39:AS39)*30*100 -> 50100 | B38: 設定
A39: =SUM(C39:AS39) -> 167 | B39: 百差 | C39: 0 | D39: 0 | E39: 41 | F39: 0 | G39: 0 | H39: 0 | I39: 46 | J39: =IF(J32="","",J32-I32) -> 0 | K39: =IF(K32="","",K32-J32) -> 0 | L39: =IF(L32="","",L32-K32) -> 80 | M39: =IF(M32="","",M32-L32) | N39: =IF(N32="","",N32-M32) | O39: =IF(O32="","",O32-N32) | P39: =IF(P32="","",P32-O32) | Q39: =IF(Q32="","",Q32-P32) | ... AS39: =IF(AS32="","",AS32-AR32)
A40: =SUM(C40:AS40) -> 2 | B40: P差 | C40: 0 | D40: 0 | E40: 1 | F40: 0 | G40: 0 | H40: 0 | I40: 0 | J40: =IF(J33="","",J33-I33) -> 0 | K40: =IF(K33="","",K33-J33) -> 0 | L40: =IF(L33="","",L33-K33) -> 1 | M40: =IF(M33="","",M33-L33) | N40: =IF(N33="","",N33-M33) | O40: =IF(O33="","",O33-N33) | P40: =IF(P33="","",P33-O33) | Q40: =IF(Q33="","",Q33-P33) | ... AS40: =IF(AS33="","",AS33-AR33)
...

Sheet 都城
A1: =SUM(A62,A74,A86,A98,A14,A26,A38,A50,A206,A218,A230,A242,A110,A122,A134,A146,A158,A170,A182,A194,A253,A265) -> 1034700 | B1: 日付 | C1: 46157 | D1: 46158 | E1: 46159 | F1: 46160 | G1: 46161 | H1: 46162 | I1: 46163 | J1: =I1+1 -> 46164 | K1: =J1+1 -> 46165 | L1: =K1+1 -> 46166 | M1: =L1+1 -> 46167 | N1: =M1+1 -> 46168 | O1: =N1+1 -> 46169 | P1: =O1+1 -> 46170 | Q1: =P1+1 -> 46171 | ... AS1: =AR1+1 -> 46199
B2: =SUM(C2:AO2) -> 3449 | C2: 0 | D2: 0 | E2: 1209 | F2: 0 | G2: 0 | H2: 0 | I2: 967 | J2: =SUM(J15,J27,J39,J51,J63,J75,J87,J99,J111,J123,J135,J147,J159,J171,J183,J195,J207,J219,J231,J243) -> 0 | K2: =SUM(K15,K27,K39,K51,K63,K75,K87,K99,K111,K123,K135,K147,K159,K171,K183,K195,K207,K219,K231,K243) -> 0 | L2: =SUM(L15,L27,L39,L51,L63,L75,L87,L99,L111,L123,L135,L147,L159,L171,L183,L195,L207,L219,L231,L243) -> 1273 | M2: =SUM(M15,M27,M39,M51,M63,M75,M87,M99,M111,M123,M135,M147,M159,M171,M183,M195,M207,M219,M231,M243) -> 0 | N2: =SUM(N15,N27,N39,N51,N63,N75,N87,N99,N111,N123,N135,N147,N159,N171,N183,N195,N207,N219,N231,N243) -> 0 | O2: =SUM(O15,O27,O39,O51,O63,O75,O87,O99,O111,O123,O135,O147,O159,O171,O183,O195,O207,O219,O231,O243) -> 0 | P2: =SUM(P15,P27,P39,P51,P63,P75,P87,P99,P111,P123,P135,P147,P159,P171,P183,P195,P207,P219,P231,P243) -> 0 | Q2: =SUM(Q15,Q27,Q39,Q51,Q63,Q75,Q87,Q99,Q111,Q123,Q135,Q147,Q159,Q171,Q183,Q195,Q207,Q219,Q231,Q243) -> 0 | ... AS2: =SUM(AS15,AS27,AS39,AS51,AS63,AS75,AS87,AS99,AS111,AS123,AS135,AS147,AS159,AS171,AS183,AS195,AS207,AS219,AS231,AS243) -> 0
A3: 集金
A4: 両替機
A5: 百出 | E5: 1227 | I5: 2120 | L5: 3310
A6: 札入 | E6: 105 | I6: 174 | L6: 265
A7: 五入 | E7: 44 | I7: 76 | L7: 132
A8: 都城 | B8: 100円 | C8: 4765 | D8: 4765 | E8: 4800 | F8: 4800 | G8: 4800 | H8: 4800 | I8: 4843 | J8: 4843 | K8: 4843 | L8: 4895
A9: BUZZ＃１ | B9: プライズ | C9: 105 | D9: 105 | E9: 105 | F9: 105 | G9: 105 | H9: 105 | I9: 106 | J9: =IF(J8="","",I9) -> 106 | K9: =IF(K8="","",J9) -> 106 | L9: 108 | M9: =IF(M8="","",L9) | N9: =IF(N8="","",M9) | O9: =IF(O8="","",N9) | P9: =IF(P8="","",O9) | Q9: =IF(Q8="","",P9) | R9: =IF(R8="","",Q9) | S9: =IF(S8="","",R9) | T9: =IF(T8="","",S9) | ... AS9: =IF(AS8="","",AR9)
A10: 1 | B10: 投入残 | C10: 13 | D10: 13 | E10: 13 | F10: 13 | G10: 13 | H10: 13 | I10: 12 | J10: =IF(J8="","",(I10+I11)) -> 12 | K10: =IF(K8="","",(J10+J11)) -> 12 | L10: 10 | M10: =IF(M8="","",(L10+L11)) | N10: =IF(N8="","",(M10+M11)) | O10: =IF(O8="","",(N10+N11)) | P10: =IF(P8="","",(O10+O11)) | Q10: =IF(Q8="","",(P10+P11)) | R10: =IF(R8="","",(Q10+Q11)) | S10: =IF(S8="","",(R10+R11)) | T10: =IF(T8="","",(S10+S11)) | ... AS10: =IF(AS8="","",(AR10+AR11))
A11: 機械合計 | B11: 補充
A12: =+(A15+A27+A39+A51)*100 -> 92700 | B12: 単価 | C12: 500 | D12: 500 | E12: 500 | F12: 500 | G12: 500 | H12: 500 | I12: 500 | J12: =IF(J8="","",I12) -> 500 | K12: =IF(K8="","",J12) -> 500 | L12: =IF(L8="","",K12) -> 500 | M12: =IF(M8="","",L12) | N12: =IF(N8="","",M12) | O12: =IF(O8="","",N12) | P12: =IF(P8="","",O12) | Q12: =IF(Q8="","",P12) | ... AS12: =IF(AS8="","",AR12)
A13: 月間予想 | B13: 景品名 | C13: フルーツモンチッチマスコット | D13: フルーツモンチッチマスコット | E13: フルーツモンチッチマスコット | F13: フルーツモンチッチマスコット | G13: フルーツモンチッチマスコット | H13: フルーツモンチッチマスコット | I13: フルーツモンチッチマスコット | J13: =IF(J8="","",I13) -> フルーツモンチッチマスコット | K13: =IF(K8="","",J13) -> フルーツモンチッチマスコット | L13: =IF(L8="","",K13) -> フルーツモンチッチマスコット | M13: =IF(M8="","",L13) | N13: =IF(N8="","",M13) | O13: =IF(O8="","",N13) | P13: =IF(P8="","",O13) | Q13: =IF(Q8="","",P13) | ... AS13: =IF(AS8="","",AR13)
A14: =AVERAGE(C15:AS15)*30*100 -> 39000 | B14: 設定
A15: =SUM(C15:AS15) -> 130 | B15: 百差 | C15: 0 | D15: 0 | E15: 35 | F15: 0 | G15: 0 | H15: 0 | I15: 43 | J15: =IF(J8="","",J8-I8) -> 0 | K15: =IF(K8="","",K8-J8) -> 0 | L15: =IF(L8="","",L8-K8) -> 52 | M15: =IF(M8="","",M8-L8) | N15: =IF(N8="","",N8-M8) | O15: =IF(O8="","",O8-N8) | P15: =IF(P8="","",P8-O8) | Q15: =IF(Q8="","",Q8-P8) | ... AS15: =IF(AS8="","",AS8-AR8)
A16: =SUM(C16:AS16) -> 3 | B16: P差 | C16: 0 | D16: 0 | E16: 0 | F16: 0 | G16: 0 | H16: 0 | I16: 1 | J16: =IF(J9="","",J9-I9) -> 0 | K16: =IF(K9="","",K9-J9) -> 0 | L16: =IF(L9="","",L9-K9) -> 2 | M16: =IF(M9="","",M9-L9) | N16: =IF(N9="","",N9-M9) | O16: =IF(O9="","",O9-N9) | P16: =IF(P9="","",P9-O9) | Q16: =IF(Q9="","",Q9-P9) | ... AS16: =IF(AS9="","",AS9-AR9)
A17: =SUM(C17:AS17) -> 3 | B17: 払出 | C17: 0 | D17: 0 | E17: 0 | F17: 0 | G17: 0 | H17: 0 | I17: 1 | J17: =IF(J10="","",I10+I11-J10) -> 0 | K17: =IF(K10="","",J10+J11-K10) -> 0 | L17: =IF(L10="","",K10+K11-L10) -> 2 | M17: =IF(M10="","",L10+L11-M10) | N17: =IF(N10="","",M10+M11-N10) | O17: =IF(O10="","",N10+N11-O10) | P17: =IF(P10="","",O10+O11-P10) | Q17: =IF(Q10="","",P10+P11-Q10) | ... AS17: =IF(AS10="","",AR10+AR11-AS10)
A18: =SUM(C18:AS18) -> 1500 | B18: 払出額 | C18: 0 | D18: 0 | E18: 0 | F18: 0 | G18: 0 | H18: 0 | I18: 500 | J18: =IF(J8="","",J17*J12) -> 0 | K18: =IF(K8="","",K17*K12) -> 0 | L18: =IF(L8="","",L17*L12) -> 1000 | M18: =IF(M8="","",M17*M12) | N18: =IF(N8="","",N17*N12) | O18: =IF(O8="","",O17*O12) | P18: =IF(P8="","",P17*P12) | Q18: =IF(Q8="","",Q17*Q12) | ... AS18: =IF(AS8="","",AS17*AS12)
A19: =IF(A18="","",A18/(A15*100)) -> 0.11538462 | B19: 原価率 | I19: 0.11627907 | J19: =IF(J18="","",IF(J18=0,"",J18/(J15*100))) | K19: =IF(K18="","",IF(K18=0,"",K18/(K15*100))) | L19: =IF(L18="","",IF(L18=0,"",L18/(L15*100))) -> 0.19230769 | M19: =IF(M18="","",IF(M18=0,"",M18/(M15*100))) | N19: =IF(N18="","",IF(N18=0,"",N18/(N15*100))) | O19: =IF(O18="","",IF(O18=0,"",O18/(O15*100))) | P19: =IF(P18="","",IF(P18=0,"",P18/(P15*100))) | Q19: =IF(Q18="","",IF(Q18=0,"",Q18/(Q15*100))) | ... AS19: =IF(AS18="","",IF(AS18=0,"",AS18/(AS15*100)))
A20: 都城 | B20: 100円 | C20: 7591 | D20: 7591 | E20: 7676 | F20: 7676 | G20: 7676 | H20: 7676 | I20: 7782 | J20: =IF(J8="","",I20) -> 7782 | K20: =IF(K8="","",J20) -> 7782 | L20: 7917 | M20: =IF(M8="","",L20) | N20: =IF(N8="","",M20) | O20: =IF(O8="","",N20) | P20: =IF(P8="","",O20) | Q20: =IF(Q8="","",P20) | R20: =IF(R8="","",Q20) | S20: =IF(S8="","",R20) | T20: =IF(T8="","",S20) | ... AS20: =IF(AS8="","",AR20)
A21: BUZZ＃１ | B21: プライズ | C21: 102 | D21: 102 | E21: 104 | F21: 104 | G21: 104 | H21: 104 | I21: 106 | J21: =IF(J8="","",I21) -> 106 | K21: =IF(K8="","",J21) -> 106 | L21: =IF(L8="","",K21) -> 106 | M21: =IF(M8="","",L21) | N21: =IF(N8="","",M21) | O21: =IF(O8="","",N21) | P21: =IF(P8="","",O21) | Q21: =IF(Q8="","",P21) | ... AS21: =IF(AS8="","",AR21)
A22: 2 | B22: 投入残 | C22: 7 | D22: 7 | E22: 3 | F22: 8 | G22: 8 | H22: 8 | I22: 6 | J22: =IF(J20="","",(I22+I23)) -> 8 | K22: =IF(K20="","",(J22+J23)) -> 8 | L22: =IF(L20="","",(K22+K23)) -> 8 | M22: =IF(M20="","",(L22+L23)) | N22: =IF(N20="","",(M22+M23)) | O22: =IF(O20="","",(N22+N23)) | P22: =IF(P20="","",(O22+O23)) | Q22: =IF(Q20="","",(P22+P23)) | ... AS22: =IF(AS20="","",(AR22+AR23))
B23: 補充 | E23: 5 | I23: 2
B24: 単価 | C24: 800 | D24: 800 | E24: 800 | F24: 800 | G24: 800 | H24: 800 | I24: 800 | J24: =IF(J20="","",I24) -> 800 | K24: =IF(K20="","",J24) -> 800 | L24: =IF(L20="","",K24) -> 800 | M24: =IF(M20="","",L24) | N24: =IF(N20="","",M24) | O24: =IF(O20="","",N24) | P24: =IF(P20="","",O24) | Q24: =IF(Q20="","",P24) | ... AS24: =IF(AS20="","",AR24)
A25: 月間予想 | B25: 景品名 | C25: ミニファン | D25: ミニファン | E25: ミニファン | F25: ミニファン | G25: ミニファン | H25: ミニファン | I25: ミニファン | J25: =IF(J20="","",I25) -> ミニファン | K25: =IF(K20="","",J25) -> ミニファン | L25: =IF(L20="","",K25) -> ミニファン | M25: =IF(M20="","",L25) | N25: =IF(N20="","",M25) | O25: =IF(O20="","",N25) | P25: =IF(P20="","",O25) | Q25: =IF(Q20="","",P25) | ... AS25: =IF(AS20="","",AR25)
A26: =AVERAGE(C27:AS27)*30*100 -> 97800 | B26: 設定
A27: =SUM(C27:AS27) -> 326 | B27: 百差 | C27: 0 | D27: 0 | E27: 85 | F27: 0 | G27: 0 | H27: 0 | I27: 106 | J27: =IF(J20="","",J20-I20) -> 0 | K27: =IF(K20="","",K20-J20) -> 0 | L27: =IF(L20="","",L20-K20) -> 135 | M27: =IF(M20="","",M20-L20) | N27: =IF(N20="","",N20-M20) | O27: =IF(O20="","",O20-N20) | P27: =IF(P20="","",P20-O20) | Q27: =IF(Q20="","",Q20-P20) | ... AS27: =IF(AS20="","",AS20-AR20)
A28: =SUM(C28:AS28) -> 4 | B28: P差 | C28: 0 | D28: 0 | E28: 2 | F28: 0 | G28: 0 | H28: 0 | I28: 2 | J28: =IF(J21="","",J21-I21) -> 0 | K28: =IF(K21="","",K21-J21) -> 0 | L28: =IF(L21="","",L21-K21) -> 0 | M28: =IF(M21="","",M21-L21) | N28: =IF(N21="","",N21-M21) | O28: =IF(O21="","",O21-N21) | P28: =IF(P21="","",P21-O21) | Q28: =IF(Q21="","",Q21-P21) | ... AS28: =IF(AS21="","",AS21-AR21)
A29: =SUM(C29:AS29) -> 6 | B29: 払出 | C29: 0 | D29: 0 | E29: 4 | F29: 0 | G29: 0 | H29: 0 | I29: 2 | J29: =IF(J22="","",I22+I23-J22) -> 0 | K29: =IF(K22="","",J22+J23-K22) -> 0 | L29: =IF(L22="","",K22+K23-L22) -> 0 | M29: =IF(M22="","",L22+L23-M22) | N29: =IF(N22="","",M22+M23-N22) | O29: =IF(O22="","",N22+N23-O22) | P29: =IF(P22="","",O22+O23-P22) | Q29: =IF(Q22="","",P22+P23-Q22) | ... AS29: =IF(AS22="","",AR22+AR23-AS22)
A30: =SUM(C30:AS30) -> 4800 | B30: 払出額 | C30: 0 | D30: 0 | E30: 3200 | F30: 0 | G30: 0 | H30: 0 | I30: 1600 | J30: =IF(J20="","",J29*J24) -> 0 | K30: =IF(K20="","",K29*K24) -> 0 | L30: =IF(L20="","",L29*L24) -> 0 | M30: =IF(M20="","",M29*M24) | N30: =IF(N20="","",N29*N24) | O30: =IF(O20="","",O29*O24) | P30: =IF(P20="","",P29*P24) | Q30: =IF(Q20="","",Q29*Q24) | ... AS30: =IF(AS20="","",AS29*AS24)
A31: =IF(A30="","",A30/(A27*100)) -> 0.14723926 | B31: 原価率 | E31: 0.37647059 | I31: 0.1509434 | J31: =IF(J30="","",IF(J30=0,"",J30/(J27*100))) | K31: =IF(K30="","",IF(K30=0,"",K30/(K27*100))) | L31: =IF(L30="","",IF(L30=0,"",L30/(L27*100))) | M31: =IF(M30="","",IF(M30=0,"",M30/(M27*100))) | N31: =IF(N30="","",IF(N30=0,"",N30/(N27*100))) | O31: =IF(O30="","",IF(O30=0,"",O30/(O27*100))) | P31: =IF(P30="","",IF(P30=0,"",P30/(P27*100))) | Q31: =IF(Q30="","",IF(Q30=0,"",Q30/(Q27*100))) | ... AS31: =IF(AS30="","",IF(AS30=0,"",AS30/(AS27*100)))
A32: 都城 | B32: 100円 | C32: 7677 | D32: 7677 | E32: 7741 | F32: 7741 | G32: 7741 | H32: 7741 | I32: 7755 | J32: =IF(J8="","",I32) -> 7755 | K32: =IF(K8="","",J32) -> 7755 | L32: 7868 | M32: =IF(M8="","",L32) | N32: =IF(N8="","",M32) | O32: =IF(O8="","",N32) | P32: =IF(P8="","",O32) | Q32: =IF(Q8="","",P32) | R32: =IF(R8="","",Q32) | S32: =IF(S8="","",R32) | T32: =IF(T8="","",S32) | ... AS32: =IF(AS8="","",AR32)
A33: BUZZ＃１ | B33: プライズ | C33: 252 | D33: 252 | E33: 252 | F33: 252 | G33: 252 | H33: 252 | I33: 253 | J33: =IF(J8="","",I33) -> 253 | K33: =IF(K8="","",J33) -> 253 | L33: 258 | M33: =IF(M8="","",L33) | N33: =IF(N8="","",M33) | O33: =IF(O8="","",N33) | P33: =IF(P8="","",O33) | Q33: =IF(Q8="","",P33) | R33: =IF(R8="","",Q33) | S33: =IF(S8="","",R33) | T33: =IF(T8="","",S33) | ... AS33: =IF(AS8="","",AR33)
A34: 3 | B34: 投入残 | C34: 6 | D34: 6 | E34: 6 | F34: 6 | G34: 6 | H34: 6 | I34: 10 | J34: =IF(J32="","",(I34+I35)) -> 10 | K34: =IF(K32="","",(J34+J35)) -> 10 | L34: 7 | M34: =IF(M32="","",(L34+L35)) | N34: =IF(N32="","",(M34+M35)) | O34: =IF(O32="","",(N34+N35)) | P34: =IF(P32="","",(O34+O35)) | Q34: =IF(Q32="","",(P34+P35)) | R34: =IF(R32="","",(Q34+Q35)) | S34: =IF(S32="","",(R34+R35)) | T34: =IF(T32="","",(S34+S35)) | ... AS34: =IF(AS32="","",(AR34+AR35))
B35: 補充 | H35: 4
B36: 単価 | C36: 175 | D36: 175 | E36: 175 | F36: 175 | G36: 175 | H36: 175 | I36: 175 | J36: =IF(J32="","",I36) -> 175 | K36: =IF(K32="","",J36) -> 175 | L36: =IF(L32="","",K36) -> 175 | M36: =IF(M32="","",L36) | N36: =IF(N32="","",M36) | O36: =IF(O32="","",N36) | P36: =IF(P32="","",O36) | Q36: =IF(Q32="","",P36) | ... AS36: =IF(AS32="","",AR36)
A37: 月間予想 | B37: 景品名 | C37: スライム | D37: スライム | E37: スライム | F37: スライム | G37: スライム | H37: スライム | I37: クリームタルトスクイーズ | J37: =IF(J32="","",I37) -> クリームタルトスクイーズ | K37: =IF(K32="","",J37) -> クリームタルトスクイーズ | L37: =IF(L32="","",K37) -> クリームタルトスクイーズ | M37: =IF(M32="","",L37) | N37: =IF(N32="","",M37) | O37: =IF(O32="","",N37) | P37: =IF(P32="","",O37) | Q37: =IF(Q32="","",P37) | ... AS37: =IF(AS32="","",AR37)
A38: =AVERAGE(C39:AS39)*30*100 -> 57300 | B38: 設定
A39: =SUM(C39:AS39) -> 191 | B39: 百差 | C39: 0 | D39: 0 | E39: 64 | F39: 0 | G39: 0 | H39: 0 | I39: 14 | J39: =IF(J32="","",J32-I32) -> 0 | K39: =IF(K32="","",K32-J32) -> 0 | L39: =IF(L32="","",L32-K32) -> 113 | M39: =IF(M32="","",M32-L32) | N39: =IF(N32="","",N32-M32) | O39: =IF(O32="","",O32-N32) | P39: =IF(P32="","",P32-O32) | Q39: =IF(Q32="","",Q32-P32) | ... AS39: =IF(AS32="","",AS32-AR32)
A40: =SUM(C40:AS40) -> 6 | B40: P差 | C40: 0 | D40: 0 | E40: 0 | F40: 0 | G40: 0 | H40: 0 | I40: 1 | J40: =IF(J33="","",J33-I33) -> 0 | K40: =IF(K33="","",K33-J33) -> 0 | L40: =IF(L33="","",L33-K33) -> 5 | M40: =IF(M33="","",M33-L33) | N40: =IF(N33="","",N33-M33) | O40: =IF(O33="","",O33-N33) | P40: =IF(P33="","",P33-O33) | Q40: =IF(Q33="","",Q33-P33) | ... AS40: =IF(AS33="","",AS33-AR33)
...

Sheet 霧島
A1: =SUM(A14,A50,A62,A74,A86,A98,A110,A122,A134,A158,A146,A170,A182,A194,A206,A218,A230,A38,A26,A242,A254) -> 1064181.8 | B1: 日付 | C1: 46156 | D1: 46157 | E1: 46158 | F1: 46159 | G1: 46160 | H1: 46161 | I1: 46162 | J1: 46163 | K1: =J1+1 -> 46164 | L1: =K1+1 -> 46165 | M1: =L1+1 -> 46166 | N1: =M1+1 -> 46167 | O1: =N1+1 -> 46168 | P1: =O1+1 -> 46169 | Q1: =P1+1 -> 46170 | R1: =Q1+1 -> 46171 | ... AS1: =AR1+1 -> 46198
B2: =SUM(C2:AO2) -> 3902 | C2: 0 | D2: 0 | E2: 0 | F2: 1436 | G2: 0 | H2: 0 | I2: 0 | J2: 1178 | K2: =SUM(K15,K255,K243,K27,K39,K231,K219,K207,K195,K183,K171,K159,K147,K135,K123,,K111,K99,K87,K75,K63,K51) -> 0 | L2: =SUM(L15,L255,L243,L27,L39,L231,L219,L207,L195,L183,L171,L159,L147,L135,L123,,L111,L99,L87,L75,L63,L51) -> 0 | M2: =SUM(M15,M255,M243,M27,M39,M231,M219,M207,M195,M183,M171,M159,M147,M135,M123,,M111,M99,M87,M75,M63,M51) -> 1288 | N2: =SUM(N15,N255,N243,N27,N39,N231,N219,N207,N195,N183,N171,N159,N147,N135,N123,,N111,N99,N87,N75,N63,N51) -> 0 | O2: =SUM(O15,O255,O243,O27,O39,O231,O219,O207,O195,O183,O171,O159,O147,O135,O123,,O111,O99,O87,O75,O63,O51) -> 0 | P2: =SUM(P15,P255,P243,P27,P39,P231,P219,P207,P195,P183,P171,P159,P147,P135,P123,,P111,P99,P87,P75,P63,P51) -> 0 | Q2: =SUM(Q15,Q255,Q243,Q27,Q39,Q231,Q219,Q207,Q195,Q183,Q171,Q159,Q147,Q135,Q123,,Q111,Q99,Q87,Q75,Q63,Q51) -> 0 | R2: =SUM(R15,R255,R243,R27,R39,R231,R219,R207,R195,R183,R171,R159,R147,R135,R123,,R111,R99,R87,R75,R63,R51) -> 0 | ... AS2: =SUM(AS15,AS255,AS243,AS27,AS39,AS231,AS219,AS207,AS195,AS183,AS171,AS159,AS147,AS135,AS123,,AS111,AS99,AS87,AS75,AS63,AS51) -> 0
A3: 集金
A4: 両替機
A5: 百出 | F5: 1635 | J5: 2715 | M5: 4075
A6: 札入 | F6: 131 | J6: 230 | M6: 336
A7: 五入 | F7: 65 | J7: 83 | M7: 143
A8: 霧島 | B8: 100円 | C8: 23405 | D8: 23405 | E8: 23405 | F8: 23450 | G8: 23450 | H8: 23450 | I8: 23450 | J8: 23513 | K8: 23513 | L8: 23513 | M8: 23553
A9: BUZZミニ | B9: プライズ | C9: 379 | D9: 379 | E9: 379 | F9: 379 | G9: 379 | H9: 379 | I9: 379 | J9: 382 | K9: =IF(K$8="","",J9) -> 382 | L9: =IF(L$8="","",K9) -> 382 | M9: 383 | N9: =IF(N$8="","",M9) | O9: =IF(O$8="","",N9) | P9: =IF(P$8="","",O9) | Q9: =IF(Q$8="","",P9) | R9: =IF(R$8="","",Q9) | S9: =IF(S$8="","",R9) | T9: =IF(T$8="","",S9) | U9: =IF(U$8="","",T9) | ... AS9: =IF(AS$8="","",AR9)
B10: 投入残 | C10: 7 | D10: 7 | E10: 7 | F10: 7 | G10: 7 | H10: 7 | I10: 7 | J10: 4 | K10: =IF(K8="","",(J10+J11)) -> 8 | L10: =IF(L8="","",(K10+K11)) -> 8 | M10: 6 | N10: =IF(N8="","",(M10+M11)) | O10: =IF(O8="","",(N10+N11)) | P10: =IF(P8="","",(O10+O11)) | Q10: =IF(Q8="","",(P10+P11)) | R10: =IF(R8="","",(Q10+Q11)) | S10: =IF(S8="","",(R10+R11)) | T10: =IF(T8="","",(S10+S11)) | U10: =IF(U8="","",(T10+T11)) | ... AS10: =IF(AS8="","",(AR10+AR11))
B11: 補充 | J11: 4 | M11: 2
B12: 単価 | C12: 715 | D12: 715 | E12: 715 | F12: 715 | G12: 715 | H12: 715 | I12: 715 | J12: 715 | K12: =IF(K8="","",J12) -> 715 | L12: =IF(L8="","",K12) -> 715 | M12: =IF(M8="","",L12) -> 715 | N12: =IF(N8="","",M12) | O12: =IF(O8="","",N12) | P12: =IF(P8="","",O12) | Q12: =IF(Q8="","",P12) | R12: =IF(R8="","",Q12) | ... AS12: =IF(AS8="","",AR12)
A13: 月間予想 | B13: 景品名 | C13: ミニファン | D13: ミニファン | E13: ミニファン | F13: ミニファン | G13: ミニファン | H13: ミニファン | I13: ミニファン | J13: ミニファン | K13: =IF(K8="","",J13) -> ミニファン | L13: =IF(L8="","",K13) -> ミニファン | M13: =IF(M8="","",L13) -> ミニファン | N13: =IF(N8="","",M13) | O13: =IF(O8="","",N13) | P13: =IF(P8="","",O13) | Q13: =IF(Q8="","",P13) | R13: =IF(R8="","",Q13) | ... AS13: =IF(AS8="","",AR13)
A14: =AVERAGE(C15:AS15)*30*100 -> 40363.636 | B14: 設定
A15: =SUM(C15:AS15) -> 148 | B15: 百差 | C15: 0 | D15: 0 | E15: 0 | F15: 45 | G15: 0 | H15: 0 | I15: 0 | J15: 63 | K15: =IF(K8="","",K8-J8) -> 0 | L15: =IF(L8="","",L8-K8) -> 0 | M15: =IF(M8="","",M8-L8) -> 40 | N15: =IF(N8="","",N8-M8) | O15: =IF(O8="","",O8-N8) | P15: =IF(P8="","",P8-O8) | Q15: =IF(Q8="","",Q8-P8) | R15: =IF(R8="","",R8-Q8) | ... AS15: =IF(AS8="","",AS8-AR8)
A16: =SUM(C16:AS16) -> 4 | B16: P差 | C16: 0 | D16: 0 | E16: 0 | F16: 0 | G16: 0 | H16: 0 | I16: 0 | J16: 3 | K16: =IF(K9="","",K9-J9) -> 0 | L16: =IF(L9="","",L9-K9) -> 0 | M16: =IF(M9="","",M9-L9) -> 1 | N16: =IF(N9="","",N9-M9) | O16: =IF(O9="","",O9-N9) | P16: =IF(P9="","",P9-O9) | Q16: =IF(Q9="","",Q9-P9) | R16: =IF(R9="","",R9-Q9) | ... AS16: =IF(AS9="","",AS9-AR9)
A17: =SUM(C17:AS17) -> 5 | B17: 払出 | C17: 0 | D17: 0 | E17: 0 | F17: 0 | G17: 0 | H17: 0 | I17: 0 | J17: 3 | K17: =IF(K10="","",J10+J11-K10) -> 0 | L17: =IF(L10="","",K10+K11-L10) -> 0 | M17: =IF(M10="","",L10+L11-M10) -> 2 | N17: =IF(N10="","",M10+M11-N10) | O17: =IF(O10="","",N10+N11-O10) | P17: =IF(P10="","",O10+O11-P10) | Q17: =IF(Q10="","",P10+P11-Q10) | R17: =IF(R10="","",Q10+Q11-R10) | ... AS17: =IF(AS10="","",AR10+AR11-AS10)
A18: =SUM(C18:AS18) -> 3575 | B18: 払出額 | C18: 0 | D18: 0 | E18: 0 | F18: 0 | G18: 0 | H18: 0 | I18: 0 | J18: 2145 | K18: =IF(K8="","",K17*K12) -> 0 | L18: =IF(L8="","",L17*L12) -> 0 | M18: =IF(M8="","",M17*M12) -> 1430 | N18: =IF(N8="","",N17*N12) | O18: =IF(O8="","",O17*O12) | P18: =IF(P8="","",P17*P12) | Q18: =IF(Q8="","",Q17*Q12) | R18: =IF(R8="","",R17*R12) | ... AS18: =IF(AS8="","",AS17*AS12)
A19: =IF(A18="","",A18/(A15*100)) -> 0.24155405 | B19: 原価率 | J19: 0.34047619 | K19: =IF(K18="","",IF(K18=0,"",K18/(K15*100))) | L19: =IF(L18="","",IF(L18=0,"",L18/(L15*100))) | M19: =IF(M18="","",IF(M18=0,"",M18/(M15*100))) -> 0.3575 | N19: =IF(N18="","",IF(N18=0,"",N18/(N15*100))) | O19: =IF(O18="","",IF(O18=0,"",O18/(O15*100))) | P19: =IF(P18="","",IF(P18=0,"",P18/(P15*100))) | Q19: =IF(Q18="","",IF(Q18=0,"",Q18/(Q15*100))) | R19: =IF(R18="","",IF(R18=0,"",R18/(R15*100))) | ... AS19: =IF(AS18="","",IF(AS18=0,"",AS18/(AS15*100)))
A20: 霧島 | B20: 100円 | C20: 18534 | D20: 18534 | E20: 18534 | F20: 18555 | G20: 18555 | H20: 18555 | I20: 18555 | J20: 18730 | K20: =IF(K$8="","",J20) -> 18730 | L20: =IF(L$8="","",K20) -> 18730 | M20: 18881 | N20: =IF(N$8="","",M20) | O20: =IF(O$8="","",N20) | P20: =IF(P$8="","",O20) | Q20: =IF(Q$8="","",P20) | R20: =IF(R$8="","",Q20) | S20: =IF(S$8="","",R20) | T20: =IF(T$8="","",S20) | U20: =IF(U$8="","",T20) | ... AS20: =IF(AS$8="","",AR20)
A21: BUZZミニ#2 | B21: プライズ | C21: 462 | D21: 462 | E21: 462 | F21: 462 | G21: 462 | H21: 462 | I21: 462 | J21: 467 | K21: =IF(K$8="","",J21) -> 467 | L21: =IF(L$8="","",K21) -> 467 | M21: 468 | N21: =IF(N$8="","",M21) | O21: =IF(O$8="","",N21) | P21: =IF(P$8="","",O21) | Q21: =IF(Q$8="","",P21) | R21: =IF(R$8="","",Q21) | S21: =IF(S$8="","",R21) | T21: =IF(T$8="","",S21) | U21: =IF(U$8="","",T21) | ... AS21: =IF(AS$8="","",AR21)
B22: 投入残 | C22: 33 | D22: 33 | E22: 33 | F22: 33 | G22: 9 | H22: 9 | I22: 9 | J22: 6 | K22: =IF(K20="","",(J22+J23)) -> 6 | L22: =IF(L20="","",(K22+K23)) -> 6 | M22: 5 | N22: =IF(N20="","",(M22+M23)) | O22: =IF(O20="","",(N22+N23)) | P22: =IF(P20="","",(O22+O23)) | Q22: =IF(Q20="","",(P22+P23)) | R22: =IF(R20="","",(Q22+Q23)) | S22: =IF(S20="","",(R22+R23)) | T22: =IF(T20="","",(S22+S23)) | U22: =IF(U20="","",(T22+T23)) | ... AS22: =IF(AS20="","",(AR22+AR23))
B23: 補充 | F23: -24 | M23: 4
B24: 単価 | C24: 700 | D24: 700 | E24: 700 | F24: 700 | G24: 700 | H24: 700 | I24: 700 | J24: 700 | K24: =IF(K20="","",J24) -> 700 | L24: =IF(L20="","",K24) -> 700 | M24: =IF(M20="","",L24) -> 700 | N24: =IF(N20="","",M24) | O24: =IF(O20="","",N24) | P24: =IF(P20="","",O24) | Q24: =IF(Q20="","",P24) | R24: =IF(R20="","",Q24) | ... AS24: =IF(AS20="","",AR24)
A25: 月間予想 | B25: 景品名 | C25: プクプクシール | D25: プクプクシール | E25: プクプクシール | F25: たまごっちボアケース | G25: たまごっちボアケース | H25: たまごっちボアケース | I25: たまごっちボアケース | J25: たまごっちボアケース | K25: =IF(K20="","",J25) -> たまごっちボアケース | L25: =IF(L20="","",K25) -> たまごっちボアケース | M25: =IF(M20="","",L25) -> たまごっちボアケース | N25: =IF(N20="","",M25) | O25: =IF(O20="","",N25) | P25: =IF(P20="","",O25) | Q25: =IF(Q20="","",P25) | R25: =IF(R20="","",Q25) | ... AS25: =IF(AS20="","",AR25)
A26: =AVERAGE(C27:AS27)*30*100 -> 94636.364 | B26: 設定
A27: =SUM(C27:AS27) -> 347 | B27: 百差 | C27: 0 | D27: 0 | E27: 0 | F27: 21 | G27: 0 | H27: 0 | I27: 0 | J27: 175 | K27: =IF(K20="","",K20-J20) -> 0 | L27: =IF(L20="","",L20-K20) -> 0 | M27: =IF(M20="","",M20-L20) -> 151 | N27: =IF(N20="","",N20-M20) | O27: =IF(O20="","",O20-N20) | P27: =IF(P20="","",P20-O20) | Q27: =IF(Q20="","",Q20-P20) | R27: =IF(R20="","",R20-Q20) | ... AS27: =IF(AS20="","",AS20-AR20)
A28: =SUM(C28:AS28) -> 6 | B28: P差 | C28: 0 | D28: 0 | E28: 0 | F28: 0 | G28: 0 | H28: 0 | I28: 0 | J28: 5 | K28: =IF(K21="","",K21-J21) -> 0 | L28: =IF(L21="","",L21-K21) -> 0 | M28: =IF(M21="","",M21-L21) -> 1 | N28: =IF(N21="","",N21-M21) | O28: =IF(O21="","",O21-N21) | P28: =IF(P21="","",P21-O21) | Q28: =IF(Q21="","",Q21-P21) | R28: =IF(R21="","",R21-Q21) | ... AS28: =IF(AS21="","",AS21-AR21)
A29: =SUM(C29:AS29) -> 4 | B29: 払出 | C29: 0 | D29: 0 | E29: 0 | F29: 0 | G29: 0 | H29: 0 | I29: 0 | J29: 3 | K29: =IF(K22="","",J22+J23-K22) -> 0 | L29: =IF(L22="","",K22+K23-L22) -> 0 | M29: =IF(M22="","",L22+L23-M22) -> 1 | N29: =IF(N22="","",M22+M23-N22) | O29: =IF(O22="","",N22+N23-O22) | P29: =IF(P22="","",O22+O23-P22) | Q29: =IF(Q22="","",P22+P23-Q22) | R29: =IF(R22="","",Q22+Q23-R22) | ... AS29: =IF(AS22="","",AR22+AR23-AS22)
A30: =SUM(C30:AS30) -> 2800 | B30: 払出額 | C30: 0 | D30: 0 | E30: 0 | F30: 0 | G30: 0 | H30: 0 | I30: 0 | J30: 2100 | K30: =IF(K20="","",K29*K24) -> 0 | L30: =IF(L20="","",L29*L24) -> 0 | M30: =IF(M20="","",M29*M24) -> 700 | N30: =IF(N20="","",N29*N24) | O30: =IF(O20="","",O29*O24) | P30: =IF(P20="","",P29*P24) | Q30: =IF(Q20="","",Q29*Q24) | R30: =IF(R20="","",R29*R24) | ... AS30: =IF(AS20="","",AS29*AS24)
A31: =IF(A30="","",A30/(A27*100)) -> 0.080691643 | B31: 原価率 | J31: 0.12 | K31: =IF(K30="","",IF(K30=0,"",K30/(K27*100))) | L31: =IF(L30="","",IF(L30=0,"",L30/(L27*100))) | M31: =IF(M30="","",IF(M30=0,"",M30/(M27*100))) -> 0.046357616 | N31: =IF(N30="","",IF(N30=0,"",N30/(N27*100))) | O31: =IF(O30="","",IF(O30=0,"",O30/(O27*100))) | P31: =IF(P30="","",IF(P30=0,"",P30/(P27*100))) | Q31: =IF(Q30="","",IF(Q30=0,"",Q30/(Q27*100))) | R31: =IF(R30="","",IF(R30=0,"",R30/(R27*100))) | ... AS31: =IF(AS30="","",IF(AS30=0,"",AS30/(AS27*100)))
A32: 霧島 | B32: 100円 | C32: 39813 | D32: 39813 | E32: 39813 | F32: 39875 | G32: 39875 | H32: 39875 | I32: 39875 | J32: 39953 | K32: =IF(K$8="","",J32) -> 39953 | L32: =IF(L$8="","",K32) -> 39953 | M32: 40023 | N32: =IF(N$8="","",M32) | O32: =IF(O$8="","",N32) | P32: =IF(P$8="","",O32) | Q32: =IF(Q$8="","",P32) | R32: =IF(R$8="","",Q32) | S32: =IF(S$8="","",R32) | T32: =IF(T$8="","",S32) | U32: =IF(U$8="","",T32) | ... AS32: =IF(AS$8="","",AR32)
A33: クリスタル | B33: プライズ | C33: 1061 | D33: 1061 | E33: 1061 | F33: 1065 | G33: 1065 | H33: 1065 | I33: 1065 | J33: 1069 | K33: =IF(K$8="","",J33) -> 1069 | L33: =IF(L$8="","",K33) -> 1069 | M33: 1072 | N33: =IF(N$8="","",M33) | O33: =IF(O$8="","",N33) | P33: =IF(P$8="","",O33) | Q33: =IF(Q$8="","",P33) | R33: =IF(R$8="","",Q33) | S33: =IF(S$8="","",R33) | T33: =IF(T$8="","",S33) | U33: =IF(U$8="","",T33) | ... AS33: =IF(AS$8="","",AR33)
B34: 投入残 | C34: 39 | D34: 39 | E34: 39 | F34: 35 | G34: 35 | H34: 35 | I34: 35 | J34: 31 | K34: =IF(K32="","",(J34+J35)) -> 31 | L34: =IF(L32="","",(K34+K35)) -> 31 | M34: 28 | N34: =IF(N32="","",(M34+M35)) | O34: =IF(O32="","",(N34+N35)) | P34: =IF(P32="","",(O34+O35)) | Q34: =IF(Q32="","",(P34+P35)) | R34: =IF(R32="","",(Q34+Q35)) | S34: =IF(S32="","",(R34+R35)) | T34: =IF(T32="","",(S34+S35)) | U34: =IF(U32="","",(T34+T35)) | ... AS34: =IF(AS32="","",(AR34+AR35))
B35: 補充
B36: 単価 | C36: 400 | D36: 400 | E36: 400 | F36: 400 | G36: 400 | H36: 400 | I36: 400 | J36: 400 | K36: =IF(K32="","",J36) -> 400 | L36: =IF(L32="","",K36) -> 400 | M36: =IF(M32="","",L36) -> 400 | N36: =IF(N32="","",M36) | O36: =IF(O32="","",N36) | P36: =IF(P32="","",O36) | Q36: =IF(Q32="","",P36) | R36: =IF(R32="","",Q36) | ... AS36: =IF(AS32="","",AR36)
A37: 月間予想 | B37: 景品名 | C37: サムエル（箱無し） | D37: サムエル（箱無し） | E37: サムエル（箱無し） | F37: サムエル（箱無し） | G37: サムエル（箱無し） | H37: サムエル（箱無し） | I37: サムエル（箱無し） | J37: サムエル（箱無し） | K37: =IF(K32="","",J37) -> サムエル（箱無し） | L37: =IF(L32="","",K37) -> サムエル（箱無し） | M37: =IF(M32="","",L37) -> サムエル（箱無し） | N37: =IF(N32="","",M37) | O37: =IF(O32="","",N37) | P37: =IF(P32="","",O37) | Q37: =IF(Q32="","",P37) | R37: =IF(R32="","",Q37) | ... AS37: =IF(AS32="","",AR37)
A38: =AVERAGE(C39:AS39)*30*100 -> 57272.727 | B38: 設定
A39: =SUM(C39:AS39) -> 210 | B39: 百差 | C39: 0 | D39: 0 | E39: 0 | F39: 62 | G39: 0 | H39: 0 | I39: 0 | J39: 78 | K39: =IF(K32="","",K32-J32) -> 0 | L39: =IF(L32="","",L32-K32) -> 0 | M39: =IF(M32="","",M32-L32) -> 70 | N39: =IF(N32="","",N32-M32) | O39: =IF(O32="","",O32-N32) | P39: =IF(P32="","",P32-O32) | Q39: =IF(Q32="","",Q32-P32) | R39: =IF(R32="","",R32-Q32) | ... AS39: =IF(AS32="","",AS32-AR32)
A40: =SUM(C40:AS40) -> 11 | B40: P差 | C40: 0 | D40: 0 | E40: 0 | F40: 4 | G40: 0 | H40: 0 | I40: 0 | J40: 4 | K40: =IF(K33="","",K33-J33) -> 0 | L40: =IF(L33="","",L33-K33) -> 0 | M40: =IF(M33="","",M33-L33) -> 3 | N40: =IF(N33="","",N33-M33) | O40: =IF(O33="","",O33-N33) | P40: =IF(P33="","",P33-O33) | Q40: =IF(Q33="","",Q33-P33) | R40: =IF(R33="","",R33-Q33) | ... AS40: =IF(AS33="","",AS33-AR33)
...

Sheet 宇宿
A1: =SUM(A14,A50,A62,A74,A86,A98,A110,A122,A134,A158,A146,A170,A182,A194,A206,A218,A230,A38,A26,A242,A254) -> 935727.27 | B1: 日付 | C1: 46156 | D1: 46157 | E1: 46158 | F1: 46159 | G1: 46160 | H1: 46161 | I1: 46162 | J1: 46163 | K1: 46164 | L1: =K1+1 -> 46165 | M1: =L1+1 -> 46166 | N1: =M1+1 -> 46167 | O1: =N1+1 -> 46168 | P1: =O1+1 -> 46169 | Q1: =P1+1 -> 46170 | R1: =Q1+1 -> 46171 | S1: =R1+1 -> 46172 | ... AS1: =AR1+1 -> 46198
B2: =SUM(C2:AO2) -> 3220 | C2: 0 | D2: 565 | E2: 0 | F2: 0 | G2: 1029 | H2: 0 | I2: 0 | J2: 0 | K2: 876 | L2: =SUM(L15,L27,L39,L51,L63,L75,L87,L99,L111,L123,L135,L147,L159,L171,L183,L195,L207,L219,L231,L245) -> 0 | M2: =SUM(M15,M27,M39,M51,M63,M75,M87,M99,M111,M123,M135,M147,M159,M171,M183,M195,M207,M219,M231,M245) -> 750 | N2: =SUM(N15,N27,N39,N51,N63,N75,N87,N99,N111,N123,N135,N147,N159,N171,N183,N195,N207,N219,N231,N245) -> 0 | O2: =SUM(O15,O27,O39,O51,O63,O75,O87,O99,O111,O123,O135,O147,O159,O171,O183,O195,O207,O219,O231,O245) -> 0 | P2: =SUM(P15,P27,P39,P51,P63,P75,P87,P99,P111,P123,P135,P147,P159,P171,P183,P195,P207,P219,P231,P245) -> 0 | Q2: =SUM(Q15,Q27,Q39,Q51,Q63,Q75,Q87,Q99,Q111,Q123,Q135,Q147,Q159,Q171,Q183,Q195,Q207,Q219,Q231,Q245) -> 0 | R2: =SUM(R15,R27,R39,R51,R63,R75,R87,R99,R111,R123,R135,R147,R159,R171,R183,R195,R207,R219,R231,R245) -> 0 | S2: =SUM(S15,S27,S39,S51,S63,S75,S87,S99,S111,S123,S135,S147,S159,S171,S183,S195,S207,S219,S231,S245) -> 0 | ... AS2: =SUM(AS15,AS27,AS39,AS51,AS63,AS75,AS87,AS99,AS111,AS123,AS135,AS147,AS159,AS171,AS183,AS195,AS207,AS219,AS231,AS245) -> 0
A3: 集金
A4: 両替機
A5: 百出 | D5: 260 | G5: 695 | K5: 1075 | M5: 455
A6: 札入 | D6: 23 | G6: 62 | K6: 94 | M6: 125
A7: 五入 | D7: 6 | G7: 15 | K7: 27 | M7: 41
A8: 宇宿 | B8: 100円 | C8: 17345 | D8: 17364 | E8: 17364 | F8: 17364 | G8: 17408 | H8: 17408 | I8: 17408 | J8: 17408 | K8: 17423 | L8: 17423 | M8: 17446
A9: BUZZ＃１ | B9: プライズ | C9: 433 | D9: 433 | E9: 433 | F9: 433 | G9: 433 | H9: 433 | I9: 433 | J9: 433 | K9: 433 | L9: =IF(L$8="","",K9) -> 433 | M9: 435 | N9: =IF(N$8="","",M9) | O9: =IF(O$8="","",N9) | P9: =IF(P$8="","",O9) | Q9: =IF(Q$8="","",P9) | R9: =IF(R$8="","",Q9) | S9: =IF(S$8="","",R9) | T9: =IF(T$8="","",S9) | U9: =IF(U$8="","",T9) | ... AS9: =IF(AS$8="","",AR9)
A10: 1 | B10: 投入残 | C10: 15 | D10: 15 | E10: 15 | F10: 15 | G10: 15 | H10: 15 | I10: 15 | J10: 15 | K10: 15 | L10: =IF(L8="","",(K10+K11)) -> 15 | M10: 13 | N10: =IF(N8="","",(M10+M11)) | O10: =IF(O8="","",(N10+N11)) | P10: =IF(P8="","",(O10+O11)) | Q10: =IF(Q8="","",(P10+P11)) | R10: =IF(R8="","",(Q10+Q11)) | S10: =IF(S8="","",(R10+R11)) | T10: =IF(T8="","",(S10+S11)) | U10: =IF(U8="","",(T10+T11)) | ... AS10: =IF(AS8="","",(AR10+AR11))
A11: 機械合計 | B11: 補充
A12: =+(A15+A27+A39+A51)*100 -> 45300 | B12: 単価 | C12: 500 | D12: 500 | E12: 500 | F12: 500 | G12: 500 | H12: 500 | I12: 500 | J12: 500 | K12: 500 | L12: =IF(L8="","",K12) -> 500 | M12: =IF(M8="","",L12) -> 500 | N12: =IF(N8="","",M12) | O12: =IF(O8="","",N12) | P12: =IF(P8="","",O12) | Q12: =IF(Q8="","",P12) | R12: =IF(R8="","",Q12) | S12: =IF(S8="","",R12) | ... AS12: =IF(AS8="","",AR12)
A13: 月間予想 | B13: 景品名 | C13: バタースクイーズ | D13: バタースクイーズ | E13: バタースクイーズ | F13: バタースクイーズ | G13: バタースクイーズ | H13: バタースクイーズ | I13: バタースクイーズ | J13: バタースクイーズ | K13: バタースクイーズ | L13: =IF(L8="","",K13) -> バタースクイーズ | M13: =IF(M8="","",L13) -> バタースクイーズ | N13: =IF(N8="","",M13) | O13: =IF(O8="","",N13) | P13: =IF(P8="","",O13) | Q13: =IF(Q8="","",P13) | R13: =IF(R8="","",Q13) | S13: =IF(S8="","",R13) | ... AS13: =IF(AS8="","",AR13)
A14: =AVERAGE(C15:AS15)*30*100 -> 27545.455 | B14: 設定
A15: =SUM(C15:AS15) -> 101 | B15: 百差 | C15: 0 | D15: 19 | E15: 0 | F15: 0 | G15: 44 | H15: 0 | I15: 0 | J15: 0 | K15: 15 | L15: =IF(L8="","",L8-K8) -> 0 | M15: =IF(M8="","",M8-L8) -> 23 | N15: =IF(N8="","",N8-M8) | O15: =IF(O8="","",O8-N8) | P15: =IF(P8="","",P8-O8) | Q15: =IF(Q8="","",Q8-P8) | R15: =IF(R8="","",R8-Q8) | S15: =IF(S8="","",S8-R8) | ... AS15: =IF(AS8="","",AS8-AR8)
A16: =SUM(C16:AS16) -> 2 | B16: P差 | C16: 0 | D16: 0 | E16: 0 | F16: 0 | G16: 0 | H16: 0 | I16: 0 | J16: 0 | K16: 0 | L16: =IF(L9="","",L9-K9) -> 0 | M16: =IF(M9="","",M9-L9) -> 2 | N16: =IF(N9="","",N9-M9) | O16: =IF(O9="","",O9-N9) | P16: =IF(P9="","",P9-O9) | Q16: =IF(Q9="","",Q9-P9) | R16: =IF(R9="","",R9-Q9) | S16: =IF(S9="","",S9-R9) | ... AS16: =IF(AS9="","",AS9-AR9)
A17: =SUM(C17:AS17) -> 2 | B17: 払出 | C17: 0 | D17: 0 | E17: 0 | F17: 0 | G17: 0 | H17: 0 | I17: 0 | J17: 0 | K17: 0 | L17: =IF(L10="","",K10+K11-L10) -> 0 | M17: =IF(M10="","",L10+L11-M10) -> 2 | N17: =IF(N10="","",M10+M11-N10) | O17: =IF(O10="","",N10+N11-O10) | P17: =IF(P10="","",O10+O11-P10) | Q17: =IF(Q10="","",P10+P11-Q10) | R17: =IF(R10="","",Q10+Q11-R10) | S17: =IF(S10="","",R10+R11-S10) | ... AS17: =IF(AS10="","",AR10+AR11-AS10)
A18: =SUM(C18:AS18) -> 1000 | B18: 払出額 | C18: 0 | D18: 0 | E18: 0 | F18: 0 | G18: 0 | H18: 0 | I18: 0 | J18: 0 | K18: 0 | L18: =IF(L8="","",L17*L12) -> 0 | M18: =IF(M8="","",M17*M12) -> 1000 | N18: =IF(N8="","",N17*N12) | O18: =IF(O8="","",O17*O12) | P18: =IF(P8="","",P17*P12) | Q18: =IF(Q8="","",Q17*Q12) | R18: =IF(R8="","",R17*R12) | S18: =IF(S8="","",S17*S12) | ... AS18: =IF(AS8="","",AS17*AS12)
A19: =IF(A18="","",A18/(A15*100)) -> 0.099009901 | B19: 原価率 | L19: =IF(L18="","",IF(L18=0,"",L18/(L15*100))) | M19: =IF(M18="","",IF(M18=0,"",M18/(M15*100))) -> 0.43478261 | N19: =IF(N18="","",IF(N18=0,"",N18/(N15*100))) | O19: =IF(O18="","",IF(O18=0,"",O18/(O15*100))) | P19: =IF(P18="","",IF(P18=0,"",P18/(P15*100))) | Q19: =IF(Q18="","",IF(Q18=0,"",Q18/(Q15*100))) | R19: =IF(R18="","",IF(R18=0,"",R18/(R15*100))) | S19: =IF(S18="","",IF(S18=0,"",S18/(S15*100))) | ... AS19: =IF(AS18="","",IF(AS18=0,"",AS18/(AS15*100)))
A20: 宇宿 | B20: 100円 | C20: 19113 | D20: 19141 | E20: 19141 | F20: 19141 | G20: 19166 | H20: 19166 | I20: 19166 | J20: 19166 | K20: 19174 | L20: =IF(L$8="","",K20) -> 19174 | M20: 19210 | N20: =IF(N$8="","",M20) | O20: =IF(O$8="","",N20) | P20: =IF(P$8="","",O20) | Q20: =IF(Q$8="","",P20) | R20: =IF(R$8="","",Q20) | S20: =IF(S$8="","",R20) | T20: =IF(T$8="","",S20) | U20: =IF(U$8="","",T20) | ... AS20: =IF(AS$8="","",AR20)
A21: BUZZ＃１ | B21: プライズ | C21: 432 | D21: 435 | E21: 435 | F21: 435 | G21: 435 | H21: 435 | I21: 435 | J21: 435 | K21: 435 | L21: =IF(L$8="","",K21) -> 435 | M21: 438 | N21: =IF(N$8="","",M21) | O21: =IF(O$8="","",N21) | P21: =IF(P$8="","",O21) | Q21: =IF(Q$8="","",P21) | R21: =IF(R$8="","",Q21) | S21: =IF(S$8="","",R21) | T21: =IF(T$8="","",S21) | U21: =IF(U$8="","",T21) | ... AS21: =IF(AS$8="","",AR21)
A22: 2 | B22: 投入残 | C22: 42 | D22: 39 | E22: 39 | F22: 39 | G22: 39 | H22: 39 | I22: 39 | J22: 39 | K22: 39 | L22: =IF(L20="","",(K22+K23)) -> 39 | M22: 36 | N22: =IF(N20="","",(M22+M23)) | O22: =IF(O20="","",(N22+N23)) | P22: =IF(P20="","",(O22+O23)) | Q22: =IF(Q20="","",(P22+P23)) | R22: =IF(R20="","",(Q22+Q23)) | S22: =IF(S20="","",(R22+R23)) | T22: =IF(T20="","",(S22+S23)) | U22: =IF(U20="","",(T22+T23)) | ... AS22: =IF(AS20="","",(AR22+AR23))
B23: 補充
B24: 単価 | C24: 682 | D24: 682 | E24: 682 | F24: 682 | G24: 682 | H24: 682 | I24: 682 | J24: 682 | K24: 682 | L24: =IF(L20="","",K24) -> 682 | M24: =IF(M20="","",L24) -> 682 | N24: =IF(N20="","",M24) | O24: =IF(O20="","",N24) | P24: =IF(P20="","",O24) | Q24: =IF(Q20="","",P24) | R24: =IF(R20="","",Q24) | S24: =IF(S20="","",R24) | ... AS24: =IF(AS20="","",AR24)
A25: 月間予想 | B25: 景品名 | C25: ミニスクイーズ | D25: ミニスクイーズ | E25: ミニスクイーズ | F25: ミニスクイーズ | G25: ミニスクイーズ | H25: ミニスクイーズ | I25: ミニスクイーズ | J25: ミニスクイーズ | K25: ミニスクイーズ | L25: =IF(L20="","",K25) -> ミニスクイーズ | M25: =IF(M20="","",L25) -> ミニスクイーズ | N25: =IF(N20="","",M25) | O25: =IF(O20="","",N25) | P25: =IF(P20="","",O25) | Q25: =IF(Q20="","",P25) | R25: =IF(R20="","",Q25) | S25: =IF(S20="","",R25) | ... AS25: =IF(AS20="","",AR25)
A26: =AVERAGE(C27:AS27)*30*100 -> 26454.545 | B26: 設定
A27: =SUM(C27:AS27) -> 97 | B27: 百差 | C27: 0 | D27: 28 | E27: 0 | F27: 0 | G27: 25 | H27: 0 | I27: 0 | J27: 0 | K27: 8 | L27: =IF(L20="","",L20-K20) -> 0 | M27: =IF(M20="","",M20-L20) -> 36 | N27: =IF(N20="","",N20-M20) | O27: =IF(O20="","",O20-N20) | P27: =IF(P20="","",P20-O20) | Q27: =IF(Q20="","",Q20-P20) | R27: =IF(R20="","",R20-Q20) | S27: =IF(S20="","",S20-R20) | ... AS27: =IF(AS20="","",AS20-AR20)
A28: =SUM(C28:AS28) -> 6 | B28: P差 | C28: 0 | D28: 3 | E28: 0 | F28: 0 | G28: 0 | H28: 0 | I28: 0 | J28: 0 | K28: 0 | L28: =IF(L21="","",L21-K21) -> 0 | M28: =IF(M21="","",M21-L21) -> 3 | N28: =IF(N21="","",N21-M21) | O28: =IF(O21="","",O21-N21) | P28: =IF(P21="","",P21-O21) | Q28: =IF(Q21="","",Q21-P21) | R28: =IF(R21="","",R21-Q21) | S28: =IF(S21="","",S21-R21) | ... AS28: =IF(AS21="","",AS21-AR21)
A29: =SUM(C29:AS29) -> 6 | B29: 払出 | C29: 0 | D29: 3 | E29: 0 | F29: 0 | G29: 0 | H29: 0 | I29: 0 | J29: 0 | K29: 0 | L29: =IF(L22="","",K22+K23-L22) -> 0 | M29: =IF(M22="","",L22+L23-M22) -> 3 | N29: =IF(N22="","",M22+M23-N22) | O29: =IF(O22="","",N22+N23-O22) | P29: =IF(P22="","",O22+O23-P22) | Q29: =IF(Q22="","",P22+P23-Q22) | R29: =IF(R22="","",Q22+Q23-R22) | S29: =IF(S22="","",R22+R23-S22) | ... AS29: =IF(AS22="","",AR22+AR23-AS22)
A30: =SUM(C30:AS30) -> 4092 | B30: 払出額 | C30: 0 | D30: 2046 | E30: 0 | F30: 0 | G30: 0 | H30: 0 | I30: 0 | J30: 0 | K30: 0 | L30: =IF(L20="","",L29*L24) -> 0 | M30: =IF(M20="","",M29*M24) -> 2046 | N30: =IF(N20="","",N29*N24) | O30: =IF(O20="","",O29*O24) | P30: =IF(P20="","",P29*P24) | Q30: =IF(Q20="","",Q29*Q24) | R30: =IF(R20="","",R29*R24) | S30: =IF(S20="","",S29*S24) | ... AS30: =IF(AS20="","",AS29*AS24)
A31: =IF(A30="","",A30/(A27*100)) -> 0.42185567 | B31: 原価率 | D31: 0.73071429 | L31: =IF(L30="","",IF(L30=0,"",L30/(L27*100))) | M31: =IF(M30="","",IF(M30=0,"",M30/(M27*100))) -> 0.56833333 | N31: =IF(N30="","",IF(N30=0,"",N30/(N27*100))) | O31: =IF(O30="","",IF(O30=0,"",O30/(O27*100))) | P31: =IF(P30="","",IF(P30=0,"",P30/(P27*100))) | Q31: =IF(Q30="","",IF(Q30=0,"",Q30/(Q27*100))) | R31: =IF(R30="","",IF(R30=0,"",R30/(R27*100))) | S31: =IF(S30="","",IF(S30=0,"",S30/(S27*100))) | ... AS31: =IF(AS30="","",IF(AS30=0,"",AS30/(AS27*100)))
A32: 宇宿 | B32: 100円 | C32: 14323 | D32: 14339 | E32: 14339 | F32: 14339 | G32: 14345 | H32: 14345 | I32: 14345 | J32: 14345 | K32: 14372 | L32: =IF(L$8="","",K32) -> 14372 | M32: 14432 | N32: =IF(N$8="","",M32) | O32: =IF(O$8="","",N32) | P32: =IF(P$8="","",O32) | Q32: =IF(Q$8="","",P32) | R32: =IF(R$8="","",Q32) | S32: =IF(S$8="","",R32) | T32: =IF(T$8="","",S32) | U32: =IF(U$8="","",T32) | ... AS32: =IF(AS$8="","",AR32)
A33: BUZZ＃１ | B33: プライズ | C33: 495 | D33: 495 | E33: 495 | F33: 495 | G33: 495 | H33: 495 | I33: 495 | J33: 495 | K33: 497 | L33: =IF(L$8="","",K33) -> 497 | M33: 497 | N33: =IF(N$8="","",M33) | O33: =IF(O$8="","",N33) | P33: =IF(P$8="","",O33) | Q33: =IF(Q$8="","",P33) | R33: =IF(R$8="","",Q33) | S33: =IF(S$8="","",R33) | T33: =IF(T$8="","",S33) | U33: =IF(U$8="","",T33) | ... AS33: =IF(AS$8="","",AR33)
A34: 3 | B34: 投入残 | C34: 21 | D34: 21 | E34: 21 | F34: 21 | G34: 21 | H34: 21 | I34: 21 | J34: 21 | K34: 19 | L34: =IF(L32="","",(K34+K35)) -> 19 | M34: =IF(M32="","",(L34+L35)) -> 19 | N34: =IF(N32="","",(M34+M35)) | O34: =IF(O32="","",(N34+N35)) | P34: =IF(P32="","",(O34+O35)) | Q34: =IF(Q32="","",(P34+P35)) | R34: =IF(R32="","",(Q34+Q35)) | S34: =IF(S32="","",(R34+R35)) | ... AS34: =IF(AS32="","",(AR34+AR35))
B35: 補充
B36: 単価 | C36: 750 | D36: 750 | E36: 750 | F36: 750 | G36: 750 | H36: 750 | I36: 750 | J36: 750 | K36: 750 | L36: =IF(L32="","",K36) -> 750 | M36: =IF(M32="","",L36) -> 750 | N36: =IF(N32="","",M36) | O36: =IF(O32="","",N36) | P36: =IF(P32="","",O36) | Q36: =IF(Q32="","",P36) | R36: =IF(R32="","",Q36) | S36: =IF(S32="","",R36) | ... AS36: =IF(AS32="","",AR36)
A37: 月間予想 | B37: 景品名 | C37: NICI | D37: NICI | E37: NICI | F37: NICI | G37: NICI | H37: NICI | I37: NICI | J37: NICI | K37: NICI | L37: =IF(L32="","",K37) -> NICI | M37: =IF(M32="","",L37) -> NICI | N37: =IF(N32="","",M37) | O37: =IF(O32="","",N37) | P37: =IF(P32="","",O37) | Q37: =IF(Q32="","",P37) | R37: =IF(R32="","",Q37) | S37: =IF(S32="","",R37) | ... AS37: =IF(AS32="","",AR37)
A38: =AVERAGE(C39:AS39)*30*100 -> 29727.273 | B38: 設定
A39: =SUM(C39:AS39) -> 109 | B39: 百差 | C39: 0 | D39: 16 | E39: 0 | F39: 0 | G39: 6 | H39: 0 | I39: 0 | J39: 0 | K39: 27 | L39: =IF(L32="","",L32-K32) -> 0 | M39: =IF(M32="","",M32-L32) -> 60 | N39: =IF(N32="","",N32-M32) | O39: =IF(O32="","",O32-N32) | P39: =IF(P32="","",P32-O32) | Q39: =IF(Q32="","",Q32-P32) | R39: =IF(R32="","",R32-Q32) | S39: =IF(S32="","",S32-R32) | ... AS39: =IF(AS32="","",AS32-AR32)
A40: =SUM(C40:AS40) -> 2 | B40: P差 | C40: 0 | D40: 0 | E40: 0 | F40: 0 | G40: 0 | H40: 0 | I40: 0 | J40: 0 | K40: 2 | L40: =IF(L33="","",L33-K33) -> 0 | M40: =IF(M33="","",M33-L33) -> 0 | N40: =IF(N33="","",N33-M33) | O40: =IF(O33="","",O33-N33) | P40: =IF(P33="","",P33-O33) | Q40: =IF(Q33="","",Q33-P33) | R40: =IF(R33="","",R33-Q33) | S40: =IF(S33="","",S33-R33) | ... AS40: =IF(AS33="","",AS33-AR33)
...

Sheet 川内
A1: =SUM(A14,A50,A62,A74,A86,A98,A110,A122,A134,A158,A146,A170,A182,A194,A206,A218,A230,A38,A26,A244) -> 1416692.3 | B1: 日付 | C1: 46155 | D1: 46156 | E1: 46157 | F1: 46158 | G1: 46159 | H1: 46160 | I1: 46161 | J1: 46162 | K1: 46163 | L1: 46164 | M1: =L1+1 -> 46165 | N1: =M1+1 -> 46166 | O1: =N1+1 -> 46167 | P1: =O1+1 -> 46168 | Q1: =P1+1 -> 46169 | R1: =Q1+1 -> 46170 | S1: =R1+1 -> 46171 | T1: =S1+1 -> 46172 | ... AS1: =AR1+1 -> 46197
B2: =SUM(C2:AO2) -> 6139 | C2: 0 | D2: 0 | E2: 1169 | F2: 0 | G2: 0 | H2: 1925 | I2: 0 | J2: 0 | K2: 0 | L2: 1702 | M2: =SUM(M15,M27,M39,M51,M63,M75,M87,M99,M111,M123,M135,M147,M159,M171,M183,M195,M207,M219,M231,M245) -> 0 | N2: =SUM(N15,N27,N39,N51,N63,N75,N87,N99,N111,N123,N135,N147,N159,N171,N183,N195,N207,N219,N231,N245) -> 0 | O2: =SUM(O15,O27,O39,O51,O63,O75,O87,O99,O111,O123,O135,O147,O159,O171,O183,O195,O207,O219,O231,O245) -> 1343 | P2: =SUM(P15,P27,P39,P51,P63,P75,P87,P99,P111,P123,P135,P147,P159,P171,P183,P195,P207,P219,P231,P245) -> 0 | Q2: =SUM(Q15,Q27,Q39,Q51,Q63,Q75,Q87,Q99,Q111,Q123,Q135,Q147,Q159,Q171,Q183,Q195,Q207,Q219,Q231,Q245) -> 0 | R2: =SUM(R15,R27,R39,R51,R63,R75,R87,R99,R111,R123,R135,R147,R159,R171,R183,R195,R207,R219,R231,R245) -> 0 | S2: =SUM(S15,S27,S39,S51,S63,S75,S87,S99,S111,S123,S135,S147,S159,S171,S183,S195,S207,S219,S231,S245) -> 0 | T2: =SUM(T15,T27,T39,T51,T63,T75,T87,T99,T111,T123,T135,T147,T159,T171,T183,T195,T207,T219,T231,T245) -> 0 | ... AS2: =SUM(AS15,AS27,AS39,AS51,AS63,AS75,AS87,AS99,AS111,AS123,AS135,AS147,AS159,AS171,AS183,AS195,AS207,AS219,AS231,AS245) -> 0
A3: 集金
A4: 両替機
A5: 百出 | E5: 1915 | H5: 3660 | L5: 6505 | O5: 8165
A6: 札入 | E6: 144 | H6: 272 | L6: 499 | O6: 626
A7: 五入 | E7: 95 | H7: 188 | L7: 303 | O7: 381
A8: 川内 | B8: 100円 | C8: 36383 | D8: 36383 | E8: 36430 | F8: 36430 | G8: 36430 | H8: 36517 | I8: 36517 | J8: 36517 | K8: 36517 | L8: 36663 | M8: 36663 | N8: 36663 | O8: 36770
A9: BUZZ＃１ | B9: プライズ | C9: 691 | D9: 691 | E9: 692 | F9: 692 | G9: 692 | H9: 694 | I9: 694 | J9: 694 | K9: 694 | L9: 697 | M9: =IF(M$8="","",L9) -> 697 | N9: =IF(N$8="","",M9) -> 697 | O9: 699 | P9: =IF(P$8="","",O9) | Q9: =IF(Q$8="","",P9) | R9: =IF(R$8="","",Q9) | S9: =IF(S$8="","",R9) | T9: =IF(T$8="","",S9) | U9: =IF(U$8="","",T9) | V9: =IF(V$8="","",U9) | W9: =IF(W$8="","",V9) | ... AS9: =IF(AS$8="","",AR9)
A10: 1 | B10: 投入残 | C10: 6 | D10: 6 | E10: 5 | F10: 9 | G10: 9 | H10: 8 | I10: 8 | J10: 8 | K10: 8 | L10: 5 | M10: =IF(M8="","",(L10+L11)) -> 5 | N10: =IF(N8="","",(M10+M11)) -> 5 | O10: 6 | P10: =IF(P8="","",(O10+O11)) | Q10: =IF(Q8="","",(P10+P11)) | R10: =IF(R8="","",(Q10+Q11)) | S10: =IF(S8="","",(R10+R11)) | T10: =IF(T8="","",(S10+S11)) | U10: =IF(U8="","",(T10+T11)) | V10: =IF(V8="","",(U10+U11)) | W10: =IF(W8="","",(V10+V11)) | ... AS10: =IF(AS8="","",(AR10+AR11))
A11: 機械合計 | B11: 補充 | E11: 4 | N11: 3 | O11: 5
A12: =+(A15+A27+A39+A51)*100 -> 119400 | B12: 単価 | C12: 800 | D12: 800 | E12: 800 | F12: 800 | G12: 800 | H12: 800 | I12: 800 | J12: 800 | K12: 800 | L12: 800 | M12: =IF(M8="","",L12) -> 800 | N12: =IF(N8="","",M12) -> 800 | O12: =IF(O8="","",N12) -> 800 | P12: =IF(P8="","",O12) | Q12: =IF(Q8="","",P12) | R12: =IF(R8="","",Q12) | S12: =IF(S8="","",R12) | T12: =IF(T8="","",S12) | ... AS12: =IF(AS8="","",AR12)
A13: 月間予想 | B13: 景品名 | C13: たまごっちミニポシェット | D13: たまごっちミニポシェット | E13: たまごっちミニポシェット | F13: たまごっちミニポシェット | G13: たまごっちミニポシェット | H13: たまごっちミニポシェット | I13: たまごっちミニポシェット | J13: たまごっちミニポシェット | K13: たまごっちミニポシェット | L13: たまごっちミニポシェット | M13: =IF(M8="","",L13) -> たまごっちミニポシェット | N13: =IF(N8="","",M13) -> たまごっちミニポシェット | O13: =IF(O8="","",N13) -> たまごっちミニポシェット | P13: =IF(P8="","",O13) | Q13: =IF(Q8="","",P13) | R13: =IF(R8="","",Q13) | S13: =IF(S8="","",R13) | T13: =IF(T8="","",S13) | ... AS13: =IF(AS8="","",AR13)
A14: =AVERAGE(C15:AS15)*30*100 -> 89307.692 | B14: 設定
A15: =SUM(C15:AS15) -> 387 | B15: 百差 | C15: 0 | D15: 0 | E15: 47 | F15: 0 | G15: 0 | H15: 87 | I15: 0 | J15: 0 | K15: 0 | L15: 146 | M15: =IF(M8="","",M8-L8) -> 0 | N15: =IF(N8="","",N8-M8) -> 0 | O15: =IF(O8="","",O8-N8) -> 107 | P15: =IF(P8="","",P8-O8) | Q15: =IF(Q8="","",Q8-P8) | R15: =IF(R8="","",R8-Q8) | S15: =IF(S8="","",S8-R8) | T15: =IF(T8="","",T8-S8) | ... AS15: =IF(AS8="","",AS8-AR8)
A16: =SUM(C16:AS16) -> 8 | B16: P差 | C16: 0 | D16: 0 | E16: 1 | F16: 0 | G16: 0 | H16: 2 | I16: 0 | J16: 0 | K16: 0 | L16: 3 | M16: =IF(M9="","",M9-L9) -> 0 | N16: =IF(N9="","",N9-M9) -> 0 | O16: =IF(O9="","",O9-N9) -> 2 | P16: =IF(P9="","",P9-O9) | Q16: =IF(Q9="","",Q9-P9) | R16: =IF(R9="","",R9-Q9) | S16: =IF(S9="","",S9-R9) | T16: =IF(T9="","",T9-S9) | ... AS16: =IF(AS9="","",AS9-AR9)
A17: =SUM(C17:AS17) -> 7 | B17: 払出 | C17: 0 | D17: 0 | E17: 1 | F17: 0 | G17: 0 | H17: 1 | I17: 0 | J17: 0 | K17: 0 | L17: 3 | M17: =IF(M10="","",L10+L11-M10) -> 0 | N17: =IF(N10="","",M10+M11-N10) -> 0 | O17: =IF(O10="","",N10+N11-O10) -> 2 | P17: =IF(P10="","",O10+O11-P10) | Q17: =IF(Q10="","",P10+P11-Q10) | R17: =IF(R10="","",Q10+Q11-R10) | S17: =IF(S10="","",R10+R11-S10) | T17: =IF(T10="","",S10+S11-T10) | ... AS17: =IF(AS10="","",AR10+AR11-AS10)
A18: =SUM(C18:AS18) -> 5600 | B18: 払出額 | C18: 0 | D18: 0 | E18: 800 | F18: 0 | G18: 0 | H18: 800 | I18: 0 | J18: 0 | K18: 0 | L18: 2400 | M18: =IF(M8="","",M17*M12) -> 0 | N18: =IF(N8="","",N17*N12) -> 0 | O18: =IF(O8="","",O17*O12) -> 1600 | P18: =IF(P8="","",P17*P12) | Q18: =IF(Q8="","",Q17*Q12) | R18: =IF(R8="","",R17*R12) | S18: =IF(S8="","",S17*S12) | T18: =IF(T8="","",T17*T12) | ... AS18: =IF(AS8="","",AS17*AS12)
A19: =IF(A18="","",A18/(A15*100)) -> 0.14470284 | B19: 原価率 | E19: 0.17021277 | H19: 0.091954023 | L19: 0.16438356 | M19: =IF(M18="","",IF(M18=0,"",M18/(M15*100))) | N19: =IF(N18="","",IF(N18=0,"",N18/(N15*100))) | O19: =IF(O18="","",IF(O18=0,"",O18/(O15*100))) -> 0.14953271 | P19: =IF(P18="","",IF(P18=0,"",P18/(P15*100))) | Q19: =IF(Q18="","",IF(Q18=0,"",Q18/(Q15*100))) | R19: =IF(R18="","",IF(R18=0,"",R18/(R15*100))) | S19: =IF(S18="","",IF(S18=0,"",S18/(S15*100))) | T19: =IF(T18="","",IF(T18=0,"",T18/(T15*100))) | ... AS19: =IF(AS18="","",IF(AS18=0,"",AS18/(AS15*100)))
A20: 川内 | B20: 100円 | C20: 39810 | D20: 39810 | E20: 39817 | F20: 39817 | G20: 39817 | H20: 39828 | I20: 39828 | J20: 39828 | K20: 39828 | L20: 39845 | M20: =IF(M$8="","",L20) -> 39845 | N20: =IF(N$8="","",M20) -> 39845 | O20: 39850 | P20: =IF(P$8="","",O20) | Q20: =IF(Q$8="","",P20) | R20: =IF(R$8="","",Q20) | S20: =IF(S$8="","",R20) | T20: =IF(T$8="","",S20) | U20: =IF(U$8="","",T20) | V20: =IF(V$8="","",U20) | W20: =IF(W$8="","",V20) | ... AS20: =IF(AS$8="","",AR20)
A21: BUZZ＃１ | B21: プライズ | C21: 936 | D21: 936 | E21: 936 | F21: 936 | G21: 936 | H21: 936 | I21: 936 | J21: 936 | K21: 936 | L21: 937 | M21: =IF(M$8="","",L21) -> 937 | N21: =IF(N$8="","",M21) -> 937 | O21: =IF(O$8="","",N21) -> 937 | P21: =IF(P$8="","",O21) | Q21: =IF(Q$8="","",P21) | R21: =IF(R$8="","",Q21) | S21: =IF(S$8="","",R21) | T21: =IF(T$8="","",S21) | ... AS21: =IF(AS$8="","",AR21)
A22: 2 | B22: 投入残 | C22: 5 | D22: 5 | E22: 5 | F22: 5 | G22: 5 | H22: 9 | I22: 10 | J22: 10 | K22: 10 | L22: 10 | M22: =IF(M20="","",(L22+L23)) -> 10 | N22: =IF(N20="","",(M22+M23)) -> 10 | O22: 24 | P22: =IF(P20="","",(O22+O23)) | Q22: =IF(Q20="","",(P22+P23)) | R22: =IF(R20="","",(Q22+Q23)) | S22: =IF(S20="","",(R22+R23)) | T22: =IF(T20="","",(S22+S23)) | U22: =IF(U20="","",(T22+T23)) | V22: =IF(V20="","",(U22+U23)) | W22: =IF(W20="","",(V22+V23)) | ... AS22: =IF(AS20="","",(AR22+AR23))
B23: 補充 | G23: 4 | H23: 1 | N23: 14
B24: 単価 | C24: 750 | D24: 750 | E24: 750 | F24: 750 | G24: 750 | H24: 750 | I24: 750 | J24: 750 | K24: 750 | L24: 750 | M24: =IF(M20="","",L24) -> 750 | N24: =IF(N20="","",M24) -> 750 | O24: =IF(O20="","",N24) -> 750 | P24: =IF(P20="","",O24) | Q24: =IF(Q20="","",P24) | R24: =IF(R20="","",Q24) | S24: =IF(S20="","",R24) | T24: =IF(T20="","",S24) | ... AS24: =IF(AS20="","",AR24)
A25: 月間予想 | B25: 景品名 | C25: ギャルキティケース | D25: ギャルキティケース | E25: ギャルキティケース | F25: ギャルキティケース | G25: ギャルキティケース | H25: アニマルアイシャドウ | I25: アニマルアイシャドウ | J25: アニマルアイシャドウ | K25: アニマルアイシャドウ | L25: アニマルアイシャドウ | M25: =IF(M20="","",L25) -> アニマルアイシャドウ | N25: =IF(N20="","",M25) -> アニマルアイシャドウ | O25: もんちっちがま口ポーチ | P25: =IF(P20="","",O25) | Q25: =IF(Q20="","",P25) | R25: =IF(R20="","",Q25) | S25: =IF(S20="","",R25) | T25: =IF(T20="","",S25) | U25: =IF(U20="","",T25) | V25: =IF(V20="","",U25) | W25: =IF(W20="","",V25) | ... AS25: =IF(AS20="","",AR25)
A26: =AVERAGE(C27:AS27)*30*100 -> 9230.7692 | B26: 設定
