Workbook

Sheet 計画
A2: 設置店舗数 | B2: =M2+AE2+BE2+BO2+AN2+AH2+T2+AQ2 -> 32 | C2: 1 | D2: 1 | E2: 1 | F2: 1 | G2: 1 | H2: 1 | I2: 2 | M2: 3 | N2: 1 | O2: 1 | P2: 1 | Q2: 2 | S2: 3 | T2: 3 | U2: 1 | V2: 1 | W2: 1 | X2: 2 | Y2: 2 | Z2: 3 | AB2: 4 | AD2: 5 | AE2: 5 | AF2: 1 | AG2: 1 | AH2: 2 | AI2: 1 | AJ2: 1 | AK2: 2 | AL2: 2 | AN2: 2 | AO2: 1 | AP2: 2 | AQ2: 3 | AS2: 1 | AT2: 2 | AU2: 2 | AV2: 3 | AW2: 3 | AX2: 3 | AY2: 4 | AZ2: 4 | BA2: 4 | BB2: 5 | BC2: 5 | BD2: 6 | BE2: 7 | BF2: 1 | BG2: 1 | BH2: 2 | BI2: 3 | BJ2: 4 | BK2: 5 | BL2: 6 | BM2: 6 | BO2: 7 | BP2: =M2+AE2+AH2+AN2+AQ2+BE2+BO2+T2 -> 32 | BQ2: 店舗
A3: 45931 | B3: 合計 | C3: 福重 | D3: 福重② | E3: 福重③ | F3: 福重④ | G3: 福重⑤ | H3: 福重⑥ | I3: 那珂川 | K3: 西新 | M3: 唐津 | N3: 飯塚 | O3: 飯塚② | P3: 飯塚③ | Q3: 小倉 | S3: 黒崎 | T3: 黒崎② | U3: 宗像 | V3: 宗像② | W3: 宗像③ | X3: 魚町 | Y3: 魚町② | Z3: 鞍手 | AB3: 長府② | AC3: 宇部① | AD3: 宇部② | AE3: 宇部③ | AF3: 佐賀① | AG3: 佐賀② | AH3: 八女 | AI3: 都城① | AJ3: 都城② | AK3: 鹿屋① | AL3: 鹿屋② | AN3: 鹿屋500 | AO3: 浜町 | AP3: 時津 | AQ3: 大村 | AS3: 菊陽② | AT3: 宇宿① | AV3: 霧島① | AW3: 霧島② | AX3: 霧島500 | AY3: 川内① | AZ3: 川内② | BA3: 川内500 | BB3: 合志 | BC3: 合志 | BD3: 南熊本 | BE3: 下通 | BF3: 今宿 | BG3: 今宿➁ | BH3: 八代 | BI3: 佐世保 | BJ3: 別府 | BK3: 行橋 | BL3: 延岡① | BM3: 延岡② | BO3: 光吉
A4: 設置台数 | B4: 57 | C4: 500GACHA | D4: 1000GACHA | E4: ティアラ | F4: ティアラ | G4: ティアラ | H4: ティアラ | I4: 1000GACHA | M4: 1000GACHA | N4: 1000GACHA | O4: デカプセル | P4: ティアラ | Q4: ティアラ | S4: ティアラ | T4: 1000GACHA | U4: ガチャコロ1 | V4: 500GATCHA | W4: 500GATCHA | X4: ティアラ | Y4: 1000GACHA | Z4: ガチャコロ2 | AB4: 1000GACHA | AC4: ティアラ | AD4: 1000GACHA | AE4: 1000GACHA | AF4: 1000GACHA | AG4: ガチャコロ2 | AH4: ガチャコロ２ | AI4: ティアラ | AJ4: 1000GACHA | AK4: 1000GACHA | AL4: 1000GACHA | AN4: 500GATCHA | AO4: 1000GACHA | AP4: ガチャコロ２ | AQ4: ガチャコロ２ | AS4: ガチャコロ２ | AT4: 1000GACHA | AV4: 1000GACHA | AW4: ティアラ | AX4: 500GATCHA | AY4: 1000GACHA | AZ4: ティアラ | BA4: 500GATCHA | BB4: ガチャコロ２ | BC4: 500GACHA | BD4: ティアラ | BE4: ガチャコロ２ | BF4: 1000GACHA | BG4: ガチャコロ2 | BH4: ガチャコロ２ | BI4: ティアラ | BJ4: ティアラ | BK4: ガチャコロ2 | BL4: 1000GACHA | BM4: 1000GACHA | BO4: ティアラ
A5: ロッカー台数 | B5: =SUM(C5:BO5) -> 146 | C5: 2 | D5: 2 | E5: 3 | F5: 3 | G5: 3 | H5: 3 | I5: 2 | M5: 2 | N5: 2 | O5: 4 | P5: 3 | Q5: 2 | S5: 2 | T5: 2 | U5: 3 | V5: 2 | W5: 0 | X5: 6 | Y5: 2 | Z5: 4 | AB5: 2 | AC5: 2 | AD5: 2 | AE5: 2 | AF5: 3 | AG5: 2 | AH5: 4 | AI5: 2 | AJ5: 2 | AK5: 3 | AL5: 3 | AN5: 2 | AO5: 2 | AP5: 4 | AQ5: 2 | AS5: 4 | AT5: 1 | AV5: 3 | AW5: 3 | AX5: 2 | AY5: 3 | AZ5: 3 | BA5: 2 | BB5: 4 | BC5: 3 | BD5: 2 | BE5: 3 | BF5: 2 | BG5: 4 | BH5: 4 | BI5: 2 | BJ5: 2 | BK5: 4 | BL5: 2 | BM5: 2 | BO5: 2 | BP5: =SUM(C5:BO5) -> 146 | BQ5: ロッカー
A6: カプセル容量 | C6: 300 | D6: 300 | E6: 300 | F6: 300 | G6: 300 | H6: 300 | I6: 300 | M6: 300 | N6: 300 | O6: 300 | P6: 300 | Q6: 300 | S6: 300 | T6: 300 | U6: 400 | V6: 150 | W6: 150 | X6: 150 | Y6: 300 | Z6: 400 | AB6: 300 | AC6: 300 | AD6: 300 | AE6: 300 | AF6: 300 | AG6: 400 | AH6: 400 | AI6: 300 | AJ6: 300 | AK6: 300 | AL6: 300 | AN6: 300 | AO6: 300 | AP6: 400 | AQ6: 400 | AS6: 400 | AT6: 300 | AV6: 300 | AW6: 300 | AX6: 300 | AY6: 300 | AZ6: 300 | BA6: 300 | BB6: 400 | BC6: 300 | BD6: 300 | BE6: 400 | BF6: 300 | BG6: 400 | BH6: 400 | BI6: 300 | BJ6: 300 | BK6: 400 | BL6: 300 | BM6: 300 | BO6: 300
A7: ガチャの種類 | C7: バラエティー | D7: バラエティー | E7: スニーカー | F7: ゲームソフト | G7: ブランド | H7: ゲーム機 | I7: バラエティー | M7: バラエティー | N7: バラエティー | O7: バラエティー | P7: スニーカー | Q7: バラエティー | S7: バラエティー | T7: バラエティー | U7: バラエティー | V7: バラエティー | W7: バラエティー | X7: バラエティー | Y7: ポケモン | Z7: バラエティー | AB7: バラエティー | AC7: バラエティー | AD7: バラエティー | AE7: バラエティー(ポケモン） | AF7: バラエティー | AG7: バラエティー | AH7: バラエティー | AI7: バラエティー | AJ7: バラエティー | AK7: バラエティー | AL7: バラエティー | AN7: バラエティー | AO7: バラエティー | AP7: バラエティー | AQ7: バラエティー | AS7: バラエティー | AT7: バラエティー | AV7: バラエティー | AW7: バラエティー | AX7: ポケモン | AY7: バラエティー | AZ7: バラエティー | BA7: ポケモン | BB7: バラエティー | BC7: バラエティー | BD7: バラエティー | BE7: バラエティー | BF7: バラエティー | BG7: バラエティー | BH7: バラエティー | BI7: バラエティー | BJ7: バラエティー | BK7: バラエティー | BL7: バラエティー | BM7: バラエティー | BO7: バラエティー | BP7: ティアラ | BQ7: 26
A8: プレイ料金 | C8: 500 | D8: 2000 | E8: 2000 | F8: 1000 | G8: 2000 | H8: 2000 | I8: 2000 | M8: 1000 | N8: 1000 | O8: 2000 | P8: 2000 | Q8: 1000 | S8: 2000 | T8: 1000 | U8: 2000 | V8: 500 | W8: 500 | X8: 2000 | Y8: 1000 | Z8: 2000 | AB8: 1000 | AC8: 1000 | AD8: 2000 | AE8: 2000 | AF8: 1000 | AG8: 2000 | AH8: 1000＆2000 | AI8: 1000 | AJ8: 2000 | AK8: 1000 | AL8: 2000 | AN8: 500 | AO8: 1000 | AP8: 1000＆2000 | AQ8: 1000＆2000 | AS8: 2000 | AT8: 2000 | AV8: 1000 | AW8: 2000 | AX8: 500 | AY8: 1000 | AZ8: 2000 | BA8: 500 | BB8: 2000 | BC8: 500 | BD8: 1000 | BE8: 1000＆2000 | BF8: 1000 | BG8: 2000 | BH8: 1000＆2000 | BI8: 1000 | BJ8: 2000 | BK8: 1000＆2000 | BL8: 1000 | BM8: 2000 | BO8: 2000 | BP8: ガチャコロ1 | BQ8: 2
A9: 前年度 | B9: =SUM(C9:BO9) -> 7025100 | C9: 74500 | D9: 306000 | I9: 109000 | J9: 240000 | K9: 223000 | L9: 222000 | M9: 123000 | N9: 94000 | O9: 244000 | Q9: 119000 | S9: 158000 | T9: 110000 | U9: 224000 | V9: 23000 | W9: 22000 | X9: 86000 | Y9: 84000 | Z9: 124000 | AB9: 156000 | AF9: 61000 | AG9: 272000 | AH9: 151000 | AI9: 111000 | AJ9: 148000 | AO9: 118000 | AP9: 118000 | AQ9: 139000 | AS9: 470000 | AT9: 56000 | AU9: 103000 | AV9: 166000 | AW9: 154000 | AX9: 65300 | AY9: 206000 | AZ9: 188000 | BA9: 112800 | BB9: 125000 | BC9: 61500 | BE9: 631000 | BF9: 55000 | BG9: 106000 | BH9: 61000 | BI9: 75000 | BJ9: 108000 | BK9: 195000 | BL9: 87000 | BM9: 80000 | BO9: 60000 | BP9: ガチャコロ2 | BQ9: 10
A10: 目標 | B10: =SUM(C10:BO10) -> 9310000 | C10: 90000 | D10: 300000 | E10: 110000 | F10: 150000 | G10: 100000 | H10: 150000 | I10: 300000 | M10: 200000 | N10: 140000 | O10: 250000 | P10: 200000 | Q10: 140000 | S10: 250000 | T10: 250000 | U10: 350000 | V10: 40000 | W10: 40000 | X10: 120000 | Y10: 150000 | Z10: 300000 | AB10: 200000 | AC10: 100000 | AD10: 180000 | AE10: 110000 | AF10: 320000 | AG10: 400000 | AH10: 240000 | AI10: 130000 | AJ10: 150000 | AK10: 110000 | AL10: 170000 | AN10: 80000 | AO10: 100000 | AP10: 160000 | AQ10: 180000 | AS10: 400000 | AT10: 160000 | AV10: 120000 | AW10: 160000 | AX10: 60000 | AY10: 160000 | AZ10: 200000 | BA10: 80000 | BB10: 180000 | BC10: 50000 | BD10: 150000 | BE10: 400000 | BF10: 100000 | BG10: 100000 | BH10: 120000 | BI10: 100000 | BJ10: 100000 | BK10: 150000 | BL10: 100000 | BM10: 100000 | BO10: 60000 | BP10: 1000GACHA | BQ10: 15
BP11: デカプセル | BQ11: 1
A12: 売上実績 | B12: =SUM(C12:BO12) -> 11380100 | C12: =福重!F41-100 -> 154000 | D12: =福重!Q41 -> 120000 | E12: =福重!AT41 -> 56000 | F12: =福重!AA41 -> 108000 | G12: =福重!AG41 -> 94000 | H12: =福重!AM41 -> 106000 | I12: =那珂川!F16 -> 306000 | M12: =唐津!E14-22000 -> 228000 | N12: =飯塚!S16 -> 384000 | O12: =飯塚!H16 -> 475000 | P12: =飯塚!AB16 -> 152000 | Q12: =小倉!F14 -> 254000 | S12: =+黒崎!F13 -> 466000 | T12: =+黒崎!Q13 -> 343000 | U12: 335000 | V12: 16000 | W12: 37000 | X12: 196000 | Y12: 172000 | Z12: 321000 | AB12: 214000 | AC12: 120000 | AD12: 336000 | AE12: 104000 | AF12: 94000 | AG12: 462000 | AH12: 317000 | AI12: 70000 | AJ12: 138000 | AK12: 173000 | AL12: 188000 | AN12: 114200 | AO12: 334000 | AP12: 360000 | AQ12: 294000 | AS12: 561000 | AT12: 250000 | AV12: 129000 | AW12: 200000 | AX12: 219300 | AY12: 176000 | AZ12: 139000 | BA12: 208300 | BB12: 150000 | BC12: 89300 | BD12: 144000 | BE12: 452000 | BF12: 59000 | BG12: 40000 | BH12: 308000 | BI12: 56000 | BJ12: 182000 | BK12: 137000 | BL12: 121000 | BM12: 78000 | BO12: 40000 | BP12: 500GACHA | BQ12: 4
A13: 目標対比 | B13: =B12/B10 -> 1.2223523 | C13: =C12/C10 -> 1.7111111 | D13: =D12/D10 -> 0.4 | E13: =E12/E10 -> 0.50909091 | F13: =F12/F10 -> 0.72 | G13: =G12/G10 -> 0.94 | H13: =H12/H10 -> 0.70666667 | I13: =I12/I10 -> 1.02 | M13: =M12/M10 -> 1.14 | N13: =N12/N10 -> 2.7428571 | O13: =O12/O10 -> 1.9 | P13: =P12/P10 -> 0.76 | Q13: =Q12/Q10 -> 1.8142857 | S13: =S12/S10 -> 1.864 | T13: =T12/T10 -> 1.372 | U13: =U12/U10 -> 0.95714286 | V13: =V12/V10 -> 0.4 | W13: =W12/W10 -> 0.925 | X13: =X12/X10 -> 1.6333333 | Y13: =Y12/Y10 -> 1.1466667 | Z13: =Z12/Z10 -> 1.07 | AB13: =AB12/AB10 -> 1.07 | AC13: =AC12/AC10 -> 1.2 | AD13: =AD12/AD10 -> 1.8666667 | AE13: =AE12/AE10 -> 0.94545455 | AF13: =IFERROR(AF12/AF10,"-") -> 0.29375 | AG13: =IFERROR(AG12/AG10,"-") -> 1.155 | AH13: =IFERROR(AH12/AH10,"-") -> 1.3208333 | AI13: =IFERROR(AI12/AI10,"-") -> 0.53846154 | AJ13: =IFERROR(AJ12/AJ10,"-") -> 0.92 | AK13: =IFERROR(AK12/AK10,"-") -> 1.5727273 | AL13: =IFERROR(AL12/AL10,"-") -> 1.1058824 | AN13: =IFERROR(AN12/AN10,"-") -> 1.4275 | AO13: =IFERROR(AO12/AO10,"-") -> 3.34 | AP13: =IFERROR(AP12/AP10,"-") -> 2.25 | AQ13: =IFERROR(AQ12/AQ10,"-") -> 1.6333333 | AS13: =IFERROR(AS12/AS10,"-") -> 1.4025 | AT13: =IFERROR(AT12/AT10,"-") -> 1.5625 | AV13: =IFERROR(AV12/AV10,"-") -> 1.075 | AW13: =IFERROR(AW12/AW10,"-") -> 1.25 | AX13: =IFERROR(AX12/AX10,"-") -> 3.655 | AY13: =IFERROR(AY12/AY10,"-") -> 1.1 | AZ13: =IFERROR(AZ12/AZ10,"-") -> 0.695 | BA13: =IFERROR(BA12/BA10,"-") -> 2.60375 | BB13: =IFERROR(BB12/BB10,"-") -> 0.83333333 | BC13: =IFERROR(BC12/BC10,"-") -> 1.786 | ... BM13: =IFERROR(BM12/BM10,"-") -> 0.78 | BO13: =IFERROR(BO12/BO10,"-") -> 0.66666667 | BQ13: =SUM(BQ4:BQ12) -> 58
A14: =B13 -> 1.2223523
A15: 予測達成率 | C15: 開始日 | D15: 全台AVE | E15: =B12/B4 -> 199650.88 | F15: ガチャ | G15: プライズ | K15: 売上目標 | L15: =SUM(C10:M10) -> 1400000 | Q15: 売上目標 | S15: =SUM(N10:T10) -> 1230000 | AC15: 売上目標 | AD15: =SUM(U10:AE10) -> 1590000 | AF15: 売上目標 | AG15: =SUM(AF10:AH10) -> 960000 | AJ15: 新 | AK15: 売上目標 | AL15: =SUM(AI10:AN10) -> 640000 | AP15: 売上目標 | AQ15: =SUM(AO10:AR10) -> 440000 | AW15: 新 | BC15: 売上目標 | BD15: =SUM(AS10:BE10) -> 2120000 | BM15: 売上目標 | BN15: =SUM(BF10:BO10) -> 930000
A16: 進捗率 | B16: 経過日数 | C16: 45917 | D16: 総売上 | E16: 37083200 | F16: =B12 -> 11380100 | G16: =E16-B12 -> 25703100 | K16: 進捗 | L16: =SUM(C12:M12) -> 1172000 | M16: =L16/L15 -> 0.83714286 | Q16: 進捗 | S16: =SUM(N12:T12) -> 2074000 | T16: =S16/S15 -> 1.6861789 | AC16: 進捗 | AD16: =SUM(U12:AE12) -> 1851000 | AE16: =AD16/AD15 -> 1.1641509 | AF16: 進捗 | AG16: =SUM(AF12:AH12) -> 873000 | AH16: =AG16/AG15 -> 0.909375 | AK16: 進捗 | AL16: =SUM(AI12:AN12) -> 683200 | AN16: =AL16/AL15 -> 1.0675 | AP16: 進捗 | AQ16: =SUM(AO12:AR12) -> 988000 | AR16: =AQ16/AQ15 -> 2.2454545 | BC16: 進捗 | BD16: =SUM(AS12:BE12) -> 2717900 | BE16: =BD16/BD15 -> 1.2820283 | BM16: 進捗 | BN16: =SUM(BF12:BO12) -> 1021000 | BO16: =BN16/BN15 -> 1.0978495
A18: 設置店舗数 | B18: =M18+AE18+BE18+BO18+AN18+AH18+T18+AQ18 -> 32 | C18: 1 | D18: 1 | E18: 1 | F18: 1 | G18: 1 | H18: 1 | I18: 2 | M18: 3 | N18: 1 | O18: 1 | P18: 1 | Q18: 2 | S18: 3 | T18: 3 | U18: 1 | V18: 1 | W18: 1 | X18: 2 | Y18: 2 | Z18: 3 | AB18: 4 | AD18: 5 | AE18: 5 | AF18: 1 | AG18: 1 | AH18: 2 | AI18: 1 | AJ18: 1 | AK18: 2 | AL18: 2 | AN18: 2 | AO18: 1 | AP18: 2 | AQ18: 3 | AR18: 4 | AS18: 1 | AT18: 2 | AV18: 3 | AW18: 3 | AX18: 3 | AY18: 4 | AZ18: 4 | BA18: 4 | BB18: 5 | BC18: 5 | BD18: 6 | BE18: 7 | BF18: 1 | BG18: 1 | BH18: 2 | BI18: 3 | BJ18: 4 | BK18: 5 | BL18: 6 | BM18: 6 | BO18: 7 | BP18: =M18+AE18+AH18+AN18+AQ18+BE18+BO18+T18 -> 32 | BQ18: 店舗
A19: 45962 | B19: 合計 | C19: 福重 | D19: 福重② | E19: 福重③ | F19: 福重④ | G19: 福重⑤ | H19: 福重⑥ | I19: 那珂川 | J19: 那珂川 | K19: 西新 | L19: 博多駅南 | M19: 唐津 | N19: 飯塚 | O19: 飯塚② | P19: 飯塚③ | Q19: 小倉 | S19: 黒崎 | T19: 黒崎② | U19: 宗像 | V19: 宗像② | W19: 宗像③ | X19: 魚町 | Y19: 魚町② | Z19: 鞍手 | AB19: 長府② | AC19: 宇部① | AD19: 宇部② | AE19: 宇部③ | AF19: 佐賀① | AG19: 佐賀② | AH19: 八女 | AI19: 都城① | AJ19: 都城② | AK19: 鹿屋① | AL19: 鹿屋② | AN19: 鹿屋500 | AO19: 浜町 | AP19: 時津 | AQ19: 大村 | AR19: 中州 | AS19: 菊陽② | AT19: 宇宿① | AV19: 霧島① | AW19: 霧島② | AX19: 霧島500 | AY19: 川内① | AZ19: 川内② | BA19: 川内500 | BB19: 合志 | BC19: 合志 | BD19: 南熊本 | BE19: 下通 | BF19: 今宿 | BG19: 今宿➁ | BH19: 八代 | BI19: 佐世保 | BJ19: 別府 | BK19: 行橋 | BL19: 延岡① | BM19: 延岡② | BO19: 光吉
A20: 設置台数 | B20: 57 | C20: 500GACHA | D20: 1000GACHA | E20: ティアラ | F20: ティアラ | G20: ティアラ | H20: ティアラ | I20: 1000GACHA | M20: 1000GACHA | N20: 1000GACHA | O20: デカプセル | P20: ティアラ | Q20: ティアラ | S20: ティアラ | T20: 1000GACHA | U20: ガチャコロ1 | V20: 500GATCHA | W20: 500GATCHA | X20: ティアラ | Y20: 1000GACHA | Z20: ガチャコロ2 | AB20: 1000GACHA | AC20: ティアラ | AD20: 1000GACHA | AE20: 1000GACHA | AF20: 1000GACHA | AG20: ガチャコロ2 | AH20: ガチャコロ２ | AI20: ティアラ | AJ20: 1000GACHA | AK20: 1000GACHA | AL20: 1000GACHA | AN20: 500GATCHA | AO20: 1000GACHA | AP20: ガチャコロ２ | AQ20: ガチャコロ２ | AR20: 1000GACHA | AS20: ガチャコロ２ | AT20: 1000GACHA | AV20: 1000GACHA | AW20: ティアラ | AX20: 500GATCHA | AY20: 1000GACHA | AZ20: ティアラ | BA20: 500GATCHA | BB20: ガチャコロ２ | BC20: 500GACHA | BD20: ティアラ | BE20: ガチャコロ２ | BF20: 1000GACHA | BG20: ガチャコロ2 | BH20: ガチャコロ２ | BI20: ティアラ | BJ20: ティアラ | BK20: ガチャコロ2 | BL20: 1000GACHA | BM20: 1000GACHA | BO20: ティアラ
A21: ロッカー台数 | B21: =SUM(C21:BO21) -> 147 | C21: 2 | D21: 2 | E21: 3 | F21: 3 | G21: 3 | H21: 3 | I21: 2 | M21: 2 | N21: 2 | O21: 4 | P21: 3 | Q21: 2 | S21: 2 | T21: 2 | U21: 3 | V21: 2 | W21: 0 | X21: 6 | Y21: 2 | Z21: 4 | AB21: 2 | AC21: 2 | AD21: 2 | AE21: 2 | AF21: 3 | AG21: 2 | AH21: 4 | AI21: 2 | AJ21: 2 | AK21: 3 | AL21: 3 | AN21: 2 | AO21: 2 | AP21: 4 | AQ21: 2 | AR21: 1 | AS21: 4 | AT21: 1 | AV21: 3 | AW21: 3 | AX21: 2 | AY21: 3 | AZ21: 3 | BA21: 2 | BB21: 4 | BC21: 3 | BD21: 2 | BE21: 3 | BF21: 2 | BG21: 4 | BH21: 4 | BI21: 2 | BJ21: 2 | BK21: 4 | BL21: 2 | BM21: 2 | BO21: 2 | BP21: =SUM(C21:BO21) -> 147 | BQ21: ロッカー
A22: カプセル容量 | C22: 300 | D22: 300 | E22: 300 | F22: 300 | G22: 300 | H22: 300 | I22: 300 | M22: 300 | N22: 300 | O22: 300 | P22: 300 | Q22: 300 | S22: 300 | T22: 300 | U22: 400 | V22: 150 | W22: 150 | X22: 150 | Y22: 300 | Z22: 400 | AB22: 300 | AC22: 300 | AD22: 300 | AE22: 300 | AF22: 300 | AG22: 400 | AH22: 400 | AI22: 300 | AJ22: 300 | AK22: 300 | AL22: 300 | AN22: 300 | AO22: 300 | AP22: 400 | AQ22: 400 | AR22: 300 | AS22: 400 | AT22: 300 | AV22: 300 | AW22: 300 | AX22: 300 | AY22: 300 | AZ22: 300 | BA22: 300 | BB22: 400 | BC22: 300 | BD22: 300 | BE22: 400 | BF22: 300 | BG22: 400 | BH22: 400 | BI22: 300 | BJ22: 300 | BK22: 400 | BL22: 300 | BM22: 300 | BO22: 300
A23: ガチャの種類 | C23: バラエティー | D23: バラエティー | E23: スニーカー | F23: ゲームソフト | G23: ブランド | H23: ゲーム機 | I23: バラエティー | M23: バラエティー | N23: バラエティー | O23: バラエティー | P23: スニーカー | Q23: バラエティー | S23: バラエティー | T23: バラエティー | U23: バラエティー | V23: バラエティー | W23: バラエティー | X23: バラエティー | Y23: ポケモン | Z23: バラエティー | AB23: バラエティー | AC23: バラエティー | AD23: バラエティー | AE23: バラエティー(ポケモン） | AF23: バラエティー | AG23: バラエティー | AH23: バラエティー | AI23: バラエティー | AJ23: バラエティー | AK23: バラエティー | AL23: バラエティー | AN23: バラエティー | AO23: バラエティー | AP23: バラエティー | AQ23: バラエティー | AR23: バラエティー | AS23: バラエティー | AT23: バラエティー | AV23: バラエティー | AW23: バラエティー | AX23: ポケモン | AY23: バラエティー | AZ23: バラエティー | BA23: ポケモン | BB23: バラエティー | BC23: バラエティー | BD23: バラエティー | BE23: バラエティー | BF23: バラエティー | BG23: バラエティー | BH23: バラエティー | BI23: バラエティー | BJ23: バラエティー | BK23: バラエティー | BL23: バラエティー | BM23: バラエティー | BO23: バラエティー | BP23: ティアラ | BQ23: 26
A24: プレイ料金 | C24: 500 | D24: 2000 | E24: 2000 | F24: 1000 | G24: 2000 | H24: 2000 | I24: 2000 | M24: 1000 | N24: 1000 | O24: 2000 | P24: 2000 | Q24: 1000 | S24: 2000 | T24: 1000 | U24: 2000 | V24: 500 | W24: 500 | X24: 2000 | Y24: 1000 | Z24: 2000 | AB24: 1000 | AC24: 1000 | AD24: 2000 | AE24: 2000 | AF24: 1000 | AG24: 2000 | AH24: 1000＆2000 | AI24: 1000 | AJ24: 2000 | AK24: 1000 | AL24: 2000 | AN24: 500 | AO24: 1000 | AP24: 1000＆2000 | AQ24: 1000＆2000 | AR24: 3000 | AS24: 2000 | AT24: 2000 | AV24: 1000 | AW24: 2000 | AX24: 500 | AY24: 1000 | AZ24: 2000 | BA24: 500 | BB24: 2000 | BC24: 500 | BD24: 1000 | BE24: 1000＆2000 | BF24: 1000 | BG24: 2000 | BH24: 1000＆2000 | BI24: 1000 | BJ24: 2000 | BK24: 1000＆2000 | BL24: 1000 | BM24: 2000 | BO24: 2000 | BP24: ガチャコロ1 | BQ24: 2
A25: 前年度 | B25: =SUM(C25:BO25) -> 7672400 | C25: 93000 | D25: 232000 | I25: 216000 | J25: 120000 | K25: 343000 | L25: 195000 | M25: 176000 | N25: 96000 | O25: 264000 | Q25: 130000 | S25: 138000 | T25: 122000 | U25: 262000 | V25: 29000 | W25: 17000 | X25: 86000 | Y25: 98000 | Z25: 176000 | AB25: 70000 | AF25: 135000 | AG25: 275000 | AH25: 284000 | AI25: 94000 | AJ25: 68000 | AO25: 120000 | AP25: 159000 | AQ25: 81000 | AS25: 513000 | AT25: 138000 | AU25: 131000 | AV25: 140000 | AW25: 138000 | AX25: 85100 | AY25: 210000 | AZ25: 228000 | BA25: 70700 | BB25: 193000 | BC25: 46600 | BE25: 699000 | BF25: 103000 | BG25: 138000 | BH25: 94000 | BI25: 72000 | BJ25: 138000 | BK25: 147000 | BL25: 97000 | BM25: 132000 | BO25: 80000 | BP25: ガチャコロ2 | BQ25: 10
A26: 目標 | B26: =SUM(C26:BO26) -> 10280000 | C26: 120000 | D26: 200000 | E26: 120000 | F26: 120000 | G26: 120000 | H26: 120000 | I26: 250000 | M26: 200000 | N26: 250000 | O26: 400000 | P26: 120000 | Q26: 200000 | S26: 300000 | T26: 250000 | U26: 280000 | V26: 40000 | W26: 40000 | X26: 140000 | Y26: 130000 | Z26: 250000 | AA26: =(AA25+AA12)/2 -> 0 | AB26: 150000 | AC26: 100000 | AD26: 250000 | AE26: 100000 | AF26: 140000 | AG26: 350000 | AH26: 290000 | AI26: 120000 | AJ26: 150000 | AK26: 150000 | AL26: 200000 | AN26: 100000 | AO26: 230000 | AP26: 260000 | AQ26: 190000 | AR26: 300000 | AS26: 500000 | AT26: 200000 | AV26: 130000 | AW26: 150000 | AX26: 120000 | AY26: 190000 | AZ26: 200000 | BA26: 140000 | BB26: 170000 | BC26: 70000 | BD26: 120000 | BE26: 450000 | BF26: 100000 | BG26: 140000 | BH26: 200000 | BI26: 70000 | BJ26: =(BJ25+BJ12)/2 -> 160000 | BK26: 140000 | BL26: 110000 | BM26: 130000 | BN26: =(BN25+BN12)/2 -> 0 | BO26: =(BO25+BO12)/2 -> 60000 | BP26: 1000GACHA | BQ26: 15
BP27: デカプセル | BQ27: 1
A28: 売上実績 | B28: =SUM(C28:BO28) -> 9423800 | C28: =福重!F85-200 -> 175000 | D28: =福重!Q85 -> 151000 | E28: =福重!AT85 -> 126000 | F28: =福重!AA85 -> 98000 | G28: =福重!AG85 -> 190000 | H28: =福重!AM85 -> 108000 | I28: =那珂川!F33 -> 208000 | M28: =唐津!E29+36000 -> 184000 | N28: =飯塚!S33 -> 115000 | O28: =飯塚!H33 -> 218000 | P28: =飯塚!AB33 -> 70000 | Q28: =小倉!F29 -> 209000 | S28: =+黒崎!F27 -> 282000 | T28: =+黒崎!Q27 -> 274000 | U28: 268000 | V28: 30000 | W28: 38500 | X28: 192000 | Y28: 163000 | Z28: 215000 | AB28: 258000 | AC28: 115000 | AD28: 204000 | AE28: 94000 | AF28: 135000 | AG28: 351000 | AH28: 202000 | AI28: 76000 | AJ28: 112000 | AK28: 149000 | AL28: 166000 | AN28: 125900 | AO28: 219000 | AP28: 294000 | AQ28: 327000 | AR28: 402000 | AS28: 484000 | AT28: 210000 | AV28: 124000 | AW28: 190000 | AX28: 70400 | AY28: 257000 | AZ28: 142000 | BA28: 127800 | BB28: 158000 | BC28: 90200 | BD28: 131000 | BE28: 255000 | BF28: 41000 | BG28: 111000 | BH28: 92000 | BI28: 66000 | BJ28: 106000 | BK28: 103000 | BL28: 55000 | BM28: 46000 | BO28: 20000 | BP28: 500GACHA | BQ28: 4
A29: 目標対比 | B29: =B28/B26 -> 0.91671206 | C29: =C28/C26 -> 1.4583333 | D29: =D28/D26 -> 0.755 | E29: =E28/E26 -> 1.05 | F29: =F28/F26 -> 0.81666667 | G29: =G28/G26 -> 1.5833333 | H29: =H28/H26 -> 0.9 | I29: =I28/I26 -> 0.832 | M29: =M28/M26 -> 0.92 | N29: =N28/N26 -> 0.46 | O29: =O28/O26 -> 0.545 | P29: =P28/P26 -> 0.58333333 | Q29: =Q28/Q26 -> 1.045 | S29: =S28/S26 -> 0.94 | T29: =T28/T26 -> 1.096 | U29: =U28/U26 -> 0.95714286 | V29: =V28/V26 -> 0.75 | W29: =W28/W26 -> 0.9625 | X29: =X28/X26 -> 1.3714286 | Y29: =Y28/Y26 -> 1.2538462 | Z29: =Z28/Z26 -> 0.86 | AB29: =AB28/AB26 -> 1.72 | AC29: =AC28/AC26 -> 1.15 | AD29: =AD28/AD26 -> 0.816 | AE29: =AE28/AE26 -> 0.94 | AF29: =IFERROR(AF28/AF26,"-") -> 0.96428571 | AG29: =IFERROR(AG28/AG26,"-") -> 1.0028571 | AH29: =IFERROR(AH28/AH26,"-") -> 0.69655172 | AI29: =IFERROR(AI28/AI26,"-") -> 0.63333333 | AJ29: =IFERROR(AJ28/AJ26,"-") -> 0.74666667 | AK29: =IFERROR(AK28/AK26,"-") -> 0.99333333 | AL29: =IFERROR(AL28/AL26,"-") -> 0.83 | AN29: =IFERROR(AN28/AN26,"-") -> 1.259 | AO29: =IFERROR(AO28/AO26,"-") -> 0.95217391 | AP29: =IFERROR(AP28/AP26,"-") -> 1.1307692 | AQ29: =IFERROR(AQ28/AQ26,"-") -> 1.7210526 | AR29: =IFERROR(AR28/AR26,"-") -> 1.34 | AS29: =IFERROR(AS28/AS26,"-") -> 0.968 | AT29: =IFERROR(AT28/AT26,"-") -> 1.05 | AV29: =IFERROR(AV28/AV26,"-") -> 0.95384615 | AW29: =IFERROR(AW28/AW26,"-") -> 1.2666667 | AX29: =IFERROR(AX28/AX26,"-") -> 0.58666667 | AY29: =IFERROR(AY28/AY26,"-") -> 1.3526316 | AZ29: =IFERROR(AZ28/AZ26,"-") -> 0.71 | BA29: =IFERROR(BA28/BA26,"-") -> 0.91285714 | BB29: =IFERROR(BB28/BB26,"-") -> 0.92941176 | BC29: =IFERROR(BC28/BC26,"-") -> 1.2885714 | ... BM29: =IFERROR(BM28/BM26,"-") -> 0.35384615 | BO29: =IFERROR(BO28/BO26,"-") -> 0.33333333 | BQ29: =SUM(BQ20:BQ28) -> 58
A30: =B29 -> 0.91671206
A31: 予測達成率 | C31: 開始日 | D31: 全台AVE | E31: =B28/B20 -> 165329.82 | F31: ガチャ | G31: プライズ | K31: 売上目標 | L31: =SUM(C26:M26) -> 1250000 | Q31: 売上目標 | S31: =SUM(N26:T26) -> 1520000 | AC31: 売上目標 | AD31: =SUM(U26:AE26) -> 1480000 | AF31: 売上目標 | AG31: =SUM(AF26:AH26) -> 780000 | AJ31: 新 | AK31: 売上目標 | AL31: =SUM(AI26:AN26) -> 720000 | AP31: 売上目標 | AQ31: =SUM(AO26:AR26) -> 980000 | AW31: 新 | BC31: 売上目標 | BD31: =SUM(AS26:BE26) -> 2440000 | BM31: 売上目標 | BN31: =SUM(BF26:BO26) -> 1110000
A32: 進捗率 | B32: 経過日数 | C32: 45947 | D32: 総売上 | E32: 33818900 | F32: =B28 -> 9423800 | G32: =E32-B28 -> 24395100 | K32: 進捗 | L32: =SUM(C28:M28) -> 1240000 | M32: =L32/L31 -> 0.992 | Q32: 進捗 | S32: =SUM(N28:T28) -> 1168000 | T32: =S32/S31 -> 0.76842105 | AC32: 進捗 | AD32: =SUM(U28:AE28) -> 1577500 | AE32: =AD32/AD31 -> 1.0658784 | AF32: 進捗 | AG32: =SUM(AF28:AH28) -> 688000 | AH32: =AG32/AG31 -> 0.88205128 | AK32: 進捗 | AL32: =SUM(AI28:AN28) -> 628900 | AN32: =AL32/AL31 -> 0.87347222 | AP32: 進捗 | AQ32: =SUM(AO28:AR28) -> 1242000 | AR32: =AQ32/AQ31 -> 1.2673469 | BC32: 進捗 | BD32: =SUM(AS28:BE28) -> 2239400 | BE32: =BD32/BD31 -> 0.91778689 | BM32: 進捗 | BN32: =SUM(BF28:BO28) -> 640000 | BO32: =BN32/BN31 -> 0.57657658
A34: 設置店舗数 | B34: =M34+AE34+BE34+BO34+AH34+T34+AL34 -> 33 | C34: 1 | D34: 1 | E34: 1 | F34: 1 | G34: 1 | H34: 1 | I34: 2 | L34: 3 | M34: 3 | N34: 1 | O34: 1 | P34: 1 | Q34: 2 | S34: 3 | T34: 3 | U34: 1 | V34: 1 | W34: 1 | X34: 2 | Y34: 2 | Z34: 3 | AB34: 4 | AD34: 5 | AE34: 5 | AF34: 1 | AG34: 1 | AH34: 2 | AI34: 1 | AJ34: 2 | AK34: 3 | AL34: 4 | AN34: 1 | AO34: 1 | AP34: 2 | AQ34: 2 | AR34: 2 | AS34: 3 | AT34: 3 | AU34: 3 | AV34: 4 | AW34: 4 | AX34: 5 | AY34: 5 | AZ34: 5 | BA34: 6 | BB34: 7 | BC34: 7 | BD34: 8 | BE34: 9 | BF34: 1 | BG34: 1 | BH34: 2 | BI34: 3 | BJ34: 4 | BK34: 5 | BL34: 6 | BM34: 6 | BO34: 7 | BP34: =M34+AE34+AH34+AL34+BE34+BO34+T34 -> 33 | BQ34: 店舗
A35: 45992 | B35: 合計 | C35: 福重 | D35: 福重② | E35: 福重③ | F35: 福重④ | G35: 福重⑤ | H35: 福重⑥ | I35: 那珂川 | J35: 那珂川 | K35: 西新 | L35: 唐津 | M35: 唐津 | N35: 飯塚 | O35: 飯塚② | P35: 飯塚③ | Q35: 小倉 | S35: 黒崎 | T35: 黒崎② | U35: 宗像 | V35: 宗像② | W35: 宗像③ | X35: 魚町 | Y35: 魚町② | Z35: 鞍手 | AB35: 長府② | AC35: 宇部① | AD35: 宇部② | AE35: 宇部③ | AF35: 佐賀① | AG35: 佐賀② | AH35: 八女 | AI35: 浜町 | AJ35: 時津 | AK35: 大村 | AL35: 中州 | AN35: 宇宿① | AO35: 宇宿② | AP35: 霧島① | AQ35: 霧島② | AR35: 霧島500 | AS35: 川内① | AT35: 川内② | AU35: 川内500 | AV35: 都城① | AW35: 都城② | AX35: 鹿屋① | AY35: 鹿屋② | AZ35: 鹿屋500 | BA35: 菊陽② | BB35: 合志 | BC35: 合志 | BD35: 南熊本 | BE35: 下通 | BF35: 今宿 | BG35: 今宿➁ | BH35: 八代 | BI35: 佐世保 | BJ35: 別府 | BK35: 行橋 | BL35: 延岡① | BM35: 延岡② | BN35: Dプラ | BO35: 光吉
A36: 設置台数 | B36: 57 | C36: 500GACHA | D36: 1000GACHA | E36: ティアラ | F36: ティアラ | G36: ティアラ | H36: ティアラ | I36: 1000GACHA | L36: 1000GACHA | M36: ティアラ | N36: 1000GACHA | O36: デカプセル | P36: ティアラ | Q36: ティアラ | S36: ティアラ | T36: 1000GACHA | U36: ガチャコロ1 | V36: 500GATCHA | W36: 500GATCHA | X36: ティアラ | Y36: 1000GACHA | Z36: ガチャコロ2 | AB36: 1000GACHA | AC36: ティアラ | AD36: 1000GACHA | AE36: 1000GACHA | AF36: 1000GACHA | AG36: ガチャコロ2 | AH36: ガチャコロ２ | AI36: 1000GACHA | AJ36: ガチャコロ２ | AK36: ガチャコロ２ | AL36: 1000GACHA | AN36: 1000GACHA | AP36: 1000GACHA | AQ36: ティアラ | AR36: 500GATCHA | AS36: 1000GACHA | AT36: ティアラ | AU36: 500GATCHA | AV36: ティアラ | AW36: 1000GACHA | AX36: 1000GACHA | AY36: 1000GACHA | AZ36: 500GATCHA | BA36: ガチャコロ２ | BB36: ガチャコロ２ | BC36: 500GACHA | BD36: ティアラ | BE36: ガチャコロ２ | BF36: 1000GACHA | BG36: ガチャコロ2 | BH36: ガチャコロ２ | BI36: ティアラ | BJ36: ティアラ | BK36: ガチャコロ2 | BL36: 1000GACHA | BM36: 1000GACHA | BO36: ティアラ
A37: ロッカー台数 | B37: =SUM(C37:BO37) -> 148 | C37: 2 | D37: 2 | E37: 3 | F37: 3 | G37: 3 | H37: 3 | I37: 2 | L37: 2 | M37: 2 | N37: 2 | O37: 4 | P37: 3 | Q37: 2 | S37: 2 | T37: 2 | U37: 3 | V37: 2 | W37: 0 | X37: 6 | Y37: 2 | Z37: 4 | AB37: 2 | AC37: 2 | AD37: 2 | AE37: 2 | AF37: 3 | AG37: 2 | AH37: 4 | AI37: 2 | AJ37: 4 | AK37: 2 | AL37: 1 | AN37: 1 | AP37: 3 | AQ37: 3 | AR37: 2 | AS37: 3 | AT37: 3 | AU37: 2 | AV37: 2 | AW37: 2 | AX37: 3 | AY37: 3 | AZ37: 2 | BA37: 4 | BB37: 4 | BC37: 3 | BD37: 2 | BE37: 3 | BF37: 2 | BG37: 4 | BH37: 3 | BI37: 2 | BJ37: 2 | BK37: 4 | BL37: 2 | BM37: 2 | BO37: 2 | BP37: =SUM(C37:BO37) -> 148 | BQ37: ロッカー
A38: カプセル容量 | C38: 300 | D38: 300 | E38: 300 | F38: 300 | G38: 300 | H38: 300 | I38: 300 | L38: 300 | M38: 300 | N38: 300 | O38: 300 | P38: 300 | Q38: 300 | S38: 300 | T38: 300 | U38: 400 | V38: 150 | W38: 150 | X38: 150 | Y38: 300 | Z38: 400 | AB38: 300 | AC38: 300 | AD38: 300 | AE38: 300 | AF38: 300 | AG38: 400 | AH38: 400 | AI38: 300 | AJ38: 400 | AK38: 400 | AL38: 300 | AN38: 300 | AP38: 300 | AQ38: 300 | AR38: 300 | AS38: 300 | AT38: 300 | AU38: 300 | AV38: 300 | AW38: 300 | AX38: 300 | AY38: 300 | AZ38: 300 | BA38: 400 | BB38: 400 | BC38: 300 | BD38: 300 | BE38: 400 | BF38: 300 | BG38: 400 | BH38: 400 | BI38: 300 | BJ38: 300 | BK38: 400 | BL38: 300 | BM38: 300 | BO38: 300
A39: ガチャの種類 | C39: バラエティー | D39: バラエティー | E39: スニーカー | F39: ゲームソフト | G39: ブランド | H39: ゲーム機 | I39: バラエティー | L39: バラエティー | M39: バラエティー | N39: バラエティー | O39: バラエティー | P39: スニーカー | Q39: バラエティー | S39: バラエティー | T39: バラエティー | U39: バラエティー | V39: バラエティー | W39: バラエティー | X39: バラエティー | Y39: ポケモン | Z39: バラエティー | AB39: バラエティー | AC39: バラエティー | AD39: バラエティー | AE39: バラエティー(ポケモン） | AF39: バラエティー | AG39: バラエティー | AH39: バラエティー | AI39: バラエティー | AJ39: バラエティー | AK39: バラエティー | AL39: バラエティー | AN39: バラエティー | AP39: バラエティー | AQ39: バラエティー | AR39: ポケモン | AS39: バラエティー | AT39: バラエティー | AU39: ポケモン | AV39: バラエティー | AW39: バラエティー | AX39: バラエティー | AY39: バラエティー | AZ39: バラエティー | BA39: バラエティー | BB39: バラエティー | BC39: バラエティー | BD39: バラエティー | BE39: バラエティー | BF39: バラエティー | BG39: バラエティー | BH39: バラエティー | BI39: バラエティー | BJ39: バラエティー | BK39: バラエティー | BL39: バラエティー | BM39: バラエティー | BO39: バラエティー | BP39: ティアラ | BQ39: 26
A40: プレイ料金 | C40: 500 | D40: 2000 | E40: 2000 | F40: 1000 | G40: 2000 | H40: 2000 | I40: 2000 | L40: 1000 | M40: 2000 | N40: 1000 | O40: 2000 | P40: 2000 | Q40: 1000 | S40: 2000 | T40: 1000 | U40: 2000 | V40: 500 | W40: 500 | X40: 2000 | Y40: 1000 | Z40: 2000 | AB40: 1000 | AC40: 1000 | AD40: 2000 | AE40: 2000 | AF40: 1000 | AG40: 2000 | AH40: 1000＆2000 | AI40: 1000 | AJ40: 1000＆2000 | AK40: 1000＆2000 | AL40: 3000 | AN40: 2000 | AP40: 1000 | AQ40: 2000 | AR40: 500 | AS40: 1000 | AT40: 2000 | AU40: 500 | AV40: 1000 | AW40: 2000 | AX40: 1000 | AY40: 2000 | AZ40: 500 | BA40: 2000 | BB40: 2000 | BC40: 500 | BD40: 1000 | BE40: 1000＆2000 | BF40: 1000 | BG40: 2000 | BH40: 1000＆2000 | BI40: 1000 | BJ40: 2000 | BK40: 1000＆2000 | BL40: 1000 | BM40: 2000 | BO40: 2000 | BP40: ガチャコロ1 | BQ40: 2
A41: 前年度 | B41: =SUM(C41:BO41) -> 8951700 | C41: 72700 | D41: 140000 | E41: 213000 | F41: 141000 | G41: 105000 | H41: 158000 | I41: 228000 | J41: 173000 | K41: 114000 | L41: 154000 | N41: 71000 | O41: 244000 | Q41: 121000 | S41: 214000 | T41: 126000 | U41: 654000 | V41: 22000 | W41: 35100 | X41: 96000 | Y41: 137000 | Z41: 256000 | AB41: 94000 | AF41: 221000 | AG41: 380000 | AH41: 112000 | AI41: 136000 | AJ41: 263000 | AK41: 101000 | AL41: 500000 | AN41: 63000 | AO41: 66000 | AP41: 154000 | AQ41: 260000 | AR41: 77600 | AS41: 159000 | AT41: 282000 | AU41: 124100 | AV41: 156000 | AW41: 90000 | BA41: 493000 | BB41: 221000 | BC41: 54200 | BE41: 340000 | BF41: 74000 | BG41: 192000 | BH41: 85000 | BI41: 91000 | BJ41: 192000 | BK41: 234000 | BL41: 78000 | BM41: 58000 | BN41: 44000 | BO41: 82000 | BP41: ガチャコロ2 | BQ41: 10
A42: 目標 | B42: =SUM(C42:BO42) -> 9171800 | C42: 150000 | D42: 150000 | E42: 150000 | F42: 120000 | G42: 150000 | H42: 120000 | I42: 200000 | J42: =J28*0.9 -> 0 | K42: =K28*0.9 -> 0 | L42: 170000 | M42: 0 | N42: 100000 | O42: 200000 | P42: 100000 | Q42: 180000 | S42: 200000 | T42: 200000 | U42: 300000 | V42: 30000 | W42: 30000 | X42: 160000 | Y42: 140000 | Z42: 190000 | AA42: =AA28*0.9 -> 0 | AB42: 200000 | AC42: 120000 | AD42: 170000 | AE42: 120000 | AF42: 180000 | AG42: 350000 | AH42: 150000 | AI42: 170000 | AJ42: 250000 | AK42: 270000 | AL42: =AR28*0.9 -> 361800 | AN42: 150000 | AO42: =AU28*0.9 -> 0 | AP42: 130000 | AQ42: 210000 | AR42: 70000 | AS42: 200000 | AT42: 200000 | AU42: 110000 | AV42: 120000 | AW42: 120000 | AX42: 150000 | AY42: 160000 | AZ42: 100000 | BA42: 450000 | BB42: 150000 | BC42: 70000 | BD42: 120000 | BE42: 280000 | BF42: 100000 | BG42: 120000 | BH42: 100000 | BI42: 100000 | BJ42: 150000 | BK42: 150000 | BL42: 100000 | BM42: 100000 | BN42: =BN28*0.9 -> 0 | BO42: 80000 | BP42: 1000GACHA | BQ42: 15
BP43: デカプセル | BQ43: 1
...

Sheet 福重
B1: ５００円 | M1: ２０００円 | X1: 1000円ソフト | AD1: 2000円ブランド | AJ1: 2000円ゲーム | AP1: 2000円スニーカー
B2: 日付 | D2: 今回ﾒｰﾀｰ | E2: ﾒｰﾀｰ差 | F2: 売上 | K2: 備考 | M2: 日付 | O2: 今回ﾒｰﾀｰ | P2: ﾒｰﾀｰ差 | Q2: 売上 | V2: 備考 | X2: 日付 | Y2: 今回ﾒｰﾀｰ | Z2: ﾒｰﾀｰ差 | AA2: 売上 | AB2: 備考 | AD2: 日付 | AE2: 今回ﾒｰﾀｰ | AF2: ﾒｰﾀｰ差 | AG2: 売上 | AH2: 備考 | AJ2: 日付 | AK2: 今回ﾒｰﾀｰ | AL2: ﾒｰﾀｰ差 | AM2: 売上 | AN2: 備考 | AP2: 日付 | AR2: 今回ﾒｰﾀｰ | AS2: ﾒｰﾀｰ差 | AT2: 売上 | AY2: 備考
B3: 45919 | C3: 56000 | D3: 13942 | E3: 10 | F3: 1000 | K3: 上段リセット済み | M3: 45919 | O3: 2302 | P3: 8 | Q3: 8000 | X3: 45919 | Y3: 7137 | Z3: 8 | AA3: 8000 | AD3: 45919 | AE3: 4731 | AF3: 6 | AG3: 6000 | AJ3: 45919 | AK3: 6927 | AL3: 10 | AM3: 10000 | AP3: 45919 | AR3: 8311 | AS3: 14 | AT3: 14000
D4: 4602 | E4: 90 | F4: 9000
B5: 45922 | C5: =SUM(IF(F5="",0,F5), IF(F6="",0,F6), IF(Q5="",0,Q5), IF(AT5="",0,AT5), IF(AA5="",0,AA5), IF(AG5="",0,AG5), IF(AM5="",0,AM5)) -> 93500 | D5: 14107 | E5: =IF(D5="","",D5-D3) -> 165 | F5: =IF(D5="","",E5*100) -> 16500 | M5: =IF(B5="","",B5) -> 45922 | O5: 2320 | P5: =IF(O5="","",O5-O3) -> 18 | Q5: =IF(O5="","",P5*1000) -> 18000 | X5: =IF(AP5="","",AP5) -> 45922 | Y5: 7142 | Z5: =IF(Y5="","",Y5-Y3) -> 5 | AA5: =IF(Y5="","",Z5*1000) -> 5000 | AD5: =IF(AP5="","",AP5) -> 45922 | AE5: 4739 | AF5: =IF(AE5="","",AE5-AE3) -> 8 | AG5: =IF(AE5="","",AF5*1000) -> 8000 | AJ5: =IF(AD5="","",AD5) -> 45922 | AK5: 6959 | AL5: =IF(AK5="","",AK5-AK3) -> 32 | AM5: =IF(AK5="","",AL5*1000) -> 32000 | AP5: =IF(M5="","",M5) -> 45922 | AR5: 8319 | AS5: =IF(AR5="","",AR5-AR3) -> 8 | AT5: =IF(AR5="","",AS5*1000) -> 8000
D6: 4662 | E6: =IF(D6="","",D6-D4) -> 60 | F6: =IF(D6="","",E6*100) -> 6000 | P6: =IF(O6="","",O6-O4) | Z6: =IF(Y6="","",Y6-Y4) | AF6: =IF(AE6="","",AE6-AE4) | AL6: =IF(AK6="","",AK6-AK4) | AS6: =IF(AR6="","",AR6-AR4)
B7: 45926 | C7: =SUM(IF(F7="",0,F7), IF(F8="",0,F8), IF(Q7="",0,Q7), IF(AT7="",0,AT7), IF(AA7="",0,AA7), IF(AG7="",0,AG7), IF(AM7="",0,AM7)) -> 113500 | D7: 14387 | E7: =IF(D7="","",D7-D5) -> 280 | F7: =IF(D7="","",E7*100) -> 28000 | M7: =IF(B7="","",B7) -> 45926 | O7: 2336 | P7: =IF(O7="","",O7-O5) -> 16 | Q7: =IF(O7="","",P7*1000) -> 16000 | X7: =IF(AP7="","",AP7) -> 45926 | Y7: 7152 | Z7: =IF(Y7="","",Y7-Y5) -> 10 | AA7: =IF(Y7="","",Z7*1000) -> 10000 | AD7: =IF(X7="","",X7) -> 45926 | AE7: 4747 | AF7: =IF(AE7="","",AE7-AE5) -> 8 | AG7: =IF(AE7="","",AF7*1000) -> 8000 | AJ7: =IF(AD7="","",AD7) -> 45926 | AK7: 6981 | AL7: =IF(AK7="","",AK7-AK5) -> 22 | AM7: =IF(AK7="","",AL7*1000) -> 22000 | AP7: =IF(M7="","",M7) -> 45926 | AR7: 8327 | AS7: =IF(AR7="","",AR7-AR5) -> 8 | AT7: =IF(AR7="","",AS7*1000) -> 8000
D8: 4877 | E8: =IF(D8="","",D8-D6) -> 215 | F8: =IF(D8="","",E8*100) -> 21500 | K8: 下段電源落とした | M8: =IF(B8="","",B8) | P8: =IF(O8="","",O8-O7) | Q8: =IF(O8="","",P8*1000) | X8: =IF(AP8="","",AP8) | Z8: =IF(Y8="","",Y8-Y7) | AA8: =IF(Y8="","",Z8*1000) | AD8: =IF(X8="","",X8) | AF8: =IF(AE8="","",AE8-AE7) | AG8: =IF(AE8="","",AF8*1000) | AJ8: =IF(AD8="","",AD8) | AL8: =IF(AK8="","",AK8-AK7) | AM8: =IF(AK8="","",AL8*1000) | AP8: =IF(M8="","",M8) | AS8: =IF(AR8="","",AR8-AR7) | AT8: =IF(AR8="","",AS8*1000)
B9: 45930 | C9: =SUM(IF(F9="",0,F9), IF(F10="",0,F10), IF(Q9="",0,Q9), IF(AT9="",0,AT9), IF(AA9="",0,AA9), IF(AG9="",0,AG9), IF(AM9="",0,AM9)) -> 54000 | D9: 14427 | E9: =IF(D9="","",D9-D7) -> 40 | F9: =IF(D9="","",E9*100) -> 4000 | K9: 上段電源切られてた | M9: =IF(B9="","",B9) -> 45930 | O9: 2354 | P9: =IF(O9="","",O9-O7) -> 18 | Q9: =IF(O9="","",P9*1000) -> 18000 | X9: =IF(AP9="","",AP9) -> 45930 | Y9: 7158 | Z9: =IF(Y9="","",Y9-Y7) -> 6 | AA9: =IF(Y9="","",Z9*1000) -> 6000 | AD9: =IF(X9="","",X9) -> 45930 | AE9: 4757 | AF9: =IF(AE9="","",AE9-AE7) -> 10 | AG9: =IF(AE9="","",AF9*1000) -> 10000 | AJ9: =IF(AD9="","",AD9) -> 45930 | AK9: 6991 | AL9: =IF(AK9="","",AK9-AK7) -> 10 | AM9: =IF(AK9="","",AL9*1000) -> 10000 | AP9: =IF(M9="","",M9) -> 45930 | AR9: 8333 | AS9: =IF(AR9="","",AR9-AR7) -> 6 | AT9: =IF(AR9="","",AS9*1000) -> 6000
D10: 4877 | E10: =IF(D10="","",D10-D8) -> 0 | F10: =IF(D10="","",E10*100) -> 0 | K10: 下段リセット済み | M10: =IF(B10="","",B10) | P10: =IF(O10="","",O10-O9) | Q10: =IF(O10="","",P10*1000) | X10: =IF(AP10="","",AP10) | Z10: =IF(Y10="","",Y10-Y9) | AA10: =IF(Y10="","",Z10*1000) | AD10: =IF(X10="","",X10) | AF10: =IF(AE10="","",AE10-AE9) | AG10: =IF(AE10="","",AF10*1000) | AJ10: =IF(AD10="","",AD10) | AL10: =IF(AK10="","",AK10-AK9) | AM10: =IF(AK10="","",AL10*1000) | AP10: =IF(M10="","",M10) | AS10: =IF(AR10="","",AR10-AR9) | AT10: =IF(AR10="","",AS10*1000)
B11: 45933 | C11: =SUM(IF(F11="",0,F11), IF(F12="",0,F12), IF(Q11="",0,Q11), IF(AT11="",0,AT11), IF(AA11="",0,AA11), IF(AG11="",0,AG11), IF(AM11="",0,AM11)) -> 37000 | D11: 14507 | E11: =IF(D11="","",D11-D9) -> 80 | F11: =IF(D11="","",E11*100) -> 8000 | M11: =IF(B11="","",B11) -> 45933 | O11: 2364 | P11: =IF(O11="","",O11-O9) -> 10 | Q11: =IF(O11="","",P11*1000) -> 10000 | X11: =IF(AP11="","",AP11) -> 45933 | Y11: 7165 | Z11: =IF(Y11="","",Y11-Y9) -> 7 | AA11: =IF(Y11="","",Z11*1000) -> 7000 | AD11: =IF(X11="","",X11) -> 45933 | AE11: 4757 | AF11: =IF(AE11="","",AE11-AE9) -> 0 | AG11: =IF(AE11="","",AF11*1000) -> 0 | AJ11: =IF(AD11="","",AD11) -> 45933 | AK11: 7001 | AL11: =IF(AK11="","",AK11-AK9) -> 10 | AM11: =IF(AK11="","",AL11*1000) -> 10000 | AP11: =IF(M11="","",M11) -> 45933 | AR11: 8333 | AS11: =IF(AR11="","",AR11-AR9) -> 0 | AT11: =IF(AR11="","",AS11*1000) -> 0
D12: 4897 | E12: =IF(D12="","",D12-D10) -> 20 | F12: =IF(D12="","",E12*100) -> 2000 | M12: =IF(B12="","",B12) | P12: =IF(O12="","",O12-O11) | Q12: =IF(O12="","",P12*1000) | X12: =IF(AP12="","",AP12) | Z12: =IF(Y12="","",Y12-Y11) | AA12: =IF(Y12="","",Z12*1000) | AD12: =IF(X12="","",X12) | AF12: =IF(AE12="","",AE12-AE11) | AG12: =IF(AE12="","",AF12*1000) | AJ12: =IF(AD12="","",AD12) | AL12: =IF(AK12="","",AK12-AK11) | AM12: =IF(AK12="","",AL12*1000) | AP12: =IF(M12="","",M12) | AS12: =IF(AR12="","",AR12-AR11) | AT12: =IF(AR12="","",AS12*1000)
B13: 45935 | C13: =SUM(IF(F13="",0,F13), IF(F14="",0,F14), IF(Q13="",0,Q13), IF(AT13="",0,AT13), IF(AA13="",0,AA13), IF(AG13="",0,AG13), IF(AM13="",0,AM13)) -> 54500 | D13: 14617 | E13: =IF(D13="","",D13-D11) -> 110 | F13: =IF(D13="","",E13*100) -> 11000 | M13: =IF(B13="","",B13) -> 45935 | O13: 2368 | P13: =IF(O13="","",O13-O11) -> 4 | Q13: =IF(O13="","",P13*1000) -> 4000 | X13: =IF(AP13="","",AP13) -> 45935 | Y13: 7183 | Z13: =IF(Y13="","",Y13-Y11) -> 18 | AA13: =IF(Y13="","",Z13*1000) -> 18000 | AD13: =IF(X13="","",X13) -> 45935 | AE13: 4765 | AF13: =IF(AE13="","",AE13-AE11) -> 8 | AG13: =IF(AE13="","",AF13*1000) -> 8000 | AJ13: =IF(AD13="","",AD13) -> 45935 | AK13: 7007 | AL13: =IF(AK13="","",AK13-AK11) -> 6 | AM13: =IF(AK13="","",AL13*1000) -> 6000 | AP13: =IF(M13="","",M13) -> 45935 | AR13: 8337 | AS13: =IF(AR13="","",AR13-AR11) -> 4 | AT13: =IF(AR13="","",AS13*1000) -> 4000
D14: 4932 | E14: =IF(D14="","",D14-D12) -> 35 | F14: =IF(D14="","",E14*100) -> 3500 | M14: =IF(B14="","",B14) | P14: =IF(O14="","",O14-O13) | Q14: =IF(O14="","",P14*1000) | X14: =IF(AP14="","",AP14) | Z14: =IF(Y14="","",Y14-Y13) | AA14: =IF(Y14="","",Z14*1000) | AD14: =IF(X14="","",X14) | AF14: =IF(AE14="","",AE14-AE13) | AG14: =IF(AE14="","",AF14*1000) | AJ14: =IF(AD14="","",AD14) | AL14: =IF(AK14="","",AK14-AK13) | AM14: =IF(AK14="","",AL14*1000) | AP14: =IF(M14="","",M14) | AS14: =IF(AR14="","",AR14-AR13) | AT14: =IF(AR14="","",AS14*1000)
B15: 45940 | C15: =SUM(IF(F15="",0,F15), IF(F16="",0,F16), IF(Q15="",0,Q15), IF(AT15="",0,AT15), IF(AA15="",0,AA15), IF(AG15="",0,AG15), IF(AM15="",0,AM15)) -> 44100 | D15: 14733 | E15: =IF(D15="","",D15-D13) -> 116 | F15: =IF(D15="","",E15*100) -> 11600 | M15: =IF(B15="","",B15) -> 45940 | O15: 2382 | P15: =IF(O15="","",O15-O13) -> 14 | Q15: =IF(O15="","",P15*1000) -> 14000 | X15: =IF(AP15="","",AP15) -> 45940 | Y15: 7187 | Z15: =IF(Y15="","",Y15-Y13) -> 4 | AA15: =IF(Y15="","",Z15*1000) -> 4000 | AB15: 止まってた | AD15: =IF(X15="","",X15) -> 45940 | AE15: 4769 | AF15: =IF(AE15="","",AE15-AE13) -> 4 | AG15: =IF(AE15="","",AF15*1000) -> 4000 | AJ15: =IF(AD15="","",AD15) -> 45940 | AK15: 7013 | AL15: =IF(AK15="","",AK15-AK13) -> 6 | AM15: =IF(AK15="","",AL15*1000) -> 6000 | AP15: =IF(M15="","",M15) -> 45940 | AR15: 8339 | AS15: =IF(AR15="","",AR15-AR13) -> 2 | AT15: =IF(AR15="","",AS15*1000) -> 2000
D16: 4957 | E16: =IF(D16="","",D16-D14) -> 25 | F16: =IF(D16="","",E16*100) -> 2500 | M16: =IF(B16="","",B16) | P16: =IF(O16="","",O16-O14) | Q16: =IF(O16="","",P16*1000) | X16: =IF(AP16="","",AP16) | Z16: =IF(Y16="","",Y16-Y14) | AA16: =IF(Y16="","",Z16*1000) | AD16: =IF(X16="","",X16) | AF16: =IF(AE16="","",AE16-AE14) | AG16: =IF(AE16="","",AF16*1000) | AJ16: =IF(AD16="","",AD16) | AL16: =IF(AK16="","",AK16-AK14) | AM16: =IF(AK16="","",AL16*1000) | AP16: =IF(M16="","",M16) | AS16: =IF(AR16="","",AR16-AR14) | AT16: =IF(AR16="","",AS16*1000)
B17: 45946 | C17: =SUM(IF(F17="",0,F17), IF(F18="",0,F18), IF(Q17="",0,Q17), IF(AT17="",0,AT17), IF(AA17="",0,AA17), IF(AG17="",0,AG17), IF(AM17="",0,AM17)) -> 185500 | D17: 14958 | E17: =IF(D17="","",D17-D15) -> 225 | F17: =IF(D17="","",E17*100) -> 22500 | M17: =IF(B17="","",B17) -> 45946 | O17: 2414 | P17: =IF(O17="","",O17-O15) -> 32 | Q17: =IF(O17="","",P17*1000) -> 32000 | V17: 10/12リセット | X17: =IF(AP17="","",AP17) -> 45946 | Y17: 7237 | Z17: =IF(Y17="","",Y17-Y15) -> 50 | AA17: =IF(Y17="","",Z17*1000) -> 50000 | AB17: 10/12リセット | AD17: =IF(X17="","",X17) -> 45946 | AE17: 4819 | AF17: =IF(AE17="","",AE17-AE15) -> 50 | AG17: =IF(AE17="","",AF17*1000) -> 50000 | AH17: 10/12リセット | AJ17: =IF(AD17="","",AD17) -> 45946 | AK17: 7023 | AL17: =IF(AK17="","",AK17-AK15) -> 10 | AM17: =IF(AK17="","",AL17*1000) -> 10000 | AP17: =IF(M17="","",M17) -> 45946 | AR17: 8353 | AS17: =IF(AR17="","",AR17-AR15) -> 14 | AT17: =IF(AR17="","",AS17*1000) -> 14000
D18: 5027 | E18: =IF(D18="","",D18-D16) -> 70 | F18: =IF(D18="","",E18*100) -> 7000
C21: =SUM(IF(F21="",0,F21), IF(F22="",0,F22), IF(Q21="",0,Q21), IF(AT21="",0,AT21), IF(AA21="",0,AA21), IF(AG21="",0,AG21), IF(AM21="",0,AM21)) -> 0 | E21: =IF(D21="","",D21-D19) | F21: =IF(D21="","",E21*100) | M21: =IF(B21="","",B21) | P21: =IF(O21="","",O21-O19) | Q21: =IF(O21="","",P21*1000) | X21: =IF(AP21="","",AP21) | Z21: =IF(Y21="","",Y21-Y19) | AA21: =IF(Y21="","",Z21*1000) | AD21: =IF(X21="","",X21) | AF21: =IF(AE21="","",AE21-AE19) | AG21: =IF(AE21="","",AF21*1000) | AJ21: =IF(AD21="","",AD21) | AL21: =IF(AK21="","",AK21-AK19) | AM21: =IF(AK21="","",AL21*1000) | AP21: =IF(M21="","",M21) | AS21: =IF(AR21="","",AR21-AR19) | AT21: =IF(AR21="","",AS21*1000)
E22: =IF(D22="","",D22-D20) | F22: =IF(D22="","",E22*100) | P22: =IF(O22="","",O22-O20) | Z22: =IF(Y22="","",Y22-Y20) | AF22: =IF(AE22="","",AE22-AE20) | AL22: =IF(AK22="","",AK22-AK20) | AS22: =IF(AR22="","",AR22-AR20)
C23: =SUM(IF(F23="",0,F23), IF(F24="",0,F24), IF(Q23="",0,Q23), IF(AT23="",0,AT23), IF(AA23="",0,AA23), IF(AG23="",0,AG23), IF(AM23="",0,AM23)) -> 0 | E23: =IF(D23="","",D23-D21) | F23: =IF(D23="","",E23*100) | M23: =IF(B23="","",B23) | P23: =IF(O23="","",O23-O21) | Q23: =IF(O23="","",P23*1000) | X23: =IF(AP23="","",AP23) | Z23: =IF(Y23="","",Y23-Y21) | AA23: =IF(Y23="","",Z23*1000) | AD23: =IF(X23="","",X23) | AF23: =IF(AE23="","",AE23-AE21) | AG23: =IF(AE23="","",AF23*1000) | AJ23: =IF(AD23="","",AD23) | AL23: =IF(AK23="","",AK23-AK21) | AM23: =IF(AK23="","",AL23*1000) | AP23: =IF(M23="","",M23) | AS23: =IF(AR23="","",AR23-AR21) | AT23: =IF(AR23="","",AS23*1000)
E24: =IF(D24="","",D24-D22) | F24: =IF(D24="","",E24*100)
C25: =SUM(IF(F25="",0,F25), IF(F26="",0,F26), IF(Q25="",0,Q25), IF(AT25="",0,AT25), IF(AA25="",0,AA25), IF(AG25="",0,AG25), IF(AM25="",0,AM25)) -> 0 | E25: =IF(D25="","",D25-D23) | F25: =IF(D25="","",E25*100) | M25: =IF(B25="","",B25) | P25: =IF(O25="","",O25-O23) | Q25: =IF(O25="","",P25*1000) | X25: =IF(AP25="","",AP25) | Z25: =IF(Y25="","",Y25-Y23) | AA25: =IF(Y25="","",Z25*1000) | AD25: =IF(X25="","",X25) | AF25: =IF(AE25="","",AE25-AE23) | AG25: =IF(AE25="","",AF25*1000) | AJ25: =IF(AD25="","",AD25) | AL25: =IF(AK25="","",AK25-AK23) | AM25: =IF(AK25="","",AL25*1000) | AP25: =IF(M25="","",M25) | AS25: =IF(AR25="","",AR25-AR23) | AT25: =IF(AR25="","",AS25*1000)
E26: =IF(D26="","",D26-D24) | F26: =IF(D26="","",E26*100) | M26: =IF(B26="","",B26)
C27: =SUM(IF(F27="",0,F27), IF(F28="",0,F28), IF(Q27="",0,Q27), IF(AT27="",0,AT27), IF(AA27="",0,AA27), IF(AG27="",0,AG27), IF(AM27="",0,AM27)) -> 0 | E27: =IF(D27="","",D27-D25) | F27: =IF(D27="","",E27*100) | M27: =IF(B27="","",B27) | P27: =IF(O27="","",O27-O25) | Q27: =IF(O27="","",P27*1000) | Z27: =IF(Y27="","",Y27-Y25) | AA27: =IF(Y27="","",Z27*1000) | AD27: =IF(X27="","",X27) | AF27: =IF(AE27="","",AE27-AE25) | AG27: =IF(AE27="","",AF27*1000) | AJ27: =IF(AD27="","",AD27) | AL27: =IF(AK27="","",AK27-AK25) | AM27: =IF(AK27="","",AL27*1000) | AP27: =IF(M27="","",M27) | AS27: =IF(AR27="","",AR27-AR25) | AT27: =IF(AR27="","",AS27*1000)
E28: =IF(D28="","",D28-D26) | F28: =IF(D28="","",E28*100)
C29: =SUM(IF(F29="",0,F29), IF(F30="",0,F30), IF(Q29="",0,Q29), IF(AT29="",0,AT29), IF(AA29="",0,AA29), IF(AG29="",0,AG29), IF(AM29="",0,AM29)) -> 0 | E29: =IF(D29="","",D29-D27) | F29: =IF(D29="","",E29*100) | M29: =IF(B29="","",B29) | P29: =IF(O29="","",O29-O27) | Q29: =IF(O29="","",P29*1000) | X29: =IF(AP29="","",AP29) | Z29: =IF(Y29="","",Y29-Y27) | AA29: =IF(Y29="","",Z29*1000) | AD29: =IF(X29="","",X29) | AF29: =IF(AE29="","",AE29-AE27) | AG29: =IF(AE29="","",AF29*1000) | AJ29: =IF(AD29="","",AD29) | AL29: =IF(AK29="","",AK29-AK27) | AM29: =IF(AK29="","",AL29*1000) | AP29: =IF(M29="","",M29) | AS29: =IF(AR29="","",AR29-AR27) | AT29: =IF(AR29="","",AS29*1000)
E30: =IF(D30="","",D30-D28) | F30: =IF(D30="","",E30*100)
C31: =SUM(IF(F31="",0,F31), IF(F32="",0,F32), IF(Q31="",0,Q31), IF(AT31="",0,AT31), IF(AA31="",0,AA31), IF(AG31="",0,AG31), IF(AM31="",0,AM31)) -> 0 | E31: =IF(D31="","",D31-D29) | F31: =IF(D31="","",E31*100) | M31: =IF(B31="","",B31) | P31: =IF(O31="","",O31-O29) | Q31: =IF(O31="","",P31*1000) | X31: =IF(AP31="","",AP31) | Z31: =IF(Y31="","",Y31-Y29) | AA31: =IF(Y31="","",Z31*1000) | AD31: =IF(X31="","",X31) | AF31: =IF(AE31="","",AE31-AE29) | AG31: =IF(AE31="","",AF31*1000) | AJ31: =IF(AD31="","",AD31) | AL31: =IF(AK31="","",AK31-AK29) | AM31: =IF(AK31="","",AL31*1000) | AP31: =IF(M31="","",M31) | AS31: =IF(AR31="","",AR31-AR29) | AT31: =IF(AR31="","",AS31*1000)
E32: =IF(D32="","",D32-D30) | F32: =IF(D32="","",E32*100)
C33: =SUM(IF(F33="",0,F33), IF(F34="",0,F34), IF(Q33="",0,Q33), IF(AT33="",0,AT33), IF(AA33="",0,AA33), IF(AG33="",0,AG33), IF(AM33="",0,AM33)) -> 0 | E33: =IF(D33="","",D33-D31) | F33: =IF(D33="","",E33*100) | M33: =IF(B33="","",B33) | P33: =IF(O33="","",O33-O31) | Q33: =IF(O33="","",P33*1000) | X33: =IF(AP33="","",AP33) | Z33: =IF(Y33="","",Y33-Y31) | AA33: =IF(Y33="","",Z33*1000) | AD33: =IF(X33="","",X33) | AF33: =IF(AE33="","",AE33-AE31) | AG33: =IF(AE33="","",AF33*1000) | AJ33: =IF(AD33="","",AD33) | AL33: =IF(AK33="","",AK33-AK31) | AM33: =IF(AK33="","",AL33*1000) | AP33: =IF(M33="","",M33) | AS33: =IF(AR33="","",AR33-AR31) | AT33: =IF(AR33="","",AS33*1000)
E34: =IF(D34="","",D34-D32) | F34: =IF(D34="","",E34*100)
C35: =SUM(IF(F35="",0,F35), IF(F36="",0,F36), IF(Q35="",0,Q35), IF(AT35="",0,AT35), IF(AA35="",0,AA35), IF(AG35="",0,AG35), IF(AM35="",0,AM35)) -> 0 | E35: =IF(D35="","",D35-D33) | F35: =IF(D35="","",E35*100) | M35: =IF(B35="","",B35) | P35: =IF(O35="","",O35-O33) | Q35: =IF(O35="","",P35*1000) | X35: =IF(AP35="","",AP35) | Z35: =IF(Y35="","",Y35-Y33) | AA35: =IF(Y35="","",Z35*1000) | AD35: =IF(X35="","",X35) | AF35: =IF(AE35="","",AE35-AE33) | AG35: =IF(AE35="","",AF35*1000) | AJ35: =IF(AD35="","",AD35) | AL35: =IF(AK35="","",AK35-AK33) | AM35: =IF(AK35="","",AL35*1000) | AP35: =IF(M35="","",M35) | AS35: =IF(AR35="","",AR35-AR33) | AT35: =IF(AR35="","",AS35*1000)
E36: =IF(D36="","",D36-D34) | F36: =IF(D36="","",E36*100)
B37: =DATEDIF(#REF!,B$17,"d") -> #REF! | E37: =IF(D37="","",D37-D29) | F37: =IF(D37="","",E37*100) | M37: =IF(B37="","",B37) -> #REF! | P37: =IF(O37="","",O37-O29) | Q37: =IF(O37="","",P37*1000) | X37: =IF(AP37="","",AP37) -> #REF! | Z37: =IF(Y37="","",Y37-Y29) | AA37: =IF(Y37="","",Z37*1000) | AD37: =IF(X37="","",X37) -> #REF! | AF37: =IF(AE37="","",AE37-AE29) | AG37: =IF(AE37="","",AF37*1000) | AJ37: =IF(AD37="","",AD37) -> #REF! | AL37: =IF(AK37="","",AK37-AK29) | AM37: =IF(AK37="","",AL37*1000) | AP37: =IF(M37="","",M37) -> #REF! | AS37: =IF(AR37="","",AR37-AR29) | AT37: =IF(AR37="","",AS37*1000)
E38: =IF(D38="","",D38-D34) | F38: =IF(D38="","",E38*100)
B39: =SUM(E3, E5, E7, E9, E11, E13, E15, E17, E19, E21, E23, E25, E39,E27,E29,E31,E33,E35,E37) -> 1026 | E39: =IF(D39="","",D39-D37) | F39: =IF(D39="","",E39*100) | M39: =SUM(P3, P5, P7, P9, P11, P13, P15, P17, P19, P21, P29, P37, P39) -> 120 | P39: =IF(O39="","",O39-O37) | Q39: =IF(O39="","",P39*1000) | X39: =SUM(Z3, Z5, Z7, Z9, Z11, Z13, Z15, Z17, Z19, Z21, Z29, Z37, Z39) -> 108 | Z39: =IF(Y39="","",Y39-Y37) | AA39: =IF(Y39="","",Z39*1000) | AD39: =SUM(AF3, AF5, AF7, AF9, AF11, AF13, AF15, AF17, AF19, AF21, AF29, AF37, AF39) -> 94 | AF39: =IF(AE39="","",AE39-AE37) | AG39: =IF(AE39="","",AF39*1000) | AJ39: =SUM(AL3, AL5, AL7, AL9, AL11, AL13, AL15, AL17, AL19, AL21, AL29, AL37, AL39) -> 106 | AL39: =IF(AK39="","",AK39-AK37) | AM39: =IF(AK39="","",AL39*1000) | AP39: =SUM(AS3, AS5, AS7, AS9, AS11, AS13, AS15, AS17, AS19, AS21, AS29, AS37, AS39) -> 56 | AS39: =IF(AR39="","",AR39-AR37) | AT39: =IF(AR39="","",AS39*1000)
B40: =SUM(E4, E6, E8, E10, E12, E14, E16, E18, E20, E22, E24, E26, E40,E28,E30,E32,E34,E36,E38) -> 515 | E40: =IF(D40="","",D40-D38) | F40: =IF(D40="","",E40*100) | M40: =SUM(P4, P6, P8, P10, P12, P14, P16, P18, P20, P22, P34, P38, P40) -> 0 | X40: =SUM(Z4, Z6, Z8, Z10, Z12, Z14, Z16, Z18, Z20, Z22, Z34, Z38, Z40) -> 0 | AD40: =SUM(AF4, AF6, AF8, AF10, AF12, AF14, AF16, AF18, AF20, AF22, AF34, AF38, AF40) -> 0 | AJ40: =SUM(AL4, AL6, AL8, AL10, AL12, AL14, AL16, AL18, AL20, AL22, AL34, AL38, AL40) -> 0 | AP40: =SUM(AS4, AS6, AS8, AS10, AS12, AS14, AS16, AS18, AS20, AS22, AS34, AS38, AS40) -> 0
C41: =SUM(C3:C34) -> 638100 | E41: =SUM(E3:E40) -> 1541 | F41: =SUM(F3:F40) -> 154100 | G41: =SUM(G3:G14) -> 0 | H41: =SUM(H3:H14) -> 0 | I41: =SUM(I3:I14) -> 0 | J41: =SUM(J3:J14) -> 0 | P41: =SUM(P3:P39) -> 120 | Q41: =SUM(Q3:Q40) -> 120000 | R41: =SUM(R3:R14) -> 0 | S41: =SUM(S3:S14) -> 0 | T41: =SUM(T3:T14) -> 0 | U41: =SUM(U3:U14) -> 0 | Z41: =SUM(Z3:Z39) -> 108 | AA41: =SUM(AA3:AA40) -> 108000 | AF41: =SUM(AF3:AF39) -> 94 | AG41: =SUM(AG3:AG40) -> 94000 | AL41: =SUM(AL3:AL39) -> 106 | AM41: =SUM(AM3:AM40) -> 106000 | AS41: =SUM(AS3:AS39) -> 56 | AT41: =SUM(AT3:AT40) -> 56000 | AU41: =SUM(AU3:AU14) -> 0 | AV41: =SUM(AV3:AV14) -> 0 | AW41: =SUM(AW3:AW14) -> 0 | AX41: =SUM(AX3:AX14) -> 0
B42: 今月の日数 | C42: 全台日売AVE | D42: 売上予想合計 | E42: AVE | F42: 売上予想 | P42: AVE | Q42: 売上予想 | Z42: AVE | AA42: 売上予想 | AF42: AVE | AG42: 売上予想 | AL42: AVE | AM42: 売上予想 | AS42: AVE | AT42: 売上予想
...

Sheet 唐津
B1: 1000円ガチャ | H1: 2000円ガチャ
B2: 日付 | C2: 今回ﾒｰﾀｰ | D2: ﾒｰﾀｰ差 | E2: 売上 | F2: 備考
B3: 45914 | C3: 622 | D3: 38 | E3: 38000
B4: 45916 | C4: 665 | D4: =IF(C4="","",C4-C3) -> 43 | E4: =IF(C4="","",D4*1000) -> 43000 | F4: 要、玉補充！！
B5: 45919 | C5: 675 | D5: =IF(C5="","",C5-C4) -> 10 | E5: =IF(C5="","",D5*1000) -> 10000 | F5: ロッカー残り6箇所
B6: 45922 | C6: 712 | D6: =IF(C6="","",C6-C5) -> 37 | E6: =IF(C6="","",D6*1000) -> 37000
B7: 45926 | C7: 725 | D7: =IF(C7="","",C7-C6) -> 13 | E7: =IF(C7="","",D7*1000) -> 13000 | F7: ロッカー残り6 60玉補充
B8: 45930 | C8: 758 | D8: =IF(C8="","",C8-C7) -> 33 | E8: =IF(C8="","",D8*1000) -> 33000 | F8: ロッカー残り6 更に60玉補充
B9: 45933 | C9: 763 | D9: =IF(C9="","",C9-C8) -> 5 | E9: =IF(C9="","",D9*1000) -> 5000
B10: 45936 | C10: 775 | D10: =IF(C10="","",C10-C9) -> 12 | E10: =IF(C10="","",D10*1000) -> 12000
B11: 45940 | C11: 798 | D11: =IF(C11="","",C11-C10) -> 23 | E11: =IF(C11="","",D11*1000) -> 23000 | F11: リセット済み
B12: 45943 | C12: 834 | D12: =IF(C12="","",C12-C11) -> 36 | E12: =IF(C12="","",D12*1000) -> 36000 | F12: ロッカー空き1箇所 残り9箇所
D13: =IF(C13="","",C13-C12) | E13: =IF(C13="","",D13*1000)
D14: =SUM(D3:D13) -> 250 | E14: =SUM(E3:E13) -> 250000
B16: 1000円ガチャ
B17: 日付 | C17: 今回ﾒｰﾀｰ | D17: ﾒｰﾀｰ差 | E17: 売上 | F17: 備考
B18: 45947 | C18: 863 | D18: =IF(C18="","",C18-C12) -> 29 | E18: =IF(C18="","",D18*1000) -> 29000
B19: 45957 | C19: 924 | D19: =IF(C19="","",C19-C18) -> 61 | E19: =IF(C19="","",D19*1000) -> 61000
B20: 45961 | C20: 930 | D20: =IF(C20="","",C20-C19) -> 6 | E20: =IF(C20="","",D20*1000) -> 6000
B21: 45964 | C21: 943 | D21: =IF(C21="","",C21-C20) -> 13 | E21: =IF(C21="","",D21*1000) -> 13000
B22: 45968 | C22: 961 | D22: =IF(C22="","",C22-C21) -> 18 | E22: =IF(C22="","",D22*1000) -> 18000
B23: 45971 | C23: 969 | D23: =IF(C23="","",C23-C22) -> 8 | E23: =IF(C23="","",D23*1000) -> 8000 | F23: リセット済み
B24: 45973 | C24: 982 | D24: =IF(C24="","",C24-C23) -> 13 | E24: =IF(C24="","",D24*1000) -> 13000
D25: =IF(C25="","",C25-C24) | E25: =IF(C25="","",D25*1000)
D26: =IF(C26="","",C26-C25) | E26: =IF(C26="","",D26*1000)
D27: =IF(C27="","",C27-C26) | E27: =IF(C27="","",D27*1000)
D28: =IF(C28="","",C28-C27) | E28: =IF(C28="","",D28*1000)
D29: =SUM(D18:D28) -> 148 | E29: =SUM(E18:E28) -> 148000
B31: 1000円ガチャ | H31: 2000円ガチャ
B32: 日付 | C32: 今回ﾒｰﾀｰ | D32: ﾒｰﾀｰ差 | E32: 売上 | F32: 備考 | H32: 日付 | I32: 今回ﾒｰﾀｰ | J32: ﾒｰﾀｰ差 | K32: 売上 | L32: 備考
B33: 45977 | C33: 1014 | D33: =IF(C33="","",C33-C24) -> 32 | E33: =IF(C33="","",D33*1000) -> 32000 | J33: =IF(I33="","",I33-I24) | K33: =IF(I33="","",J33*1000)
B34: 45982 | C34: 1022 | D34: =IF(C34="","",C34-C33) -> 8 | E34: =IF(C34="","",D34*1000) -> 8000 | J34: =IF(I34="","",I34-I33) | K34: =IF(I34="","",J34*1000)
B35: 45985 | C35: 1028 | D35: =IF(C35="","",C35-C34) -> 6 | E35: =IF(C35="","",D35*1000) -> 6000 | J35: =IF(I35="","",I35-I34) | K35: =IF(I35="","",J35*1000)
B36: 45989 | C36: 1057 | D36: =IF(C36="","",C36-C35) -> 29 | E36: =IF(C36="","",D36*1000) -> 29000 | J36: =IF(I36="","",I36-I35) | K36: =IF(I36="","",J36*1000)
B37: 45996 | C37: 1094 | D37: =IF(C37="","",C37-C36) -> 37 | E37: =IF(C37="","",D37*1000) -> 37000 | J37: =IF(I37="","",I37-I36) | K37: =IF(I37="","",J37*1000)
B38: 45999 | C38: 1118 | D38: =IF(C38="","",C38-C37) -> 24 | E38: =IF(C38="","",D38*1000) -> 24000 | J38: =IF(I38="","",I38-I37) | K38: =IF(I38="","",J38*1000)
B39: 46002 | C39: 1134 | D39: =IF(C39="","",C39-C38) -> 16 | E39: =IF(C39="","",D39*1000) -> 16000 | H39: 46002 | I39: 7699 | K39: =IF(I39="","",J39*1000) -> 0 | L39: 設置
B40: 46006 | C40: 1167 | D40: =IF(C40="","",C40-C39) -> 33 | E40: =IF(C40="","",D40*1000) -> 33000 | H40: 46008 | I40: 7741 | J40: =IF(I40="","",I40-I39) -> 42 | K40: =IF(I40="","",J40*1000) -> 42000
B41: 46008 | C41: 1188 | D41: =IF(C41="","",C41-C40) -> 21 | E41: =IF(C41="","",D41*1000) -> 21000
J42: =IF(I42="","",I42-I41) | K42: =IF(I42="","",J42*1000)
...

Sheet 飯塚
B1: 2000円 | C1: 店番00309 | J1: 473.2 | M1: 1000円 | U1: 473.2 | X1: ティアラ2000円 | AF1: 473.2
B2: 日付 | C2: 前回ﾒｰﾀｰ | D2: 今回ﾒｰﾀｰ | E2: ﾒｰﾀｰ差 | F2: 売上 | G2: 立替金 | H2: 総売上 | I2: ＢＯＸ払出 | J2: ＣＰ払出 | K2: 備考 | M2: 日付 | N2: 前回ﾒｰﾀｰ | O2: 今回ﾒｰﾀｰ | P2: ﾒｰﾀｰ差 | Q2: 売上 | R2: 立替金 | S2: 総売上 | T2: ＢＯＸ払出 | U2: ＣＰ払出 | V2: 備考 | X2: 日付 | Y2: 前回ﾒｰﾀｰ | Z2: 今回ﾒｰﾀｰ | AA2: ﾒｰﾀｰ差 | AB2: 売上 | AC2: 立替金 | AD2: 総売上 | AE2: ＢＯＸ払出 | AF2: ＣＰ払出 | AG2: 備考
B3: 45922 | C3: 17177 | D3: 17185 | E3: =+D3-C3 -> 8 | F3: =+E3*1000 -> 8000 | G3: 0 | H3: =+F3-G3 -> 8000 | J3: =E3*#REF!/2 -> #REF! | M3: 45922 | N3: 2808 | O3: 2831 | P3: =+O3-N3 -> 23 | Q3: =+P3*1000 -> 23000 | R3: 0 | S3: =+Q3-R3 -> 23000 | U3: =P3*#REF!/2 -> #REF! | X3: 45922 | Y3: 7086 | Z3: 7104 | AA3: =+Z3-Y3 -> 18 | AB3: =+AA3*1000 -> 18000 | AC3: 0 | AD3: =+AB3-AC3 -> 18000 | AF3: =AA3*#REF!/2 -> #REF!
B4: 45926 | C4: 17185 | D4: 17209 | E4: =+D4-C4 -> 24 | F4: =+E4*1000 -> 24000 | G4: 0 | H4: =+F4-G4 -> 24000 | J4: =E4*#REF!/2 -> #REF! | M4: 45926 | N4: 2831 | O4: 2880 | P4: =+O4-N4 -> 49 | Q4: =+P4*1000 -> 49000 | R4: 0 | S4: =+Q4-R4 -> 49000 | U4: =P4*#REF!/2 -> #REF! | X4: 45926 | Y4: 7104 | Z4: 7134 | AA4: =+Z4-Y4 -> 30 | AB4: =+AA4*1000 -> 30000 | AC4: 0 | AD4: =+AB4-AC4 -> 30000 | AF4: =AA4*#REF!/2 -> #REF!
B5: 45929 | C5: 17209 | D5: 17237 | E5: =+D5-C5 -> 28 | F5: =+E5*1000 -> 28000 | G5: 0 | H5: =+F5-G5 -> 28000 | J5: =E5*#REF!/2 -> #REF! | M5: 45929 | N5: 2880 | O5: 2930 | P5: =+O5-N5 -> 50 | Q5: =+P5*1000 -> 50000 | R5: 0 | S5: =+Q5-R5 -> 50000 | U5: =P5*#REF!/2 -> #REF! | X5: 45929 | Y5: 7134 | Z5: 7148 | AA5: =+Z5-Y5 -> 14 | AB5: =+AA5*1000 -> 14000 | AC5: 0 | AD5: =+AB5-AC5 -> 14000 | AF5: =AA5*#REF!/2 -> #REF!
B6: 45933 | C6: 17237 | D6: 17259 | E6: =+D6-C6 -> 22 | F6: =+E6*1000 -> 22000 | G6: 0 | H6: =+F6-G6 -> 22000 | J6: =E6*#REF!/2 -> #REF! | M6: 45933 | N6: 2930 | O6: 3056 | P6: =+O6-N6 -> 126 | Q6: =+P6*1000 -> 126000 | R6: 0 | S6: =+Q6-R6 -> 126000 | U6: =P6*#REF!/2 -> #REF! | X6: 45933 | Y6: 7148 | Z6: 7156 | AA6: =+Z6-Y6 -> 8 | AB6: =+AA6*1000 -> 8000 | AC6: 0 | AD6: =+AB6-AC6 -> 8000 | AF6: =AA6*#REF!/2 -> #REF!
B7: 45936 | C7: 17259 | D7: 17275 | E7: =+D7-C7 -> 16 | F7: =+E7*1000 -> 16000 | G7: 0 | H7: =+F7-G7 -> 16000 | J7: =E7*#REF!/2 -> #REF! | M7: 45936 | N7: 3056 | O7: 3073 | P7: =+O7-N7 -> 17 | Q7: =+P7*1000 -> 17000 | R7: 0 | S7: =+Q7-R7 -> 17000 | U7: =P7*#REF!/2 -> #REF! | X7: 45936 | Y7: 7156 | Z7: 7170 | AA7: =+Z7-Y7 -> 14 | AB7: =+AA7*1000 -> 14000 | AC7: 0 | AD7: =+AB7-AC7 -> 14000 | AF7: =AA7*#REF!/2 -> #REF!
B8: 45940 | C8: 17275 | D8: 17341 | E8: =+D8-C8 -> 66 | F8: =+E8*1000 -> 66000 | G8: 0 | H8: =+F8-G8 -> 66000 | J8: =E8*#REF!/2 -> #REF! | M8: 45940 | N8: 3073 | O8: 3086 | P8: =+O8-N8 -> 13 | Q8: =+P8*1000 -> 13000 | R8: 0 | S8: =+Q8-R8 -> 13000 | U8: =P8*#REF!/2 -> #REF! | X8: 45940 | Y8: 7170 | Z8: 7190 | AA8: =+Z8-Y8 -> 20 | AB8: =+AA8*1000 -> 20000 | AC8: 0 | AD8: =+AB8-AC8 -> 20000 | AF8: =AA8*#REF!/2 -> #REF!
B9: 45943 | C9: 17341 | D9: 17383 | E9: =+D9-C9 -> 42 | F9: =+E9*1000 -> 42000 | G9: 0 | H9: =+F9-G9 -> 42000 | J9: =E9*#REF!/2 -> #REF! | M9: 45943 | N9: 3086 | O9: 3099 | P9: =+O9-N9 -> 13 | Q9: =+P9*1000 -> 13000 | R9: 0 | S9: =+Q9-R9 -> 13000 | U9: =P9*#REF!/2 -> #REF! | X9: 45943 | Y9: 7190 | Z9: 7204 | AA9: =+Z9-Y9 -> 14 | AB9: =+AA9*1000 -> 14000 | AC9: 0 | AD9: =+AB9-AC9 -> 14000 | AF9: =AA9*#REF!/2 -> #REF!
B10: 45947 | C10: 17383 | D10: 17463 | E10: =+D10-C10 -> 80 | F10: =+E10*1000 -> 80000 | G10: 0 | H10: =+F10-G10 -> 80000 | J10: =E10*#REF!/2 -> #REF! | M10: 45947 | N10: 3099 | O10: 3129 | P10: =+O10-N10 -> 30 | Q10: =+P10*1000 -> 30000 | R10: 0 | S10: =+Q10-R10 -> 30000 | U10: =P10*#REF!/2 -> #REF! | X10: 45947 | Y10: 7204 | Z10: 7220 | AA10: =+Z10-Y10 -> 16 | AB10: =+AA10*1000 -> 16000 | AC10: 0 | AD10: =+AB10-AC10 -> 16000 | AF10: =AA10*#REF!/2 -> #REF!
B11: 45950 | C11: 17463 | D11: 17652 | E11: =+D11-C11 -> 189 | F11: =+E11*1000 -> 189000 | G11: 0 | H11: =+F11-G11 -> 189000 | J11: =E11*#REF!/2 -> #REF! | L11: 景品原価 | M11: 45950 | N11: 3129 | O11: 3192 | P11: =+O11-N11 -> 63 | Q11: =+P11*1000 -> 63000 | R11: 0 | S11: =+Q11-R11 -> 63000 | U11: =P11*#REF!/2 -> #REF! | W11: 景品原価 | X11: 45950 | Y11: 7220 | Z11: 7238 | AA11: =+Z11-Y11 -> 18 | AB11: =+AA11*1000 -> 18000 | AC11: 0 | AD11: =+AB11-AC11 -> 18000 | AF11: =AA11*#REF!/2 -> #REF! | AH11: 景品原価
E12: =+D12-C12 -> 0 | F12: =+E12*1000 -> 0 | G12: 0 | H12: =+F12-G12 -> 0 | J12: =E12*#REF!/2 -> #REF! | P12: =+O12-N12 -> 0 | Q12: =+P12*1000 -> 0 | R12: 0 | S12: =+Q12-R12 -> 0 | U12: =P12*#REF!/2 -> #REF! | AA12: =+Z12-Y12 -> 0 | AB12: =+AA12*1000 -> 0 | AC12: 0 | AD12: =+AB12-AC12 -> 0 | AF12: =AA12*#REF!/2 -> #REF!
E13: =+D13-C13 -> 0 | F13: =+E13*1000 -> 0 | G13: 0 | H13: =+F13-G13 -> 0 | J13: =E13*#REF!/2 -> #REF! | P13: =+O13-N13 -> 0 | Q13: =+P13*1000 -> 0 | R13: 0 | S13: =+Q13-R13 -> 0 | U13: =P13*#REF!/2 -> #REF! | AA13: =+Z13-Y13 -> 0 | AB13: =+AA13*1000 -> 0 | AC13: 0 | AD13: =+AB13-AC13 -> 0 | AF13: =AA13*#REF!/2 -> #REF!
E14: =+D14-C14 -> 0 | F14: =+E14*1000 -> 0 | G14: 0 | H14: =+F14-G14 -> 0 | J14: =E14*#REF!/2 -> #REF! | P14: =+O14-N14 -> 0 | Q14: =+P14*1000 -> 0 | R14: 0 | S14: =+Q14-R14 -> 0 | U14: =P14*#REF!/2 -> #REF! | AA14: =+Z14-Y14 -> 0 | AB14: =+AA14*1000 -> 0 | AC14: 0 | AD14: =+AB14-AC14 -> 0 | AF14: =AA14*#REF!/2 -> #REF!
E15: =+D15-C15 -> 0 | F15: =+E15*1000 -> 0 | G15: 0 | H15: =+F15-G15 -> 0 | J15: =E15*#REF!/2 -> #REF! | L15: 利益率 | P15: =+O15-N15 -> 0 | Q15: =+P15*1000 -> 0 | R15: 0 | S15: =+Q15-R15 -> 0 | U15: =P15*#REF!/2 -> #REF! | W15: 利益率 | AA15: =+Z15-Y15 -> 0 | AB15: =+AA15*1000 -> 0 | AC15: 0 | AD15: =+AB15-AC15 -> 0 | AF15: =AA15*#REF!/2 -> #REF! | AH15: 利益率
E16: =SUM(E3:E15) -> 475 | F16: =SUM(F3:F15) -> 475000 | G16: =SUM(G3:G15) -> 0 | H16: =SUM(H3:H15) -> 475000 | I16: =SUM(I3:I15) -> 0 | J16: =SUM(J3:J15) -> #REF! | K16: =+H16*0.6-G16-J16 -> #REF! | L16: =+K16/H16 -> #REF! | P16: =SUM(P3:P15) -> 384 | Q16: =SUM(Q3:Q15) -> 384000 | R16: =SUM(R3:R15) -> 0 | S16: =SUM(S3:S15) -> 384000 | T16: =SUM(T3:T15) -> 0 | U16: =SUM(U3:U15) -> #REF! | V16: =+S16*0.6-R16-U16 -> #REF! | W16: =+V16/S16 -> #REF! | AA16: =SUM(AA3:AA15) -> 152 | AB16: =SUM(AB3:AB15) -> 152000 | AC16: =SUM(AC3:AC15) -> 0 | AD16: =SUM(AD3:AD15) -> 152000 | AE16: =SUM(AE3:AE15) -> 0 | AF16: =SUM(AF3:AF15) -> #REF! | AG16: =+AD16*0.6-AC16-AF16 -> #REF! | AH16: =+AG16/AD16 -> #REF!
B18: 2000円 | C18: 店番00309 | J18: 473.2 | M18: 1000円 | U18: 473.2 | X18: ティアラ2000円 | AF18: 473.2
B19: 日付 | C19: 前回ﾒｰﾀｰ | D19: 今回ﾒｰﾀｰ | E19: ﾒｰﾀｰ差 | F19: 売上 | G19: 立替金 | H19: 総売上 | I19: ＢＯＸ払出 | J19: ＣＰ払出 | K19: 備考 | M19: 日付 | N19: 前回ﾒｰﾀｰ | O19: 今回ﾒｰﾀｰ | P19: ﾒｰﾀｰ差 | Q19: 売上 | R19: 立替金 | S19: 総売上 | T19: ＢＯＸ払出 | U19: ＣＰ払出 | V19: 備考 | X19: 日付 | Y19: 前回ﾒｰﾀｰ | Z19: 今回ﾒｰﾀｰ | AA19: ﾒｰﾀｰ差 | AB19: 売上 | AC19: 立替金 | AD19: 総売上 | AE19: ＢＯＸ払出 | AF19: ＣＰ払出 | AG19: 備考
B20: 45954 | C20: 17652 | D20: 17672 | E20: =+D20-C20 -> 20 | F20: =+E20*1000 -> 20000 | G20: 0 | H20: =+F20-G20 -> 20000 | J20: =E20*#REF!/2 -> #REF! | M20: 45954 | N20: 3192 | O20: 3200 | P20: =+O20-N20 -> 8 | Q20: =+P20*1000 -> 8000 | R20: 0 | S20: =+Q20-R20 -> 8000 | U20: =P20*#REF!/2 -> #REF! | X20: 45954 | Y20: 7238 | Z20: 7240 | AA20: =+Z20-Y20 -> 2 | AB20: =+AA20*1000 -> 2000 | AC20: 0 | AD20: =+AB20-AC20 -> 2000 | AF20: =AA20*#REF!/2 -> #REF!
B21: 45957 | C21: 17672 | D21: 17704 | E21: =+D21-C21 -> 32 | F21: =+E21*1000 -> 32000 | G21: 0 | H21: =+F21-G21 -> 32000 | J21: =E21*#REF!/2 -> #REF! | M21: 45957 | N21: 3200 | O21: 3235 | P21: =+O21-N21 -> 35 | Q21: =+P21*1000 -> 35000 | R21: 0 | S21: =+Q21-R21 -> 35000 | U21: =P21*#REF!/2 -> #REF! | X21: 45957 | Y21: 7240 | Z21: 7260 | AA21: =+Z21-Y21 -> 20 | AB21: =+AA21*1000 -> 20000 | AC21: 0 | AD21: =+AB21-AC21 -> 20000 | AF21: =AA21*#REF!/2 -> #REF!
B22: 45961 | C22: 17704 | D22: 17722 | E22: =+D22-C22 -> 18 | F22: =+E22*1000 -> 18000 | G22: 0 | H22: =+F22-G22 -> 18000 | J22: =E22*#REF!/2 -> #REF! | M22: 45961 | N22: 3235 | O22: 3240 | P22: =+O22-N22 -> 5 | Q22: =+P22*1000 -> 5000 | R22: 0 | S22: =+Q22-R22 -> 5000 | U22: =P22*#REF!/2 -> #REF! | X22: 45961 | Y22: 7260 | Z22: 7260 | AA22: =+Z22-Y22 -> 0 | AB22: =+AA22*1000 -> 0 | AC22: 0 | AD22: =+AB22-AC22 -> 0 | AF22: =AA22*#REF!/2 -> #REF!
B23: 45964 | C23: 17722 | D23: 17764 | E23: =+D23-C23 -> 42 | F23: =+E23*1000 -> 42000 | G23: 0 | H23: =+F23-G23 -> 42000 | J23: =E23*#REF!/2 -> #REF! | M23: 45964 | N23: 3240 | O23: 3254 | P23: =+O23-N23 -> 14 | Q23: =+P23*1000 -> 14000 | R23: 0 | S23: =+Q23-R23 -> 14000 | U23: =P23*#REF!/2 -> #REF! | X23: 45964 | Y23: 7260 | Z23: 7268 | AA23: =+Z23-Y23 -> 8 | AB23: =+AA23*1000 -> 8000 | AC23: 0 | AD23: =+AB23-AC23 -> 8000 | AF23: =AA23*#REF!/2 -> #REF!
