Workbook

Sheet クレーン佐賀八女
A1: =SUM(A9,A21,A33,A45,A57,A69,A81,A93,A105,A117,A129,A141,A153,A165,A177,A189,A201,A213,A225,A237,A249,A261,A273,A285,A297,A309,A321,A333,A345,A357,A369) -> 1013727.3 | B1: 日付 | C1: 46160 | D1: =C1+1 -> 46161 | E1: =D1+1 -> 46162 | F1: =E1+1 -> 46163 | G1: =F1+1 -> 46164 | H1: =G1+1 -> 46165 | I1: =H1+1 -> 46166 | J1: =I1+1 -> 46167 | K1: =J1+1 -> 46168 | ... BC1: =BB1+1 -> 46212
B2: =SUM(C2:AO2) -> 3717 | C2: 0 | D2: =SUM(D10,D22,D34,D46,D58,D70,D82,D94,D106,D118,D130,D142,D154,D166,D178,D190,D202,D214,D226,D238,D250,D262,D274,D286,D298,D310,D322,D334,D346,D358,D370) -> 0 | E2: =SUM(E10,E22,E34,E46,E58,E70,E82,E94,E106,E118,E130,E142,E154,E166,E178,E190,E202,E214,E226,E238,E250,E262,E274,E286,E298,E310,E322,E334,E346,E358,E370) -> 0 | F2: =SUM(F10,F22,F34,F46,F58,F70,F82,F94,F106,F118,F130,F142,F154,F166,F178,F190,F202,F214,F226,F238,F250,F262,F274,F286,F298,F310,F322,F334,F346,F358,F370) -> 1835 | G2: =SUM(G10,G22,G34,G46,G58,G70,G82,G94,G106,G118,G130,G142,G154,G166,G178,G190,G202,G214,G226,G238,G250,G262,G274,G286,G298,G310,G322,G334,G346,G358,G370) -> 0 | H2: =SUM(H10,H22,H34,H46,H58,H70,H82,H94,H106,H118,H130,H142,H154,H166,H178,H190,H202,H214,H226,H238,H250,H262,H274,H286,H298,H310,H322,H334,H346,H358,H370) -> 0 | I2: =SUM(I10,I22,I34,I46,I58,I70,I82,I94,I106,I118,I130,I142,I154,I166,I178,I190,I202,I214,I226,I238,I250,I262,I274,I286,I298,I310,I322,I334,I346,I358,I370) -> 1882 | J2: =SUM(J10,J22,J34,J46,J58,J70,J82,J94,J106,J118,J130,J142,J154,J166,J178,J190,J202,J214,J226,J238,J250,J262,J274,J286,J298,J310,J322,J334,J346,J358,J370) -> 0 | K2: =SUM(K10,K22,K34,K46,K58,K70,K82,K94,K106,K118,K130,K142,K154,K166,K178,K190,K202,K214,K226,K238,K250,K262,K274,K286,K298,K310,K322,K334,K346,K358,K370) -> 0 | ... BC2: =SUM(BC10,BC22,BC34,BC46,BC58,BC70,BC82,BC94,BC106,BC118,BC130,BC142,BC154,BC166,BC178,BC190,BC202,BC214,BC226,BC238,BC250,BC262,BC274,BC286,BC298,BC310,BC322,BC334,BC346,BC358,BC370) -> 0
A3: 八女 | B3: 100円 | C3: 33500 | D3: 33500 | E3: 33500 | F3: 33558 | G3: 33558 | H3: 33558 | I3: 33618 | J3: 33618 | K3: 33618 | L3: 33618 | M3: 33618
A4: クリスタル | B4: プライズ | C4: 1234 | D4: =IF(D$3="","",C4) -> 1234 | E4: =IF(E$3="","",D4) -> 1234 | F4: 1241 | G4: =IF(G$3="","",F4) -> 1241 | H4: =IF(H$3="","",G4) -> 1241 | I4: 1242 | J4: =IF(J$3="","",I4) -> 1242 | K4: =IF(K$3="","",J4) -> 1242 | L4: =IF(L$3="","",K4) -> 1242 | M4: =IF(M$3="","",L4) -> 1242 | N4: =IF(N$3="","",M4) | O4: =IF(O$3="","",N4) | P4: =IF(P$3="","",O4) | Q4: =IF(Q$3="","",P4) | ... BC4: =IF(BC$3="","",BB4)
B5: 投入残 | C5: 46 | D5: =IF(D3="","",(C5+C6)) -> 46 | E5: =IF(E3="","",(D5+D6)) -> 46 | F5: 39 | G5: =IF(G3="","",(F5+F6)) -> 39 | H5: =IF(H3="","",(G5+G6)) -> 39 | I5: 38 | J5: =IF(J3="","",(I5+I6)) -> 58 | K5: =IF(K3="","",(J5+J6)) -> 58 | L5: =IF(L3="","",(K5+K6)) -> 58 | M5: =IF(M3="","",(L5+L6)) -> 58 | N5: =IF(N3="","",(M5+M6)) | O5: =IF(O3="","",(N5+N6)) | P5: =IF(P3="","",(O5+O6)) | Q5: =IF(Q3="","",(P5+P6)) | ... BC5: =IF(BC3="","",(BB5+BB6))
B6: 補充 | I6: 20
B7: 単価 | C7: 300 | D7: =IF(D3="","",C7) -> 300 | E7: =IF(E3="","",D7) -> 300 | F7: =IF(F3="","",E7) -> 300 | G7: =IF(G3="","",F7) -> 300 | H7: =IF(H3="","",G7) -> 300 | I7: =IF(I3="","",H7) -> 300 | J7: =IF(J3="","",I7) -> 300 | K7: =IF(K3="","",J7) -> 300 | ... BC7: =IF(BC3="","",BB7)
A8: 月間予想 | B8: 景品名 | C8: フルーツスクイーズ | D8: =IF(D3="","",C8) -> フルーツスクイーズ | E8: =IF(E3="","",D8) -> フルーツスクイーズ | F8: =IF(F3="","",E8) -> フルーツスクイーズ | G8: =IF(G3="","",F8) -> フルーツスクイーズ | H8: =IF(H3="","",G8) -> フルーツスクイーズ | I8: =IF(I3="","",H8) -> フルーツスクイーズ | J8: =IF(J3="","",I8) -> フルーツスクイーズ | K8: =IF(K3="","",J8) -> フルーツスクイーズ | ... BC8: =IF(BC3="","",BB8)
A9: =AVERAGE(C10:AS10)*30*100 -> 32181.818 | B9: 設定
A10: =SUM(C10:AS10) -> 118 | B10: 百差 | C10: 0 | D10: =IF(D3="","",D3-C3) -> 0 | E10: =IF(E3="","",E3-D3) -> 0 | F10: =IF(F3="","",F3-E3) -> 58 | G10: =IF(G3="","",G3-F3) -> 0 | H10: =IF(H3="","",H3-G3) -> 0 | I10: =IF(I3="","",I3-H3) -> 60 | J10: =IF(J3="","",J3-I3) -> 0 | K10: =IF(K3="","",K3-J3) -> 0 | ... BC10: =IF(BC3="","",BC3-BB3)
A11: =SUM(C11:AS11) -> 8 | B11: P差 | C11: 0 | D11: =IF(D4="","",D4-C4) -> 0 | E11: =IF(E4="","",E4-D4) -> 0 | F11: =IF(F4="","",F4-E4) -> 7 | G11: =IF(G4="","",G4-F4) -> 0 | H11: =IF(H4="","",H4-G4) -> 0 | I11: =IF(I4="","",I4-H4) -> 1 | J11: =IF(J4="","",J4-I4) -> 0 | K11: =IF(K4="","",K4-J4) -> 0 | ... BC11: =IF(BC4="","",BC4-BB4)
A12: =SUM(C12:AS12) -> 8 | B12: 払出 | C12: 0 | D12: =IF(D5="","",C5+C6-D5) -> 0 | E12: =IF(E5="","",D5+D6-E5) -> 0 | F12: =IF(F5="","",E5+E6-F5) -> 7 | G12: =IF(G5="","",F5+F6-G5) -> 0 | H12: =IF(H5="","",G5+G6-H5) -> 0 | I12: =IF(I5="","",H5+H6-I5) -> 1 | J12: =IF(J5="","",I5+I6-J5) -> 0 | K12: =IF(K5="","",J5+J6-K5) -> 0 | ... BC12: =IF(BC5="","",BB5+BB6-BC5)
A13: =SUM(C13:AS13) -> 2400 | B13: 払出額 | C13: 0 | D13: =IF(D3="","",D12*D7) -> 0 | E13: =IF(E3="","",E12*E7) -> 0 | F13: =IF(F3="","",F12*F7) -> 2100 | G13: =IF(G3="","",G12*G7) -> 0 | H13: =IF(H3="","",H12*H7) -> 0 | I13: =IF(I3="","",I12*I7) -> 300 | J13: =IF(J3="","",J12*J7) -> 0 | K13: =IF(K3="","",K12*K7) -> 0 | ... BC13: =IF(BC3="","",BC12*BC7)
A14: =IF(A13="","",A13/(A10*100)) -> 0.20338983 | B14: 原価率 | D14: =IF(D13="","",IF(D13=0,"",D13/(D10*100))) | E14: =IF(E13="","",IF(E13=0,"",E13/(E10*100))) | F14: =IF(F13="","",IF(F13=0,"",F13/(F10*100))) -> 0.36206897 | G14: =IF(G13="","",IF(G13=0,"",G13/(G10*100))) | H14: =IF(H13="","",IF(H13=0,"",H13/(H10*100))) | I14: =IF(I13="","",IF(I13=0,"",I13/(I10*100))) -> 0.05 | J14: =IF(J13="","",IF(J13=0,"",J13/(J10*100))) | K14: =IF(K13="","",IF(K13=0,"",K13/(K10*100))) | ... BC14: =IF(BC13="","",IF(BC13=0,"",BC13/(BC10*100)))
A15: 八女 | B15: 100円 | C15: 28348 | D15: =IF(D$3="","",C15) -> 28348 | E15: =IF(E$3="","",D15) -> 28348 | F15: 28443 | G15: =IF(G$3="","",F15) -> 28443 | H15: =IF(H$3="","",G15) -> 28443 | I15: 28496 | J15: =IF(J$3="","",I15) -> 28496 | K15: =IF(K$3="","",J15) -> 28496 | L15: =IF(L$3="","",K15) -> 28496 | M15: =IF(M$3="","",L15) -> 28496 | N15: =IF(N$3="","",M15) | O15: =IF(O$3="","",N15) | P15: =IF(P$3="","",O15) | Q15: =IF(Q$3="","",P15) | ... BC15: =IF(BC$3="","",BB15)
A16: BUZZ＃1 | B16: プライズ | C16: 997 | D16: =IF(D$3="","",C16) -> 997 | E16: =IF(E$3="","",D16) -> 997 | F16: =IF(F$3="","",E16) -> 997 | G16: =IF(G$3="","",F16) -> 997 | H16: =IF(H$3="","",G16) -> 997 | I16: 998 | J16: =IF(J$3="","",I16) -> 998 | K16: =IF(K$3="","",J16) -> 998 | L16: =IF(L$3="","",K16) -> 998 | M16: =IF(M$3="","",L16) -> 998 | N16: =IF(N$3="","",M16) | O16: =IF(O$3="","",N16) | P16: =IF(P$3="","",O16) | Q16: =IF(Q$3="","",P16) | ... BC16: =IF(BC$3="","",BB16)
A17: 1 | B17: 投入残 | C17: 11 | D17: =IF(D15="","",(C17+C18)) -> 11 | E17: =IF(E15="","",(D17+D18)) -> 11 | F17: =IF(F15="","",(E17+E18)) -> 11 | G17: =IF(G15="","",(F17+F18)) -> 11 | H17: =IF(H15="","",(G17+G18)) -> 11 | I17: 10 | J17: =IF(J15="","",(I17+I18)) -> 10 | K17: =IF(K15="","",(J17+J18)) -> 10 | L17: =IF(L15="","",(K17+K18)) -> 10 | M17: =IF(M15="","",(L17+L18)) -> 10 | N17: =IF(N15="","",(M17+M18)) | O17: =IF(O15="","",(N17+N18)) | P17: =IF(P15="","",(O17+O18)) | Q17: =IF(Q15="","",(P17+P18)) | ... BC17: =IF(BC15="","",(BB17+BB18))
A18: 機械合計 | B18: 補充
A19: =+(A22+A34+A46+A58)*100 -> 69800 | B19: 単価 | C19: 1100 | D19: =IF(D15="","",C19) -> 1100 | E19: =IF(E15="","",D19) -> 1100 | F19: =IF(F15="","",E19) -> 1100 | G19: =IF(G15="","",F19) -> 1100 | H19: =IF(H15="","",G19) -> 1100 | I19: =IF(I15="","",H19) -> 1100 | J19: =IF(J15="","",I19) -> 1100 | K19: =IF(K15="","",J19) -> 1100 | ... BC19: =IF(BC15="","",BB19)
A20: 月間予想 | B20: 景品名 | C20: サンリオファン | D20: =IF(D15="","",C20) -> サンリオファン | E20: =IF(E15="","",D20) -> サンリオファン | F20: =IF(F15="","",E20) -> サンリオファン | G20: =IF(G15="","",F20) -> サンリオファン | H20: =IF(H15="","",G20) -> サンリオファン | I20: =IF(I15="","",H20) -> サンリオファン | J20: =IF(J15="","",I20) -> サンリオファン | K20: =IF(K15="","",J20) -> サンリオファン | ... BC20: =IF(BC15="","",BB20)
A21: =AVERAGE(C22:AS22)*30*100 -> 40363.636 | B21: 設定
A22: =SUM(C22:AS22) -> 148 | B22: 百差 | C22: 0 | D22: =IF(D15="","",D15-C15) -> 0 | E22: =IF(E15="","",E15-D15) -> 0 | F22: =IF(F15="","",F15-E15) -> 95 | G22: =IF(G15="","",G15-F15) -> 0 | H22: =IF(H15="","",H15-G15) -> 0 | I22: =IF(I15="","",I15-H15) -> 53 | J22: =IF(J15="","",J15-I15) -> 0 | K22: =IF(K15="","",K15-J15) -> 0 | ... BC22: =IF(BC15="","",BC15-BB15)
A23: =SUM(C23:AS23) -> 1 | B23: P差 | C23: 0 | D23: =IF(D16="","",D16-C16) -> 0 | E23: =IF(E16="","",E16-D16) -> 0 | F23: =IF(F16="","",F16-E16) -> 0 | G23: =IF(G16="","",G16-F16) -> 0 | H23: =IF(H16="","",H16-G16) -> 0 | I23: =IF(I16="","",I16-H16) -> 1 | J23: =IF(J16="","",J16-I16) -> 0 | K23: =IF(K16="","",K16-J16) -> 0 | ... BC23: =IF(BC16="","",BC16-BB16)
A24: =SUM(C24:AS24) -> 1 | B24: 払出 | C24: 0 | D24: =IF(D17="","",C17+C18-D17) -> 0 | E24: =IF(E17="","",D17+D18-E17) -> 0 | F24: =IF(F17="","",E17+E18-F17) -> 0 | G24: =IF(G17="","",F17+F18-G17) -> 0 | H24: =IF(H17="","",G17+G18-H17) -> 0 | I24: =IF(I17="","",H17+H18-I17) -> 1 | J24: =IF(J17="","",I17+I18-J17) -> 0 | K24: =IF(K17="","",J17+J18-K17) -> 0 | ... BC24: =IF(BC17="","",BB17+BB18-BC17)
A25: =SUM(C25:AS25) -> 1100 | B25: 払出額 | C25: 0 | D25: =IF(D15="","",D24*D19) -> 0 | E25: =IF(E15="","",E24*E19) -> 0 | F25: =IF(F15="","",F24*F19) -> 0 | G25: =IF(G15="","",G24*G19) -> 0 | H25: =IF(H15="","",H24*H19) -> 0 | I25: =IF(I15="","",I24*I19) -> 1100 | J25: =IF(J15="","",J24*J19) -> 0 | K25: =IF(K15="","",K24*K19) -> 0 | ... BC25: =IF(BC15="","",BC24*BC19)
A26: =IF(A25="","",A25/(A22*100)) -> 0.074324324 | B26: 原価率 | D26: =IF(D25="","",IF(D25=0,"",D25/(D22*100))) | E26: =IF(E25="","",IF(E25=0,"",E25/(E22*100))) | F26: =IF(F25="","",IF(F25=0,"",F25/(F22*100))) | G26: =IF(G25="","",IF(G25=0,"",G25/(G22*100))) | H26: =IF(H25="","",IF(H25=0,"",H25/(H22*100))) | I26: =IF(I25="","",IF(I25=0,"",I25/(I22*100))) -> 0.20754717 | J26: =IF(J25="","",IF(J25=0,"",J25/(J22*100))) | K26: =IF(K25="","",IF(K25=0,"",K25/(K22*100))) | ... BC26: =IF(BC25="","",IF(BC25=0,"",BC25/(BC22*100)))
A27: 八女 | B27: 100円 | C27: 21919 | D27: =IF(D$3="","",C27) -> 21919 | E27: =IF(E$3="","",D27) -> 21919 | F27: 22145 | G27: =IF(G$3="","",F27) -> 22145 | H27: =IF(H$3="","",G27) -> 22145 | I27: 22186 | J27: =IF(J$3="","",I27) -> 22186 | K27: =IF(K$3="","",J27) -> 22186 | L27: =IF(L$3="","",K27) -> 22186 | M27: =IF(M$3="","",L27) -> 22186 | N27: =IF(N$3="","",M27) | O27: =IF(O$3="","",N27) | P27: =IF(P$3="","",O27) | Q27: =IF(Q$3="","",P27) | ... BC27: =IF(BC$3="","",BB27)
A28: BUZZ＃1 | B28: プライズ | C28: 1001 | D28: =IF(D$3="","",C28) -> 1001 | E28: =IF(E$3="","",D28) -> 1001 | F28: 1011 | G28: =IF(G$3="","",F28) -> 1011 | H28: =IF(H$3="","",G28) -> 1011 | I28: 1017 | J28: =IF(J$3="","",I28) -> 1017 | K28: =IF(K$3="","",J28) -> 1017 | L28: =IF(L$3="","",K28) -> 1017 | M28: =IF(M$3="","",L28) -> 1017 | N28: =IF(N$3="","",M28) | O28: =IF(O$3="","",N28) | P28: =IF(P$3="","",O28) | Q28: =IF(Q$3="","",P28) | ... BC28: =IF(BC$3="","",BB28)
A29: 2 | B29: 投入残 | C29: 18 | D29: =IF(D27="","",(C29+C30)) -> 18 | E29: =IF(E27="","",(D29+D30)) -> 18 | F29: =IF(F27="","",(E29+E30)) -> 18 | G29: =IF(G27="","",(F29+F30)) -> 18 | H29: =IF(H27="","",(G29+G30)) -> 18 | I29: 17 | J29: =IF(J27="","",(I29+I30)) -> 17 | K29: =IF(K27="","",(J29+J30)) -> 17 | L29: =IF(L27="","",(K29+K30)) -> 17 | M29: =IF(M27="","",(L29+L30)) -> 17 | N29: =IF(N27="","",(M29+M30)) | O29: =IF(O27="","",(N29+N30)) | P29: =IF(P27="","",(O29+O30)) | Q29: =IF(Q27="","",(P29+P30)) | ... BC29: =IF(BC27="","",(BB29+BB30))
B30: 補充
B31: 単価 | C31: 500 | D31: =IF(D27="","",C31) -> 500 | E31: =IF(E27="","",D31) -> 500 | F31: =IF(F27="","",E31) -> 500 | G31: =IF(G27="","",F31) -> 500 | H31: =IF(H27="","",G31) -> 500 | I31: =IF(I27="","",H31) -> 500 | J31: =IF(J27="","",I31) -> 500 | K31: =IF(K27="","",J31) -> 500 | ... BC31: =IF(BC27="","",BB31)
A32: 月間予想 | B32: 景品名 | C32: サンリオデカぱっちん | D32: =IF(D27="","",C32) -> サンリオデカぱっちん | E32: =IF(E27="","",D32) -> サンリオデカぱっちん | F32: =IF(F27="","",E32) -> サンリオデカぱっちん | G32: =IF(G27="","",F32) -> サンリオデカぱっちん | H32: =IF(H27="","",G32) -> サンリオデカぱっちん | I32: =IF(I27="","",H32) -> サンリオデカぱっちん | J32: =IF(J27="","",I32) -> サンリオデカぱっちん | K32: =IF(K27="","",J32) -> サンリオデカぱっちん | ... BC32: =IF(BC27="","",BB32)
A33: =AVERAGE(C34:AS34)*30*100 -> 72818.182 | B33: 設定
A34: =SUM(C34:AS34) -> 267 | B34: 百差 | C34: 0 | D34: =IF(D27="","",D27-C27) -> 0 | E34: =IF(E27="","",E27-D27) -> 0 | F34: =IF(F27="","",F27-E27) -> 226 | G34: =IF(G27="","",G27-F27) -> 0 | H34: =IF(H27="","",H27-G27) -> 0 | I34: =IF(I27="","",I27-H27) -> 41 | J34: =IF(J27="","",J27-I27) -> 0 | K34: =IF(K27="","",K27-J27) -> 0 | ... BC34: =IF(BC27="","",BC27-BB27)
A35: =SUM(C35:AS35) -> 16 | B35: P差 | C35: 0 | D35: =IF(D28="","",D28-C28) -> 0 | E35: =IF(E28="","",E28-D28) -> 0 | F35: =IF(F28="","",F28-E28) -> 10 | G35: =IF(G28="","",G28-F28) -> 0 | H35: =IF(H28="","",H28-G28) -> 0 | I35: =IF(I28="","",I28-H28) -> 6 | J35: =IF(J28="","",J28-I28) -> 0 | K35: =IF(K28="","",K28-J28) -> 0 | ... BC35: =IF(BC28="","",BC28-BB28)
A36: =SUM(C36:AS36) -> 1 | B36: 払出 | C36: 0 | D36: =IF(D29="","",C29+C30-D29) -> 0 | E36: =IF(E29="","",D29+D30-E29) -> 0 | F36: =IF(F29="","",E29+E30-F29) -> 0 | G36: =IF(G29="","",F29+F30-G29) -> 0 | H36: =IF(H29="","",G29+G30-H29) -> 0 | I36: =IF(I29="","",H29+H30-I29) -> 1 | J36: =IF(J29="","",I29+I30-J29) -> 0 | K36: =IF(K29="","",J29+J30-K29) -> 0 | ... BC36: =IF(BC29="","",BB29+BB30-BC29)
A37: =SUM(C37:AS37) -> 500 | B37: 払出額 | C37: 0 | D37: =IF(D27="","",D36*D31) -> 0 | E37: =IF(E27="","",E36*E31) -> 0 | F37: =IF(F27="","",F36*F31) -> 0 | G37: =IF(G27="","",G36*G31) -> 0 | H37: =IF(H27="","",H36*H31) -> 0 | I37: =IF(I27="","",I36*I31) -> 500 | J37: =IF(J27="","",J36*J31) -> 0 | K37: =IF(K27="","",K36*K31) -> 0 | ... BC37: =IF(BC27="","",BC36*BC31)
A38: =IF(A37="","",A37/(A34*100)) -> 0.018726592 | B38: 原価率 | D38: =IF(D37="","",IF(D37=0,"",D37/(D34*100))) | E38: =IF(E37="","",IF(E37=0,"",E37/(E34*100))) | F38: =IF(F37="","",IF(F37=0,"",F37/(F34*100))) | G38: =IF(G37="","",IF(G37=0,"",G37/(G34*100))) | H38: =IF(H37="","",IF(H37=0,"",H37/(H34*100))) | I38: =IF(I37="","",IF(I37=0,"",I37/(I34*100))) -> 0.12195122 | J38: =IF(J37="","",IF(J37=0,"",J37/(J34*100))) | K38: =IF(K37="","",IF(K37=0,"",K37/(K34*100))) | ... BC38: =IF(BC37="","",IF(BC37=0,"",BC37/(BC34*100)))
A39: 八女 | B39: 100円 | C39: 22220 | D39: =IF(D$3="","",C39) -> 22220 | E39: =IF(E$3="","",D39) -> 22220 | F39: 22301 | G39: =IF(G$3="","",F39) -> 22301 | H39: =IF(H$3="","",G39) -> 22301 | I39: 22382 | J39: =IF(J$3="","",I39) -> 22382 | K39: =IF(K$3="","",J39) -> 22382 | L39: =IF(L$3="","",K39) -> 22382 | M39: =IF(M$3="","",L39) -> 22382 | N39: =IF(N$3="","",M39) | O39: =IF(O$3="","",N39) | P39: =IF(P$3="","",O39) | Q39: =IF(Q$3="","",P39) | ... BC39: =IF(BC$3="","",BB39)
A40: BUZZ＃1 | B40: プライズ | C40: 1045 | D40: =IF(D$3="","",C40) -> 1045 | E40: =IF(E$3="","",D40) -> 1045 | F40: 1052 | G40: =IF(G$3="","",F40) -> 1052 | H40: =IF(H$3="","",G40) -> 1052 | I40: 1055 | J40: =IF(J$3="","",I40) -> 1055 | K40: =IF(K$3="","",J40) -> 1055 | L40: =IF(L$3="","",K40) -> 1055 | M40: =IF(M$3="","",L40) -> 1055 | N40: =IF(N$3="","",M40) | O40: =IF(O$3="","",N40) | P40: =IF(P$3="","",O40) | Q40: =IF(Q$3="","",P40) | ... BC40: =IF(BC$3="","",BB40)
...

Sheet ガチャ
B1: 日付 | C1: 46157 | D1: =C1+1 -> 46158 | E1: =D1+1 -> 46159 | F1: =E1+1 -> 46160 | G1: =F1+1 -> 46161 | H1: =G1+1 -> 46162 | I1: =H1+1 -> 46163 | J1: =I1+1 -> 46164 | K1: =J1+1 -> 46165 | ... AU1: =AT1+1 -> 46201
A2: 八女 | B2: 1000円 | C2: 6561 | D2: 6568 | E2: 6573 | F2: 6576 | G2: 6576 | H2: 6581 | I2: 6582 | J2: 6582 | K2: 6587 | L2: 6587 | M2: 6587 | N2: 6590 | O2: 6591
A3: ガチャコロ | B3: カプセル上 | C3: 1814 | D3: 1817 | E3: 1818 | F3: 1819 | G3: 1819 | H3: 1821 | I3: 1821 | J3: 1821 | K3: 1823 | L3: 1823 | M3: 1823 | N3: 1824 | O3: 1824
A4: =+A9*1000 -> 30000 | B4: カプセル下 | C4: 3201 | D4: 3202 | E4: 3205 | F4: 3206 | G4: 3206 | H4: 3207 | I4: 3208 | J4: 3208 | K4: 3209 | L4: 3209 | M4: 3209 | N4: 3210 | O4: 3211
A5: 月間予想 | B5: 補充
A6: =AVERAGE(C9:AS9)*30*1000 -> 75000 | B6: 単価
B7: 払出No
B8: 備考
A9: =SUM(C9:AS9) -> 30 | B9: 千差 | D9: =IF(D2="","",D2-C2) -> 7 | E9: =IF(E2="","",E2-D2) -> 5 | F9: =IF(F2="","",F2-E2) -> 3 | G9: =IF(G2="","",G2-F2) -> 0 | H9: =IF(H2="","",H2-G2) -> 5 | I9: =IF(I2="","",I2-H2) -> 1 | J9: =IF(J2="","",J2-I2) -> 0 | K9: =IF(K2="","",K2-J2) -> 5 | ... AU9: =IF(AU2="","",AU2-AT2)
A10: =SUM(C10:AS10) -> 10 | B10: CP上差 | D10: =IF(D3="","",D3-C3) -> 3 | E10: =IF(E3="","",E3-D3) -> 1 | F10: =IF(F3="","",F3-E3) -> 1 | G10: =IF(G3="","",G3-F3) -> 0 | H10: =IF(H3="","",H3-G3) -> 2 | I10: =IF(I3="","",I3-H3) -> 0 | J10: =IF(J3="","",J3-I3) -> 0 | K10: =IF(K3="","",K3-J3) -> 2 | ... AU10: =IF(AU3="","",AU3-AT3)
A11: =SUM(C11:AS11) -> 11 | B11: CP下差 | D11: =IF(D4="","",D4-C4) -> 1 | E11: =IF(E4="","",E4-D4) -> 3 | F11: =IF(F4="","",F4-E4) -> 1 | G11: =IF(G4="","",G4-F4) -> 0 | H11: =IF(H4="","",H4-G4) -> 1 | I11: =IF(I4="","",I4-H4) -> 1 | J11: =IF(J4="","",J4-I4) -> 0 | K11: =IF(K4="","",K4-J4) -> 1 | ... AE11: =IF(AE4="","",AE4-AD4) | AF11: 1 | AG11: =IF(AG4="","",AG4-AF4) | AH11: =IF(AH4="","",AH4-AG4) | AI11: =IF(AI4="","",AI4-AH4) | AJ11: =IF(AJ4="","",AJ4-AI4) | AK11: =IF(AK4="","",AK4-AJ4) | AL11: =IF(AL4="","",AL4-AK4) | AM11: =IF(AM4="","",AM4-AL4) | AN11: =IF(AN4="","",AN4-AM4) | ... AU11: =IF(AU4="","",AU4-AT4)
A12: =SUM(C12:AJ12) -> 0 | B12: 払出額
A13: =IF(A12="","",A12/(A9*100)) -> 0 | B13: 原価率

Sheet 集金
B1: 前回M | C1: 今回M | D1: 枚数 | F1: 千 | G1: 五百 | H1: 百 | I1: 金額 | K1: 立替
A2: 八女 | E2: =SUM(E3:E39) -> 4017 | L2: 両替機 | M2: メーター | O2: 途中両替
A3: ガチャコロ | B3: =MIN(ガチャ!2:2) -> 6561 | C3: =MAX(ガチャ!2:2) -> 6591 | D3: =C3-B3 -> 30 | E3: =D3*10 -> 300 | I3: =F3*1000 -> 0 | J3: =I3-E3*100 -> -30000 | L3: 千 | M3: 1006 | N3: =M3*1000 -> 1006000
A4: BUZZ1 | B4: =MIN(クレーン佐賀八女!A15:AR15) -> 28348 | C4: {=LOOKUP(2,1/(ISNUMBER(クレーン佐賀八女!B15:AS15)),クレーン佐賀八女!B15:AS15)} -> 28496 | D4: =C4-B4 -> 148 | E4: =SUM(D4:D7) -> 698 | I4: =F4*1000+G4*500+H4*100 -> 0 | J4: =I4-E4*100 -> -69800 | L4: 五百 | M4: 476 | N4: =M4*500 -> 238000
B5: =MIN(クレーン佐賀八女!A27:AR27) -> 21919 | C5: {=LOOKUP(2,1/(ISNUMBER(クレーン佐賀八女!B27:AS27)),クレーン佐賀八女!B27:AS27)} -> 22186 | D5: =C5-B5 -> 267 | L5: 百 | M5: 2440 | N5: =M5*100 -> 244000
B6: =MIN(クレーン佐賀八女!A39:AR39) -> 22220 | C6: {=LOOKUP(2,1/(ISNUMBER(クレーン佐賀八女!B39:AS39)),クレーン佐賀八女!B39:AS39)} -> 22382 | D6: =C6-B6 -> 162 | L6: 集金時実数
B7: =MIN(クレーン佐賀八女!A51:AR51) -> 18777 | C7: {=LOOKUP(2,1/(ISNUMBER(クレーン佐賀八女!B51:AS51)),クレーン佐賀八女!B51:AS51)} -> 18898 | D7: =C7-B7 -> 121 | L7: 千 | N7: =M7*1000 -> 0
A8: クリスタル | B8: =MIN(クレーン佐賀八女!A3:AR3) -> 33500 | C8: {=LOOKUP(2,1/(ISNUMBER(クレーン佐賀八女!B3:AS3)),クレーン佐賀八女!B3:AS3)} -> 33618 | D8: =C8-B8 -> 118 | E8: =SUM(D8) -> 118 | I8: =F8*1000+G8*500+H8*100 -> 0 | J8: =I8-E8*100 -> -11800 | L8: 五百 | N8: =M8*500 -> 0
A9: BUZZ２ | B9: =MIN(クレーン佐賀八女!A63:AR63) -> 24397 | C9: {=LOOKUP(2,1/(ISNUMBER(クレーン佐賀八女!B63:AS63)),クレーン佐賀八女!B63:AS63)} -> 24496 | D9: =C9-B9 -> 99 | E9: =SUM(D9:D12) -> 597 | I9: =F9*1000+G9*500+H9*100 -> 0 | J9: =I9-E9*100 -> -59700 | L9: 百残り | N9: =M9*100 -> 0
B10: =MIN(クレーン佐賀八女!A75:AR75) -> 19552 | C10: {=LOOKUP(2,1/(ISNUMBER(クレーン佐賀八女!B75:AS75)),クレーン佐賀八女!B75:AS75)} -> 19761 | D10: =C10-B10 -> 209 | L10: 集金後
B11: =MIN(クレーン佐賀八女!A87:AR87) -> 21267 | C11: {=LOOKUP(2,1/(ISNUMBER(クレーン佐賀八女!B87:AS87)),クレーン佐賀八女!B87:AS87)} -> 21467 | D11: =C11-B11 -> 200 | I11: =F11*1000+G11*500+H11*100 -> 0 | J11: =I11-E11*100 -> 0 | L11: 千 | N11: =M11*1000 -> 0
B12: =MIN(クレーン佐賀八女!A99:AR99) -> 17991 | C12: {=LOOKUP(2,1/(ISNUMBER(クレーン佐賀八女!B99:AS99)),クレーン佐賀八女!B99:AS99)} -> 18080 | D12: =C12-B12 -> 89 | L12: 五百 | N12: =M12*500 -> 0
A13: BUZZ3 | B13: =MIN(クレーン佐賀八女!A111:AR111) -> 7997 | C13: {=LOOKUP(2,1/(ISNUMBER(クレーン佐賀八女!B111:AS111)),クレーン佐賀八女!B111:AS111)} -> 8021 | D13: =C13-B13 -> 24 | E13: =SUM(D13:D16) -> 212 | I13: =F13*1000+G13*500+H13*100 -> 0 | J13: =I13-E13*100 -> -21200 | L13: 百 | M13: 2000 | N13: =M13*100 -> 200000 | O13: 両替金
B14: =MIN(クレーン佐賀八女!A123:AR123) -> 11553 | C14: {=LOOKUP(2,1/(ISNUMBER(クレーン佐賀八女!B123:AS123)),クレーン佐賀八女!B123:AS123)} -> 11604 | D14: =C14-B14 -> 51 | N14: =SUM(N11:N13) -> 200000 | O14: 200000
B15: =MIN(クレーン佐賀八女!A135:AR135) -> 7938 | C15: {=LOOKUP(2,1/(ISNUMBER(クレーン佐賀八女!B135:AS135)),クレーン佐賀八女!B135:AS135)} -> 8053 | D15: =C15-B15 -> 115 | I15: =F15*1000+G15*500+H15*100 -> 0 | J15: =I15-E15*100 -> 0
B16: =MIN(クレーン佐賀八女!A147:AR147) -> 9161 | C16: {=LOOKUP(2,1/(ISNUMBER(クレーン佐賀八女!B147:AS147)),クレーン佐賀八女!B147:AS147)} -> 9183 | D16: =C16-B16 -> 22
A17: Buzzミニ | B17: =MIN(クレーン佐賀八女!A159:AR159) -> 26427 | C17: {=LOOKUP(2,1/(ISNUMBER(クレーン佐賀八女!B159:AS159)),クレーン佐賀八女!B159:AS159)} -> 27236 | D17: =C17-B17 -> 809 | E17: =SUM(D17) -> 809 | I17: =F17*1000+G17*500+H17*100 -> 0 | J17: =I17-E17*100 -> -80900
A18: Buzzミニ | B18: =MIN(クレーン佐賀八女!A171:AR171) -> 14373 | C18: {=LOOKUP(2,1/(ISNUMBER(クレーン佐賀八女!B171:AS171)),クレーン佐賀八女!B171:AS171)} -> 14413 | D18: =C18-B18 -> 40 | E18: =SUM(D18) -> 40 | I18: =F18*1000+G18*500+H18*100 -> 0 | J18: =I18-E18*100 -> -4000
A19: Buzzミニ | B19: =MIN(クレーン佐賀八女!183:183) -> 6478 | C19: =MAX(クレーン佐賀八女!183:183) -> 6932 | D19: =C19-B19 -> 454 | E19: =SUM(D19) -> 454 | I19: =F19*1000+G19*500+H19*100 -> 0 | J19: =I19-E19*100 -> -45400
A20: BUZZ4 | B20: =MIN(クレーン佐賀八女!195:195) -> 0 | C20: =MAX(クレーン佐賀八女!195:195) -> 139 | D20: =C20-B20 -> 139 | E20: =SUM(D20:D23) -> 248 | I20: =F20*1000+G20*500+H20*100 -> 0 | J20: =I20-E20*100 -> -24800
B21: =MIN(クレーン佐賀八女!207:207) -> 0 | C21: =MAX(クレーン佐賀八女!207:207) -> 22 | D21: =C21-B21 -> 22
B22: =MIN(クレーン佐賀八女!A219:AR219) -> 0 | C22: =MAX(クレーン佐賀八女!B219:AS219) -> 42 | D22: =C22-B22 -> 42 | I22: =F22*1000+G22*500+H22*100 -> 0 | J22: =I22-E22*100 -> 0
B23: =MIN(クレーン佐賀八女!A231:AR231) -> 0 | C23: =MAX(クレーン佐賀八女!B231:AS231) -> 45 | D23: =C23-B23 -> 45
A24: BUZZ5 | B24: =MIN(クレーン佐賀八女!A243:AR243) -> 0 | C24: =MAX(クレーン佐賀八女!B243:AS243) -> 9 | D24: =C24-B24 -> 9 | E24: =SUM(D24:D27) -> 141 | I24: =F24*1000+G24*500+H24*100 -> 0 | J24: =I24-E24*100 -> -14100
B25: =MIN(クレーン佐賀八女!A255:AR255) -> 0 | C25: =MAX(クレーン佐賀八女!B255:AS255) -> 59 | D25: =C25-B25 -> 59
B26: =MIN(クレーン佐賀八女!A267:AR267) -> 0 | C26: =MAX(クレーン佐賀八女!B267:AS267) -> 44 | D26: =C26-B26 -> 44 | I26: =F26*1000+G26*500+H26*100 -> 0 | J26: =I26-E26*100 -> 0
B27: =MIN(クレーン佐賀八女!A279:AR279) -> 0 | C27: =MAX(クレーン佐賀八女!B279:AS279) -> 29 | D27: =C27-B27 -> 29
A28: BUZZ6 | B28: =MIN(クレーン佐賀八女!A291:AR291) -> 0 | C28: =MAX(クレーン佐賀八女!B291:AS291) -> 42 | D28: =C28-B28 -> 42 | E28: =SUM(D28:D31) -> 151 | I28: =F28*1000+G28*500+H28*100 -> 0 | J28: =I28-E28*100 -> -15100
B29: =MIN(クレーン佐賀八女!A303:AR303) -> 0 | C29: =MAX(クレーン佐賀八女!B303:AS303) -> 12 | D29: =C29-B29 -> 12
B30: =MIN(クレーン佐賀八女!A315:AR315) -> 0 | C30: =MAX(クレーン佐賀八女!B315:AS315) -> 19 | D30: =C30-B30 -> 19 | I30: =F30*1000+G30*500+H30*100 -> 0 | J30: =I30-E30*100 -> 0
B31: =MIN(クレーン佐賀八女!A327:AR327) -> 0 | C31: =MAX(クレーン佐賀八女!B327:AS327) -> 78 | D31: =C31-B31 -> 78
A32: Buzzミニ | B32: =MIN(クレーン佐賀八女!339:339) -> 237 | C32: =MAX(クレーン佐賀八女!339:339) -> 327 | D32: =C32-B32 -> 90 | E32: =SUM(D32) -> 90 | I32: =F32*1000+G32*500+H32*100 -> 0 | J32: =I32-E32*100 -> -9000
A33: Buzzミニ | B33: =MIN(クレーン佐賀八女!351:351) -> 230 | C33: =MAX(クレーン佐賀八女!351:351) -> 332 | D33: =C33-B33 -> 102 | E33: =SUM(D33) -> 102 | I33: =F33*1000+G33*500+H33*100 -> 0 | J33: =I33-E33*100 -> -10200
A34: Buzzミニ | B34: =MIN(クレーン佐賀八女!363:363) -> 230 | C34: =MAX(クレーン佐賀八女!363:363) -> 287 | D34: =C34-B34 -> 57 | E34: =SUM(D34:D51) -> 57 | I34: =F34*1000+G34*500+H34*100 -> 0 | J34: =I34-E34*100 -> -5700
I35: =SUM(I3:I19) -> 0

Sheet Sheet1
B1: 日付 | C1: 46129 | D1: =C1+1 -> 46130 | E1: =D1+1 -> 46131 | F1: =E1+1 -> 46132 | G1: =F1+1 -> 46133 | H1: =G1+1 -> 46134 | I1: =H1+1 -> 46135 | J1: =I1+1 -> 46136 | K1: =J1+1 -> 46137 | ... AU1: =AT1+1 -> 46173
A2: 八女 | B2: 1000円 | C2: 6380 | D2: 6380 | E2: 6394 | F2: 6400 | G2: 6409 | H2: 6413 | I2: 6416 | J2: 6416 | K2: 6422 | L2: 6447 | M2: 6452 | N2: 6461 | O2: 6466 | P2: 6467 | Q2: 6468 | R2: 6475 | S2: 6486 | T2: 6492 | U2: 6498 | V2: 6517 | W2: 6518 | X2: 6525 | Y2: 6527 | Z2: 6542 | AA2: 6545 | AB2: 6553 | AC2: 6555 | AD2: 6555 | AE2: 6561 | AF2: 6568 | AG2: 6573 | AH2: 6576 | AI2: 6576 | AJ2: 6581 | AK2: 6582 | AL2: 6582 | AM2: 6587
A3: ガチャコロ | B3: カプセル上 | C3: 1772 | D3: 1772 | E3: 1774 | F3: 1774 | G3: 1775 | H3: 1776 | I3: 1776 | J3: 1776 | K3: 1777 | L3: 1782 | M3: 1783 | N3: 1787 | O3: 1789 | P3: 1789 | Q3: 1789 | R3: 1791 | S3: 1793 | T3: 1795 | U3: 1795 | V3: 1801 | W3: 1801 | X3: 1804 | Y3: 1804 | Z3: 1807 | AA3: 1807 | AB3: 1811 | AC3: 1812 | AD3: 1812 | AE3: 1814 | AF3: 1817 | AG3: 1818 | AH3: 1819 | AI3: 1819 | AJ3: 1821 | AK3: 1821 | AL3: 1821 | AM3: 1823
A4: =+A9*1000 -> 207000 | B4: カプセル下 | C4: 3106 | D4: 3106 | E4: 3115 | F4: 3121 | G4: 3128 | H4: 3129 | I4: 3132 | J4: 3132 | K4: 3136 | L4: 3151 | M4: 3154 | N4: 3155 | O4: 3156 | P4: 3157 | Q4: 3158 | R4: 3161 | S4: 3168 | T4: 3170 | U4: 3176 | V4: 3183 | W4: 3184 | X4: 3185 | Y4: 3187 | Z4: 3196 | AA4: 3199 | AB4: 3199 | AC4: 3199 | AD4: 3199 | AE4: 3201 | AF4: 3202 | AG4: 3205 | AH4: 3206 | AI4: 3206 | AJ4: 3207 | AK4: 3208 | AL4: 3208 | AM4: 3209
A5: 月間予想 | B5: 補充
A6: =AVERAGE(C9:AS9)*30*1000 -> 172500 | B6: 単価
B7: 払出No
B8: 備考
A9: =SUM(C9:AS9) -> 207 | B9: 千差 | D9: =IF(D2="","",D2-C2) -> 0 | E9: =IF(E2="","",E2-D2) -> 14 | F9: =IF(F2="","",F2-E2) -> 6 | G9: =IF(G2="","",G2-F2) -> 9 | H9: =IF(H2="","",H2-G2) -> 4 | I9: =IF(I2="","",I2-H2) -> 3 | J9: =IF(J2="","",J2-I2) -> 0 | K9: =IF(K2="","",K2-J2) -> 6 | ... AU9: =IF(AU2="","",AU2-AT2)
A10: =SUM(C10:AS10) -> 51 | B10: CP上差 | D10: =IF(D3="","",D3-C3) -> 0 | E10: =IF(E3="","",E3-D3) -> 2 | F10: =IF(F3="","",F3-E3) -> 0 | G10: =IF(G3="","",G3-F3) -> 1 | H10: =IF(H3="","",H3-G3) -> 1 | I10: =IF(I3="","",I3-H3) -> 0 | J10: =IF(J3="","",J3-I3) -> 0 | K10: =IF(K3="","",K3-J3) -> 1 | ... AU10: =IF(AU3="","",AU3-AT3)
A11: =SUM(C11:AS11) -> 103 | B11: CP下差 | D11: =IF(D4="","",D4-C4) -> 0 | E11: =IF(E4="","",E4-D4) -> 9 | F11: =IF(F4="","",F4-E4) -> 6 | G11: =IF(G4="","",G4-F4) -> 7 | H11: =IF(H4="","",H4-G4) -> 1 | I11: =IF(I4="","",I4-H4) -> 3 | J11: =IF(J4="","",J4-I4) -> 0 | K11: =IF(K4="","",K4-J4) -> 4 | ... AE11: =IF(AE4="","",AE4-AD4) -> 2 | AF11: 1 | AG11: =IF(AG4="","",AG4-AF4) -> 3 | AH11: =IF(AH4="","",AH4-AG4) -> 1 | AI11: =IF(AI4="","",AI4-AH4) -> 0 | AJ11: =IF(AJ4="","",AJ4-AI4) -> 1 | AK11: =IF(AK4="","",AK4-AJ4) -> 1 | AL11: =IF(AL4="","",AL4-AK4) -> 0 | AM11: =IF(AM4="","",AM4-AL4) -> 1 | AN11: =IF(AN4="","",AN4-AM4) | ... AU11: =IF(AU4="","",AU4-AT4)
A12: =SUM(C12:AJ12) -> 0 | B12: 払出額
A13: =IF(A12="","",A12/(A9*100)) -> 0 | B13: 原価率
A14: =SUM(A22,A34,A46,A58,A70,A82,A94,A106,A118,A130,A142,A154,A166,A178,A190,A202) -> 1546497.5 | B14: 日付 | C14: 46129 | D14: =C14+1 -> 46130 | E14: =D14+1 -> 46131 | F14: =E14+1 -> 46132 | G14: =F14+1 -> 46133 | H14: =G14+1 -> 46134 | I14: =H14+1 -> 46135 | J14: =I14+1 -> 46136 | K14: =J14+1 -> 46137 | ... BC14: =BB14+1 -> 46181
B15: =SUM(C15:AO15) -> 17989 | C15: 450 | D15: =SUM(D23,D35,D47,D59,D71,D83,D95,D107,D119,D131,D143,D155,D167,D179,D191,D203) -> 0 | E15: =SUM(E23,E35,E47,E59,E71,E83,E95,E107,E119,E131,E143,E155,E167,E179,E191,E203) -> 1630 | F15: =SUM(F23,F35,F47,F59,F71,F83,F95,F107,F119,F131,F143,F155,F167,F179,F191,F203) -> 0 | G15: =SUM(G23,G35,G47,G59,G71,G83,G95,G107,G119,G131,G143,G155,G167,G179,G191,G203) -> 0 | H15: =SUM(H23,H35,H47,H59,H71,H83,H95,H107,H119,H131,H143,H155,H167,H179,H191,H203) -> 0 | I15: =SUM(I23,I35,I47,I59,I71,I83,I95,I107,I119,I131,I143,I155,I167,I179,I191,I203) -> 1113 | J15: =SUM(J23,J35,J47,J59,J71,J83,J95,J107,J119,J131,J143,J155,J167,J179,J191,J203) -> 0 | K15: =SUM(K23,K35,K47,K59,K71,K83,K95,K107,K119,K131,K143,K155,K167,K179,K191,K203) -> 0 | ... BC15: =SUM(BC23,BC35,BC47,BC59,BC71,BC83,BC95,BC107,BC119,BC131,BC143,BC155,BC167,BC179,BC191,BC203) -> 0
A16: 八女 | B16: 100円 | C16: 32769 | D16: 32769 | E16: 32823 | F16: 32823 | G16: 32823 | H16: 32823 | I16: 32879 | J16: 32879 | K16: 32879 | L16: 32983 | M16: 32983 | N16: 32983 | O16: 33062 | P16: 33062 | Q16: 33062 | R16: 33156 | S16: 33156 | T16: 33256 | U16: 33256 | V16: 33256 | W16: 33287 | X16: 33287 | Y16: 33287 | Z16: 33373 | AA16: 33373 | AB16: 33373 | AC16: 33373 | AD16: 33448 | AE16: 33448 | AF16: 33448 | AG16: 33500 | AH16: 33500 | AI16: 33500 | AJ16: 33500 | AK16: 33558
A17: クリスタル | B17: プライズ | C17: 1181 | D17: =IF(D$16="","",C17) -> 1181 | E17: 1182 | F17: =IF(F$16="","",E17) -> 1182 | G17: =IF(G$16="","",F17) -> 1182 | H17: =IF(H$16="","",G17) -> 1182 | I17: 1183 | J17: =IF(J$16="","",I17) -> 1183 | K17: =IF(K$16="","",J17) -> 1183 | L17: 1192 | M17: =IF(M$16="","",L17) -> 1192 | N17: =IF(N$16="","",M17) -> 1192 | O17: 1200 | P17: =IF(P$16="","",O17) -> 1200 | Q17: =IF(Q$16="","",P17) -> 1200 | R17: 1209 | S17: =IF(S$16="","",R17) -> 1209 | T17: 1215 | U17: =IF(U$16="","",T17) -> 1215 | V17: =IF(V$16="","",U17) -> 1215 | W17: 1217 | X17: =IF(X$16="","",W17) -> 1217 | Y17: =IF(Y$16="","",X17) -> 1217 | Z17: 1223 | AA17: =IF(AA$16="","",Z17) -> 1223 | AB17: =IF(AB$16="","",AA17) -> 1223 | AC17: =IF(AC$16="","",AB17) -> 1223 | AD17: 1228 | AE17: =IF(AE$16="","",AD17) -> 1228 | AF17: =IF(AF$16="","",AE17) -> 1228 | AG17: 1234 | AH17: =IF(AH$16="","",AG17) -> 1234 | AI17: =IF(AI$16="","",AH17) -> 1234 | AJ17: =IF(AJ$16="","",AI17) -> 1234 | AK17: 1241 | AL17: =IF(AL$16="","",AK17) | AM17: =IF(AM$16="","",AL17) | AN17: =IF(AN$16="","",AM17) | AO17: =IF(AO$16="","",AN17) | AP17: =IF(AP$16="","",AO17) | AQ17: =IF(AQ$16="","",AP17) | AR17: =IF(AR$16="","",AQ17) | AS17: =IF(AS$16="","",AR17) | ... BC17: =IF(BC$16="","",BB17)
B18: 投入残 | C18: 23 | D18: =IF(D16="","",(C18+C19)) -> 23 | E18: 22 | F18: =IF(F16="","",(E18+E19)) -> 22 | G18: =IF(G16="","",(F18+F19)) -> 22 | H18: =IF(H16="","",(G18+G19)) -> 22 | I18: 21 | J18: =IF(J16="","",(I18+I19)) -> 37 | K18: =IF(K16="","",(J18+J19)) -> 37 | L18: 33 | M18: =IF(M16="","",(L18+L19)) -> 33 | N18: =IF(N16="","",(M18+M19)) -> 33 | O18: 29 | P18: =IF(P16="","",(O18+O19)) -> 44 | Q18: =IF(Q16="","",(P18+P19)) -> 44 | R18: 39 | S18: =IF(S16="","",(R18+R19)) -> 39 | T18: 33 | U18: =IF(U16="","",(T18+T19)) -> 33 | V18: =IF(V16="","",(U18+U19)) -> 33 | W18: =IF(W16="","",(V18+V19)) -> 33 | X18: =IF(X16="","",(W18+W19)) -> 63 | Y18: =IF(Y16="","",(X18+X19)) -> 63 | Z18: 57 | AA18: =IF(AA16="","",(Z18+Z19)) -> 57 | AB18: =IF(AB16="","",(AA18+AA19)) -> 57 | AC18: =IF(AC16="","",(AB18+AB19)) -> 57 | AD18: 52 | AE18: =IF(AE16="","",(AD18+AD19)) -> 52 | AF18: =IF(AF16="","",(AE18+AE19)) -> 52 | AG18: 46 | AH18: =IF(AH16="","",(AG18+AG19)) -> 46 | AI18: =IF(AI16="","",(AH18+AH19)) -> 46 | AJ18: =IF(AJ16="","",(AI18+AI19)) -> 46 | AK18: 39 | AL18: =IF(AL16="","",(AK18+AK19)) | AM18: =IF(AM16="","",(AL18+AL19)) | AN18: =IF(AN16="","",(AM18+AM19)) | AO18: =IF(AO16="","",(AN18+AN19)) | AP18: =IF(AP16="","",(AO18+AO19)) | AQ18: =IF(AQ16="","",(AP18+AP19)) | AR18: =IF(AR16="","",(AQ18+AQ19)) | AS18: =IF(AS16="","",(AR18+AR19)) | ... BC18: =IF(BC16="","",(BB18+BB19))
B19: 補充 | I19: 16 | O19: 15 | W19: 30
B20: 単価 | C20: 1100 | D20: =IF(D16="","",C20) -> 1100 | E20: =IF(E16="","",D20) -> 1100 | F20: 300 | G20: =IF(G16="","",F20) -> 300 | H20: =IF(H16="","",G20) -> 300 | I20: =IF(I16="","",H20) -> 300 | J20: =IF(J16="","",I20) -> 300 | K20: =IF(K16="","",J20) -> 300 | L20: =IF(L16="","",K20) -> 300 | M20: =IF(M16="","",L20) -> 300 | N20: =IF(N16="","",M20) -> 300 | ... BC20: =IF(BC16="","",BB20)
A21: 月間予想 | B21: 景品名 | C21: マスコットポーチヒョウ | D21: =IF(D16="","",C21) -> マスコットポーチヒョウ | E21: =IF(E16="","",D21) -> マスコットポーチヒョウ | F21: フルーツスクイーズ | G21: =IF(G16="","",F21) -> フルーツスクイーズ | H21: =IF(H16="","",G21) -> フルーツスクイーズ | I21: =IF(I16="","",H21) -> フルーツスクイーズ | J21: =IF(J16="","",I21) -> フルーツスクイーズ | K21: =IF(K16="","",J21) -> フルーツスクイーズ | L21: =IF(L16="","",K21) -> フルーツスクイーズ | M21: =IF(M16="","",L21) -> フルーツスクイーズ | N21: =IF(N16="","",M21) -> フルーツスクイーズ | ... BC21: =IF(BC16="","",BB21)
A22: =AVERAGE(C23:AS23)*30*100 -> 69617.647 | B22: 設定
A23: =SUM(C23:AS23) -> 789 | B23: 百差 | D23: =IF(D16="","",D16-C16) -> 0 | E23: =IF(E16="","",E16-D16) -> 54 | F23: =IF(F16="","",F16-E16) -> 0 | G23: =IF(G16="","",G16-F16) -> 0 | H23: =IF(H16="","",H16-G16) -> 0 | I23: =IF(I16="","",I16-H16) -> 56 | J23: =IF(J16="","",J16-I16) -> 0 | K23: =IF(K16="","",K16-J16) -> 0 | ... BC23: =IF(BC16="","",BC16-BB16)
A24: =SUM(C24:AS24) -> 62 | B24: P差 | C24: 2 | D24: =IF(D17="","",D17-C17) -> 0 | E24: =IF(E17="","",E17-D17) -> 1 | F24: =IF(F17="","",F17-E17) -> 0 | G24: =IF(G17="","",G17-F17) -> 0 | H24: =IF(H17="","",H17-G17) -> 0 | I24: =IF(I17="","",I17-H17) -> 1 | J24: =IF(J17="","",J17-I17) -> 0 | K24: =IF(K17="","",K17-J17) -> 0 | ... BC24: =IF(BC17="","",BC17-BB17)
A25: =SUM(C25:AS25) -> 45 | B25: 払出 | C25: 0 | D25: =IF(D18="","",C18+C19-D18) -> 0 | E25: =IF(E18="","",D18+D19-E18) -> 1 | F25: =IF(F18="","",E18+E19-F18) -> 0 | G25: =IF(G18="","",F18+F19-G18) -> 0 | H25: =IF(H18="","",G18+G19-H18) -> 0 | I25: =IF(I18="","",H18+H19-I18) -> 1 | J25: =IF(J18="","",I18+I19-J18) -> 0 | K25: =IF(K18="","",J18+J19-K18) -> 0 | ... BC25: =IF(BC18="","",BB18+BB19-BC18)
A26: =SUM(C26:AS26) -> 14300 | B26: 払出額 | C26: 0 | D26: =IF(D16="","",D25*D20) -> 0 | E26: =IF(E16="","",E25*E20) -> 1100 | F26: =IF(F16="","",F25*F20) -> 0 | G26: =IF(G16="","",G25*G20) -> 0 | H26: =IF(H16="","",H25*H20) -> 0 | I26: =IF(I16="","",I25*I20) -> 300 | J26: =IF(J16="","",J25*J20) -> 0 | K26: =IF(K16="","",K25*K20) -> 0 | ... BC26: =IF(BC16="","",BC25*BC20)
A27: =IF(A26="","",A26/(A23*100)) -> 0.18124208 | B27: 原価率 | D27: =IF(D26="","",IF(D26=0,"",D26/(D23*100))) | E27: =IF(E26="","",IF(E26=0,"",E26/(E23*100))) -> 0.2037037 | F27: =IF(F26="","",IF(F26=0,"",F26/(F23*100))) | G27: =IF(G26="","",IF(G26=0,"",G26/(G23*100))) | H27: =IF(H26="","",IF(H26=0,"",H26/(H23*100))) | I27: =IF(I26="","",IF(I26=0,"",I26/(I23*100))) -> 0.053571429 | J27: =IF(J26="","",IF(J26=0,"",J26/(J23*100))) | K27: =IF(K26="","",IF(K26=0,"",K26/(K23*100))) | ... BC27: =IF(BC26="","",IF(BC26=0,"",BC26/(BC23*100)))
A28: 八女 | B28: 100円 | C28: 27401 | D28: =IF(D$16="","",C28) -> 27401 | E28: 27523 | F28: =IF(F$16="","",E28) -> 27523 | G28: =IF(G$16="","",F28) -> 27523 | H28: =IF(H$16="","",G28) -> 27523 | I28: 27644 | J28: =IF(J$16="","",I28) -> 27644 | K28: =IF(K$16="","",J28) -> 27644 | L28: 27710 | M28: =IF(M$16="","",L28) -> 27710 | N28: =IF(N$16="","",M28) -> 27710 | O28: 27785 | P28: =IF(P$16="","",O28) -> 27785 | Q28: =IF(Q$16="","",P28) -> 27785 | R28: 27867 | S28: =IF(S$16="","",R28) -> 27867 | T28: 28052 | U28: =IF(U$16="","",T28) -> 28052 | V28: =IF(V$16="","",U28) -> 28052 | W28: 28102 | X28: =IF(X$16="","",W28) -> 28102 | Y28: =IF(Y$16="","",X28) -> 28102 | Z28: 28162 | AA28: =IF(AA$16="","",Z28) -> 28162 | AB28: =IF(AB$16="","",AA28) -> 28162 | AC28: =IF(AC$16="","",AB28) -> 28162 | AD28: 28286 | AE28: =IF(AE$16="","",AD28) -> 28286 | AF28: =IF(AF$16="","",AE28) -> 28286 | AG28: 28348 | AH28: =IF(AH$16="","",AG28) -> 28348 | AI28: =IF(AI$16="","",AH28) -> 28348 | AJ28: =IF(AJ$16="","",AI28) -> 28348 | AK28: 28443 | AL28: =IF(AL$16="","",AK28) | AM28: =IF(AM$16="","",AL28) | AN28: =IF(AN$16="","",AM28) | AO28: =IF(AO$16="","",AN28) | AP28: =IF(AP$16="","",AO28) | AQ28: =IF(AQ$16="","",AP28) | AR28: =IF(AR$16="","",AQ28) | AS28: =IF(AS$16="","",AR28) | ... BC28: =IF(BC$16="","",BB28)
A29: BUZZ＃1 | B29: プライズ | C29: 965 | D29: =IF(D$16="","",C29) -> 965 | E29: 970 | F29: =IF(F$16="","",E29) -> 970 | G29: =IF(G$16="","",F29) -> 970 | H29: =IF(H$16="","",G29) -> 970 | I29: 975 | J29: =IF(J$16="","",I29) -> 975 | K29: =IF(K$16="","",J29) -> 975 | L29: 978 | M29: =IF(M$16="","",L29) -> 978 | N29: =IF(N$16="","",M29) -> 978 | O29: 983 | P29: =IF(P$16="","",O29) -> 983 | Q29: =IF(Q$16="","",P29) -> 983 | R29: 987 | S29: =IF(S$16="","",R29) -> 987 | T29: 988 | U29: =IF(U$16="","",T29) -> 988 | V29: =IF(V$16="","",U29) -> 988 | W29: 989 | X29: =IF(X$16="","",W29) -> 989 | Y29: =IF(Y$16="","",X29) -> 989 | Z29: 991 | AA29: =IF(AA$16="","",Z29) -> 991 | AB29: =IF(AB$16="","",AA29) -> 991 | AC29: =IF(AC$16="","",AB29) -> 991 | AD29: 993 | AE29: =IF(AE$16="","",AD29) -> 993 | AF29: =IF(AF$16="","",AE29) -> 993 | AG29: 997 | AH29: =IF(AH$16="","",AG29) -> 997 | AI29: =IF(AI$16="","",AH29) -> 997 | AJ29: =IF(AJ$16="","",AI29) -> 997 | AK29: =IF(AK$16="","",AJ29) -> 997 | AL29: =IF(AL$16="","",AK29) | AM29: =IF(AM$16="","",AL29) | AN29: =IF(AN$16="","",AM29) | AO29: =IF(AO$16="","",AN29) | ... BC29: =IF(BC$16="","",BB29)
A30: 1 | B30: 投入残 | C30: 11 | D30: =IF(D28="","",(C30+C31)) -> 12 | E30: 9 | F30: =IF(F28="","",(E30+E31)) -> 9 | G30: =IF(G28="","",(F30+F31)) -> 9 | H30: =IF(H28="","",(G30+G31)) -> 9 | I30: 7 | J30: =IF(J28="","",(I30+I31)) -> 12 | K30: =IF(K28="","",(J30+J31)) -> 12 | L30: 10 | M30: =IF(M28="","",(L30+L31)) -> 14 | N30: =IF(N28="","",(M30+M31)) -> 14 | O30: 12 | P30: =IF(P28="","",(O30+O31)) -> 12 | Q30: =IF(Q28="","",(P30+P31)) -> 12 | R30: 11 | S30: =IF(S28="","",(R30+R31)) -> 11 | T30: 10 | U30: =IF(U28="","",(T30+T31)) -> 12 | V30: =IF(V28="","",(U30+U31)) -> 12 | W30: =IF(W28="","",(V30+V31)) -> 12 | X30: =IF(X28="","",(W30+W31)) -> 12 | Y30: =IF(Y28="","",(X30+X31)) -> 12 | Z30: 11 | AA30: =IF(AA28="","",(Z30+Z31)) -> 11 | AB30: =IF(AB28="","",(AA30+AA31)) -> 11 | AC30: =IF(AC28="","",(AB30+AB31)) -> 11 | AD30: 9 | AE30: =IF(AE28="","",(AD30+AD31)) -> 11 | AF30: =IF(AF28="","",(AE30+AE31)) -> 11 | AG30: 9 | AH30: =IF(AH28="","",(AG30+AG31)) -> 11 | AI30: =IF(AI28="","",(AH30+AH31)) -> 11 | AJ30: =IF(AJ28="","",(AI30+AI31)) -> 11 | AK30: =IF(AK28="","",(AJ30+AJ31)) -> 11 | AL30: =IF(AL28="","",(AK30+AK31)) | AM30: =IF(AM28="","",(AL30+AL31)) | AN30: =IF(AN28="","",(AM30+AM31)) | AO30: =IF(AO28="","",(AN30+AN31)) | ... BC30: =IF(BC28="","",(BB30+BB31))
A31: 機械合計 | B31: 補充 | C31: 1 | I31: 5 | L31: 4 | T31: 2 | AD31: 2 | AG31: 2
A32: =+(A35+A47+A59+A71)*100 -> 551100 | B32: 単価 | C32: 1100 | D32: =IF(D28="","",C32) -> 1100 | E32: =IF(E28="","",D32) -> 1100 | F32: =IF(F28="","",E32) -> 1100 | G32: =IF(G28="","",F32) -> 1100 | H32: =IF(H28="","",G32) -> 1100 | I32: =IF(I28="","",H32) -> 1100 | J32: =IF(J28="","",I32) -> 1100 | K32: =IF(K28="","",J32) -> 1100 | ... BC32: =IF(BC28="","",BB32)
A33: 月間予想 | B33: 景品名 | C33: サンリオファン | D33: =IF(D28="","",C33) -> サンリオファン | E33: =IF(E28="","",D33) -> サンリオファン | F33: =IF(F28="","",E33) -> サンリオファン | G33: =IF(G28="","",F33) -> サンリオファン | H33: =IF(H28="","",G33) -> サンリオファン | I33: =IF(I28="","",H33) -> サンリオファン | J33: =IF(J28="","",I33) -> サンリオファン | K33: =IF(K28="","",J33) -> サンリオファン | ... BC33: =IF(BC28="","",BB33)
A34: =AVERAGE(C35:AS35)*30*100 -> 91941.176 | B34: 設定
A35: =SUM(C35:AS35) -> 1042 | B35: 百差 | D35: =IF(D28="","",D28-C28) -> 0 | E35: =IF(E28="","",E28-D28) -> 122 | F35: =IF(F28="","",F28-E28) -> 0 | G35: =IF(G28="","",G28-F28) -> 0 | H35: =IF(H28="","",H28-G28) -> 0 | I35: =IF(I28="","",I28-H28) -> 121 | J35: =IF(J28="","",J28-I28) -> 0 | K35: =IF(K28="","",K28-J28) -> 0 | ... BC35: =IF(BC28="","",BC28-BB28)
A36: =SUM(C36:AS36) -> 35 | B36: P差 | C36: 3 | D36: =IF(D29="","",D29-C29) -> 0 | E36: =IF(E29="","",E29-D29) -> 5 | F36: =IF(F29="","",F29-E29) -> 0 | G36: =IF(G29="","",G29-F29) -> 0 | H36: =IF(H29="","",H29-G29) -> 0 | I36: =IF(I29="","",I29-H29) -> 5 | J36: =IF(J29="","",J29-I29) -> 0 | K36: =IF(K29="","",K29-J29) -> 0 | ... BC36: =IF(BC29="","",BC29-BB29)
A37: =SUM(C37:AS37) -> 17 | B37: 払出 | C37: 1 | D37: =IF(D30="","",C30+C31-D30) -> 0 | E37: =IF(E30="","",D30+D31-E30) -> 3 | F37: =IF(F30="","",E30+E31-F30) -> 0 | G37: =IF(G30="","",F30+F31-G30) -> 0 | H37: =IF(H30="","",G30+G31-H30) -> 0 | I37: =IF(I30="","",H30+H31-I30) -> 2 | J37: =IF(J30="","",I30+I31-J30) -> 0 | K37: =IF(K30="","",J30+J31-K30) -> 0 | ... BC37: =IF(BC30="","",BB30+BB31-BC30)
A38: =SUM(C38:AS38) -> 18700 | B38: 払出額 | C38: 1100 | D38: =IF(D28="","",D37*D32) -> 0 | E38: =IF(E28="","",E37*E32) -> 3300 | F38: =IF(F28="","",F37*F32) -> 0 | G38: =IF(G28="","",G37*G32) -> 0 | H38: =IF(H28="","",H37*H32) -> 0 | I38: =IF(I28="","",I37*I32) -> 2200 | J38: =IF(J28="","",J37*J32) -> 0 | K38: =IF(K28="","",K37*K32) -> 0 | ... BC38: =IF(BC28="","",BC37*BC32)
A39: =IF(A38="","",A38/(A35*100)) -> 0.17946257 | B39: 原価率 | C39: 0.21153846 | D39: =IF(D38="","",IF(D38=0,"",D38/(D35*100))) | E39: =IF(E38="","",IF(E38=0,"",E38/(E35*100))) -> 0.2704918 | F39: =IF(F38="","",IF(F38=0,"",F38/(F35*100))) | G39: =IF(G38="","",IF(G38=0,"",G38/(G35*100))) | H39: =IF(H38="","",IF(H38=0,"",H38/(H35*100))) | I39: =IF(I38="","",IF(I38=0,"",I38/(I35*100))) -> 0.18181818 | J39: =IF(J38="","",IF(J38=0,"",J38/(J35*100))) | K39: =IF(K38="","",IF(K38=0,"",K38/(K35*100))) | ... BC39: =IF(BC38="","",IF(BC38=0,"",BC38/(BC35*100)))
A40: 八女 | B40: 100円 | C40: 20828 | D40: =IF(D$16="","",C40) -> 20828 | E40: 20925 | F40: =IF(F$16="","",E40) -> 20925 | G40: =IF(G$16="","",F40) -> 20925 | H40: =IF(H$16="","",G40) -> 20925 | I40: 20982 | J40: =IF(J$16="","",I40) -> 20982 | K40: =IF(K$16="","",J40) -> 20982 | L40: 21172 | M40: =IF(M$16="","",L40) -> 21172 | N40: =IF(N$16="","",M40) -> 21172 | O40: 21331 | P40: =IF(P$16="","",O40) -> 21331 | Q40: =IF(Q$16="","",P40) -> 21331 | R40: 21428 | S40: =IF(S$16="","",R40) -> 21428 | T40: 21500 | U40: =IF(U$16="","",T40) -> 21500 | V40: =IF(V$16="","",U40) -> 21500 | W40: 21578 | X40: =IF(X$16="","",W40) -> 21578 | Y40: =IF(Y$16="","",X40) -> 21578 | Z40: 21804 | AA40: =IF(AA$16="","",Z40) -> 21804 | AB40: =IF(AB$16="","",AA40) -> 21804 | AC40: =IF(AC$16="","",AB40) -> 21804 | AD40: 21844 | AE40: =IF(AE$16="","",AD40) -> 21844 | AF40: =IF(AF$16="","",AE40) -> 21844 | AG40: 21919 | AH40: =IF(AH$16="","",AG40) -> 21919 | AI40: =IF(AI$16="","",AH40) -> 21919 | AJ40: =IF(AJ$16="","",AI40) -> 21919 | AK40: 22145 | AL40: =IF(AL$16="","",AK40) | AM40: =IF(AM$16="","",AL40) | AN40: =IF(AN$16="","",AM40) | AO40: =IF(AO$16="","",AN40) | AP40: =IF(AP$16="","",AO40) | AQ40: =IF(AQ$16="","",AP40) | AR40: =IF(AR$16="","",AQ40) | AS40: =IF(AS$16="","",AR40) | ... BC40: =IF(BC$16="","",BB40)
...
