Workbook

Sheet 鹿屋
A1: =SUM(A57,A69,A81,A93,A9,A21,A33,A45,A201,A213,A225,A237,A105,A117,A129,A141,A153,A165,A177,A189,A249,A261) -> 1273333.3 | B1: 日付 | C1: 46100 | D1: =C1+1 -> 46101 | E1: =D1+1 -> 46102 | F1: =E1+1 -> 46103 | G1: =F1+1 -> 46104 | H1: =G1+1 -> 46105 | I1: =H1+1 -> 46106 | J1: =I1+1 -> 46107 | K1: =J1+1 -> 46108 | ... AS1: =AR1+1 -> 46142
B2: =SUM(C2:AO2) -> 7640 | C2: 0 | D2: =SUM(D58,D70,D82,D94,D10,D22,D34,D46,D202,D214,D226,D238,D190,D178,D166,D154,D142,D130,D118,D106,D250,D262) -> 0 | E2: =SUM(E58,E70,E82,E94,E10,E22,E34,E46,E202,E214,E226,E238,E190,E178,E166,E154,E142,E130,E118,E106,E250,E262) -> 0 | F2: =SUM(F58,F70,F82,F94,F10,F22,F34,F46,F202,F214,F226,F238,F190,F178,F166,F154,F142,F130,F118,F106,F250,F262) -> 2122 | G2: =SUM(G58,G70,G82,G94,G10,G22,G34,G46,G202,G214,G226,G238,G190,G178,G166,G154,G142,G130,G118,G106,G250,G262) -> 0 | H2: =SUM(H58,H70,H82,H94,H10,H22,H34,H46,H202,H214,H226,H238,H190,H178,H166,H154,H142,H130,H118,H106,H250,H262) -> 0 | I2: =SUM(I58,I70,I82,I94,I10,I22,I34,I46,I202,I214,I226,I238,I190,I178,I166,I154,I142,I130,I118,I106,I250,I262) -> 0 | J2: =SUM(J58,J70,J82,J94,J10,J22,J34,J46,J202,J214,J226,J238,J190,J178,J166,J154,J142,J130,J118,J106,J250,J262) -> 1355 | K2: =SUM(K58,K70,K82,K94,K10,K22,K34,K46,K202,K214,K226,K238,K190,K178,K166,K154,K142,K130,K118,K106,K250,K262) -> 0 | ... AS2: =SUM(AS58,AS70,AS82,AS94,AS10,AS22,AS34,AS46,AS202,AS214,AS226,AS238,AS190,AS178,AS166,AS154,AS142,AS130,AS118,AS106,AS250,AS262) -> 0
A3: 鹿屋 | B3: 100円 | C3: 4201 | D3: 4201 | E3: 4201 | F3: 4281 | G3: 4281 | H3: 4281 | I3: 4281 | J3: 4387 | K3: 4387 | L3: 4387 | M3: 4485 | N3: 4485 | O3: 4485 | P3: 4485 | Q3: 4534 | R3: 4534 | S3: 4534 | T3: 4595
A4: BUZZ＃１ | B4: プライズ | C4: 292 | D4: =IF(D3="","",C4) -> 292 | E4: =IF(E3="","",D4) -> 292 | F4: 296 | G4: =IF(G3="","",F4) -> 296 | H4: =IF(H3="","",G4) -> 296 | I4: =IF(I3="","",H4) -> 296 | J4: 298 | K4: =IF(K3="","",J4) -> 298 | L4: =IF(L3="","",K4) -> 298 | M4: 300 | N4: =IF(N3="","",M4) -> 300 | O4: =IF(O3="","",N4) -> 300 | P4: =IF(P3="","",O4) -> 300 | Q4: 303 | R4: =IF(R3="","",Q4) -> 303 | S4: =IF(S3="","",R4) -> 303 | T4: 307 | U4: =IF(U3="","",T4) | V4: =IF(V3="","",U4) | W4: =IF(W3="","",V4) | X4: =IF(X3="","",W4) | Y4: =IF(Y3="","",X4) | Z4: =IF(Z3="","",Y4) | AA4: =IF(AA3="","",Z4) | AB4: =IF(AB3="","",AA4) | ... AS4: =IF(AS3="","",AR4)
A5: 1 | B5: 投入残 | C5: 15 | D5: =IF(D3="","",(C5+C6)) -> 15 | E5: =IF(E3="","",(D5+D6)) -> 15 | F5: 13 | G5: =IF(G3="","",(F5+F6)) -> 18 | H5: =IF(H3="","",(G5+G6)) -> 18 | I5: =IF(I3="","",(H5+H6)) -> 18 | J5: 16 | K5: =IF(K3="","",(J5+J6)) -> 21 | L5: =IF(L3="","",(K5+K6)) -> 21 | M5: 19 | N5: =IF(N3="","",(M5+M6)) -> 24 | O5: =IF(O3="","",(N5+N6)) -> 24 | P5: =IF(P3="","",(O5+O6)) -> 24 | Q5: 21 | R5: =IF(R3="","",(Q5+Q6)) -> 21 | S5: =IF(S3="","",(R5+R6)) -> 21 | T5: 17 | U5: =IF(U3="","",(T5+T6)) | V5: =IF(V3="","",(U5+U6)) | W5: =IF(W3="","",(V5+V6)) | X5: =IF(X3="","",(W5+W6)) | Y5: =IF(Y3="","",(X5+X6)) | Z5: =IF(Z3="","",(Y5+Y6)) | AA5: =IF(AA3="","",(Z5+Z6)) | AB5: =IF(AB3="","",(AA5+AA6)) | ... AS5: =IF(AS3="","",(AR5+AR6))
A6: 機械合計 | B6: 補充 | F6: 5 | J6: 5 | M6: 5 | T6: 8
A7: =+(A10+A22+A34+A46)*100 -> 139100 | B7: 単価 | C7: 500 | D7: =IF(D3="","",C7) -> 500 | E7: =IF(E3="","",D7) -> 500 | F7: =IF(F3="","",E7) -> 500 | G7: =IF(G3="","",F7) -> 500 | H7: =IF(H3="","",G7) -> 500 | I7: =IF(I3="","",H7) -> 500 | J7: =IF(J3="","",I7) -> 500 | K7: =IF(K3="","",J7) -> 500 | ... AS7: =IF(AS3="","",AR7)
A8: 月間予想 | B8: 景品名 | C8: 電ブル | D8: =IF(D3="","",C8) -> 電ブル | E8: =IF(E3="","",D8) -> 電ブル | F8: =IF(F3="","",E8) -> 電ブル | G8: =IF(G3="","",F8) -> 電ブル | H8: =IF(H3="","",G8) -> 電ブル | I8: =IF(I3="","",H8) -> 電ブル | J8: =IF(J3="","",I8) -> 電ブル | K8: =IF(K3="","",J8) -> 電ブル | ... AS8: =IF(AS3="","",AR8)
A9: =AVERAGE(C10:AS10)*30*100 -> 65666.667 | B9: 設定
A10: =SUM(C10:AS10) -> 394 | B10: 百差 | C10: 0 | D10: =IF(D3="","",D3-C3) -> 0 | E10: =IF(E3="","",E3-D3) -> 0 | F10: =IF(F3="","",F3-E3) -> 80 | G10: =IF(G3="","",G3-F3) -> 0 | H10: =IF(H3="","",H3-G3) -> 0 | I10: =IF(I3="","",I3-H3) -> 0 | J10: =IF(J3="","",J3-I3) -> 106 | K10: =IF(K3="","",K3-J3) -> 0 | ... AS10: =IF(AS3="","",AS3-AR3)
A11: =SUM(C11:AS11) -> 15 | B11: P差 | C11: 0 | D11: =IF(D4="","",D4-C4) -> 0 | E11: =IF(E4="","",E4-D4) -> 0 | F11: =IF(F4="","",F4-E4) -> 4 | G11: =IF(G4="","",G4-F4) -> 0 | H11: =IF(H4="","",H4-G4) -> 0 | I11: =IF(I4="","",I4-H4) -> 0 | J11: =IF(J4="","",J4-I4) -> 2 | K11: =IF(K4="","",K4-J4) -> 0 | ... AS11: =IF(AS4="","",AS4-AR4)
A12: =SUM(C12:AS12) -> 13 | B12: 払出 | C12: 0 | D12: =IF(D5="","",C5+C6-D5) -> 0 | E12: =IF(E5="","",D5+D6-E5) -> 0 | F12: =IF(F5="","",E5+E6-F5) -> 2 | G12: =IF(G5="","",F5+F6-G5) -> 0 | H12: =IF(H5="","",G5+G6-H5) -> 0 | I12: =IF(I5="","",H5+H6-I5) -> 0 | J12: =IF(J5="","",I5+I6-J5) -> 2 | K12: =IF(K5="","",J5+J6-K5) -> 0 | ... AS12: =IF(AS5="","",AR5+AR6-AS5)
A13: =SUM(C13:AS13) -> 6500 | B13: 払出額 | C13: 0 | D13: =IF(D3="","",D12*D7) -> 0 | E13: =IF(E3="","",E12*E7) -> 0 | F13: =IF(F3="","",F12*F7) -> 1000 | G13: =IF(G3="","",G12*G7) -> 0 | H13: =IF(H3="","",H12*H7) -> 0 | I13: =IF(I3="","",I12*I7) -> 0 | J13: =IF(J3="","",J12*J7) -> 1000 | K13: =IF(K3="","",K12*K7) -> 0 | ... AS13: =IF(AS3="","",AS12*AS7) | AT13: =
A14: =IF(A13="","",A13/(A10*100)) -> 0.16497462 | B14: 原価率 | D14: =IF(D13="","",IF(D13=0,"",D13/(D10*100))) | E14: =IF(E13="","",IF(E13=0,"",E13/(E10*100))) | F14: =IF(F13="","",IF(F13=0,"",F13/(F10*100))) -> 0.125 | G14: =IF(G13="","",IF(G13=0,"",G13/(G10*100))) | H14: =IF(H13="","",IF(H13=0,"",H13/(H10*100))) | I14: =IF(I13="","",IF(I13=0,"",I13/(I10*100))) | J14: =IF(J13="","",IF(J13=0,"",J13/(J10*100))) -> 0.094339623 | K14: =IF(K13="","",IF(K13=0,"",K13/(K10*100))) | ... AS14: =IF(AS13="","",IF(AS13=0,"",AS13/(AS10*100)))
A15: 鹿屋 | B15: 100円 | C15: 7200 | D15: =IF(D3="","",C15) -> 7200 | E15: =IF(E3="","",D15) -> 7200 | F15: 7258 | G15: =IF(G3="","",F15) -> 7258 | H15: =IF(H3="","",G15) -> 7258 | I15: =IF(I3="","",H15) -> 7258 | J15: 7328 | K15: =IF(K3="","",J15) -> 7328 | L15: =IF(L3="","",K15) -> 7328 | M15: 7353 | N15: =IF(N3="","",M15) -> 7353 | O15: =IF(O3="","",N15) -> 7353 | P15: =IF(P3="","",O15) -> 7353 | Q15: 7388 | R15: =IF(R3="","",Q15) -> 7388 | S15: =IF(S3="","",R15) -> 7388 | T15: 7420 | U15: =IF(U3="","",T15) | V15: =IF(V3="","",U15) | W15: =IF(W3="","",V15) | X15: =IF(X3="","",W15) | Y15: =IF(Y3="","",X15) | Z15: =IF(Z3="","",Y15) | AA15: =IF(AA3="","",Z15) | AB15: =IF(AB3="","",AA15) | ... AS15: =IF(AS3="","",AR15)
A16: BUZZ＃１ | B16: プライズ | C16: 313 | D16: =IF(D3="","",C16) -> 313 | E16: =IF(E3="","",D16) -> 313 | F16: =IF(F3="","",E16) -> 313 | G16: =IF(G3="","",F16) -> 313 | H16: =IF(H3="","",G16) -> 313 | I16: =IF(I3="","",H16) -> 313 | J16: =IF(J3="","",I16) -> 313 | K16: =IF(K3="","",J16) -> 313 | L16: =IF(L3="","",K16) -> 313 | M16: 314 | N16: =IF(N3="","",M16) -> 314 | O16: =IF(O3="","",N16) -> 314 | P16: =IF(P3="","",O16) -> 314 | Q16: =IF(Q3="","",P16) -> 314 | R16: =IF(R3="","",Q16) -> 314 | S16: =IF(S3="","",R16) -> 314 | T16: =IF(T3="","",S16) -> 314 | U16: =IF(U3="","",T16) | ... AS16: =IF(AS3="","",AR16)
A17: 2 | B17: 投入残 | C17: 3 | D17: =IF(D15="","",(C17+C18)) -> 3 | E17: =IF(E15="","",(D17+D18)) -> 3 | F17: =IF(F15="","",(E17+E18)) -> 3 | G17: =IF(G15="","",(F17+F18)) -> 3 | H17: =IF(H15="","",(G17+G18)) -> 3 | I17: =IF(I15="","",(H17+H18)) -> 3 | J17: =IF(J15="","",(I17+I18)) -> 3 | K17: =IF(K15="","",(J17+J18)) -> 3 | L17: =IF(L15="","",(K17+K18)) -> 3 | M17: 2 | N17: =IF(N15="","",(M17+M18)) -> 2 | O17: =IF(O15="","",(N17+N18)) -> 2 | P17: =IF(P15="","",(O17+O18)) -> 2 | Q17: =IF(Q15="","",(P17+P18)) -> 2 | R17: =IF(R15="","",(Q17+Q18)) -> 2 | S17: =IF(S15="","",(R17+R18)) -> 2 | T17: =IF(T15="","",(S17+S18)) -> 2 | U17: =IF(U15="","",(T17+T18)) | ... AS17: =IF(AS15="","",(AR17+AR18))
B18: 補充
B19: 単価 | C19: 750 | D19: =IF(D15="","",C19) -> 750 | E19: =IF(E15="","",D19) -> 750 | F19: =IF(F15="","",E19) -> 750 | G19: =IF(G15="","",F19) -> 750 | H19: =IF(H15="","",G19) -> 750 | I19: =IF(I15="","",H19) -> 750 | J19: =IF(J15="","",I19) -> 750 | K19: =IF(K15="","",J19) -> 750 | ... AS19: =IF(AS15="","",AR19)
A20: 月間予想 | B20: 景品名 | C20: スンスンフェイスポーチ | D20: =IF(D15="","",C20) -> スンスンフェイスポーチ | E20: =IF(E15="","",D20) -> スンスンフェイスポーチ | F20: =IF(F15="","",E20) -> スンスンフェイスポーチ | G20: =IF(G15="","",F20) -> スンスンフェイスポーチ | H20: =IF(H15="","",G20) -> スンスンフェイスポーチ | I20: =IF(I15="","",H20) -> スンスンフェイスポーチ | J20: =IF(J15="","",I20) -> スンスンフェイスポーチ | K20: =IF(K15="","",J20) -> スンスンフェイスポーチ | ... AS20: =IF(AS15="","",AR20)
A21: =AVERAGE(C22:AS22)*30*100 -> 36666.667 | B21: 設定
A22: =SUM(C22:AS22) -> 220 | B22: 百差 | C22: 0 | D22: =IF(D15="","",D15-C15) -> 0 | E22: =IF(E15="","",E15-D15) -> 0 | F22: =IF(F15="","",F15-E15) -> 58 | G22: =IF(G15="","",G15-F15) -> 0 | H22: =IF(H15="","",H15-G15) -> 0 | I22: =IF(I15="","",I15-H15) -> 0 | J22: =IF(J15="","",J15-I15) -> 70 | K22: =IF(K15="","",K15-J15) -> 0 | ... AS22: =IF(AS15="","",AS15-AR15)
A23: =SUM(C23:AS23) -> 1 | B23: P差 | C23: 0 | D23: =IF(D16="","",D16-C16) -> 0 | E23: =IF(E16="","",E16-D16) -> 0 | F23: =IF(F16="","",F16-E16) -> 0 | G23: =IF(G16="","",G16-F16) -> 0 | H23: =IF(H16="","",H16-G16) -> 0 | I23: =IF(I16="","",I16-H16) -> 0 | J23: =IF(J16="","",J16-I16) -> 0 | K23: =IF(K16="","",K16-J16) -> 0 | ... AS23: =IF(AS16="","",AS16-AR16)
A24: =SUM(C24:AS24) -> 1 | B24: 払出 | C24: 0 | D24: =IF(D17="","",C17+C18-D17) -> 0 | E24: =IF(E17="","",D17+D18-E17) -> 0 | F24: =IF(F17="","",E17+E18-F17) -> 0 | G24: =IF(G17="","",F17+F18-G17) -> 0 | H24: =IF(H17="","",G17+G18-H17) -> 0 | I24: =IF(I17="","",H17+H18-I17) -> 0 | J24: =IF(J17="","",I17+I18-J17) -> 0 | K24: =IF(K17="","",J17+J18-K17) -> 0 | ... AS24: =IF(AS17="","",AR17+AR18-AS17)
A25: =SUM(C25:AS25) -> 750 | B25: 払出額 | C25: 0 | D25: =IF(D15="","",D24*D19) -> 0 | E25: =IF(E15="","",E24*E19) -> 0 | F25: =IF(F15="","",F24*F19) -> 0 | G25: =IF(G15="","",G24*G19) -> 0 | H25: =IF(H15="","",H24*H19) -> 0 | I25: =IF(I15="","",I24*I19) -> 0 | J25: =IF(J15="","",J24*J19) -> 0 | K25: =IF(K15="","",K24*K19) -> 0 | ... AS25: =IF(AS15="","",AS24*AS19)
A26: =IF(A25="","",A25/(A22*100)) -> 0.034090909 | B26: 原価率 | D26: =IF(D25="","",IF(D25=0,"",D25/(D22*100))) | E26: =IF(E25="","",IF(E25=0,"",E25/(E22*100))) | F26: =IF(F25="","",IF(F25=0,"",F25/(F22*100))) | G26: =IF(G25="","",IF(G25=0,"",G25/(G22*100))) | H26: =IF(H25="","",IF(H25=0,"",H25/(H22*100))) | I26: =IF(I25="","",IF(I25=0,"",I25/(I22*100))) | J26: =IF(J25="","",IF(J25=0,"",J25/(J22*100))) | K26: =IF(K25="","",IF(K25=0,"",K25/(K22*100))) | ... AS26: =IF(AS25="","",IF(AS25=0,"",AS25/(AS22*100)))
A27: 鹿屋 | B27: 100円 | C27: 5365 | D27: =IF(D3="","",C27) -> 5365 | E27: =IF(E3="","",D27) -> 5365 | F27: 5558 | G27: =IF(G3="","",F27) -> 5558 | H27: =IF(H3="","",G27) -> 5558 | I27: =IF(I3="","",H27) -> 5558 | J27: 5686 | K27: =IF(K3="","",J27) -> 5686 | L27: =IF(L3="","",K27) -> 5686 | M27: 5777 | N27: =IF(N3="","",M27) -> 5777 | O27: =IF(O3="","",N27) -> 5777 | P27: =IF(P3="","",O27) -> 5777 | Q27: 5884 | R27: =IF(R3="","",Q27) -> 5884 | S27: =IF(S3="","",R27) -> 5884 | T27: 5977 | U27: =IF(U3="","",T27) | V27: =IF(V3="","",U27) | W27: =IF(W3="","",V27) | X27: =IF(X3="","",W27) | Y27: =IF(Y3="","",X27) | Z27: =IF(Z3="","",Y27) | AA27: =IF(AA3="","",Z27) | AB27: =IF(AB3="","",AA27) | ... AS27: =IF(AS3="","",AR27)
A28: BUZZ＃１ | B28: プライズ | C28: 378 | D28: =IF(D3="","",C28) -> 378 | E28: =IF(E3="","",D28) -> 378 | F28: =IF(F3="","",E28) -> 378 | G28: =IF(G3="","",F28) -> 378 | H28: =IF(H3="","",G28) -> 378 | I28: =IF(I3="","",H28) -> 378 | J28: 379 | K28: =IF(K3="","",J28) -> 379 | L28: =IF(L3="","",K28) -> 379 | M28: =IF(M3="","",L28) -> 379 | N28: =IF(N3="","",M28) -> 379 | O28: =IF(O3="","",N28) -> 379 | P28: =IF(P3="","",O28) -> 379 | Q28: =IF(Q3="","",P28) -> 379 | R28: =IF(R3="","",Q28) -> 379 | S28: =IF(S3="","",R28) -> 379 | T28: 380 | U28: =IF(U3="","",T28) | V28: =IF(V3="","",U28) | W28: =IF(W3="","",V28) | X28: =IF(X3="","",W28) | Y28: =IF(Y3="","",X28) | Z28: =IF(Z3="","",Y28) | AA28: =IF(AA3="","",Z28) | AB28: =IF(AB3="","",AA28) | ... AS28: =IF(AS3="","",AR28)
A29: 3 | B29: 投入残 | C29: 8 | D29: =IF(D27="","",(C29+C30)) -> 8 | E29: =IF(E27="","",(D29+D30)) -> 8 | F29: =IF(F27="","",(E29+E30)) -> 8 | G29: =IF(G27="","",(F29+F30)) -> 9 | H29: =IF(H27="","",(G29+G30)) -> 9 | I29: =IF(I27="","",(H29+H30)) -> 9 | J29: 8 | K29: =IF(K27="","",(J29+J30)) -> 8 | L29: =IF(L27="","",(K29+K30)) -> 8 | M29: =IF(M27="","",(L29+L30)) -> 8 | N29: =IF(N27="","",(M29+M30)) -> 8 | O29: =IF(O27="","",(N29+N30)) -> 8 | P29: =IF(P27="","",(O29+O30)) -> 8 | Q29: =IF(Q27="","",(P29+P30)) -> 8 | R29: =IF(R27="","",(Q29+Q30)) -> 18 | S29: =IF(S27="","",(R29+R30)) -> 18 | T29: 17 | U29: =IF(U27="","",(T29+T30)) | V29: =IF(V27="","",(U29+U30)) | W29: =IF(W27="","",(V29+V30)) | X29: =IF(X27="","",(W29+W30)) | Y29: =IF(Y27="","",(X29+X30)) | Z29: =IF(Z27="","",(Y29+Y30)) | AA29: =IF(AA27="","",(Z29+Z30)) | AB29: =IF(AB27="","",(AA29+AA30)) | ... AS29: =IF(AS27="","",(AR29+AR30))
B30: 補充 | F30: 1 | Q30: 10
B31: 単価 | C31: 450 | D31: =IF(D27="","",C31) -> 450 | E31: =IF(E27="","",D31) -> 450 | F31: =IF(F27="","",E31) -> 450 | G31: =IF(G27="","",F31) -> 450 | H31: =IF(H27="","",G31) -> 450 | I31: =IF(I27="","",H31) -> 450 | J31: =IF(J27="","",I31) -> 450 | K31: =IF(K27="","",J31) -> 450 | ... AS31: =IF(AS27="","",AR31)
A32: 月間予想 | B32: 景品名 | C32: たまごっちマスコット | D32: =IF(D27="","",C32) -> たまごっちマスコット | E32: =IF(E27="","",D32) -> たまごっちマスコット | F32: =IF(F27="","",E32) -> たまごっちマスコット | G32: =IF(G27="","",F32) -> たまごっちマスコット | H32: =IF(H27="","",G32) -> たまごっちマスコット | I32: =IF(I27="","",H32) -> たまごっちマスコット | J32: =IF(J27="","",I32) -> たまごっちマスコット | K32: =IF(K27="","",J32) -> たまごっちマスコット | ... AS32: =IF(AS27="","",AR32)
A33: =AVERAGE(C34:AS34)*30*100 -> 102000 | B33: 設定
A34: =SUM(C34:AS34) -> 612 | B34: 百差 | C34: 0 | D34: =IF(D27="","",D27-C27) -> 0 | E34: =IF(E27="","",E27-D27) -> 0 | F34: =IF(F27="","",F27-E27) -> 193 | G34: =IF(G27="","",G27-F27) -> 0 | H34: =IF(H27="","",H27-G27) -> 0 | I34: =IF(I27="","",I27-H27) -> 0 | J34: =IF(J27="","",J27-I27) -> 128 | K34: =IF(K27="","",K27-J27) -> 0 | ... AS34: =IF(AS27="","",AS27-AR27)
A35: =SUM(C35:AS35) -> 2 | B35: P差 | C35: 0 | D35: =IF(D28="","",D28-C28) -> 0 | E35: =IF(E28="","",E28-D28) -> 0 | F35: =IF(F28="","",F28-E28) -> 0 | G35: =IF(G28="","",G28-F28) -> 0 | H35: =IF(H28="","",H28-G28) -> 0 | I35: =IF(I28="","",I28-H28) -> 0 | J35: =IF(J28="","",J28-I28) -> 1 | K35: =IF(K28="","",K28-J28) -> 0 | ... AS35: =IF(AS28="","",AS28-AR28)
A36: =SUM(C36:AS36) -> 2 | B36: 払出 | C36: 0 | D36: =IF(D29="","",C29+C30-D29) -> 0 | E36: =IF(E29="","",D29+D30-E29) -> 0 | F36: =IF(F29="","",E29+E30-F29) -> 0 | G36: =IF(G29="","",F29+F30-G29) -> 0 | H36: =IF(H29="","",G29+G30-H29) -> 0 | I36: =IF(I29="","",H29+H30-I29) -> 0 | J36: =IF(J29="","",I29+I30-J29) -> 1 | K36: =IF(K29="","",J29+J30-K29) -> 0 | ... AS36: =IF(AS29="","",AR29+AR30-AS29)
A37: =SUM(C37:AS37) -> 900 | B37: 払出額 | C37: 0 | D37: =IF(D27="","",D36*D31) -> 0 | E37: =IF(E27="","",E36*E31) -> 0 | F37: =IF(F27="","",F36*F31) -> 0 | G37: =IF(G27="","",G36*G31) -> 0 | H37: =IF(H27="","",H36*H31) -> 0 | I37: =IF(I27="","",I36*I31) -> 0 | J37: =IF(J27="","",J36*J31) -> 450 | K37: =IF(K27="","",K36*K31) -> 0 | ... AS37: =IF(AS27="","",AS36*AS31)
A38: =IF(A37="","",A37/(A34*100)) -> 0.014705882 | B38: 原価率 | D38: =IF(D37="","",IF(D37=0,"",D37/(D34*100))) | E38: =IF(E37="","",IF(E37=0,"",E37/(E34*100))) | F38: =IF(F37="","",IF(F37=0,"",F37/(F34*100))) | G38: =IF(G37="","",IF(G37=0,"",G37/(G34*100))) | H38: =IF(H37="","",IF(H37=0,"",H37/(H34*100))) | I38: =IF(I37="","",IF(I37=0,"",I37/(I34*100))) | J38: =IF(J37="","",IF(J37=0,"",J37/(J34*100))) -> 0.03515625 | K38: =IF(K37="","",IF(K37=0,"",K37/(K34*100))) | ... AS38: =IF(AS37="","",IF(AS37=0,"",AS37/(AS34*100)))
A39: 鹿屋 | B39: 100円 | C39: 9500 | D39: =IF(D3="","",C39) -> 9500 | E39: =IF(E3="","",D39) -> 9500 | F39: 9540 | G39: =IF(G3="","",F39) -> 9540 | H39: =IF(H3="","",G39) -> 9540 | I39: =IF(I3="","",H39) -> 9540 | J39: 9549 | K39: =IF(K3="","",J39) -> 9549 | L39: =IF(L3="","",K39) -> 9549 | M39: 9581 | N39: =IF(N3="","",M39) -> 9581 | O39: =IF(O3="","",N39) -> 9581 | P39: =IF(P3="","",O39) -> 9581 | Q39: 9614 | R39: =IF(R3="","",Q39) -> 9614 | S39: =IF(S3="","",R39) -> 9614 | T39: 9665 | U39: =IF(U3="","",T39) | V39: =IF(V3="","",U39) | W39: =IF(W3="","",V39) | X39: =IF(X3="","",W39) | Y39: =IF(Y3="","",X39) | Z39: =IF(Z3="","",Y39) | AA39: =IF(AA3="","",Z39) | AB39: =IF(AB3="","",AA39) | ... AS39: =IF(AS3="","",AR39)
A40: BUZZ＃１ | B40: プライズ | C40: 556 | D40: =IF(D3="","",C40) -> 556 | E40: =IF(E3="","",D40) -> 556 | F40: 558 | G40: =IF(G3="","",F40) -> 558 | H40: =IF(H3="","",G40) -> 558 | I40: =IF(I3="","",H40) -> 558 | J40: =IF(J3="","",I40) -> 558 | K40: =IF(K3="","",J40) -> 558 | L40: =IF(L3="","",K40) -> 558 | M40: 560 | N40: =IF(N3="","",M40) -> 560 | O40: =IF(O3="","",N40) -> 560 | P40: =IF(P3="","",O40) -> 560 | Q40: 563 | R40: =IF(R3="","",Q40) -> 563 | S40: =IF(S3="","",R40) -> 563 | T40: 568 | U40: =IF(U3="","",T40) | V40: =IF(V3="","",U40) | W40: =IF(W3="","",V40) | X40: =IF(X3="","",W40) | Y40: =IF(Y3="","",X40) | Z40: =IF(Z3="","",Y40) | AA40: =IF(AA3="","",Z40) | AB40: =IF(AB3="","",AA40) | ... AS40: =IF(AS3="","",AR40)
...

Sheet 都城
A1: =SUM(A57,A69,A81,A93,A9,A21,A33,A45,A201,A213,A225,A237,A105,A117,A129,A141,A153,A165,A177,A189,A249,A261) -> 1085875 | B1: 日付 | C1: 46094 | D1: =C1+1 -> 46095 | E1: =D1+1 -> 46096 | F1: =E1+1 -> 46097 | G1: =F1+1 -> 46098 | H1: =G1+1 -> 46099 | I1: =H1+1 -> 46100 | J1: =I1+1 -> 46101 | K1: =J1+1 -> 46102 | ... AS1: =AR1+1 -> 46136
B2: =SUM(C2:AO2) -> 8687 | C2: 0 | D2: =SUM(D10,D22,D34,D46,D58,D70,D82,D94,D106,D118,D130,D142,D154,D166,D178,D190,D202,D214,D226,D238) -> 0 | E2: =SUM(E10,E22,E34,E46,E58,E70,E82,E94,E106,E118,E130,E142,E154,E166,E178,E190,E202,E214,E226,E238) -> 1174 | F2: =SUM(F10,F22,F34,F46,F58,F70,F82,F94,F106,F118,F130,F142,F154,F166,F178,F190,F202,F214,F226,F238) -> 0 | G2: =SUM(G10,G22,G34,G46,G58,G70,G82,G94,G106,G118,G130,G142,G154,G166,G178,G190,G202,G214,G226,G238) -> 0 | H2: =SUM(H10,H22,H34,H46,H58,H70,H82,H94,H106,H118,H130,H142,H154,H166,H178,H190,H202,H214,H226,H238) -> 917 | I2: =SUM(I10,I22,I34,I46,I58,I70,I82,I94,I106,I118,I130,I142,I154,I166,I178,I190,I202,I214,I226,I238) -> 0 | J2: =SUM(J10,J22,J34,J46,J58,J70,J82,J94,J106,J118,J130,J142,J154,J166,J178,J190,J202,J214,J226,J238) -> 0 | K2: =SUM(K10,K22,K34,K46,K58,K70,K82,K94,K106,K118,K130,K142,K154,K166,K178,K190,K202,K214,K226,K238) -> 0 | ... AS2: =SUM(AS10,AS22,AS34,AS46,AS58,AS70,AS82,AS94,AS106,AS118,AS130,AS142,AS154,AS166,AS178,AS190,AS202,AS214,AS226,AS238) -> 0
A3: 都城 | B3: 100円 | C3: 3874 | D3: 3874 | E3: 3917 | F3: 3917 | G3: 3917 | H3: 3945 | I3: 3945 | J3: 3945 | K3: 3945 | L3: 3955 | M3: 3955 | N3: 3955 | O3: 3955 | P3: 3966 | Q3: 3966 | R3: 3966 | S3: 3977 | T3: 3977 | U3: 4011 | V3: 4011 | W3: 4029 | X3: 4029 | Y3: 4029 | Z3: 4117
A4: BUZZ＃１ | B4: プライズ | C4: 86 | D4: =IF(D3="","",C4) -> 86 | E4: =IF(E3="","",D4) -> 86 | F4: =IF(F3="","",E4) -> 86 | G4: =IF(G3="","",F4) -> 86 | H4: 87 | I4: =IF(I3="","",H4) -> 87 | J4: =IF(J3="","",I4) -> 87 | K4: =IF(K3="","",J4) -> 87 | L4: =IF(L3="","",K4) -> 87 | M4: =IF(M3="","",L4) -> 87 | N4: =IF(N3="","",M4) -> 87 | O4: =IF(O3="","",N4) -> 87 | P4: =IF(P3="","",O4) -> 87 | Q4: =IF(Q3="","",P4) -> 87 | R4: 87 | S4: =IF(S3="","",R4) -> 87 | T4: =IF(T3="","",S4) -> 87 | U4: 93 | V4: =IF(V3="","",U4) -> 93 | W4: =IF(W3="","",V4) -> 93 | X4: =IF(X3="","",W4) -> 93 | Y4: =IF(Y3="","",X4) -> 93 | Z4: 94 | AA4: =IF(AA3="","",Z4) | AB4: =IF(AB3="","",AA4) | AC4: =IF(AC3="","",AB4) | AD4: =IF(AD3="","",AC4) | AE4: =IF(AE3="","",AD4) | AF4: =IF(AF3="","",AE4) | AG4: =IF(AG3="","",AF4) | AH4: =IF(AH3="","",AG4) | ... AS4: =IF(AS3="","",AR4)
A5: 1 | B5: 投入残 | C5: 4 | D5: =IF(D3="","",(C5+C6)) -> 4 | E5: =IF(E3="","",(D5+D6)) -> 4 | F5: =IF(F3="","",(E5+E6)) -> 4 | G5: =IF(G3="","",(F5+F6)) -> 4 | H5: 3 | I5: =IF(I3="","",(H5+H6)) -> 3 | J5: =IF(J3="","",(I5+I6)) -> 3 | K5: =IF(K3="","",(J5+J6)) -> 3 | L5: =IF(L3="","",(K5+K6)) -> 3 | M5: =IF(M3="","",(L5+L6)) -> 4 | N5: =IF(N3="","",(M5+M6)) -> 4 | O5: =IF(O3="","",(N5+N6)) -> 4 | P5: =IF(P3="","",(O5+O6)) -> 4 | ... T5: =IF(T3="","",(S5+S6)) -> 6 | U5: 0 | V5: =IF(V3="","",(U5+U6)) -> 3 | W5: 2 | X5: =IF(X3="","",(W5+W6)) -> 5 | Y5: =IF(Y3="","",(X5+X6)) -> 5 | Z5: 3 | AA5: =IF(AA3="","",(Z5+Z6)) | AB5: =IF(AB3="","",(AA5+AA6)) | AC5: =IF(AC3="","",(AB5+AB6)) | AD5: =IF(AD3="","",(AC5+AC6)) | AE5: =IF(AE3="","",(AD5+AD6)) | AF5: =IF(AF3="","",(AE5+AE6)) | AG5: =IF(AG3="","",(AF5+AF6)) | AH5: =IF(AH3="","",(AG5+AG6)) | ... AS5: =IF(AS3="","",(AR5+AR6))
A6: 機械合計 | B6: 補充 | L6: 1 | S6: 2 | U6: 3 | W6: 3
A7: =+(A10+A22+A34+A46)*100 -> 133800 | B7: 単価 | C7: 500 | D7: =IF(D3="","",C7) -> 500 | E7: =IF(E3="","",D7) -> 500 | F7: =IF(F3="","",E7) -> 500 | G7: =IF(G3="","",F7) -> 500 | H7: =IF(H3="","",G7) -> 500 | I7: =IF(I3="","",H7) -> 500 | J7: =IF(J3="","",I7) -> 500 | K7: =IF(K3="","",J7) -> 500 | ... AS7: =IF(AS3="","",AR7)
A8: 月間予想 | B8: 景品名 | C8: サンリオフェイスポーチ | D8: =IF(D3="","",C8) -> サンリオフェイスポーチ | E8: =IF(E3="","",D8) -> サンリオフェイスポーチ | F8: =IF(F3="","",E8) -> サンリオフェイスポーチ | G8: =IF(G3="","",F8) -> サンリオフェイスポーチ | H8: =IF(H3="","",G8) -> サンリオフェイスポーチ | I8: =IF(I3="","",H8) -> サンリオフェイスポーチ | J8: =IF(J3="","",I8) -> サンリオフェイスポーチ | K8: =IF(K3="","",J8) -> サンリオフェイスポーチ | ... R8: =IF(R3="","",Q8) -> サンリオフェイスポーチ | S8: フルーツモンチッチマスコット | T8: =IF(T3="","",S8) -> フルーツモンチッチマスコット | U8: =IF(U3="","",T8) -> フルーツモンチッチマスコット | V8: =IF(V3="","",U8) -> フルーツモンチッチマスコット | W8: =IF(W3="","",V8) -> フルーツモンチッチマスコット | X8: =IF(X3="","",W8) -> フルーツモンチッチマスコット | Y8: =IF(Y3="","",X8) -> フルーツモンチッチマスコット | Z8: =IF(Z3="","",Y8) -> フルーツモンチッチマスコット | AA8: =IF(AA3="","",Z8) | ... AS8: =IF(AS3="","",AR8)
A9: =AVERAGE(C10:AS10)*30*100 -> 30375 | B9: 設定
A10: =SUM(C10:AS10) -> 243 | B10: 百差 | C10: 0 | D10: =IF(D3="","",D3-C3) -> 0 | E10: =IF(E3="","",E3-D3) -> 43 | F10: =IF(F3="","",F3-E3) -> 0 | G10: =IF(G3="","",G3-F3) -> 0 | H10: =IF(H3="","",H3-G3) -> 28 | I10: =IF(I3="","",I3-H3) -> 0 | J10: =IF(J3="","",J3-I3) -> 0 | K10: =IF(K3="","",K3-J3) -> 0 | ... AS10: =IF(AS3="","",AS3-AR3)
A11: =SUM(C11:AS11) -> 8 | B11: P差 | C11: 0 | D11: =IF(D4="","",D4-C4) -> 0 | E11: =IF(E4="","",E4-D4) -> 0 | F11: =IF(F4="","",F4-E4) -> 0 | G11: =IF(G4="","",G4-F4) -> 0 | H11: =IF(H4="","",H4-G4) -> 1 | I11: =IF(I4="","",I4-H4) -> 0 | J11: =IF(J4="","",J4-I4) -> 0 | K11: =IF(K4="","",K4-J4) -> 0 | ... AS11: =IF(AS4="","",AS4-AR4)
A12: =SUM(C12:AS12) -> 10 | B12: 払出 | C12: 0 | D12: =IF(D5="","",C5+C6-D5) -> 0 | E12: =IF(E5="","",D5+D6-E5) -> 0 | F12: =IF(F5="","",E5+E6-F5) -> 0 | G12: =IF(G5="","",F5+F6-G5) -> 0 | H12: =IF(H5="","",G5+G6-H5) -> 1 | I12: =IF(I5="","",H5+H6-I5) -> 0 | J12: =IF(J5="","",I5+I6-J5) -> 0 | K12: =IF(K5="","",J5+J6-K5) -> 0 | ... AS12: =IF(AS5="","",AR5+AR6-AS5)
A13: =SUM(C13:AS13) -> 5000 | B13: 払出額 | C13: 0 | D13: =IF(D3="","",D12*D7) -> 0 | E13: =IF(E3="","",E12*E7) -> 0 | F13: =IF(F3="","",F12*F7) -> 0 | G13: =IF(G3="","",G12*G7) -> 0 | H13: =IF(H3="","",H12*H7) -> 500 | I13: =IF(I3="","",I12*I7) -> 0 | J13: =IF(J3="","",J12*J7) -> 0 | K13: =IF(K3="","",K12*K7) -> 0 | ... AS13: =IF(AS3="","",AS12*AS7)
A14: =IF(A13="","",A13/(A10*100)) -> 0.20576132 | B14: 原価率 | D14: =IF(D13="","",IF(D13=0,"",D13/(D10*100))) | E14: =IF(E13="","",IF(E13=0,"",E13/(E10*100))) | F14: =IF(F13="","",IF(F13=0,"",F13/(F10*100))) | G14: =IF(G13="","",IF(G13=0,"",G13/(G10*100))) | H14: =IF(H13="","",IF(H13=0,"",H13/(H10*100))) -> 0.17857143 | I14: =IF(I13="","",IF(I13=0,"",I13/(I10*100))) | J14: =IF(J13="","",IF(J13=0,"",J13/(J10*100))) | K14: =IF(K13="","",IF(K13=0,"",K13/(K10*100))) | ... AS14: =IF(AS13="","",IF(AS13=0,"",AS13/(AS10*100)))
A15: 都城 | B15: 100円 | C15: 6317 | D15: =IF(D3="","",C15) -> 6317 | E15: 6378 | F15: =IF(F3="","",E15) -> 6378 | G15: =IF(G3="","",F15) -> 6378 | H15: 6390 | I15: =IF(I3="","",H15) -> 6390 | J15: =IF(J3="","",I15) -> 6390 | K15: =IF(K3="","",J15) -> 6390 | L15: 6459 | M15: =IF(M3="","",L15) -> 6459 | N15: =IF(N3="","",M15) -> 6459 | O15: =IF(O3="","",N15) -> 6459 | P15: 6508 | Q15: =IF(Q3="","",P15) -> 6508 | R15: =IF(R3="","",Q15) -> 6508 | S15: 6565 | T15: =IF(T3="","",S15) -> 6565 | U15: =IF(U3="","",T15) -> 6565 | V15: =IF(V3="","",U15) -> 6565 | W15: 6630 | X15: =IF(X3="","",W15) -> 6630 | Y15: =IF(Y3="","",X15) -> 6630 | Z15: 6724 | AA15: =IF(AA3="","",Z15) | AB15: =IF(AB3="","",AA15) | AC15: =IF(AC3="","",AB15) | AD15: =IF(AD3="","",AC15) | AE15: =IF(AE3="","",AD15) | AF15: =IF(AF3="","",AE15) | AG15: =IF(AG3="","",AF15) | AH15: =IF(AH3="","",AG15) | ... AS15: =IF(AS3="","",AR15)
A16: BUZZ＃１ | B16: プライズ | C16: 86 | D16: =IF(D3="","",C16) -> 86 | E16: 87 | F16: =IF(F3="","",E16) -> 87 | G16: =IF(G3="","",F16) -> 87 | H16: =IF(H3="","",G16) -> 87 | I16: =IF(I3="","",H16) -> 87 | J16: =IF(J3="","",I16) -> 87 | K16: =IF(K3="","",J16) -> 87 | L16: 88 | M16: =IF(M3="","",L16) -> 88 | N16: =IF(N3="","",M16) -> 88 | O16: =IF(O3="","",N16) -> 88 | P16: =IF(P3="","",O16) -> 88 | Q16: =IF(Q3="","",P16) -> 88 | R16: =IF(R3="","",Q16) -> 88 | S16: 89 | T16: =IF(T3="","",S16) -> 89 | U16: =IF(U3="","",T16) -> 89 | V16: =IF(V3="","",U16) -> 89 | W16: 90 | X16: =IF(X3="","",W16) -> 90 | Y16: =IF(Y3="","",X16) -> 90 | Z16: =IF(Z3="","",Y16) -> 90 | AA16: =IF(AA3="","",Z16) | AB16: =IF(AB3="","",AA16) | AC16: =IF(AC3="","",AB16) | AD16: =IF(AD3="","",AC16) | AE16: =IF(AE3="","",AD16) | ... AS16: =IF(AS3="","",AR16)
A17: 2 | B17: 投入残 | C17: 7 | D17: =IF(D15="","",(C17+C18)) -> 7 | E17: 5 | F17: =IF(F15="","",(E17+E18)) -> 5 | G17: =IF(G15="","",(F17+F18)) -> 5 | H17: =IF(H15="","",(G17+G18)) -> 5 | I17: =IF(I15="","",(H17+H18)) -> 5 | J17: =IF(J15="","",(I17+I18)) -> 5 | K17: =IF(K15="","",(J17+J18)) -> 5 | L17: 3 | M17: =IF(M15="","",(L17+L18)) -> 7 | N17: =IF(N15="","",(M17+M18)) -> 7 | O17: =IF(O15="","",(N17+N18)) -> 7 | P17: =IF(P15="","",(O17+O18)) -> 7 | Q17: =IF(Q15="","",(P17+P18)) -> 7 | R17: =IF(R15="","",(Q17+Q18)) -> 7 | S17: 6 | T17: =IF(T15="","",(S17+S18)) -> 6 | U17: =IF(U15="","",(T17+T18)) -> 6 | V17: =IF(V15="","",(U17+U18)) -> 6 | W17: 5 | X17: =IF(X15="","",(W17+W18)) -> 6 | Y17: =IF(Y15="","",(X17+X18)) -> 6 | Z17: =IF(Z15="","",(Y17+Y18)) -> 6 | AA17: =IF(AA15="","",(Z17+Z18)) | AB17: =IF(AB15="","",(AA17+AA18)) | AC17: =IF(AC15="","",(AB17+AB18)) | AD17: =IF(AD15="","",(AC17+AC18)) | AE17: =IF(AE15="","",(AD17+AD18)) | ... AS17: =IF(AS15="","",(AR17+AR18))
B18: 補充 | L18: 4 | W18: 1
B19: 単価 | C19: 800 | D19: =IF(D15="","",C19) -> 800 | E19: =IF(E15="","",D19) -> 800 | F19: =IF(F15="","",E19) -> 800 | G19: =IF(G15="","",F19) -> 800 | H19: =IF(H15="","",G19) -> 800 | I19: =IF(I15="","",H19) -> 800 | J19: =IF(J15="","",I19) -> 800 | K19: =IF(K15="","",J19) -> 800 | ... AS19: =IF(AS15="","",AR19)
A20: 月間予想 | B20: 景品名 | C20: ミニデジタルカメラ | D20: =IF(D15="","",C20) -> ミニデジタルカメラ | E20: =IF(E15="","",D20) -> ミニデジタルカメラ | F20: =IF(F15="","",E20) -> ミニデジタルカメラ | G20: =IF(G15="","",F20) -> ミニデジタルカメラ | H20: =IF(H15="","",G20) -> ミニデジタルカメラ | I20: =IF(I15="","",H20) -> ミニデジタルカメラ | J20: =IF(J15="","",I20) -> ミニデジタルカメラ | K20: =IF(K15="","",J20) -> ミニデジタルカメラ | ... AS20: =IF(AS15="","",AR20)
A21: =AVERAGE(C22:AS22)*30*100 -> 50875 | B21: 設定
A22: =SUM(C22:AS22) -> 407 | B22: 百差 | C22: 0 | D22: =IF(D15="","",D15-C15) -> 0 | E22: =IF(E15="","",E15-D15) -> 61 | F22: =IF(F15="","",F15-E15) -> 0 | G22: =IF(G15="","",G15-F15) -> 0 | H22: =IF(H15="","",H15-G15) -> 12 | I22: =IF(I15="","",I15-H15) -> 0 | J22: =IF(J15="","",J15-I15) -> 0 | K22: =IF(K15="","",K15-J15) -> 0 | ... AS22: =IF(AS15="","",AS15-AR15)
A23: =SUM(C23:AS23) -> 4 | B23: P差 | C23: 0 | D23: =IF(D16="","",D16-C16) -> 0 | E23: =IF(E16="","",E16-D16) -> 1 | F23: =IF(F16="","",F16-E16) -> 0 | G23: =IF(G16="","",G16-F16) -> 0 | H23: =IF(H16="","",H16-G16) -> 0 | I23: =IF(I16="","",I16-H16) -> 0 | J23: =IF(J16="","",J16-I16) -> 0 | K23: =IF(K16="","",K16-J16) -> 0 | ... AS23: =IF(AS16="","",AS16-AR16)
A24: =SUM(C24:AS24) -> 6 | B24: 払出 | C24: 0 | D24: =IF(D17="","",C17+C18-D17) -> 0 | E24: =IF(E17="","",D17+D18-E17) -> 2 | F24: =IF(F17="","",E17+E18-F17) -> 0 | G24: =IF(G17="","",F17+F18-G17) -> 0 | H24: =IF(H17="","",G17+G18-H17) -> 0 | I24: =IF(I17="","",H17+H18-I17) -> 0 | J24: =IF(J17="","",I17+I18-J17) -> 0 | K24: =IF(K17="","",J17+J18-K17) -> 0 | ... AS24: =IF(AS17="","",AR17+AR18-AS17)
A25: =SUM(C25:AS25) -> 4800 | B25: 払出額 | C25: 0 | D25: =IF(D15="","",D24*D19) -> 0 | E25: =IF(E15="","",E24*E19) -> 1600 | F25: =IF(F15="","",F24*F19) -> 0 | G25: =IF(G15="","",G24*G19) -> 0 | H25: =IF(H15="","",H24*H19) -> 0 | I25: =IF(I15="","",I24*I19) -> 0 | J25: =IF(J15="","",J24*J19) -> 0 | K25: =IF(K15="","",K24*K19) -> 0 | ... AS25: =IF(AS15="","",AS24*AS19)
A26: =IF(A25="","",A25/(A22*100)) -> 0.11793612 | B26: 原価率 | D26: =IF(D25="","",IF(D25=0,"",D25/(D22*100))) | E26: =IF(E25="","",IF(E25=0,"",E25/(E22*100))) -> 0.26229508 | F26: =IF(F25="","",IF(F25=0,"",F25/(F22*100))) | G26: =IF(G25="","",IF(G25=0,"",G25/(G22*100))) | H26: =IF(H25="","",IF(H25=0,"",H25/(H22*100))) | I26: =IF(I25="","",IF(I25=0,"",I25/(I22*100))) | J26: =IF(J25="","",IF(J25=0,"",J25/(J22*100))) | K26: =IF(K25="","",IF(K25=0,"",K25/(K22*100))) | ... AS26: =IF(AS25="","",IF(AS25=0,"",AS25/(AS22*100)))
A27: 都城 | B27: 100円 | C27: 6840 | D27: =IF(D3="","",C27) -> 6840 | E27: 6908 | F27: =IF(F3="","",E27) -> 6908 | G27: =IF(G3="","",F27) -> 6908 | H27: 6921 | I27: =IF(I3="","",H27) -> 6921 | J27: =IF(J3="","",I27) -> 6921 | K27: =IF(K3="","",J27) -> 6921 | L27: 6991 | M27: =IF(M3="","",L27) -> 6991 | N27: =IF(N3="","",M27) -> 6991 | O27: =IF(O3="","",N27) -> 6991 | P27: 7047 | Q27: =IF(Q3="","",P27) -> 7047 | R27: =IF(R3="","",Q27) -> 7047 | S27: 7098 | T27: =IF(T3="","",S27) -> 7098 | U27: =IF(U3="","",T27) -> 7098 | V27: =IF(V3="","",U27) -> 7098 | W27: 7191 | X27: =IF(X3="","",W27) -> 7191 | Y27: =IF(Y3="","",X27) -> 7191 | Z27: 7242 | AA27: =IF(AA3="","",Z27) | AB27: =IF(AB3="","",AA27) | AC27: =IF(AC3="","",AB27) | AD27: =IF(AD3="","",AC27) | AE27: =IF(AE3="","",AD27) | AF27: =IF(AF3="","",AE27) | AG27: =IF(AG3="","",AF27) | AH27: =IF(AH3="","",AG27) | ... AS27: =IF(AS3="","",AR27)
A28: BUZZ＃１ | B28: プライズ | C28: 241 | D28: =IF(D3="","",C28) -> 241 | E28: 242 | F28: =IF(F3="","",E28) -> 242 | G28: =IF(G3="","",F28) -> 242 | H28: =IF(H3="","",G28) -> 242 | I28: =IF(I3="","",H28) -> 242 | J28: =IF(J3="","",I28) -> 242 | K28: =IF(K3="","",J28) -> 242 | L28: =IF(L3="","",K28) -> 242 | M28: =IF(M3="","",L28) -> 242 | ... O28: =IF(O3="","",N28) -> 242 | P28: 243 | Q28: =IF(Q3="","",P28) -> 243 | R28: =IF(R3="","",Q28) -> 243 | S28: 244 | T28: =IF(T3="","",S28) -> 244 | U28: =IF(U3="","",T28) -> 244 | V28: =IF(V3="","",U28) -> 244 | W28: 245 | X28: =IF(X3="","",W28) -> 245 | Y28: =IF(Y3="","",X28) -> 245 | Z28: 246 | AA28: =IF(AA3="","",Z28) | AB28: =IF(AB3="","",AA28) | AC28: =IF(AC3="","",AB28) | AD28: =IF(AD3="","",AC28) | AE28: =IF(AE3="","",AD28) | AF28: =IF(AF3="","",AE28) | AG28: =IF(AG3="","",AF28) | AH28: =IF(AH3="","",AG28) | ... AS28: =IF(AS3="","",AR28)
A29: 3 | B29: 投入残 | C29: 9 | D29: =IF(D27="","",(C29+C30)) -> 9 | E29: 8 | F29: =IF(F27="","",(E29+E30)) -> 8 | G29: =IF(G27="","",(F29+F30)) -> 8 | H29: =IF(H27="","",(G29+G30)) -> 8 | I29: =IF(I27="","",(H29+H30)) -> 8 | J29: =IF(J27="","",(I29+I30)) -> 8 | K29: =IF(K27="","",(J29+J30)) -> 8 | L29: =IF(L27="","",(K29+K30)) -> 8 | M29: =IF(M27="","",(L29+L30)) -> 8 | ... V29: =IF(V27="","",(U29+U30)) -> 8 | W29: 7 | X29: =IF(X27="","",(W29+W30)) -> 7 | Y29: =IF(Y27="","",(X29+X30)) -> 7 | Z29: =IF(Z27="","",(Y29+Y30)) -> 7 | AA29: =IF(AA27="","",(Z29+Z30)) | AB29: =IF(AB27="","",(AA29+AA30)) | AC29: =IF(AC27="","",(AB29+AB30)) | AD29: =IF(AD27="","",(AC29+AC30)) | AE29: =IF(AE27="","",(AD29+AD30)) | ... AS29: =IF(AS27="","",(AR29+AR30))
B30: 補充
B31: 単価 | C31: 175 | D31: =IF(D27="","",C31) -> 175 | E31: =IF(E27="","",D31) -> 175 | F31: =IF(F27="","",E31) -> 175 | G31: =IF(G27="","",F31) -> 175 | H31: =IF(H27="","",G31) -> 175 | I31: =IF(I27="","",H31) -> 175 | J31: =IF(J27="","",I31) -> 175 | K31: =IF(K27="","",J31) -> 175 | ... AS31: =IF(AS27="","",AR31)
A32: 月間予想 | B32: 景品名 | C32: スライム | D32: =IF(D27="","",C32) -> スライム | E32: =IF(E27="","",D32) -> スライム | F32: =IF(F27="","",E32) -> スライム | G32: =IF(G27="","",F32) -> スライム | H32: =IF(H27="","",G32) -> スライム | I32: =IF(I27="","",H32) -> スライム | J32: =IF(J27="","",I32) -> スライム | K32: =IF(K27="","",J32) -> スライム | ... AS32: =IF(AS27="","",AR32)
A33: =AVERAGE(C34:AS34)*30*100 -> 50250 | B33: 設定
A34: =SUM(C34:AS34) -> 402 | B34: 百差 | C34: 0 | D34: =IF(D27="","",D27-C27) -> 0 | E34: =IF(E27="","",E27-D27) -> 68 | F34: =IF(F27="","",F27-E27) -> 0 | G34: =IF(G27="","",G27-F27) -> 0 | H34: =IF(H27="","",H27-G27) -> 13 | I34: =IF(I27="","",I27-H27) -> 0 | J34: =IF(J27="","",J27-I27) -> 0 | K34: =IF(K27="","",K27-J27) -> 0 | ... AS34: =IF(AS27="","",AS27-AR27)
A35: =SUM(C35:AS35) -> 5 | B35: P差 | C35: 0 | D35: =IF(D28="","",D28-C28) -> 0 | E35: =IF(E28="","",E28-D28) -> 1 | F35: =IF(F28="","",F28-E28) -> 0 | G35: =IF(G28="","",G28-F28) -> 0 | H35: =IF(H28="","",H28-G28) -> 0 | I35: =IF(I28="","",I28-H28) -> 0 | J35: =IF(J28="","",J28-I28) -> 0 | K35: =IF(K28="","",K28-J28) -> 0 | ... AS35: =IF(AS28="","",AS28-AR28)
A36: =SUM(C36:AS36) -> 2 | B36: 払出 | C36: 0 | D36: =IF(D29="","",C29+C30-D29) -> 0 | E36: =IF(E29="","",D29+D30-E29) -> 1 | F36: =IF(F29="","",E29+E30-F29) -> 0 | G36: =IF(G29="","",F29+F30-G29) -> 0 | H36: =IF(H29="","",G29+G30-H29) -> 0 | I36: =IF(I29="","",H29+H30-I29) -> 0 | J36: =IF(J29="","",I29+I30-J29) -> 0 | K36: =IF(K29="","",J29+J30-K29) -> 0 | ... AS36: =IF(AS29="","",AR29+AR30-AS29)
A37: =SUM(C37:AS37) -> 350 | B37: 払出額 | C37: 0 | D37: =IF(D27="","",D36*D31) -> 0 | E37: =IF(E27="","",E36*E31) -> 175 | F37: =IF(F27="","",F36*F31) -> 0 | G37: =IF(G27="","",G36*G31) -> 0 | H37: =IF(H27="","",H36*H31) -> 0 | I37: =IF(I27="","",I36*I31) -> 0 | J37: =IF(J27="","",J36*J31) -> 0 | K37: =IF(K27="","",K36*K31) -> 0 | ... AS37: =IF(AS27="","",AS36*AS31)
A38: =IF(A37="","",A37/(A34*100)) -> 0.0087064677 | B38: 原価率 | D38: =IF(D37="","",IF(D37=0,"",D37/(D34*100))) | E38: =IF(E37="","",IF(E37=0,"",E37/(E34*100))) -> 0.025735294 | F38: =IF(F37="","",IF(F37=0,"",F37/(F34*100))) | G38: =IF(G37="","",IF(G37=0,"",G37/(G34*100))) | H38: =IF(H37="","",IF(H37=0,"",H37/(H34*100))) | I38: =IF(I37="","",IF(I37=0,"",I37/(I34*100))) | J38: =IF(J37="","",IF(J37=0,"",J37/(J34*100))) | K38: =IF(K37="","",IF(K37=0,"",K37/(K34*100))) | ... AS38: =IF(AS37="","",IF(AS37=0,"",AS37/(AS34*100)))
A39: 都城 | B39: 100円 | C39: 3452 | D39: =IF(D3="","",C39) -> 3452 | E39: 3495 | F39: =IF(F3="","",E39) -> 3495 | G39: =IF(G3="","",F39) -> 3495 | H39: 3502 | I39: =IF(I3="","",H39) -> 3502 | J39: =IF(J3="","",I39) -> 3502 | K39: =IF(K3="","",J39) -> 3502 | L39: 3545 | M39: =IF(M3="","",L39) -> 3545 | N39: =IF(N3="","",M39) -> 3545 | O39: =IF(O3="","",N39) -> 3545 | P39: 3559 | Q39: =IF(Q3="","",P39) -> 3559 | R39: =IF(R3="","",Q39) -> 3559 | S39: 3588 | T39: =IF(T3="","",S39) -> 3588 | U39: =IF(U3="","",T39) -> 3588 | V39: =IF(V3="","",U39) -> 3588 | W39: 3714 | X39: =IF(X3="","",W39) -> 3714 | Y39: =IF(Y3="","",X39) -> 3714 | Z39: 3738 | AA39: =IF(AA3="","",Z39) | AB39: =IF(AB3="","",AA39) | AC39: =IF(AC3="","",AB39) | AD39: =IF(AD3="","",AC39) | AE39: =IF(AE3="","",AD39) | AF39: =IF(AF3="","",AE39) | AG39: =IF(AG3="","",AF39) | AH39: =IF(AH3="","",AG39) | ... AS39: =IF(AS3="","",AR39)
A40: BUZZ＃１ | B40: プライズ | C40: 70 | D40: =IF(D3="","",C40) -> 70 | E40: 73 | F40: =IF(F3="","",E40) -> 73 | G40: =IF(G3="","",F40) -> 73 | H40: =IF(H3="","",G40) -> 73 | I40: =IF(I3="","",H40) -> 73 | J40: =IF(J3="","",I40) -> 73 | K40: =IF(K3="","",J40) -> 73 | L40: 74 | M40: =IF(M3="","",L40) -> 74 | N40: =IF(N3="","",M40) -> 74 | O40: =IF(O3="","",N40) -> 74 | P40: 76 | Q40: =IF(Q3="","",P40) -> 76 | R40: =IF(R3="","",Q40) -> 76 | S40: =IF(S3="","",R40) -> 76 | T40: =IF(T3="","",S40) -> 76 | U40: =IF(U3="","",T40) -> 76 | V40: =IF(V3="","",U40) -> 76 | W40: 88 | X40: =IF(X3="","",W40) -> 88 | Y40: =IF(Y3="","",X40) -> 88 | Z40: 91 | AA40: =IF(AA3="","",Z40) | AB40: =IF(AB3="","",AA40) | AC40: =IF(AC3="","",AB40) | AD40: =IF(AD3="","",AC40) | AE40: =IF(AE3="","",AD40) | AF40: =IF(AF3="","",AE40) | AG40: =IF(AG3="","",AF40) | AH40: =IF(AH3="","",AG40) | ... AS40: =IF(AS3="","",AR40)
...

Sheet 霧島
A1: =SUM(A9,A45,A57,A69,A81,A93,A105,A117,A129,A153,A141,A165,A177,A189,A201,A213,A225,A33,A21,A237,A249) -> 1199166.7 | B1: 日付 | C1: 46100 | D1: =C1+1 -> 46101 | E1: =D1+1 -> 46102 | F1: =E1+1 -> 46103 | G1: =F1+1 -> 46104 | H1: =G1+1 -> 46105 | I1: =H1+1 -> 46106 | J1: =I1+1 -> 46107 | K1: =J1+1 -> 46108 | ... AS1: =AR1+1 -> 46142
B2: =SUM(C2:AO2) -> 7195 | C2: 0 | D2: =SUM(D10,D250,D238,D22,D34,D226,D214,D202,D190,D178,D166,D154,D142,D130,D118,,D106,D94,D82,D70,D58,D46) -> 0 | E2: =SUM(E10,E250,E238,E22,E34,E226,E214,E202,E190,E178,E166,E154,E142,E130,E118,,E106,E94,E82,E70,E58,E46) -> 0 | F2: =SUM(F10,F250,F238,F22,F34,F226,F214,F202,F190,F178,F166,F154,F142,F130,F118,,F106,F94,F82,F70,F58,F46) -> 1650 | G2: =SUM(G10,G250,G238,G22,G34,G226,G214,G202,G190,G178,G166,G154,G142,G130,G118,,G106,G94,G82,G70,G58,G46) -> 0 | H2: =SUM(H10,H250,H238,H22,H34,H226,H214,H202,H190,H178,H166,H154,H142,H130,H118,,H106,H94,H82,H70,H58,H46) -> 0 | I2: =SUM(I10,I250,I238,I22,I34,I226,I214,I202,I190,I178,I166,I154,I142,I130,I118,,I106,I94,I82,I70,I58,I46) -> 0 | J2: =SUM(J10,J250,J238,J22,J34,J226,J214,J202,J190,J178,J166,J154,J142,J130,J118,,J106,J94,J82,J70,J58,J46) -> 1221 | K2: =SUM(K10,K250,K238,K22,K34,K226,K214,K202,K190,K178,K166,K154,K142,K130,K118,,K106,K94,K82,K70,K58,K46) -> 0 | ... AS2: =SUM(AS10,AS250,AS238,AS22,AS34,AS226,AS214,AS202,AS190,AS178,AS166,AS154,AS142,AS130,AS118,,AS106,AS94,AS82,AS70,AS58,AS46) -> 0
A3: 霧島 | B3: 100円 | C3: 22554 | D3: 22554 | E3: 22554 | F3: 22584 | G3: 22584 | H3: 22584 | I3: 22584 | J3: 22644 | K3: 22644 | L3: 22644 | M3: 22699 | N3: 22699 | O3: 22699 | P3: 22699 | Q3: 22737 | R3: 22737 | S3: 22737 | T3: 22831
A4: BUZZミニ | B4: プライズ | C4: 368 | D4: =IF(D$3="","",C4) -> 368 | E4: =IF(E$3="","",D4) -> 368 | F4: 369 | G4: =IF(G$3="","",F4) -> 369 | H4: =IF(H$3="","",G4) -> 369 | I4: =IF(I$3="","",H4) -> 369 | J4: 370 | K4: =IF(K$3="","",J4) -> 370 | L4: =IF(L$3="","",K4) -> 370 | M4: 371 | N4: =IF(N$3="","",M4) -> 371 | O4: =IF(O$3="","",N4) -> 371 | P4: =IF(P$3="","",O4) -> 371 | Q4: =IF(Q$3="","",P4) -> 371 | R4: =IF(R$3="","",Q4) -> 371 | S4: =IF(S$3="","",R4) -> 371 | T4: 372 | U4: =IF(U$3="","",T4) | V4: =IF(V$3="","",U4) | W4: =IF(W$3="","",V4) | X4: =IF(X$3="","",W4) | Y4: =IF(Y$3="","",X4) | Z4: =IF(Z$3="","",Y4) | AA4: =IF(AA$3="","",Z4) | AB4: =IF(AB$3="","",AA4) | ... AS4: =IF(AS$3="","",AR4)
B5: 投入残 | C5: 29 | D5: =IF(D3="","",(C5+C6)) -> 29 | E5: =IF(E3="","",(D5+D6)) -> 29 | F5: 28 | G5: =IF(G3="","",(F5+F6)) -> 28 | H5: =IF(H3="","",(G5+G6)) -> 28 | I5: =IF(I3="","",(H5+H6)) -> 28 | J5: 27 | K5: =IF(K3="","",(J5+J6)) -> 32 | L5: =IF(L3="","",(K5+K6)) -> 32 | M5: 31 | N5: =IF(N3="","",(M5+M6)) -> 31 | O5: =IF(O3="","",(N5+N6)) -> 31 | P5: =IF(P3="","",(O5+O6)) -> 31 | Q5: =IF(Q3="","",(P5+P6)) -> 31 | R5: =IF(R3="","",(Q5+Q6)) -> 31 | S5: =IF(S3="","",(R5+R6)) -> 31 | T5: 30 | U5: =IF(U3="","",(T5+T6)) | V5: =IF(V3="","",(U5+U6)) | W5: =IF(W3="","",(V5+V6)) | X5: =IF(X3="","",(W5+W6)) | Y5: =IF(Y3="","",(X5+X6)) | Z5: =IF(Z3="","",(Y5+Y6)) | AA5: =IF(AA3="","",(Z5+Z6)) | AB5: =IF(AB3="","",(AA5+AA6)) | ... AS5: =IF(AS3="","",(AR5+AR6))
B6: 補充 | J6: 5
B7: 単価 | C7: 715 | D7: =IF(D3="","",C7) -> 715 | E7: =IF(E3="","",D7) -> 715 | F7: =IF(F3="","",E7) -> 715 | G7: =IF(G3="","",F7) -> 715 | H7: =IF(H3="","",G7) -> 715 | I7: =IF(I3="","",H7) -> 715 | J7: =IF(J3="","",I7) -> 715 | K7: =IF(K3="","",J7) -> 715 | ... AS7: =IF(AS3="","",AR7)
A8: 月間予想 | B8: 景品名 | C8: サムエル（箱無し） | D8: =IF(D3="","",C8) -> サムエル（箱無し） | E8: =IF(E3="","",D8) -> サムエル（箱無し） | F8: =IF(F3="","",E8) -> サムエル（箱無し） | G8: =IF(G3="","",F8) -> サムエル（箱無し） | H8: =IF(H3="","",G8) -> サムエル（箱無し） | I8: =IF(I3="","",H8) -> サムエル（箱無し） | J8: =IF(J3="","",I8) -> サムエル（箱無し） | K8: =IF(K3="","",J8) -> サムエル（箱無し） | ... AS8: =IF(AS3="","",AR8)
A9: =AVERAGE(C10:AS10)*30*100 -> 46166.667 | B9: 設定
A10: =SUM(C10:AS10) -> 277 | B10: 百差 | C10: 0 | D10: =IF(D3="","",D3-C3) -> 0 | E10: =IF(E3="","",E3-D3) -> 0 | F10: =IF(F3="","",F3-E3) -> 30 | G10: =IF(G3="","",G3-F3) -> 0 | H10: =IF(H3="","",H3-G3) -> 0 | I10: =IF(I3="","",I3-H3) -> 0 | J10: =IF(J3="","",J3-I3) -> 60 | K10: =IF(K3="","",K3-J3) -> 0 | ... AS10: =IF(AS3="","",AS3-AR3)
A11: =SUM(C11:AS11) -> 4 | B11: P差 | C11: 0 | D11: =IF(D4="","",D4-C4) -> 0 | E11: =IF(E4="","",E4-D4) -> 0 | F11: =IF(F4="","",F4-E4) -> 1 | G11: =IF(G4="","",G4-F4) -> 0 | H11: =IF(H4="","",H4-G4) -> 0 | I11: =IF(I4="","",I4-H4) -> 0 | J11: =IF(J4="","",J4-I4) -> 1 | K11: =IF(K4="","",K4-J4) -> 0 | ... AS11: =IF(AS4="","",AS4-AR4)
A12: =SUM(C12:AS12) -> 4 | B12: 払出 | C12: 0 | D12: =IF(D5="","",C5+C6-D5) -> 0 | E12: =IF(E5="","",D5+D6-E5) -> 0 | F12: =IF(F5="","",E5+E6-F5) -> 1 | G12: =IF(G5="","",F5+F6-G5) -> 0 | H12: =IF(H5="","",G5+G6-H5) -> 0 | I12: =IF(I5="","",H5+H6-I5) -> 0 | J12: =IF(J5="","",I5+I6-J5) -> 1 | K12: =IF(K5="","",J5+J6-K5) -> 0 | ... AS12: =IF(AS5="","",AR5+AR6-AS5)
A13: =SUM(C13:AS13) -> 2860 | B13: 払出額 | C13: 0 | D13: =IF(D3="","",D12*D7) -> 0 | E13: =IF(E3="","",E12*E7) -> 0 | F13: =IF(F3="","",F12*F7) -> 715 | G13: =IF(G3="","",G12*G7) -> 0 | H13: =IF(H3="","",H12*H7) -> 0 | I13: =IF(I3="","",I12*I7) -> 0 | J13: =IF(J3="","",J12*J7) -> 715 | K13: =IF(K3="","",K12*K7) -> 0 | ... AS13: =IF(AS3="","",AS12*AS7)
A14: =IF(A13="","",A13/(A10*100)) -> 0.1032491 | B14: 原価率 | D14: =IF(D13="","",IF(D13=0,"",D13/(D10*100))) | E14: =IF(E13="","",IF(E13=0,"",E13/(E10*100))) | F14: =IF(F13="","",IF(F13=0,"",F13/(F10*100))) -> 0.23833333 | G14: =IF(G13="","",IF(G13=0,"",G13/(G10*100))) | H14: =IF(H13="","",IF(H13=0,"",H13/(H10*100))) | I14: =IF(I13="","",IF(I13=0,"",I13/(I10*100))) | J14: =IF(J13="","",IF(J13=0,"",J13/(J10*100))) -> 0.11916667 | K14: =IF(K13="","",IF(K13=0,"",K13/(K10*100))) | ... AS14: =IF(AS13="","",IF(AS13=0,"",AS13/(AS10*100)))
A15: 霧島 | B15: 100円 | C15: 17763 | D15: =IF(D$3="","",C15) -> 17763 | E15: =IF(E$3="","",D15) -> 17763 | F15: 17810 | G15: =IF(G$3="","",F15) -> 17810 | H15: =IF(H$3="","",G15) -> 17810 | I15: =IF(I$3="","",H15) -> 17810 | J15: 17843 | K15: =IF(K$3="","",J15) -> 17843 | L15: =IF(L$3="","",K15) -> 17843 | M15: 17934 | N15: =IF(N$3="","",M15) -> 17934 | O15: =IF(O$3="","",N15) -> 17934 | P15: =IF(P$3="","",O15) -> 17934 | Q15: 17965 | R15: =IF(R$3="","",Q15) -> 17965 | S15: =IF(S$3="","",R15) -> 17965 | T15: 18046 | U15: =IF(U$3="","",T15) | V15: =IF(V$3="","",U15) | W15: =IF(W$3="","",V15) | X15: =IF(X$3="","",W15) | Y15: =IF(Y$3="","",X15) | Z15: =IF(Z$3="","",Y15) | AA15: =IF(AA$3="","",Z15) | AB15: =IF(AB$3="","",AA15) | ... AS15: =IF(AS$3="","",AR15)
A16: BUZZミニ#2 | B16: プライズ | C16: 442 | D16: =IF(D$3="","",C16) -> 442 | E16: =IF(E$3="","",D16) -> 442 | F16: 443 | G16: =IF(G$3="","",F16) -> 443 | H16: =IF(H$3="","",G16) -> 443 | I16: =IF(I$3="","",H16) -> 443 | J16: 445 | K16: =IF(K$3="","",J16) -> 445 | L16: =IF(L$3="","",K16) -> 445 | M16: 446 | N16: =IF(N$3="","",M16) -> 446 | O16: =IF(O$3="","",N16) -> 446 | P16: =IF(P$3="","",O16) -> 446 | Q16: 447 | R16: =IF(R$3="","",Q16) -> 447 | S16: =IF(S$3="","",R16) -> 447 | T16: 449 | U16: =IF(U$3="","",T16) | V16: =IF(V$3="","",U16) | W16: =IF(W$3="","",V16) | X16: =IF(X$3="","",W16) | Y16: =IF(Y$3="","",X16) | Z16: =IF(Z$3="","",Y16) | AA16: =IF(AA$3="","",Z16) | AB16: =IF(AB$3="","",AA16) | ... AS16: =IF(AS$3="","",AR16)
B17: 投入残 | C17: 34 | D17: =IF(D15="","",(C17+C18)) -> 34 | E17: =IF(E15="","",(D17+D18)) -> 34 | F17: 33 | G17: =IF(G15="","",(F17+F18)) -> 33 | H17: =IF(H15="","",(G17+G18)) -> 33 | I17: =IF(I15="","",(H17+H18)) -> 33 | J17: 32 | K17: =IF(K15="","",(J17+J18)) -> 32 | L17: =IF(L15="","",(K17+K18)) -> 32 | M17: 31 | N17: =IF(N15="","",(M17+M18)) -> 31 | O17: =IF(O15="","",(N17+N18)) -> 31 | P17: =IF(P15="","",(O17+O18)) -> 31 | Q17: 30 | R17: =IF(R15="","",(Q17+Q18)) -> 20 | S17: =IF(S15="","",(R17+R18)) -> 20 | T17: 18 | U17: =IF(U15="","",(T17+T18)) | V17: =IF(V15="","",(U17+U18)) | W17: =IF(W15="","",(V17+V18)) | X17: =IF(X15="","",(W17+W18)) | Y17: =IF(Y15="","",(X17+X18)) | Z17: =IF(Z15="","",(Y17+Y18)) | AA17: =IF(AA15="","",(Z17+Z18)) | AB17: =IF(AB15="","",(AA17+AA18)) | ... AS17: =IF(AS15="","",(AR17+AR18))
B18: 補充 | Q18: -10
B19: 単価 | C19: 700 | D19: =IF(D15="","",C19) -> 700 | E19: =IF(E15="","",D19) -> 700 | F19: =IF(F15="","",E19) -> 700 | G19: =IF(G15="","",F19) -> 700 | H19: =IF(H15="","",G19) -> 700 | I19: =IF(I15="","",H19) -> 700 | J19: =IF(J15="","",I19) -> 700 | K19: =IF(K15="","",J19) -> 700 | ... AS19: =IF(AS15="","",AR19)
A20: 月間予想 | B20: 景品名 | C20: サンリオマスコット | D20: =IF(D15="","",C20) -> サンリオマスコット | E20: =IF(E15="","",D20) -> サンリオマスコット | F20: =IF(F15="","",E20) -> サンリオマスコット | G20: =IF(G15="","",F20) -> サンリオマスコット | H20: =IF(H15="","",G20) -> サンリオマスコット | I20: =IF(I15="","",H20) -> サンリオマスコット | J20: =IF(J15="","",I20) -> サンリオマスコット | K20: =IF(K15="","",J20) -> サンリオマスコット | ... P20: =IF(P15="","",O20) -> サンリオマスコット | Q20: プクプクシール | R20: =IF(R15="","",Q20) -> プクプクシール | S20: =IF(S15="","",R20) -> プクプクシール | T20: =IF(T15="","",S20) -> プクプクシール | U20: =IF(U15="","",T20) | V20: =IF(V15="","",U20) | W20: =IF(W15="","",V20) | X20: =IF(X15="","",W20) | Y20: =IF(Y15="","",X20) | ... AS20: =IF(AS15="","",AR20)
A21: =AVERAGE(C22:AS22)*30*100 -> 47166.667 | B21: 設定
A22: =SUM(C22:AS22) -> 283 | B22: 百差 | C22: 0 | D22: =IF(D15="","",D15-C15) -> 0 | E22: =IF(E15="","",E15-D15) -> 0 | F22: =IF(F15="","",F15-E15) -> 47 | G22: =IF(G15="","",G15-F15) -> 0 | H22: =IF(H15="","",H15-G15) -> 0 | I22: =IF(I15="","",I15-H15) -> 0 | J22: =IF(J15="","",J15-I15) -> 33 | K22: =IF(K15="","",K15-J15) -> 0 | ... AS22: =IF(AS15="","",AS15-AR15)
A23: =SUM(C23:AS23) -> 7 | B23: P差 | C23: 0 | D23: =IF(D16="","",D16-C16) -> 0 | E23: =IF(E16="","",E16-D16) -> 0 | F23: =IF(F16="","",F16-E16) -> 1 | G23: =IF(G16="","",G16-F16) -> 0 | H23: =IF(H16="","",H16-G16) -> 0 | I23: =IF(I16="","",I16-H16) -> 0 | J23: =IF(J16="","",J16-I16) -> 2 | K23: =IF(K16="","",K16-J16) -> 0 | ... AS23: =IF(AS16="","",AS16-AR16)
A24: =SUM(C24:AS24) -> 6 | B24: 払出 | C24: 0 | D24: =IF(D17="","",C17+C18-D17) -> 0 | E24: =IF(E17="","",D17+D18-E17) -> 0 | F24: =IF(F17="","",E17+E18-F17) -> 1 | G24: =IF(G17="","",F17+F18-G17) -> 0 | H24: =IF(H17="","",G17+G18-H17) -> 0 | I24: =IF(I17="","",H17+H18-I17) -> 0 | J24: =IF(J17="","",I17+I18-J17) -> 1 | K24: =IF(K17="","",J17+J18-K17) -> 0 | ... AS24: =IF(AS17="","",AR17+AR18-AS17)
A25: =SUM(C25:AS25) -> 4200 | B25: 払出額 | C25: 0 | D25: =IF(D15="","",D24*D19) -> 0 | E25: =IF(E15="","",E24*E19) -> 0 | F25: =IF(F15="","",F24*F19) -> 700 | G25: =IF(G15="","",G24*G19) -> 0 | H25: =IF(H15="","",H24*H19) -> 0 | I25: =IF(I15="","",I24*I19) -> 0 | J25: =IF(J15="","",J24*J19) -> 700 | K25: =IF(K15="","",K24*K19) -> 0 | ... AS25: =IF(AS15="","",AS24*AS19)
A26: =IF(A25="","",A25/(A22*100)) -> 0.14840989 | B26: 原価率 | D26: =IF(D25="","",IF(D25=0,"",D25/(D22*100))) | E26: =IF(E25="","",IF(E25=0,"",E25/(E22*100))) | F26: =IF(F25="","",IF(F25=0,"",F25/(F22*100))) -> 0.14893617 | G26: =IF(G25="","",IF(G25=0,"",G25/(G22*100))) | H26: =IF(H25="","",IF(H25=0,"",H25/(H22*100))) | I26: =IF(I25="","",IF(I25=0,"",I25/(I22*100))) | J26: =IF(J25="","",IF(J25=0,"",J25/(J22*100))) -> 0.21212121 | K26: =IF(K25="","",IF(K25=0,"",K25/(K22*100))) | ... AS26: =IF(AS25="","",IF(AS25=0,"",AS25/(AS22*100)))
A27: 霧島 | B27: 100円 | C27: 38744 | D27: =IF(D$3="","",C27) -> 38744 | E27: =IF(E$3="","",D27) -> 38744 | F27: 38846 | G27: =IF(G$3="","",F27) -> 38846 | H27: =IF(H$3="","",G27) -> 38846 | I27: =IF(I$3="","",H27) -> 38846 | J27: 38892 | K27: =IF(K$3="","",J27) -> 38892 | L27: =IF(L$3="","",K27) -> 38892 | M27: 38999 | N27: =IF(N$3="","",M27) -> 38999 | O27: =IF(O$3="","",N27) -> 38999 | P27: =IF(P$3="","",O27) -> 38999 | Q27: 39046 | R27: =IF(R$3="","",Q27) -> 39046 | S27: =IF(S$3="","",R27) -> 39046 | T27: 39134 | U27: =IF(U$3="","",T27) | V27: =IF(V$3="","",U27) | W27: =IF(W$3="","",V27) | X27: =IF(X$3="","",W27) | Y27: =IF(Y$3="","",X27) | Z27: =IF(Z$3="","",Y27) | AA27: =IF(AA$3="","",Z27) | AB27: =IF(AB$3="","",AA27) | ... AS27: =IF(AS$3="","",AR27)
A28: クリスタル | B28: プライズ | C28: 1011 | D28: =IF(D$3="","",C28) -> 1011 | E28: =IF(E$3="","",D28) -> 1011 | F28: 1016 | G28: =IF(G$3="","",F28) -> 1016 | H28: =IF(H$3="","",G28) -> 1016 | I28: =IF(I$3="","",H28) -> 1016 | J28: 1017 | K28: =IF(K$3="","",J28) -> 1017 | L28: =IF(L$3="","",K28) -> 1017 | M28: 1021 | N28: =IF(N$3="","",M28) -> 1021 | O28: =IF(O$3="","",N28) -> 1021 | P28: =IF(P$3="","",O28) -> 1021 | Q28: 1023 | R28: =IF(R$3="","",Q28) -> 1023 | S28: =IF(S$3="","",R28) -> 1023 | T28: 1024 | U28: =IF(U$3="","",T28) | V28: =IF(V$3="","",U28) | W28: =IF(W$3="","",V28) | X28: =IF(X$3="","",W28) | Y28: =IF(Y$3="","",X28) | Z28: =IF(Z$3="","",Y28) | AA28: =IF(AA$3="","",Z28) | AB28: =IF(AB$3="","",AA28) | ... AS28: =IF(AS$3="","",AR28)
B29: 投入残 | C29: 25 | D29: =IF(D27="","",(C29+C30)) -> 25 | E29: =IF(E27="","",(D29+D30)) -> 25 | F29: 21 | G29: =IF(G27="","",(F29+F30)) -> 21 | H29: =IF(H27="","",(G29+G30)) -> 21 | I29: =IF(I27="","",(H29+H30)) -> 21 | J29: 20 | K29: =IF(K27="","",(J29+J30)) -> 25 | L29: =IF(L27="","",(K29+K30)) -> 25 | M29: 22 | N29: =IF(N27="","",(M29+M30)) -> 22 | O29: =IF(O27="","",(N29+N30)) -> 22 | P29: =IF(P27="","",(O29+O30)) -> 22 | Q29: 20 | R29: =IF(R27="","",(Q29+Q30)) -> 30 | S29: =IF(S27="","",(R29+R30)) -> 30 | T29: =IF(T27="","",(S29+S30)) -> 30 | U29: =IF(U27="","",(T29+T30)) | V29: =IF(V27="","",(U29+U30)) | W29: =IF(W27="","",(V29+V30)) | X29: =IF(X27="","",(W29+W30)) | Y29: =IF(Y27="","",(X29+X30)) | ... AS29: =IF(AS27="","",(AR29+AR30))
B30: 補充 | J30: 5 | Q30: 10
B31: 単価 | C31: 400 | D31: =IF(D27="","",C31) -> 400 | E31: =IF(E27="","",D31) -> 400 | F31: =IF(F27="","",E31) -> 400 | G31: =IF(G27="","",F31) -> 400 | H31: =IF(H27="","",G31) -> 400 | I31: =IF(I27="","",H31) -> 400 | J31: =IF(J27="","",I31) -> 400 | K31: =IF(K27="","",J31) -> 400 | ... AS31: =IF(AS27="","",AR31)
A32: 月間予想 | B32: 景品名 | C32: サムエル（箱無し） | D32: =IF(D27="","",C32) -> サムエル（箱無し） | E32: =IF(E27="","",D32) -> サムエル（箱無し） | F32: =IF(F27="","",E32) -> サムエル（箱無し） | G32: =IF(G27="","",F32) -> サムエル（箱無し） | H32: =IF(H27="","",G32) -> サムエル（箱無し） | I32: =IF(I27="","",H32) -> サムエル（箱無し） | J32: =IF(J27="","",I32) -> サムエル（箱無し） | K32: =IF(K27="","",J32) -> サムエル（箱無し） | ... AS32: =IF(AS27="","",AR32)
A33: =AVERAGE(C34:AS34)*30*100 -> 65000 | B33: 設定
A34: =SUM(C34:AS34) -> 390 | B34: 百差 | C34: 0 | D34: =IF(D27="","",D27-C27) -> 0 | E34: =IF(E27="","",E27-D27) -> 0 | F34: =IF(F27="","",F27-E27) -> 102 | G34: =IF(G27="","",G27-F27) -> 0 | H34: =IF(H27="","",H27-G27) -> 0 | I34: =IF(I27="","",I27-H27) -> 0 | J34: =IF(J27="","",J27-I27) -> 46 | K34: =IF(K27="","",K27-J27) -> 0 | ... AS34: =IF(AS27="","",AS27-AR27)
A35: =SUM(C35:AS35) -> 13 | B35: P差 | C35: 0 | D35: =IF(D28="","",D28-C28) -> 0 | E35: =IF(E28="","",E28-D28) -> 0 | F35: =IF(F28="","",F28-E28) -> 5 | G35: =IF(G28="","",G28-F28) -> 0 | H35: =IF(H28="","",H28-G28) -> 0 | I35: =IF(I28="","",I28-H28) -> 0 | J35: =IF(J28="","",J28-I28) -> 1 | K35: =IF(K28="","",K28-J28) -> 0 | ... AS35: =IF(AS28="","",AS28-AR28)
A36: =SUM(C36:AS36) -> 10 | B36: 払出 | C36: 0 | D36: =IF(D29="","",C29+C30-D29) -> 0 | E36: =IF(E29="","",D29+D30-E29) -> 0 | F36: =IF(F29="","",E29+E30-F29) -> 4 | G36: =IF(G29="","",F29+F30-G29) -> 0 | H36: =IF(H29="","",G29+G30-H29) -> 0 | I36: =IF(I29="","",H29+H30-I29) -> 0 | J36: =IF(J29="","",I29+I30-J29) -> 1 | K36: =IF(K29="","",J29+J30-K29) -> 0 | ... AS36: =IF(AS29="","",AR29+AR30-AS29)
A37: =SUM(C37:AS37) -> 4000 | B37: 払出額 | C37: 0 | D37: =IF(D27="","",D36*D31) -> 0 | E37: =IF(E27="","",E36*E31) -> 0 | F37: =IF(F27="","",F36*F31) -> 1600 | G37: =IF(G27="","",G36*G31) -> 0 | H37: =IF(H27="","",H36*H31) -> 0 | I37: =IF(I27="","",I36*I31) -> 0 | J37: =IF(J27="","",J36*J31) -> 400 | K37: =IF(K27="","",K36*K31) -> 0 | ... AS37: =IF(AS27="","",AS36*AS31)
A38: =IF(A37="","",A37/(A34*100)) -> 0.1025641 | B38: 原価率 | D38: =IF(D37="","",IF(D37=0,"",D37/(D34*100))) | E38: =IF(E37="","",IF(E37=0,"",E37/(E34*100))) | F38: =IF(F37="","",IF(F37=0,"",F37/(F34*100))) -> 0.15686275 | G38: =IF(G37="","",IF(G37=0,"",G37/(G34*100))) | H38: =IF(H37="","",IF(H37=0,"",H37/(H34*100))) | I38: =IF(I37="","",IF(I37=0,"",I37/(I34*100))) | J38: =IF(J37="","",IF(J37=0,"",J37/(J34*100))) -> 0.086956522 | K38: =IF(K37="","",IF(K37=0,"",K37/(K34*100))) | ... AS38: =IF(AS37="","",IF(AS37=0,"",AS37/(AS34*100)))
A39: 霧島 | B39: 100円 | C39: 14168 | D39: =IF(D$3="","",C39) -> 14168 | E39: =IF(E$3="","",D39) -> 14168 | F39: 14224 | G39: =IF(G$3="","",F39) -> 14224 | H39: =IF(H$3="","",G39) -> 14224 | I39: =IF(I$3="","",H39) -> 14224 | J39: 14274 | K39: =IF(K$3="","",J39) -> 14274 | L39: =IF(L$3="","",K39) -> 14274 | M39: 14323 | N39: =IF(N$3="","",M39) -> 14323 | O39: =IF(O$3="","",N39) -> 14323 | P39: =IF(P$3="","",O39) -> 14323 | Q39: 14376 | R39: =IF(R$3="","",Q39) -> 14376 | S39: =IF(S$3="","",R39) -> 14376 | T39: 14421 | U39: =IF(U$3="","",T39) | V39: =IF(V$3="","",U39) | W39: =IF(W$3="","",V39) | X39: =IF(X$3="","",W39) | Y39: =IF(Y$3="","",X39) | Z39: =IF(Z$3="","",Y39) | AA39: =IF(AA$3="","",Z39) | AB39: =IF(AB$3="","",AA39) | ... AS39: =IF(AS$3="","",AR39)
A40: BUZZ＃１ | B40: プライズ | C40: 333 | D40: =IF(D$3="","",C40) -> 333 | E40: =IF(E$3="","",D40) -> 333 | F40: 334 | G40: =IF(G$3="","",F40) -> 334 | H40: =IF(H$3="","",G40) -> 334 | I40: =IF(I$3="","",H40) -> 334 | J40: =IF(J$3="","",I40) -> 334 | K40: =IF(K$3="","",J40) -> 334 | L40: =IF(L$3="","",K40) -> 334 | M40: =IF(M$3="","",L40) -> 334 | N40: =IF(N$3="","",M40) -> 334 | ... P40: =IF(P$3="","",O40) -> 334 | Q40: 335 | R40: =IF(R$3="","",Q40) -> 335 | S40: =IF(S$3="","",R40) -> 335 | T40: =IF(T$3="","",S40) -> 335 | U40: =IF(U$3="","",T40) | V40: =IF(V$3="","",U40) | W40: =IF(W$3="","",V40) | X40: =IF(X$3="","",W40) | Y40: =IF(Y$3="","",X40) | ... AS40: =IF(AS$3="","",AR40)
...

Sheet 宇宿
A1: =SUM(A9,A45,A57,A69,A81,A93,A105,A117,A129,A153,A141,A165,A177,A189,A201,A213,A225,A33,A21,A237,A249) -> 1122000 | B1: 日付 | C1: 46099 | D1: =C1+1 -> 46100 | E1: =D1+1 -> 46101 | F1: =E1+1 -> 46102 | G1: =F1+1 -> 46103 | H1: =G1+1 -> 46104 | I1: =H1+1 -> 46105 | J1: =I1+1 -> 46106 | K1: =J1+1 -> 46107 | ... AS1: =AR1+1 -> 46141
B2: =SUM(C2:AO2) -> 7321 | C2: 0 | D2: =SUM(D10,D22,D34,D46,D58,D70,D82,D94,D106,D118,D130,D142,D154,D166,D178,D190,D202,D214,D226,D240) -> 0 | E2: =SUM(E10,E22,E34,E46,E58,E70,E82,E94,E106,E118,E130,E142,E154,E166,E178,E190,E202,E214,E226,E240) -> 1179 | F2: =SUM(F10,F22,F34,F46,F58,F70,F82,F94,F106,F118,F130,F142,F154,F166,F178,F190,F202,F214,F226,F240) -> 0 | G2: =SUM(G10,G22,G34,G46,G58,G70,G82,G94,G106,G118,G130,G142,G154,G166,G178,G190,G202,G214,G226,G240) -> 0 | H2: =SUM(H10,H22,H34,H46,H58,H70,H82,H94,H106,H118,H130,H142,H154,H166,H178,H190,H202,H214,H226,H240) -> 1147 | I2: =SUM(I10,I22,I34,I46,I58,I70,I82,I94,I106,I118,I130,I142,I154,I166,I178,I190,I202,I214,I226,I240) -> 0 | J2: =SUM(J10,J22,J34,J46,J58,J70,J82,J94,J106,J118,J130,J142,J154,J166,J178,J190,J202,J214,J226,J240) -> 0 | K2: =SUM(K10,K22,K34,K46,K58,K70,K82,K94,K106,K118,K130,K142,K154,K166,K178,K190,K202,K214,K226,K240) -> 0 | ... AS2: =SUM(AS10,AS22,AS34,AS46,AS58,AS70,AS82,AS94,AS106,AS118,AS130,AS142,AS154,AS166,AS178,AS190,AS202,AS214,AS226,AS240) -> 0
A3: 宇宿 | B3: 100円 | C3: 16252 | D3: 16252 | E3: 16328 | F3: 16328 | G3: 16328 | H3: 16390 | I3: 16390 | J3: 16390 | K3: 16390 | L3: 16444 | M3: 16444 | N3: 16444 | O3: 16489 | P3: 16489 | Q3: 16489 | R3: 16489 | S3: 16489 | T3: 16578 | U3: 16578 | V3: 16578 | W3: 16633
A4: BUZZ＃１ | B4: プライズ | C4: 420 | D4: =IF(D$3="","",C4) -> 420 | E4: 421 | F4: =IF(F$3="","",E4) -> 421 | G4: =IF(G$3="","",F4) -> 421 | H4: 422 | I4: =IF(I$3="","",H4) -> 422 | J4: =IF(J$3="","",I4) -> 422 | K4: =IF(K$3="","",J4) -> 422 | L4: 423 | M4: =IF(M$3="","",L4) -> 423 | N4: =IF(N$3="","",M4) -> 423 | O4: 424 | P4: =IF(P$3="","",O4) -> 424 | Q4: =IF(Q$3="","",P4) -> 424 | R4: =IF(R$3="","",Q4) -> 424 | S4: =IF(S$3="","",R4) -> 424 | T4: 425 | U4: =IF(U$3="","",T4) -> 425 | V4: =IF(V$3="","",U4) -> 425 | W4: 426 | X4: =IF(X$3="","",W4) | Y4: =IF(Y$3="","",X4) | Z4: =IF(Z$3="","",Y4) | AA4: =IF(AA$3="","",Z4) | AB4: =IF(AB$3="","",AA4) | AC4: =IF(AC$3="","",AB4) | AD4: =IF(AD$3="","",AC4) | AE4: =IF(AE$3="","",AD4) | ... AS4: =IF(AS$3="","",AR4)
A5: 1 | B5: 投入残 | C5: 6 | D5: =IF(D3="","",(C5+C6)) -> 6 | E5: 5 | F5: =IF(F3="","",(E5+E6)) -> 5 | G5: =IF(G3="","",(F5+F6)) -> 5 | H5: 4 | I5: =IF(I3="","",(H5+H6)) -> 4 | J5: =IF(J3="","",(I5+I6)) -> 4 | K5: =IF(K3="","",(J5+J6)) -> 4 | L5: 2 | M5: =IF(M3="","",(L5+L6)) -> 2 | N5: =IF(N3="","",(M5+M6)) -> 2 | O5: =IF(O3="","",(N5+N6)) -> 2 | P5: =IF(P3="","",(O5+O6)) -> 4 | Q5: =IF(Q3="","",(P5+P6)) -> 4 | R5: =IF(R3="","",(Q5+Q6)) -> 4 | S5: =IF(S3="","",(R5+R6)) -> 4 | T5: 3 | U5: =IF(U3="","",(T5+T6)) -> 3 | V5: =IF(V3="","",(U5+U6)) -> 3 | W5: 2 | X5: =IF(X3="","",(W5+W6)) | Y5: =IF(Y3="","",(X5+X6)) | Z5: =IF(Z3="","",(Y5+Y6)) | AA5: =IF(AA3="","",(Z5+Z6)) | AB5: =IF(AB3="","",(AA5+AA6)) | AC5: =IF(AC3="","",(AB5+AB6)) | AD5: =IF(AD3="","",(AC5+AC6)) | AE5: =IF(AE3="","",(AD5+AD6)) | ... AS5: =IF(AS3="","",(AR5+AR6))
A6: 機械合計 | B6: 補充 | O6: 2 | W6: 1
A7: =+(A10+A22+A34+A46)*100 -> 105100 | B7: 単価 | C7: 500 | D7: =IF(D3="","",C7) -> 500 | E7: =IF(E3="","",D7) -> 500 | F7: =IF(F3="","",E7) -> 500 | G7: =IF(G3="","",F7) -> 500 | H7: =IF(H3="","",G7) -> 500 | I7: =IF(I3="","",H7) -> 500 | J7: =IF(J3="","",I7) -> 500 | K7: =IF(K3="","",J7) -> 500 | ... AS7: =IF(AS3="","",AR7)
A8: 月間予想 | B8: 景品名 | C8: たまごっちマスコット | D8: =IF(D3="","",C8) -> たまごっちマスコット | E8: =IF(E3="","",D8) -> たまごっちマスコット | F8: =IF(F3="","",E8) -> たまごっちマスコット | G8: =IF(G3="","",F8) -> たまごっちマスコット | H8: =IF(H3="","",G8) -> たまごっちマスコット | I8: =IF(I3="","",H8) -> たまごっちマスコット | J8: =IF(J3="","",I8) -> たまごっちマスコット | K8: =IF(K3="","",J8) -> たまごっちマスコット | L8: バタースクイーズ | M8: =IF(M3="","",L8) -> バタースクイーズ | N8: =IF(N3="","",M8) -> バタースクイーズ | O8: =IF(O3="","",N8) -> バタースクイーズ | P8: =IF(P3="","",O8) -> バタースクイーズ | Q8: =IF(Q3="","",P8) -> バタースクイーズ | R8: =IF(R3="","",Q8) -> バタースクイーズ | S8: =IF(S3="","",R8) -> バタースクイーズ | T8: =IF(T3="","",S8) -> バタースクイーズ | ... AS8: =IF(AS3="","",AR8)
A9: =AVERAGE(C10:AS10)*30*100 -> 54428.571 | B9: 設定
A10: =SUM(C10:AS10) -> 381 | B10: 百差 | C10: 0 | D10: =IF(D3="","",D3-C3) -> 0 | E10: =IF(E3="","",E3-D3) -> 76 | F10: =IF(F3="","",F3-E3) -> 0 | G10: =IF(G3="","",G3-F3) -> 0 | H10: =IF(H3="","",H3-G3) -> 62 | I10: =IF(I3="","",I3-H3) -> 0 | J10: =IF(J3="","",J3-I3) -> 0 | K10: =IF(K3="","",K3-J3) -> 0 | ... AS10: =IF(AS3="","",AS3-AR3)
A11: =SUM(C11:AS11) -> 6 | B11: P差 | C11: 0 | D11: =IF(D4="","",D4-C4) -> 0 | E11: =IF(E4="","",E4-D4) -> 1 | F11: =IF(F4="","",F4-E4) -> 0 | G11: =IF(G4="","",G4-F4) -> 0 | H11: =IF(H4="","",H4-G4) -> 1 | I11: =IF(I4="","",I4-H4) -> 0 | J11: =IF(J4="","",J4-I4) -> 0 | K11: =IF(K4="","",K4-J4) -> 0 | ... AS11: =IF(AS4="","",AS4-AR4)
A12: =SUM(C12:AS12) -> 6 | B12: 払出 | C12: 0 | D12: =IF(D5="","",C5+C6-D5) -> 0 | E12: =IF(E5="","",D5+D6-E5) -> 1 | F12: =IF(F5="","",E5+E6-F5) -> 0 | G12: =IF(G5="","",F5+F6-G5) -> 0 | H12: =IF(H5="","",G5+G6-H5) -> 1 | I12: =IF(I5="","",H5+H6-I5) -> 0 | J12: =IF(J5="","",I5+I6-J5) -> 0 | K12: =IF(K5="","",J5+J6-K5) -> 0 | ... AS12: =IF(AS5="","",AR5+AR6-AS5)
A13: =SUM(C13:AS13) -> 3000 | B13: 払出額 | C13: 0 | D13: =IF(D3="","",D12*D7) -> 0 | E13: =IF(E3="","",E12*E7) -> 500 | F13: =IF(F3="","",F12*F7) -> 0 | G13: =IF(G3="","",G12*G7) -> 0 | H13: =IF(H3="","",H12*H7) -> 500 | I13: =IF(I3="","",I12*I7) -> 0 | J13: =IF(J3="","",J12*J7) -> 0 | K13: =IF(K3="","",K12*K7) -> 0 | ... AS13: =IF(AS3="","",AS12*AS7)
