Workbook

Sheet 本田
A1: 46081
A2: 店舗 | B2: 機械名 | C2: 景品名 | D2: 単価 | E2: 在庫数 | H2: 金額
E3: 倉庫① | F3: 倉庫② | G3: 機械内
E4: =SUM(E5:E275) -> 0 | F4: =SUM(F5:F275) -> 0 | G4: =SUM(G5:G275) -> 1846 | H4: =SUM(H5:H275) -> 1800520
A5: 合志 | B5: ガチャコロ２ | C5: スイッチ2本体 | D5: 49980 | G5: 1 | H5: =D5*(E5+F5+G5) -> 49980
C6: スイッチ本体 | D6: 39800 | G6: 1 | H6: =D6*(E6+F6+G6) -> 39800
C7: instax | D7: 19800 | G7: 1 | H7: =D7*(E7+F7+G7) -> 19800
C8: fire11max | D8: 39800 | G8: 1 | H8: =D8*(E8+F8+G8) -> 39800
C9: NIKEスニーカー | D9: 20000 | G9: 1 | H9: =D9*(E9+F9+G9) -> 20000
C10: A景品 | D10: 1100 | G10: 4 | H10: =D10*(E10+F10+G10) -> 4400
H11: =D11*(E11+F11+G11) -> 0
C12: スイッチ本体 | D12: 39800 | G12: 1 | H12: =D12*(E12+F12+G12) -> 39800
C13: ポケモンカードBOX | D13: 5800 | G13: 6 | H13: =D13*(E13+F13+G13) -> 34800
C14: イーブイ | D14: 50000 | G14: 1 | H14: =D14*(E14+F14+G14) -> 50000
H15: =D15*(E15+F15+G15) -> 0
C16: カプセル2000 | D16: 450 | G16: 150 | H16: =D16*(E16+F16+G16) -> 67500
C17: カプセル2000ポケ | D17: 450 | G17: 150 | H17: =D17*(E17+F17+G17) -> 67500
H18: =D18*(E18+F18+G18) -> 0
H19: =D19*(E19+F19+G19) -> 0
H20: =D20*(E20+F20+G20) -> 0
B21: 500GATCHA | C21: ボンドロ | D21: 1500 | G21: 7 | H21: =D21*(E21+F21+G21) -> 10500
H22: =D22*(E22+F22+G22) -> 0
H23: =D23*(E23+F23+G23) -> 0
C24: A景品 | D24: 1100 | G24: 6 | H24: =D24*(E24+F24+G24) -> 6600
H25: =D25*(E25+F25+G25) -> 0
C26: カプセル500 | D26: 50 | G26: 200 | H26: =D26*(E26+F26+G26) -> 10000
H27: =D27*(E27+F27+G27) -> 0
B28: BUZZ | C28: サンリオキーケース | D28: 750 | G28: 4 | H28: =D28*(E28+F28+G28) -> 3000
C29: サンリオバンズクリップ | D29: 800 | G29: 5 | H29: =D29*(E29+F29+G29) -> 4000
C30: ラブブMC | D30: 400 | G30: 5 | H30: =D30*(E30+F30+G30) -> 2000
C31: 海外シール | D31: 200 | G31: 10 | H31: =D31*(E31+F31+G31) -> 2000
C32: モンチッチMC | D32: 800 | G32: 4 | H32: =D32*(E32+F32+G32) -> 3200
C33: ギャルキティMC | D33: 850 | G33: 7 | H33: =D33*(E33+F33+G33) -> 5950
C34: しば犬たまご | D34: 60 | G34: 9 | H34: =D34*(E34+F34+G34) -> 540
C35: たまごっちMC | D35: 820 | G35: 7 | H35: =D35*(E35+F35+G35) -> 5740
C36: ボンドロ | D36: 1500 | G36: 20 | H36: =D36*(E36+F36+G36) -> 30000
C37: じゃがりこ財布 | D37: 759 | G37: 20 | H37: =D37*(E37+F37+G37) -> 15180
C38: サンリオホワイト | D38: 450 | G38: 50 | H38: =D38*(E38+F38+G38) -> 22500
C39: ファー | D39: 84 | G39: 100 | H39: =D39*(E39+F39+G39) -> 8400
C40: ジョージKH | D40: 319 | G40: 10 | H40: =D40*(E40+F40+G40) -> 3190
...

Sheet 吉井
A1: 46081
A2: 店舗 | B2: 機械名 | C2: 景品名 | D2: 単価 | E2: 在庫数 | H2: 金額
E3: 倉庫① | F3: 倉庫② | G3: 機械内
H4: =SUM(H5:H121) -> 2713894
A5: 鞍手 | B5: ガチャコロ2 | C5: A景品 | D5: 1050 | G5: 2 | H5: =D5*(E5+F5+G5) -> 2100
B6: ガチャコロ2 | C6: 1000円カプセル景品 | D6: 150 | G6: 142 | H6: =D6*(E6+F6+G6) -> 21300
B7: ガチャコロ2 | C7: 2000円カプセル景品 | D7: 450 | G7: 132 | H7: =D7*(E7+F7+G7) -> 59400
B8: ガチャコロ2 | C8: ｐｓ5デジタル | D8: 60000 | G8: 1 | H8: =D8*(E8+F8+G8) -> 60000
B9: ガチャコロ2 | C9: スイッチ本体 | D9: 38000 | G9: 1 | H9: =D9*(E9+F9+G9) -> 38000
B10: ガチャコロ2 | C10: リファシャワー | D10: 35000 | G10: 1 | H10: =D10*(E10+F10+G10) -> 35000
B11: ガチャコロ2 | C11: エアポッツ | D11: 35090 | G11: 1 | H11: =D11*(E11+F11+G11) -> 35090
B12: ガチャコロ2 | C12: ＮＩＫＥスニーカー | D12: 21600 | G12: 1 | H12: =D12*(E12+F12+G12) -> 21600
B13: ガチャコロ2 | C13: PSポータルリモート | D13: 31498 | G13: 1 | H13: =D13*(E13+F13+G13) -> 31498
B14: ガチャコロ2 | C14: ボンボンシール | D14: 3500 | G14: 4 | H14: =D14*(E14+F14+G14) -> 14000
B15: ガチャコロ2 | C15: ポケカプレ値 | D15: 12000 | G15: 3 | H15: =D15*(E15+F15+G15) -> 36000
B16: ガチャコロ2 | C16: ラブブ小 | D16: 2400 | G16: 3 | H16: =D16*(E16+F16+G16) -> 7200
B17: ガチャコロ2 | C17: スイッチライト本体 | D17: 21970 | G17: 1 | H17: =D17*(E17+F17+G17) -> 21970
... B19: ガチャコロ2 | C19: 加湿器 | D19: 5980 | G19: 1 | H19: =D19*(E19+F19+G19) -> 5980
H20: =D20*(E20+F20+G20) -> 0
A21: 宗像 | B21: ガチャコロ | C21: A景品 | D21: 1050 | G21: 10 | H21: =D21*(E21+F21+G21) -> 10500
B22: ガチャコロ | C22: 2000円カプセル景品 | D22: 450 | G22: 233 | H22: =D22*(E22+F22+G22) -> 104850
B23: ガチャコロ | C23: ｐｓ5デジタル | D23: 60000 | G23: 1 | H23: =D23*(E23+F23+G23) -> 60000
B24: ガチャコロ | C24: スイッチ本体 | D24: 38000 | G24: 1 | H24: =D24*(E24+F24+G24) -> 38000
B25: ガチャコロ | C25: PSポータルリモート | D25: 31498 | G25: 1 | H25: =D25*(E25+F25+G25) -> 31498
B26: ガチャコロ | C26: スイッチソフト | D26: 5600 | G26: 1 | H26: =D26*(E26+F26+G26) -> 5600
B27: ガチャコロ | C27: ボンボンシール | D27: 3500 | G27: 12 | H27: =D27*(E27+F27+G27) -> 42000
B28: ガチャコロ | C28: ポケカプレ値 | D28: 12000 | G28: 2 | H28: =D28*(E28+F28+G28) -> 24000
B29: ガチャコロ | C29: スイッチライト本体 | D29: 21970 | G29: 1 | H29: =D29*(E29+F29+G29) -> 21970
B30: ガチャコロ | C30: ラブブ小 | D30: 2400 | G30: 4 | H30: =D30*(E30+F30+G30) -> 9600
B31: ガチャコロ | C31: ラブブ | D31: 3500 | G31: 4 | H31: =D31*(E31+F31+G31) -> 14000
B32: 500GATCHA | C32: 500円カプセル景品 | D32: 100 | G32: 168 | H32: =D32*(E32+F32+G32) -> 16800
B33: 500GATCHA | C33: スイッチソフト | D33: 5600 | G33: 2 | H33: =D33*(E33+F33+G33) -> 11200
... B36: 500GATCHA | C36: A景品 | D36: 1050 | G36: 10 | H36: =D36*(E36+F36+G36) -> 10500
H37: =D37*(E37+F37+G37) -> 0
A38: 長府 | B38: 1000GATCHA | C38: 1000円カプセル景品 | D38: 150 | G38: 236 | H38: =D38*(E38+F38+G38) -> 35400
B39: 1000GATCHA | C39: A景品 | D39: 1050 | G39: 3 | H39: =D39*(E39+F39+G39) -> 3150
B40: 1000GATCHA | C40: スイッチライト本体 | D40: 21970 | G40: 1 | H40: =D40*(E40+F40+G40) -> 21970
B41: 1000GATCHA | C41: ボンボンシール | D41: 3500 | G41: 6 | H41: =D41*(E41+F41+G41) -> 21000
B42: 1000GATCHA | C42: ラブブ | D42: 4000 | G42: 2 | H42: =D42*(E42+F42+G42) -> 8000
B43: 1000GATCHA | C43: スイッチソフト | D43: 5600 | G43: 1 | H43: =D43*(E43+F43+G43) -> 5600
...

Sheet 中島
A1: 46053 | J1: 46081 | S1: 46112
A2: 店舗 | B2: 景品名 | C2: 機械名 | D2: 単価 | E2: 在庫数 | H2: 金額 | J2: 店舗 | K2: 景品名 | L2: 機械名 | M2: 単価 | N2: 在庫数 | Q2: 金額 | S2: 店舗 | T2: 景品名 | U2: 機械名 | V2: 単価 | W2: 在庫数 | Z2: 金額
E3: 手持ち | F3: 倉庫② | G3: 機械内 | N3: 手持ち | O3: 倉庫② | P3: 機械内 | W3: 手持ち | X3: 倉庫② | Y3: 機械内
H4: 952171 | Q4: =SUM(Q5:Q77) -> 1266633 | Z4: =SUM(Z5:Z70) -> 1137158
A5: 八女店 | B5: PS5 | C5: ガチャコロ（2000） | D5: 70000 | G5: 1 | H5: 70000 | J5: ドンキ八女店 | K5: PS5 | L5: ガチャコロ（2000） | M5: 70000 | P5: 1 | Q5: =(N5+O5+P5)*M5 -> 70000 | S5: ドンキ八女店 | T5: PS5 | U5: ガチャコロ（2000） | V5: 70000 | Y5: 1 | Z5: =(W5+X5+Y5)*V5 -> 70000
B6: DWリング | C6: ガチャコロ（2000） | D6: 10000 | G6: 0 | H6: 0 | K6: DWリング | L6: ガチャコロ（2000） | M6: 10000 | O6: 1 | Q6: =(N6+O6+P6)*M6 -> 10000 | T6: ニューモ | U6: ガチャコロ（2000） | V6: 7306 | Y6: 1 | Z6: =(W6+X6+Y6)*V6 -> 7306
B7: UGGブーツ | C7: ガチャコロ（2000） | D7: 20000 | F7: 1 | G7: 0 | H7: 20000 | K7: UGGブーツ | L7: ガチャコロ（2000） | M7: 20000 | Q7: =(N7+O7+P7)*M7 -> 0 | T7: アディダス中国限定トラックジャケット | U7: ガチャコロ（2000） | V7: 14000 | Y7: 1 | Z7: =(W7+X7+Y7)*V7 -> 14000
B8: ラブブBOX | C8: ガチャコロ（2000） | D8: 25000 | H8: 0 | K8: ラブブBOX | L8: ガチャコロ（2000） | M8: 25000 | P8: 1 | Q8: =(N8+O8+P8)*M8 -> 25000 | T8: サクセス | U8: ガチャコロ（2000） | V8: 5000 | Y8: 1 | Z8: =(W8+X8+Y8)*V8 -> 5000
B9: ポケカ（東北） | C9: ガチャコロ（2000） | D9: 25800 | G9: 1 | H9: 25800 | K9: ポケカ（東北） | L9: ガチャコロ（2000） | M9: 25800 | P9: 1 | Q9: =(N9+O9+P9)*M9 -> 25800 | T9: DISM 美顔器 | U9: ガチャコロ（2000） | V9: 30624 | Y9: 1 | Z9: =(W9+X9+Y9)*V9 -> 30624
B10: スイッチ本体 | C10: ガチャコロ（2000） | D10: 40000 | F10: 1 | H10: 40000 | K10: スイッチ本体 | L10: ガチャコロ（2000） | M10: 40000 | O10: 1 | Q10: =(N10+O10+P10)*M10 -> 40000 | T10: リファギフトセット | U10: ガチャコロ（2000） | V10: 9790 | Y10: 1 | Z10: =(W10+X10+Y10)*V10 -> 9790
B11: 2000円カプセル景品 | C11: ガチャコロ（2000） | D11: 450 | E11: 33 | G11: 200 | H11: 104850 | K11: 2000円カプセル景品 | L11: ガチャコロ（2000） | M11: 450 | N11: 33 | P11: 200 | Q11: =(N11+O11+P11)*M11 -> 104850 | T11: SK2 | U11: ガチャコロ（2000） | V11: 13970 | Y11: 1 | Z11: =(W11+X11+Y11)*V11 -> 13970
B12: スニーカー | C12: ガチャコロ（2000） | D12: 20000 | G12: 2 | H12: 40000 | K12: スニーカー | L12: ガチャコロ（2000） | M12: 20000 | O12: 1 | P12: 1 | Q12: =(N12+O12+P12)*M12 -> 40000 | T12: ラブブBOX | U12: ガチャコロ（2000） | V12: 25000 | Y12: 1 | Z12: =(W12+X12+Y12)*V12 -> 25000
B13: ポケカBOX | C13: ガチャコロ（2000） | D13: 10000 | H13: 0 | K13: スイッチ2 ソフト | L13: ガチャコロ（2000） | M13: 8000 | P13: 2 | Q13: =(N13+O13+P13)*M13 -> 16000 | T13: ポケカ（東北） | U13: ガチャコロ（2000） | V13: 25800 | Y13: 1 | Z13: =(W13+X13+Y13)*V13 -> 25800
B14: ナイキテックセット | C14: ガチャコロ（2000） | D14: 22000 | G14: 1 | H14: 22000 | K14: ナイキテックセット | L14: ガチャコロ（2000） | M14: 22000 | P14: 1 | Q14: =(N14+O14+P14)*M14 -> 22000 | T14: ディオールマキシマイザー | U14: ガチャコロ（2000） | V14: 4000 | Y14: 1 | Z14: =(W14+X14+Y14)*V14 -> 4000
B15: 9090リング | C15: ガチャコロ（2000） | D15: 4900 | G15: 1 | H15: 4900 | K15: 9090リング | L15: ガチャコロ（2000） | M15: 4900 | P15: 1 | Q15: =(N15+O15+P15)*M15 -> 4900 | T15: 2000円カプセル景品 | U15: ガチャコロ（2000） | V15: 450 | W15: 33 | Y15: 200 | Z15: =(W15+X15+Y15)*V15 -> 104850
B16: ラブブコーラBOX | C16: ガチャコロ（2000） | D16: 26989 | G16: 1 | H16: 26989 | K16: ラブブコーラBOX | L16: ガチャコロ（2000） | M16: 26989 | P16: 1 | Q16: =(N16+O16+P16)*M16 -> 26989 | T16: スニーカー | U16: ガチャコロ（2000） | V16: 20000 | X16: 1 | Y16: 1 | Z16: =(W16+X16+Y16)*V16 -> 40000
C17: ガチャコロ（1000） | D17: 11892 | H17: 0 | K17: ボンボンドロップシール | L17: ガチャコロ（2000） | M17: 2000 | P17: 4 | Q17: =(N17+O17+P17)*M17 -> 8000 | T17: スイッチ2 ソフト | U17: ガチャコロ（2000） | V17: 8000 | Y17: 2 | Z17: =(W17+X17+Y17)*V17 -> 16000
B18: ラブブ | C18: ガチャコロ（2000） | D18: 2500 | G18: 3 | H18: 7500 | K18: ラブブ | L18: ガチャコロ（2000） | M18: 2500 | P18: 3 | Q18: =(N18+O18+P18)*M18 -> 7500 | T18: ナイキテックセット | U18: ガチャコロ（2000） | V18: 22000 | Y18: 1 | Z18: =(W18+X18+Y18)*V18 -> 22000
B19: adidas グランドコートミュール | C19: ガチャコロ（2000） | D19: 16900 | G19: 1 | H19: 16900 | K19: たまごっち板チョコシール | L19: ガチャコロ（2000） | M19: 780 | P19: 3 | Q19: =(N19+O19+P19)*M19 -> 2340 | T19: 9090リング | U19: ガチャコロ（2000） | V19: 4900 | Y19: 1 | Z19: =(W19+X19+Y19)*V19 -> 4900
B20: スイッチコントローラー | C20: ガチャコロ（2000） | D20: 6000 | G20: 1 | H20: 6000 | K20: スイッチコントローラー | L20: ガチャコロ（2000） | M20: 6000 | P20: 0 | Q20: =(N20+O20+P20)*M20 -> 0 | T20: ボンボンドロップシール | U20: ガチャコロ（2000） | V20: 2000 | Y20: 4 | Z20: =(W20+X20+Y20)*V20 -> 8000
B21: スイッチソフト | C21: ガチャコロ（2000） | D21: 5000 | G21: 3 | H21: 15000 | K21: スイッチソフト | L21: ガチャコロ（2000） | M21: 5000 | P21: 0 | Q21: =(N21+O21+P21)*M21 -> 0 | T21: たまごっち板チョコシール | U21: ガチャコロ（2000） | V21: 780 | Y21: 3 | Z21: =(W21+X21+Y21)*V21 -> 2340
B22: A景品 | C22: ガチャコロ（2000） | D22: 1050 | G22: 9 | H22: 9450 | K22: A景品 | L22: ガチャコロ（2000） | M22: 1050 | P22: 9 | Q22: =(N22+O22+P22)*M22 -> 9450 | T22: A景品 | U22: ガチャコロ（2000） | V22: 1050 | Y22: 3 | Z22: =(W22+X22+Y22)*V22 -> 3150
B23: ２０００円カプセル景品 | C23: ガチャコロ（2000） | D23: 450 | G23: 200 | H23: 90000 | K23: ２０００円カプセル景品 | L23: ガチャコロ（2000） | M23: 450 | N23: 33 | P23: 200 | Q23: =(N23+O23+P23)*M23 -> 104850 | T23: ２０００円カプセル景品 | U23: ガチャコロ（2000） | V23: 450 | W23: 33 | Y23: 200 | Z23: =(W23+X23+Y23)*V23 -> 104850
B24: スイッチライト | C24: ガチャコロ（1000） | D24: 23000 | G24: 1 | H24: 23000 | K24: スイッチライト | L24: ガチャコロ（1000） | M24: 23000 | N24: 1 | P24: 1 | Q24: =(N24+O24+P24)*M24 -> 46000 | T24: スイッチライト | U24: ガチャコロ（1000） | V24: 23000 | W24: 1 | Y24: 1 | Z24: =(W24+X24+Y24)*V24 -> 46000
B25: スイッチソフト | C25: ガチャコロ（1000） | D25: 5000 | G25: 0 | H25: 0 | K25: スイッチソフト | L25: ガチャコロ（1000） | M25: 5000 | P25: 0 | Q25: =(N25+O25+P25)*M25 -> 0 | T25: 任天堂食器 | U25: ガチャコロ（1000） | V25: 3500 | Y25: 2 | Z25: =(W25+X25+Y25)*V25 -> 7000
B26: ポケカBOX | C26: ガチャコロ（1000） | D26: 8000 | G26: 2 | H26: 16000 | K26: ポケカBOX | L26: ガチャコロ（1000） | M26: 8000 | N26: 2 | P26: 2 | Q26: =(N26+O26+P26)*M26 -> 32000 | T26: ポケカBOX | U26: ガチャコロ（1000） | V26: 8000 | W26: 2 | Y26: 2 | Z26: =(W26+X26+Y26)*V26 -> 32000
B27: シール | C27: ガチャコロ（1000） | D27: 1500 | G27: 4 | H27: 6000 | K27: ボンボンドロップシール | L27: ガチャコロ（1000） | M27: 2000 | N27: 5 | P27: 2 | Q27: =(N27+O27+P27)*M27 -> 14000 | T27: ボンボンドロップシール | U27: ガチャコロ（1000） | V27: 2000 | W27: 3 | Y27: 4 | Z27: =(W27+X27+Y27)*V27 -> 14000
B28: ラブブ（イニシャル） | C28: ガチャコロ（1000） | D28: 1800 | G28: 3 | H28: 5400 | K28: ラブブ（イニシャル） | L28: ガチャコロ（1000） | M28: 1800 | P28: 3 | Q28: =(N28+O28+P28)*M28 -> 5400 | T28: ラブブ（イニシャル） | U28: ガチャコロ（1000） | V28: 1800 | Y28: 3 | Z28: =(W28+X28+Y28)*V28 -> 5400
B29: メロジョイスクイーズ | C29: ガチャコロ（1000） | D29: 6000 | G29: 1 | H29: 6000 | K29: メロジョイスクイーズ | L29: ガチャコロ（1000） | M29: 6000 | P29: 1 | Q29: =(N29+O29+P29)*M29 -> 6000 | T29: メロジョイスクイーズ | U29: ガチャコロ（1000） | V29: 6000 | Y29: 1 | Z29: =(W29+X29+Y29)*V29 -> 6000
B30: ラブブチェックメイト | C30: ガチャコロ（1000） | D30: 11892 | G30: 1 | H30: 11892 | K30: 1000円カプセル景品 | L30: ガチャコロ（1000） | M30: 150 | N30: 33 | P30: 200 | Q30: =(N30+O30+P30)*M30 -> 34950 | T30: 1000円カプセル景品 | U30: ガチャコロ（1000） | V30: 150 | W30: 33 | Y30: 200 | Z30: =(W30+X30+Y30)*V30 -> 34950
B31: クライベイビーパワーパフ | C31: ガチャコロ（1000） | D31: 2077 | H31: 0 | K31: プロテイン | L31: ガチャコロ（1000） | M31: 5000 | Q31: =(N31+O31+P31)*M31 -> 0 | T31: A景品 | U31: ガチャコロ（1000） | V31: 1050 | Y31: 6 | Z31: =(W31+X31+Y31)*V31 -> 6300
B32: スカルパンダ | C32: ガチャコロ（1000） | D32: 4383 | H32: 0 | K32: A景品 | L32: ガチャコロ（1000） | M32: 1050 | P32: 4 | Q32: =(N32+O32+P32)*M32 -> 4200 | S32: スポガ久留米 | T32: 1０００円カプセル景品 | U32: 1000GACHA | V32: 150 | Y32: 300 | Z32: =(W32+X32+Y32)*V32 -> 45000
C33: ガチャコロ（1000） | D33: 1100 | H33: 0 | K33: ニューモ | L33: ガチャコロ（1000） | M33: 7306 | O33: 1 | Q33: =(N33+O33+P33)*M33 -> 7306 | T33: スイッチライト | U33: 1000GACHA | V33: 20000 | Y33: 2 | Z33: =(W33+X33+Y33)*V33 -> 40000
B34: 1000円カプセル景品 | C34: ガチャコロ（1000） | D34: 150 | E34: 33 | G34: 200 | H34: 34950 | K34: アディダス中国限定トラックジャケット | L34: ガチャコロ（1000） | M34: 14000 | O34: 1 | Q34: =(N34+O34+P34)*M34 -> 14000 | T34: マリオ特大ぬいぐるみ | U34: 1000GACHA | V34: 7300 | Y34: 1 | Z34: =(W34+X34+Y34)*V34 -> 7300
B35: プロテイン | C35: ガチャコロ（1000） | D35: 5000 | H35: 0 | K35: サクセス | L35: ガチャコロ（1000） | M35: 5000 | O35: 1 | Q35: =(N35+O35+P35)*M35 -> 5000 | T35: スイッチ②ソフト | U35: 1000GACHA | V35: 7300 | Y35: 3 | Z35: =(W35+X35+Y35)*V35 -> 21900
B36: A景品 | C36: ガチャコロ（1000） | D36: 1050 | G36: 6 | H36: 6300 | K36: DISM 美顔器 | L36: ガチャコロ（1000） | M36: 30624 | N36: 1 | Q36: =(N36+O36+P36)*M36 -> 30624 | T36: 任天堂Tシャツ | U36: 1000GACHA | V36: 5500 | Y36: 1 | Z36: =(W36+X36+Y36)*V36 -> 5500
A37: 久留米 | B37: 1０００円カプセル景品 | C37: 1000GACHA | D37: 150 | G37: 300 | H37: 45000 | J37: スポガ久留米 | K37: 1０００円カプセル景品 | L37: 1000GACHA | M37: 150 | P37: 300 | Q37: =(N37+O37+P37)*M37 -> 45000 | T37: WBC応援グッズ | U37: 1000GACHA | V37: 6000 | Y37: 1 | Z37: =(W37+X37+Y37)*V37 -> 6000
B38: スイッチライト | C38: 1000GACHA | D38: 20000 | G38: 2 | H38: 40000 | K38: スイッチライト | L38: 1000GACHA | M38: 20000 | P38: 2 | Q38: =(N38+O38+P38)*M38 -> 40000 | T38: グッチキャップ | U38: 1000GACHA | V38: 9000 | Y38: 1 | Z38: =(W38+X38+Y38)*V38 -> 9000
B39: たまごっち | C39: 1000GACHA | D39: 6500 | G39: 1 | H39: 6500 | K39: たまごっち | L39: 1000GACHA | M39: 6500 | Q39: =(N39+O39+P39)*M39 -> 0 | T39: フランフランギフトセット | U39: 1000GACHA | V39: 4000 | Y39: 1 | Z39: =(W39+X39+Y39)*V39 -> 4000
B40: CHANEL | C40: 1000GACHA | D40: 6000 | G40: 1 | H40: 6000 | K40: CHANEL | L40: 1000GACHA | M40: 6000 | Q40: =(N40+O40+P40)*M40 -> 0 | T40: DIESEL財布 | U40: 1000GACHA | V40: 10000 | Y40: 1 | Z40: =(W40+X40+Y40)*V40 -> 10000
...

Sheet 久留米 
A1: 46053 | J1: 46081 | S1: 46112
A2: 店舗 | B2: 景品名 | C2: 機械名 | D2: 単価 | E2: 在庫数 | H2: 金額 | J2: 店舗 | K2: 景品名 | L2: 機械名 | M2: 単価 | N2: 在庫数 | Q2: 金額 | S2: 店舗 | T2: 景品名 | U2: 機械名 | V2: 単価 | W2: 在庫数 | Z2: 金額
E3: 倉庫① | F3: 倉庫② | G3: 機械内 | N3: 倉庫① | O3: 倉庫② | P3: 機械内 | W3: 倉庫① | X3: 倉庫② | Y3: 機械内
H4: =SUM(H5:H208) -> 9461050 | Q4: =SUM(Q5:Q215) -> 7323379 | Z4: =SUM(Z5:Z198) -> 7703370
B5: モンチッチスノーLサイズぬいぐるみ | C5: デカクレα | D5: 1183 | F5: 10 | G5: 25 | H5: =(E5+F5+G5)*D5 -> 41405 | K5: クレヨンしんちゃん ふわふわクッションver7 | L5: デカクレ③ | M5: 1100 | O5: 9 | Q5: =(N5+O5+P5)*M5 -> 9900 | T5: ポケモンキラキラサンシャイン | U5: 100円ガチャ | V5: 120 | W5: 0 | X5: 0 | Y5: 56 | Z5: =(W5+X5+Y5)*V5 -> 6720
B6: クレヨンしんちゃん ふわふわクッションver7 | C6: デカクレ③ | D6: 1100 | F6: 10 | G6: 6 | H6: =(E6+F6+G6)*D6 -> 17600 | K6: クレヨンしんちゃん フランネルボアブランケット | L6: デカクレ③ | M6: 1100 | P6: 4 | Q6: =(N6+O6+P6)*M6 -> 4400 | T6: ﾎﾟｹピースミニクッションマスコット | U6: 100円ガチャ | V6: 180 | W6: 0 | X6: 7 | Y6: 0 | Z6: =(W6+X6+Y6)*V6 -> 1260
B7: クマぬいぐるみ他 | C7: クレナグラン | D7: 1050 | G7: 30 | H7: =(E7+F7+G7)*D7 -> 31500 | K7: クマぬいぐるみ他 | L7: クレナグラン | M7: 1050 | P7: 22 | Q7: =(N7+O7+P7)*M7 -> 23100 | T7: パックンチョ ディズニープリンセス | U7: 100円ガチャ | V7: 180 | W7: 0 | X7: 0 | Y7: 115 | Z7: =(W7+X7+Y7)*V7 -> 20700
B8: 神袋 | C8: キューブモール③ | D8: 400 | E8: 36 | G8: 107 | H8: =(E8+F8+G8)*D8 -> 57200 | K8: 神袋 | L8: キューブモール③ | M8: 400 | N8: 40 | P8: 99 | Q8: =(N8+O8+P8)*M8 -> 55600 | T8: 白くま | U8: 100円ガチャ | V8: 180 | W8: 0 | X8: 0 | Y8: 12 | Z8: =(W8+X8+Y8)*V8 -> 2160
B9: サンリオころふわ寝そべりクッション | C9: トリプルツイン① | D9: 858 | F9: 17 | G9: 30 | H9: =(E9+F9+G9)*D9 -> 40326 | K9: サンリオフランネルボアブランケット | L9: トリプルツイン① | M9: 1100 | P9: 14 | Q9: =(N9+O9+P9)*M9 -> 15400 | T9: カムカムレモン | U9: 100円ガチャ | V9: 240 | W9: 0 | X9: 39 | Y9: 0 | Z9: =(W9+X9+Y9)*V9 -> 9360
B10: ラブブ風ぬいぐるみ 30cm | C10: トリプルツイン② | D10: 2000 | G10: 11 | H10: =(E10+F10+G10)*D10 -> 22000 | K10: モンチッチスノーLサイズぬいぐるみ | L10: トリプルツイン② | M10: 1183 | P10: 10 | Q10: =(N10+O10+P10)*M10 -> 11830 | T10: 雪印（乳飲料とヨーグルト） | U10: 100円ガチャ | V10: 180 | W10: 0 | X10: 0 | Y10: 74 | Z10: =(W10+X10+Y10)*V10 -> 13320
B11: ベイビースリーにゃんにゃんふぇいすブラインドBOX | C11: ダイヤモンドクレーン①左 | D11: 1050 | F11: 276 | G11: 10 | H11: =(E11+F11+G11)*D11 -> 300300 | K11: サンリオぬいぐるみポシェットボアミニポーチ | L11: ダイヤモンドクレーン①左、BUZZミニ⑤ | M11: 700 | N11: 37 | P11: 76 | Q11: =(N11+O11+P11)*M11 -> 79100 | T11: ミンティアシャカシャカキーチェーン | U11: 100円ガチャ | V11: 180 | W11: 0 | X11: 0 | Y11: 18 | Z11: =(W11+X11+Y11)*V11 -> 3240
B12: マスカットのなみだ | C12: ダイヤモンドクレーン①右 | D12: 352 | E12: 40 | G12: 27 | H12: =(E12+F12+G12)*D12 -> 23584 | K12: ベイビースリーにゃんにゃんふぇいすブラインドBOX | L12: ダイヤモンドクレーン①右 | M12: 1050 | O12: 408 | P12: 13 | Q12: =(N12+O12+P12)*M12 -> 442050 | T12: ペヤングやきそばミニチュアチャーム | U12: 100円ガチャ | V12: 180 | W12: 0 | X12: 0 | Y12: 26 | Z12: =(W12+X12+Y12)*V12 -> 4680
B13: ぬいぐるみ5種 AI MONSTERS 22㎝～37㎝ | C13: ダイヤモンドクレーン②左 | D13: 495 | E13: 16 | G13: 57 | H13: =(E13+F13+G13)*D13 -> 36135 | K13: サンリオウィンドウチャームver2 | L13: ガチャクレ① | M13: 594 | N13: 159 | P13: 63 | Q13: =(N13+O13+P13)*M13 -> 131868 | T13: オタフクソースミニチュアチャーム | U13: 100円ガチャ | V13: 180 | W13: 0 | X13: 0 | Y13: 101 | Z13: =(W13+X13+Y13)*V13 -> 18180
B14: サンリオぬいぐるみポシェットボアミニポーチ | C14: ダイヤモンドクレーン②右、BUZZミニ⑤ | D14: 700 | E14: 76 | G14: 76 | H14: =(E14+F14+G14)*D14 -> 106400 | K14: YAYAブラインドBOX BIRTHDAY | L14: ガチャクレ②、トライデッキ右下 | M14: 638 | N14: 57 | O14: 472 | Q14: =(N14+O14+P14)*M14 -> 337502 | T14: JINROチャミスルミニチャーム | U14: 100円ガチャ | V14: 180 | W14: 0 | X14: 0 | Y14: 54 | Z14: =(W14+X14+Y14)*V14 -> 9720
B15: ふわにん | C15: クリスタル | D15: 854 | H15: =(E15+F15+G15)*D15 -> 0 | K15: ポケカ（安い物） | L15: ガチャクレ③ | M15: 250 | N15: 11 | Q15: =(N15+O15+P15)*M15 -> 2750 | T15: ハローキティぬいぐるみチャーム | U15: 100円ガチャ | V15: 240 | W15: 0 | X15: 54 | Y15: 103 | Z15: =(W15+X15+Y15)*V15 -> 37680
B16: サンリオウィンドウチャームver2 | C16: ガチャクレ① | D16: 594 | E16: 263 | G16: 94 | H16: =(E16+F16+G16)*D16 -> 212058 | K16: ポケカ（テラスタルフェス、１５１、Vユニ） | L16: ガチャクレ③、BUZZクレーン②-１、BUZZクレーン④-3 | M16: 1000 | P16: 128 | Q16: =(N16+O16+P16)*M16 -> 128000 | T16: ニップンオーマイBIGシリーズミニチュアチャーム | U16: 100円ガチャ | V16: 180 | W16: 0 | X16: 0 | Y16: 63 | Z16: =(W16+X16+Y16)*V16 -> 11340
B17: YAYAブラインドBOX BIRTHDAY | C17: ガチャクレ②、トライデッキ右下 | D17: 638 | F17: 80 | G17: 63 | H17: =(E17+F17+G17)*D17 -> 91234 | K17: 海外製シール | L17: BUZZミニ①、スイートランド５、トライデッキ左上 | M17: 130 | N17: 6 | P17: 52 | Q17: =(N17+O17+P17)*M17 -> 7540 | T17: ペット毛キーチェーン2 | U17: 100円ガチャ | V17: 240 | W17: 0 | X17: 0 | Y17: 0 | Z17: =(W17+X17+Y17)*V17 -> 0
B18: ポケカ（安い物） | C18: ガチャクレ③ | D18: 250 | E18: 11 | H18: =(E18+F18+G18)*D18 -> 2750 | K18: ボンボンドロップシール(正規品全種類） | L18: BUZZミニ② | M18: 2000 | P18: 10 | Q18: =(N18+O18+P18)*M18 -> 20000 | T18: Niconミニチュアカメラコレクション2 | U18: 100円ガチャ | V18: 300 | W18: 0 | X18: 0 | Y18: 0 | Z18: =(W18+X18+Y18)*V18 -> 0
B19: ポケカ（テラスタルフェス、１５１、Vユニ） | C19: ガチャクレ③、BUZZクレーン②-１ | D19: 1000 | E19: 175 | G19: 47 | H19: =(E19+F19+G19)*D19 -> 222000 | K19: サミュエル干支マスコット | L19: BUZZミニ③ | M19: 745 | N19: 48 | P19: 28 | Q19: =(N19+O19+P19)*M19 -> 56620 | T19: モンチッチ475ラバー前髪クリップ | U19: 100円ガチャ | V19: 240 | W19: 0 | X19: 0 | Y19: 8 | Z19: =(W19+X19+Y19)*V19 -> 1920
B20: イニシャルラブブ | C20: BUZZミニ①、BUZZ②-2、トライデッキ右上 | D20: 1800 | G20: 24 | H20: =(E20+F20+G20)*D20 -> 43200 | K20: 日本製シール | L20: BUZZミニ④ | M20: 1300 | P20: 10 | Q20: =(N20+O20+P20)*M20 -> 13000 | T20: 愛猫けだまポケット | U20: 100円ガチャ | V20: 240 | W20: 0 | X20: 24 | Y20: 0 | Z20: =(W20+X20+Y20)*V20 -> 5760
B21: ボンボンドロップシール | C21: BUZZミニ② | D21: 2000 | E21: 3 | G21: 9 | H21: =(E21+F21+G21)*D21 -> 24000 | K21: ラブブ | L21: BUZZミニ⑤、トライデッキ左下 | M21: 2500 | P21: 19 | Q21: =(N21+O21+P21)*M21 -> 47500 | T21: サンリオグッズアソート（シール入） | U21: 100円ガチャ | V21: 300 | W21: 40 | X21: 0 | Y21: 31 | Z21: =(W21+X21+Y21)*V21 -> 21300
B22: サミュエル干支マスコット | C22: BUZZミニ③ | D22: 745 | E22: 123 | G22: 26 | H22: =(E22+F22+G22)*D22 -> 111005 | K22: ゴールドモバイルバッテリー | L22: BUZZミニ⑥ | M22: 1100 | P22: 29 | Q22: =(N22+O22+P22)*M22 -> 31900 | T22: スンスン前髪クリップ | U22: 100円ガチャ | V22: 180 | W22: 0 | X22: 0 | Y22: 0 | Z22: =(W22+X22+Y22)*V22 -> 0
B23: 日本製シール | C23: BUZZミニ④ | D23: 1300 | G23: 6 | H23: =(E23+F23+G23)*D23 -> 7800 | K23: スンスンボアミラポーチ | L23: BUZZミニ⑦ | M23: 1100 | N23: 10 | P23: 15 | Q23: =(N23+O23+P23)*M23 -> 27500 | T23: うちの子けだまだま | U23: 100円ガチャ | V23: 240 | W23: 0 | X23: 0 | Y23: 15 | Z23: =(W23+X23+Y23)*V23 -> 3600
B24: ラブブ | C24: BUZZミニ⑤ | D24: 2500 | E24: 6 | G24: 12 | H24: =(E24+F24+G24)*D24 -> 45000 | K24: きゅるる | L24: リトルブルプリズム | M24: 687 | N24: 48 | P24: 45 | Q24: =(N24+O24+P24)*M24 -> 63891 | T24: サンリオミニサンダルキーホルダー | U24: 100円ガチャ | V24: 396 | W24: 0 | X24: 0 | Y24: 27 | Z24: =(W24+X24+Y24)*V24 -> 10692
B25: サミュエルラッキーラビット | C25: 倉庫① | D25: 745 | E25: 65 | H25: =(E25+F25+G25)*D25 -> 48425 | K25: 忍者グミ | L25: BUZZクレーン①-1 | M25: 500 | N25: 25 | P25: 17 | Q25: =(N25+O25+P25)*M25 -> 21000 | T25: サンリオPVCマスコット | U25: 100円ガチャ | V25: 398 | W25: 0 | X25: 0 | Y25: 19 | Z25: =(W25+X25+Y25)*V25 -> 7562
B26: 忍者グミ | C26: BUZZクレーン①-1 | D26: 500 | E26: 16 | G26: 25 | H26: =(E26+F26+G26)*D26 -> 20500 | K26: ピュレグミイヤホン | L26: BUZZクレーン①-2 | M26: 1100 | P26: 8 | Q26: =(N26+O26+P26)*M26 -> 8800 | T26: AIモンスターぬいぐるみMCKH | U26: 100円ガチャ | V26: 286 | W26: 0 | X26: 0 | Y26: 14 | Z26: =(W26+X26+Y26)*V26 -> 4004
B27: ピュレグミイヤホン | C27: BUZZクレーン①-2 | D27: 1100 | G27: 25 | H27: =(E27+F27+G27)*D27 -> 27500 | K27: サンリオボアバンスクリップ | L27: BUZZクレーン①-3 | M27: 700 | N27: 50 | P27: 12 | Q27: =(N27+O27+P27)*M27 -> 43400 | T27: トッポ | U27: 100円ガチャ | V27: 180 | W27: 0 | X27: 24 | Y27: 0 | Z27: =(W27+X27+Y27)*V27 -> 4320
B28: パペットスンスンボアバンスクリップ | C28: BUZZクレーン①-3 | D28: 1100 | H28: =(E28+F28+G28)*D28 -> 0 | K28: しばいぬたまごスクイーズ | L28: BUZZクレーン①-4、クレナマルチ②-3 | M28: 82 | N28: 92 | P28: 108 | Q28: =(N28+O28+P28)*M28 -> 16400 | T28: 雪印乳製品カマンベールチーズ | U28: 100円ガチャ | V28: 180 | W28: 0 | X28: 44 | Y28: 0 | Z28: =(W28+X28+Y28)*V28 -> 7920
B29: しばいぬたまごスクイーズ | C29: BUZZクレーン①-4、クレナマルチ②-3 | D29: 82 | E29: 360 | G29: 53 | H29: =(E29+F29+G29)*D29 -> 33866 | K29: イニシャルラブブ | L29: BUZZクレーン②-2、トライデッキ右上 | M29: 1800 | P29: 18 | Q29: =(N29+O29+P29)*M29 -> 32400 | T29: 花王ミニチュアチャーム | U29: 100円ガチャ | V29: 180 | W29: 0 | X29: 20 | Y29: 86 | Z29: =(W29+X29+Y29)*V29 -> 19080
B30: 金の玉 | C30: BUZZクレーン②-3 | D30: 121 | E30: 69 | G30: 154 | H30: =(E30+F30+G30)*D30 -> 26983 | K30: カピバラスクイーズ | L30: BUZZクレーン②-3 | M30: 78 | N30: 12 | P30: 44 | Q30: =(N30+O30+P30)*M30 -> 4368 | T30: 雪印ヨーグルトとデザート | U30: 100円ガチャ | V30: 180 | W30: 0 | X30: 29 | Y30: 0 | Z30: =(W30+X30+Y30)*V30 -> 5220
B31: ボンボンドロップシール小分け | C31: BUZZクレーン②-4、BUZZクレーン⑦-2 | D31: 300 | E31: 9 | G31: 4 | H31: =(E31+F31+G31)*D31 -> 3900 | K31: ボンボンドロップシール小分け | L31: BUZZクレーン②-4、BUZZクレーン⑦-2 | M31: 300 | P31: 18 | Q31: =(N31+O31+P31)*M31 -> 5400 | T31: リプトンミニチュアチャーム | U31: 100円ガチャ | V31: 180 | W31: 0 | X31: 34 | Y31: 0 | Z31: =(W31+X31+Y31)*V31 -> 6120
B32: サンリオ ラインストーンミニクッション | C32: BUZZクレーン④-1 | D32: 500 | E32: 148 | G32: 44 | H32: =(E32+F32+G32)*D32 -> 96000 | K32: pro4コントローラーワイヤレスイヤホン | L32: BUZZクレーン④-1 | M32: 773 | P32: 5 | Q32: =(N32+O32+P32)*M32 -> 3865 | T32: ピクミンゆらゆらフィギュア | U32: 100円ガチャ | V32: 120 | W32: 0 | X32: 0 | Y32: 0 | Z32: =(W32+X32+Y32)*V32 -> 0
B33: サンリオスマートキーケースギャル | C33: BUZZクレーン④-2、クレナマルチ①-2 | D33: 726 | E33: 70 | G33: 45 | H33: =(E33+F33+G33)*D33 -> 83490 | K33: サンリオスマートキーケースギャル | L33: BUZZクレーン④-2 | M33: 726 | N33: 48 | P33: 14 | Q33: =(N33+O33+P33)*M33 -> 45012 | T33: たべっこどうぶつマスコットチャーム | U33: 100円ガチャ | V33: 180 | W33: 0 | X33: 12 | Y33: 0 | Z33: =(W33+X33+Y33)*V33 -> 2160
B34: モンチッチスノーマスコット | C34: BUZZクレーン④-3 | D34: 605 | E34: 26 | G34: 12 | H34: =(E34+F34+G34)*D34 -> 22990 | K34: サンリオミニフェイスポーチギャル③ | L34: BUZZクレーン④-4 | M34: 825 | N34: 63 | P34: 17 | Q34: =(N34+O34+P34)*M34 -> 66000 | T34: エバラダブルチャームスイング | U34: 100円ガチャ | V34: 180 | W34: 0 | X34: 143 | Y34: 0 | Z34: =(W34+X34+Y34)*V34 -> 25740
B35: サンリオミニフェイスポーチギャル③ | C35: BUZZクレーン④-4 | D35: 825 | E35: 210 | G35: 21 | H35: =(E35+F35+G35)*D35 -> 190575 | K35: ブランドミニ香水 | L35: BUZZクレーン⑤-1 | M35: 1050 | N35: 16 | P35: 28 | Q35: =(N35+O35+P35)*M35 -> 46200 | T35: スプライトミニチュアチャーム | U35: 100円ガチャ | V35: 180 | W35: 0 | X35: 55 | Y35: 0 | Z35: =(W35+X35+Y35)*V35 -> 9900
B36: ブランドミニ香水 | C36: BUZZクレーン⑤-1 | D36: 1050 | E36: 10 | G36: 36 | H36: =(E36+F36+G36)*D36 -> 48300 | K36: ぶるりん | L36: BUZZクレーン⑤-2 | M36: 180 | P36: 73 | Q36: =(N36+O36+P36)*M36 -> 13140 | T36: コカコーラミニチュアチャーム | U36: 100円ガチャ | V36: 180 | W36: 0 | X36: 0 | Y36: 19 | Z36: =(W36+X36+Y36)*V36 -> 3420
B37: ぶるりん | C37: BUZZクレーン⑤-2 | D37: 180 | G37: 83 | H37: =(E37+F37+G37)*D37 -> 14940 | K37: 電ブルcuet | L37: BUZZクレーン⑤-2 | M37: 240 | P37: 51 | Q37: =(N37+O37+P37)*M37 -> 12240 | T37: ハリボーミニクッションマスコット | U37: 100円ガチャ | V37: 198 | W37: 0 | X37: 0 | Y37: 46 | Z37: =(W37+X37+Y37)*V37 -> 9108
B38: 電ブル | C38: BUZZクレーン⑤-2 | D38: 240 | E38: 78 | G38: 64 | H38: =(E38+F38+G38)*D38 -> 34080 | K38: にくまんスクイーズ | L38: BUZZクレーン⑤-3 | M38: 100 | N38: 14 | P38: 15 | Q38: =(N38+O38+P38)*M38 -> 2900 | T38: ノーベル製菓 シャカシャカミニチュアチャーム | U38: 100円ガチャ | V38: 198 | W38: 0 | X38: 0 | Y38: 40 | Z38: =(W38+X38+Y38)*V38 -> 7920
B39: ミニフェイスポーチ ふわふわケープ サンリオ | C39: BUZZクレーン⑤-3 | D39: 792 | E39: 69 | G39: 9 | H39: =(E39+F39+G39)*D39 -> 61776 | K39: ラブブ風マスコット | L39: BUZZクレーン⑤-4 | M39: 400 | P39: 22 | Q39: =(N39+O39+P39)*M39 -> 8800 | T39: NEW ERA | U39: 100円ガチャ | V39: 330 | W39: 0 | X39: 0 | Y39: 30 | Z39: =(W39+X39+Y39)*V39 -> 9900
B40: ラブブ風マスコット | C40: BUZZクレーン⑤-4 | D40: 400 | E40: 7 | G40: 34 | H40: =(E40+F40+G40)*D40 -> 16400 | K40: サンリオフローティングダブルミラー | L40: BUZZクレーン⑥-1 | M40: 600 | N40: 79 | P40: 15 | Q40: =(N40+O40+P40)*M40 -> 56400 | T40: miniMDリアルコレクション | U40: 100円ガチャ | V40: 198 | W40: 0 | X40: 1 | Y40: 39 | Z40: =(W40+X40+Y40)*V40 -> 7920
...

Sheet 久留米(ドンキ景品)
A1: 46053 | I1: 46081 | Q1: 46112
A2: 景品名 | B2: 機械名 | C2: 単価 | D2: 倉庫① | E2: 倉庫② | F2: 機械 | G2: 金額 | I2: 景品名 | J2: 機械名 | K2: 単価 | L2: 倉庫① | M2: 倉庫② | N2: 機械 | O2: 金額 | Q2: 景品名 | R2: 機械名 | S2: 単価 | T2: 倉庫① | U2: 倉庫② | V2: 機械 | W2: 金額
G3: =SUM(G4:G52) -> 1410626 | O3: =SUM(O4:O52) -> 874222 | W3: =SUM(W4:W52) -> 1117156
A4: ほっと一息NOODLE CUP | B4: 倉庫② | C4: 1050 | E4: 30 | G4: =(D4+E4+F4)*C4 -> 31500 | I4: ほっと一息NOODLE CUP | J4: 倉庫② | K4: 1050 | M4: 31 | O4: =(L4+M4+N4)*K4 -> 32550 | Q4: ほっと一息NOODLE CUP | R4: 倉庫② | S4: 1050 | U4: 25 | W4: =(T4+U4+V4)*S4 -> 26250
A5: ５秒でぽかぽかHEATING | B5: 倉庫② | C5: 110 | E5: 16 | G5: =(D5+E5+F5)*C5 -> 1760 | I5: ５秒でぽかぽかHEATING | J5: 倉庫② | K5: 1050 | M5: 11 | O5: =(L5+M5+N5)*K5 -> 11550 | Q5: ５秒でぽかぽかHEATING | R5: 倉庫② | S5: 1050 | U5: 5 | W5: =(T5+U5+V5)*S5 -> 5250
A6: ジャグラーティッシュクロック | B6: 倉庫② | C6: 1133 | G6: =(D6+E6+F6)*C6 -> 0 | I6: ジャグラーティッシュクロック | J6: 倉庫② | K6: 1050 | O6: =(L6+M6+N6)*K6 -> 0 | Q6: ジャグラーティッシュクロック | R6: 倉庫② | S6: 1050 | U6: 0 | W6: =(T6+U6+V6)*S6 -> 0
A7: じゃがりこ マルチ収納ボックス | B7: 倉庫② | C7: 1100 | E7: 10 | G7: =(D7+E7+F7)*C7 -> 11000 | I7: じゃがりこ マルチ収納ボックス | J7: 倉庫② | K7: 1050 | M7: 10 | O7: =(L7+M7+N7)*K7 -> 10500 | Q7: じゃがりこ マルチ収納ボックス | R7: 倉庫② | S7: 1050 | U7: 4 | W7: =(T7+U7+V7)*S7 -> 4200
A8: クロミ・ポチャッコ ダストBOX | B8: 倉庫② | C8: 1100 | E8: 5 | G8: =(D8+E8+F8)*C8 -> 5500 | I8: クロミ・ポチャッコ ダストBOX | J8: 倉庫② | K8: 1050 | O8: =(L8+M8+N8)*K8 -> 0 | Q8: クロミ・ポチャッコ ダストBOX | R8: 倉庫② | S8: 1050 | U8: 0 | W8: =(T8+U8+V8)*S8 -> 0
A9: 匠のバチ | B9: 倉庫② | C9: 1050 | E9: 5 | G9: =(D9+E9+F9)*C9 -> 5250 | I9: 匠のバチ | J9: 倉庫② | K9: 1050 | M9: 4 | O9: =(L9+M9+N9)*K9 -> 4200 | Q9: 匠のバチ | R9: 倉庫② | S9: 1050 | U9: 1 | W9: =(T9+U9+V9)*S9 -> 1050
A10: タコ焼き器メーカー | B10: 倉庫② | C10: 1050 | E10: 7 | G10: =(D10+E10+F10)*C10 -> 7350 | I10: タコ焼き器メーカー | J10: 倉庫② | K10: 1050 | M10: 2 | O10: =(L10+M10+N10)*K10 -> 2100 | Q10: タコ焼き器メーカー | R10: 倉庫② | S10: 1050 | U10: 0 | W10: =(T10+U10+V10)*S10 -> 0
A11: 9L自動開閉 センサーダストボックス | B11: 倉庫② | C11: 1050 | E11: 9 | G11: =(D11+E11+F11)*C11 -> 9450 | I11: 9L自動開閉 センサーダストボックス | J11: 倉庫② | K11: 1050 | M11: 5 | O11: =(L11+M11+N11)*K11 -> 5250 | Q11: 9L自動開閉 センサーダストボックス | R11: 倉庫② | S11: 1050 | U11: 2 | W11: =(T11+U11+V11)*S11 -> 2100
A12: Switch2対応 ｺﾝﾄﾛｰﾗｰﾁｬｰｼﾞｽﾀﾝﾄﾞ | B12: 倉庫② | C12: 1050 | E12: 8 | G12: =(D12+E12+F12)*C12 -> 8400 | I12: Switch2対応 ｺﾝﾄﾛｰﾗｰﾁｬｰｼﾞｽﾀﾝﾄﾞ | J12: 倉庫② | K12: 1050 | M12: 1 | O12: =(L12+M12+N12)*K12 -> 1050 | Q12: Switch2対応 ｺﾝﾄﾛｰﾗｰﾁｬｰｼﾞｽﾀﾝﾄﾞ | R12: 倉庫② | S12: 1050 | U12: 14 | W12: =(T12+U12+V12)*S12 -> 14700
A13: ジャグラーダストボックス10 | B13: 倉庫② | C13: 1050 | E13: 11 | G13: =(D13+E13+F13)*C13 -> 11550 | I13: ジャグラーダストボックス10 | J13: 倉庫② | K13: 1050 | M13: 6 | O13: =(L13+M13+N13)*K13 -> 6300 | Q13: ジャグラーダストボックス10 | R13: 倉庫② | S13: 1050 | U13: 2 | W13: =(T13+U13+V13)*S13 -> 2100
A14: デビルワイヤレスヘッドホン | B14: 倉庫② | C14: 1050 | E14: 1 | G14: =(D14+E14+F14)*C14 -> 1050 | I14: デビルワイヤレスヘッドホン | J14: 倉庫② | K14: 1050 | O14: =(L14+M14+N14)*K14 -> 0 | Q14: デビルワイヤレスヘッドホン | R14: 倉庫② | S14: 1050 | U14: 0 | W14: =(T14+U14+V14)*S14 -> 0
A15: スピーカー | B15: 倉庫② | C15: 1050 | E15: 3 | G15: =(D15+E15+F15)*C15 -> 3150 | I15: スピーカー | J15: 倉庫② | K15: 1050 | O15: =(L15+M15+N15)*K15 -> 0 | Q15: スピーカー | R15: 倉庫② | S15: 1050 | U15: 0 | W15: =(T15+U15+V15)*S15 -> 0
A16: サンリオキャラクターぷっくりミニダストBOX | B16: 倉庫② | C16: 1050 | E16: 96 | G16: =(D16+E16+F16)*C16 -> 100800 | I16: サンリオキャラクターぷっくりミニダストBOX | J16: 倉庫② | K16: 1050 | M16: 91 | O16: =(L16+M16+N16)*K16 -> 95550 | Q16: サンリオキャラクターぷっくりミニダストBOX | R16: 倉庫② | S16: 1050 | U16: 75 | W16: =(T16+U16+V16)*S16 -> 78750
A17: ジャグラーキルトマット2 | B17: 倉庫② | C17: 1050 | E17: 24 | G17: =(D17+E17+F17)*C17 -> 25200 | I17: ジャグラーキルトマット2 | J17: 倉庫② | K17: 1050 | M17: 13 | O17: =(L17+M17+N17)*K17 -> 13650 | Q17: ジャグラーキルトマット2 | R17: 倉庫② | S17: 1050 | U17: 0 | W17: =(T17+U17+V17)*S17 -> 0
A18: ジャグラーシルエットライト | B18: 倉庫② | C18: 1050 | E18: 34 | G18: =(D18+E18+F18)*C18 -> 35700 | I18: ジャグラーシルエットライト | J18: 倉庫② | K18: 1050 | M18: 27 | O18: =(L18+M18+N18)*K18 -> 28350 | Q18: ジャグラーシルエットライト | R18: 倉庫② | S18: 1050 | U18: 16 | W18: =(T18+U18+V18)*S18 -> 16800
A19: ジャグラー超BIGボストンバッグ | B19: 倉庫② | C19: 1050 | E19: 1 | G19: =(D19+E19+F19)*C19 -> 1050 | I19: ジャグラー超BIGボストンバッグ | J19: 倉庫② | K19: 1050 | M19: 1 | O19: =(L19+M19+N19)*K19 -> 1050 | Q19: ジャグラー超BIGボストンバッグ | R19: 倉庫② | S19: 1050 | U19: 1 | W19: =(T19+U19+V19)*S19 -> 1050
A20: ジャグラーソーラースウィング | B20: 倉庫② | C20: 1050 | E20: 35 | G20: =(D20+E20+F20)*C20 -> 36750 | I20: ジャグラーソーラースウィング | J20: 倉庫② | K20: 1050 | M20: 42 | O20: =(L20+M20+N20)*K20 -> 44100 | Q20: ジャグラーソーラースウィング | R20: 倉庫② | S20: 1050 | U20: 31 | W20: =(T20+U20+V20)*S20 -> 32550
A21: 底マチボア―トートバッグ（キティ） | B21: 倉庫② | C21: 1050 | E21: 20 | G21: =(D21+E21+F21)*C21 -> 21000 | I21: 底マチボア―トートバッグ（キティ） | J21: 倉庫② | K21: 1050 | M21: 13 | O21: =(L21+M21+N21)*K21 -> 13650 | Q21: 底マチボア―トートバッグ（キティ） | R21: 倉庫② | S21: 1050 | U21: 7 | W21: =(T21+U21+V21)*S21 -> 7350
A22: ジャグラーオーバルクッション | B22: 倉庫② | C22: 1050 | E22: 12 | G22: =(D22+E22+F22)*C22 -> 12600 | I22: ジャグラーオーバルクッション | J22: 倉庫② | K22: 1050 | O22: =(L22+M22+N22)*K22 -> 0 | Q22: ジャグラーオーバルクッション | R22: 倉庫② | S22: 1050 | U22: 0 | W22: =(T22+U22+V22)*S22 -> 0
A23: ハローキティ保温保冷BIGマルチバッグ | B23: 倉庫② | C23: 1050 | E23: 17 | G23: =(D23+E23+F23)*C23 -> 17850 | I23: ハローキティ保温保冷BIGマルチバッグ | J23: 倉庫② | K23: 1050 | M23: 10 | O23: =(L23+M23+N23)*K23 -> 10500 | Q23: ハローキティ保温保冷BIGマルチバッグ | R23: 倉庫② | S23: 1050 | U23: 6 | W23: =(T23+U23+V23)*S23 -> 6300
A24: コンパクトデジタルカメラ | B24: 倉庫② | C24: 1050 | E24: 171 | G24: =(D24+E24+F24)*C24 -> 179550 | I24: コンパクトデジタルカメラ | J24: 倉庫② | K24: 1050 | M24: 135 | O24: =(L24+M24+N24)*K24 -> 141750 | Q24: コンパクトデジタルカメラ | R24: 倉庫② | S24: 1050 | U24: 144 | W24: =(T24+U24+V24)*S24 -> 151200
A25: スピニングゴールドスピナー | B25: 1000円ガチャ | C25: 154 | E25: 75 | G25: =(D25+E25+F25)*C25 -> 11550 | I25: ジャグラーミニグラス | J25: 倉庫② | K25: 1050 | M25: 33 | O25: =(L25+M25+N25)*K25 -> 34650 | Q25: ジャグラーミニグラス | R25: 倉庫② | S25: 1050 | U25: 13 | W25: =(T25+U25+V25)*S25 -> 13650
A26: ミニ懐中電灯ライトキーホルダー | B26: 1000円ガチャ | C26: 42 | E26: 471 | G26: =(D26+E26+F26)*C26 -> 19782 | I26: ハローキティ・クロミラバーマスコットクロック | J26: 倉庫② | K26: 1050 | O26: =(L26+M26+N26)*K26 -> 0 | Q26: ハローキティ・クロミラバーマスコットクロック | R26: 倉庫② | S26: 1050 | U26: 54 | W26: =(T26+U26+V26)*S26 -> 56700
A27: 押してくせになるプチ呼び鈴 | B27: 1000円ガチャ | C27: 77 | E27: 240 | G27: =(D27+E27+F27)*C27 -> 18480 | I27: スピニングゴールドスピナー | J27: 1000円ガチャ | K27: 154 | O27: =(L27+M27+N27)*K27 -> 0 | Q27: 日焼けキティ保温保冷BIGクリアバッグ | R27: 倉庫② | S27: 1050 | U27: 30 | W27: =(T27+U27+V27)*S27 -> 31500
A28: どうぶつのしっぽキーホルダー | B28: 1000円ガチャ | C28: 99 | E28: 132 | G28: =(D28+E28+F28)*C28 -> 13068 | I28: ミニ懐中電灯ライトキーホルダー | J28: 1000円ガチャ | K28: 42 | M28: 408 | O28: =(L28+M28+N28)*K28 -> 17136 | Q28: クロミジャンボパイルケット | R28: 倉庫② | S28: 1050 | U28: 2 | W28: =(T28+U28+V28)*S28 -> 2100
A29: 光る！麻雀牌～SP～ | B29: 1000円ガチャ | C29: 106 | E29: 336 | G29: =(D29+E29+F29)*C29 -> 35616 | I29: 押してくせになるプチ呼び鈴 | J29: 1000円ガチャ | K29: 77 | M29: 240 | O29: =(L29+M29+N29)*K29 -> 18480 | Q29: 保温保冷多機能BIGトートバッグ | R29: 倉庫② | S29: 1050 | U29: 3 | W29: =(T29+U29+V29)*S29 -> 3150
A30: ミニピストルライトストラップ | B30: 1000円ガチャ | C30: 32 | E30: 1080 | G30: =(D30+E30+F30)*C30 -> 34560 | I30: どうぶつのしっぽキーホルダー | J30: 1000円ガチャ | K30: 99 | O30: =(L30+M30+N30)*K30 -> 0 | Q30: ミッキーリュック | R30: 倉庫② | S30: 1050 | U30: 5 | W30: =(T30+U30+V30)*S30 -> 5250
A31: びりびりKH8種 | B31: 1000円ガチャ | C31: 150 | E31: 300 | G31: =(D31+E31+F31)*C31 -> 45000 | I31: 光る！麻雀牌～SP～ | J31: 1000円ガチャ | K31: 106 | O31: =(L31+M31+N31)*K31 -> 0 | Q31: サンリオキャラクターズ２層式ナップサック | R31: 倉庫② | S31: 1050 | U31: 33 | W31: =(T31+U31+V31)*S31 -> 34650
A32: びりびり⑤ | B32: 1000円ガチャ | C32: 150 | E32: 240 | G32: =(D32+E32+F32)*C32 -> 36000 | I32: ミニピストルライトストラップ | J32: 1000円ガチャ | K32: 32 | M32: 288 | O32: =(L32+M32+N32)*K32 -> 9216 | Q32: 3in1取り巻き式充電ケーブル | R32: 1000円ガチャ | S32: 250 | U32: 240 | W32: =(T32+U32+V32)*S32 -> 60000
A33: バラ | B33: 1000円ガチャ | C33: 200 | E33: 700 | G33: =(D33+E33+F33)*C33 -> 140000 | I33: びりびりKH8種 | J33: 1000円ガチャ | K33: 150 | M33: 240 | O33: =(L33+M33+N33)*K33 -> 36000 | Q33: ミニ懐中電灯ライトキーホルダー | R33: 1000円ガチャ | S33: 42 | U33: 322 | W33: =(T33+U33+V33)*S33 -> 13524
A34: ジャグラーミニミニポーチ | B34: 2000円ガチャ | C34: 280 | E34: 120 | G34: =(D34+E34+F34)*C34 -> 33600 | I34: バラ | J34: 1000円ガチャ | K34: 200 | M34: 100 | O34: =(L34+M34+N34)*K34 -> 20000 | Q34: 押してくせになるプチ呼び鈴 | R34: 1000円ガチャ | S34: 77 | U34: 120 | W34: =(T34+U34+V34)*S34 -> 9240
A35: コンパクトボイスチェンジャー | B35: 2000円ガチャ | C35: 220 | E35: 288 | G35: =(D35+E35+F35)*C35 -> 63360 | I35: 33個アソート済み | J35: 1000円ガチャ | K35: 150 | M35: 23 | O35: =(L35+M35+N35)*K35 -> 3450 | Q35: もぐらたたきゲーム | R35: 1000円ガチャ | S35: 90 | U35: 140 | W35: =(T35+U35+V35)*S35 -> 12600
A36: 早押しクイズボタン | B36: 2000円ガチャ | C36: 256 | E36: 600 | G36: =(D36+E36+F36)*C36 -> 153600 | I36: ジャグラーミニミニポーチ | J36: 2000円ガチャ | K36: 280 | O36: =(L36+M36+N36)*K36 -> 0 | Q36: ミニピストルライトキーホルダー | R36: 1000円ガチャ | S36: 32 | U36: 240 | W36: =(T36+U36+V36)*S36 -> 7680
A37: バラ | B37: 2000円ガチャ | C37: 200 | E37: 50 | G37: =(D37+E37+F37)*C37 -> 10000 | I37: コンパクトボイスチェンジャー | J37: 2000円ガチャ | K37: 220 | O37: =(L37+M37+N37)*K37 -> 0 | Q37: ミニピストルライトストラップ | R37: 1000円ガチャ | S37: 32 | U37: 400 | W37: =(T37+U37+V37)*S37 -> 12800
A38: アソート済み | B38: 2000円ガチャ | C38: 450 | E38: 10 | G38: =(D38+E38+F38)*C38 -> 4500 | I38: 早押しクイズボタン | J38: 2000円ガチャ | K38: 256 | M38: 240 | O38: =(L38+M38+N38)*K38 -> 61440 | Q38: びりびりアソート | R38: 1000円ガチャ | S38: 150 | U38: 440 | W38: =(T38+U38+V38)*S38 -> 66000
A39: バラエティー中身 | B39: バラエティー500 | C39: 50 | E39: 3500 | G39: =(D39+E39+F39)*C39 -> 175000 | I39: バラ | J39: 2000円ガチャ | K39: 200 | M39: 50 | O39: =(L39+M39+N39)*K39 -> 10000 | Q39: バラ | R39: 1000円ガチャ | S39: 200 | U39: 30 | W39: =(T39+U39+V39)*S39 -> 6000
A40: アソート済み | B40: バラエティー500 | C40: 50 | E40: 1 | G40: =(D40+E40+F40)*C40 -> 50 | I40: アソート済み | J40: 2000円ガチャ | K40: 450 | M40: 6 | O40: =(L40+M40+N40)*K40 -> 2700 | Q40: 33個アソート済み | R40: 1000円ガチャ | S40: 150 | U40: 43 | W40: =(T40+U40+V40)*S40 -> 6450
...

Sheet 飯塚
A1: 46053
B2: 景品名 | C2: 機械名 | D2: 単価 | E2: 在庫数 | H2: 金額
E3: 倉庫① | F3: 倉庫②(棚) | G3: 機械内
A4: 飯塚 | H4: =SUM(H5:H141) -> 3437686
B5: サンリオ MCポーチギャル２ | C5: BUZZミニクレーン① | D5: 1009 | E5: 0 | F5: 10 | G5: 20 | H5: =D5*(E5+F5+G5) -> 30270
B6: サンリオボアミラーポーチ | C6: BUZZミニクレーン② | D6: 1000 | E6: 0 | F6: 40 | G6: 7 | H6: =D6*(E6+F6+G6) -> 47000
B7: AIモンスターぬいぐるみ15種 | C7: BUZZミニクレーン③ | D7: 500 | E7: 0 | F7: 128 | G7: 18 | H7: =D7*(E7+F7+G7) -> 73000
B8: PIN FOR LOVE ラブブ | C8: BUZZミニクレーン④ | D8: 2622 | E8: 0 | F8: 0 | G8: 14 | H8: =D8*(E8+F8+G8) -> 36708
B9: サンリオぬいぐるみポシェットボアミニポーチ | C9: BUZZミニクレーン⑤ | D9: 920 | E9: 0 | F9: 12 | G9: 16 | H9: =D9*(E9+F9+G9) -> 25760
B10: AIモンスターぬいぐるみ15種 | C10: BUZZミニクレーン⑥ | D10: 500 | E10: 0 | F10: 128 | G10: 18 | H10: =D10*(E10+F10+G10) -> 73000
B11: 液晶付きミニデジタルカメラvogue | C11: BUZZミニクレーン⑧ | D11: 977 | E11: 0 | F11: 0 | G11: 64 | H11: =D11*(E11+F11+G11) -> 62528
B12: AIモンスターマスコットキーホルダー（約18cm） | C12: BUZZミニクレーン⑨ | D12: 358 | E12: 0 | F12: 140 | G12: 52 | H12: =D12*(E12+F12+G12) -> 68736
B13: ルララぬいぐるみ | C13: BUZZミニクレーン⑩ | D13: 650 | E13: 0 | F13: 54 | G13: 18 | H13: =D13*(E13+F13+G13) -> 46800
B14: スティッチキラキラキーケース | C14: BUZZクレ4①左上 | D14: 650 | E14: 48 | F14: 0 | G14: 30 | H14: =D14*(E14+F14+G14) -> 50700
B15: スマートキーケースギャル サンリオ | C15: BUZZクレ4①右上 | D15: 726 | E15: 0 | F15: 19 | G15: 16 | H15: =D15*(E15+F15+G15) -> 25410
B16: サンリオスマートキーケースきらきらドリームシリーズ | C16: BUZZクレ4①右上 | D16: 710 | E16: 0 | F16: 0 | G16: 10 | H16: =D16*(E16+F16+G16) -> 7100
... B53: おさるのジョージマスコット付きボールペン4色ボールペン | C53: とれんだ４ 1－2左 | D53: 220 | E53: 0 | F53: 0 | G53: 7 | H53: =D53*(E53+F53+G53) -> 1540
B54: お菓子アソート | C54: とれんだ４ 1－2右 | D54: 40 | E54: 0 | G54: 55 | H54: =D54*(E54+F54+G54) -> 2200
B55: リコーダーペン | C55: とれんだ４ 2－1左 | D55: 35 | E55: 0 | F55: 0 | G55: 134 | H55: =D55*(E55+F55+G55) -> 4690
B56: 注射器ペン | C56: とれんだ４ 2－1左 | D56: 108 | E56: 0 | F56: 0 | G56: 247 | H56: =D56*(E56+F56+G56) -> 26676
B57: SPGマスコット10種 8cm | C57: とれんだ４ 2－2右 | D57: 165 | E57: 0 | F57: 0 | G57: 112 | H57: =D57*(E57+F57+G57) -> 18480
B58: メタリックカラー手錠 | C58: とれんだ４ 2－2左 | D58: 104 | E58: 0 | F58: 0 | G58: 46 | H58: =D58*(E58+F58+G58) -> 4784
B59: サンリオ巻き寿司型ミニポーチ | C59: とれんだ４ 2－2右 | D59: 726 | E59: 0 | F59: 42 | G59: 27 | H59: =D59*(E59+F59+G59) -> 50094
B60: ジャグラーめちゃでか毛布（白） | C60: デカクレ | D60: 1094 | E60: 9 | F60: 0 | G60: 3 | H60: =D60*(E60+F60+G60) -> 13128
B61: ジャグラーアウトドア多機能ブランケット | C61: デカクレ | D61: 1073 | E61: 9 | F61: 0 | G61: 7 | H61: =D61*(E61+F61+G61) -> 17168
B62: つぶらな瞳のなまがきおめかしムラサキカラー | C62: デカクレ | D62: 1114 | E62: 0 | F62: 0 | G62: 10 | H62: =D62*(E62+F62+G62) -> 11140
B63: サンリオフェイスクッション第6弾 | C63: トリプルツイン左 | D63: 968 | E63: 0 | F63: 2 | G63: 3 | H63: =D63*(E63+F63+G63) -> 4840
B64: クレヨンしんちゃん寝そべりキュートBIGぬいぐるみ2 | C64: トリプルツイン右 | D64: 924 | E64: 0 | F64: 4 | G64: 5 | H64: =D64*(E64+F64+G64) -> 8316
B65: ハローキティ レトロカラードールGJ | C65: クレナグラン | D65: 1100 | E65: 0 | F65: 1 | G65: 6 | H65: =D65*(E65+F65+G65) -> 7700
B66: ハローキティ クリームソーダドールGJ | C66: クレナグラン | D66: 1100 | E66: 0 | F66: 0 | G66: 1 | H66: =D66*(E66+F66+G66) -> 1100
... B92: 湖池屋ポテトチップス5個パック2種 | C92: 台湾キャッチャー② | D92: 389 | E92: 0 | F92: 32 | G92: 24 | H92: =D92*(E92+F92+G92) -> 21784
B93: ポケモンカード ロストアビス | D93: 170 | E93: 0 | F93: 1 | G93: 0 | H93: =D93*(E93+F93+G93) -> 170
B94: ポケカ バトルパートナーズ | D94: 300 | E94: 0 | F94: 17 | G94: 0 | H94: =D94*(E94+F94+G94) -> 5100
B95: ポケモンカード | D95: 200 | E95: 0 | F95: 20 | G95: 0 | H95: =D95*(E95+F95+G95) -> 4000
B96: ジャグラー 保温保冷ステンレスタンブラー | D96: 1134 | E96: 0 | F96: 1 | G96: 0 | H96: =D96*(E96+F96+G96) -> 1134
B97: ジャグラー ダイカットクロック | D97: 1044 | E97: 0 | F97: 6 | G97: 0 | H97: =D97*(E97+F97+G97) -> 6264
B98: Bluetooth switch対応 ゲームコントローラー クリア８ | D98: 1200 | E98: 15 | F98: 1 | G98: 0 | H98: =D98*(E98+F98+G98) -> 19200
B99: ほっと一息 NOODLE CUP | D99: 1100 | E99: 24 | F99: 8 | G99: 0 | H99: =D99*(E99+F99+G99) -> 35200
B100: スヌーピーモップクーラーボックス | D100: 1100 | E100: 5 | F100: 6 | G100: 0 | H100: =D100*(E100+F100+G100) -> 12100
B101: ダイナソー ピンポンボールゲーム | D101: 1194 | E101: 16 | F101: 0 | G101: 0 | H101: =D101*(E101+F101+G101) -> 19104
...

Sheet 堤
A1: 46053
A2: 店舗 | B2: 景品名 | C2: 機械名 | D2: 単価 | E2: 在庫数 | H2: 金額
E3: 倉庫① | F3: 倉庫②(棚) | G3: 機械内 | H3: =SUM(H4:H97) -> 1923889
A4: 小倉1000円ガチャ | B4: A景品 | C4: ティアラ1000 | D4: 1050 | E4: 0 | F4: 0 | G4: 4 | H4: =D4*(E4+F4+G4) -> 4200
B5: 1000円カプセル景品 | C5: ティアラ1000 | D5: 150 | E5: 0 | F5: 0 | G5: 126 | H5: =D5*(E5+F5+G5) -> 18900
B6: スイッチライト本体 | C6: ティアラ1000 | D6: 21970 | E6: 0 | F6: 0 | G6: 2 | H6: =D6*(E6+F6+G6) -> 43940
B7: スイッチソフト | C7: ティアラ1000 | D7: 5600 | E7: 0 | F7: 0 | G7: 4 | H7: =D7*(E7+F7+G7) -> 22400
B8: ＮＩＫＥスニーカー | C8: ティアラ1000 | D8: 21970 | E8: 1 | F8: 0 | G8: 0 | H8: =D8*(E8+F8+G8) -> 21970
B9: ポケカメガブレイブ | C9: ティアラ1000 | D9: 24440 | E9: 0 | F9: 0 | G9: 1 | H9: =D9*(E9+F9+G9) -> 24440
B10: ラブブエナジーシリーズ | C10: ティアラ1000 | D10: 3943 | E10: 0 | F10: 0 | G10: 1 | H10: =D10*(E10+F10+G10) -> 3943
B11: ラブブマカロンシリーズ | C11: ティアラ1000 | D11: 4579 | E11: 0 | F11: 0 | G11: 1 | H11: =D11*(E11+F11+G11) -> 4579
B12: VRゴーグル | C12: ティアラ1000 | D12: 4999 | E12: 0 | F12: 0 | G12: 1 | H12: =D12*(E12+F12+G12) -> 4999
B13: ドローン | C13: ティアラ1000 | D13: 14256 | E13: 0 | F13: 0 | G13: 1 | H13: =D13*(E13+F13+G13) -> 14256
H14: =D14*(E14+F14+G14) -> 0
A15: 飯塚2000円ガチャ | B15: A景品 | C15: デカプセル | D15: 1050 | E15: 0 | F15: 0 | G15: 8 | H15: =D15*(E15+F15+G15) -> 8400
B16: 2000円ガチャカプセル景品 | C16: デカプセル | D16: 450 | E16: 200 | F16: 0 | G16: 180 | H16: =D16*(E16+F16+G16) -> 171000
B17: PS5 | C17: デカプセル | D17: 72930 | E17: 0 | F17: 0 | G17: 1 | H17: =D17*(E17+F17+G17) -> 72930
B18: アップルウォッチ | C18: デカプセル | D18: 34800 | E18: 0 | F18: 0 | G18: 1 | H18: =D18*(E18+F18+G18) -> 34800
B19: スイッチライト本体 | C19: デカプセル | D19: 21970 | E19: 0 | F19: 0 | G19: 2 | H19: =D19*(E19+F19+G19) -> 43940
B20: スイッチソフト大乱闘スマッシュブラザーズ | C20: デカプセル | D20: 6498 | E20: 0 | F20: 0 | G20: 1 | H20: =D20*(E20+F20+G20) -> 6498
B21: PS5ポータブル | C21: デカプセル | D21: 36842 | E21: 0 | F21: 0 | G21: 1 | H21: =D21*(E21+F21+G21) -> 36842
B22: スイッチソフトマリオパーティ | C22: デカプセル | D22: 5148 | E22: 0 | F22: 0 | G22: 1 | H22: =D22*(E22+F22+G22) -> 5148
B23: スイッチ本体 | C23: デカプセル | D23: 38000 | E23: 0 | F23: 0 | G23: 2 | H23: =D23*(E23+F23+G23) -> 76000
B24: リファシャワーヘッド | C24: デカプセル | D24: 30000 | E24: 0 | F24: 0 | G24: 1 | H24: =D24*(E24+F24+G24) -> 30000
B25: サロニアヘアドライヤー | C25: デカプセル | D25: 5380 | E25: 0 | F25: 0 | G25: 1 | H25: =D25*(E25+F25+G25) -> 5380
B26: アップルイヤホン | C26: デカプセル | D26: 29800 | E26: 0 | F26: 0 | G26: 1 | H26: =D26*(E26+F26+G26) -> 29800
B27: リファストレートアイロン | C27: デカプセル | D27: 23000 | E27: 0 | F27: 0 | G27: 1 | H27: =D27*(E27+F27+G27) -> 23000
... B33: ラブブマカロンシリーズ | C33: デカプセル | D33: 4579 | E33: 1 | F33: 0 | G33: 2 | H33: =D33*(E33+F33+G33) -> 13737
B34: switch2 | D34: 70000 | E34: 1 | F34: 0 | G34: 0 | H34: =D34*(E34+F34+G34) -> 70000
H35: =D35*(E35+F35+G35) -> 0
A36: 飯塚1000円ガチャ | B36: A景品 | C36: 1000円ガチャ | D36: 1050 | E36: 0 | F36: 0 | G36: 7 | H36: =D36*(E36+F36+G36) -> 7350
B37: 1000円カプセル景品 | C37: 1000円ガチャ | D37: 150 | E37: 100 | F37: 0 | G37: 142 | H37: =D37*(E37+F37+G37) -> 36300
B38: ポケカメガブレイブ | C38: 1000円ガチャ | D38: 12200 | E38: 0 | F38: 0 | G38: 1 | H38: =D38*(E38+F38+G38) -> 12200
B39: ポケカメガシンフォニア | C39: 1000円ガチャ | D39: 7880 | E39: 0 | F39: 0 | G39: 1 | H39: =D39*(E39+F39+G39) -> 7880
B40: しなこマシュマロ | C40: 1000円ガチャ | D40: 864 | E40: 0 | F40: 3 | G40: 0 | H40: =D40*(E40+F40+G40) -> 2592
B41: しなこ水筒 | C41: 1000円ガチャ | D41: 9878 | E41: 0 | F41: 0 | G41: 1 | H41: =D41*(E41+F41+G41) -> 9878
B42: たまごっちUNI | C42: 1000円ガチャ | D42: 11000 | E42: 0 | F42: 0 | G42: 1 | H42: =D42*(E42+F42+G42) -> 11000
B43: スイッチライトハイラルエディション | C43: 1000円ガチャ | D43: 22980 | E43: 0 | F43: 0 | G43: 1 | H43: =D43*(E43+F43+G43) -> 22980
B44: VRゴーグル | C44: 1000円ガチャ | D44: 2490 | E44: 0 | F44: 0 | G44: 1 | H44: =D44*(E44+F44+G44) -> 2490
B45: カメラ付きドローン | C45: 1000円ガチャ | D45: 6441 | E45: 0 | F45: 0 | G45: 1 | H45: =D45*(E45+F45+G45) -> 6441
...

Sheet 鹿児島
A1: 46081
A2: 店舗 | B2: 機械名 | C2: 景品名 | D2: 単価 | E2: 在庫数 | H2: 金額
E3: 倉庫① | F3: 倉庫② | G3: 機械内
E4: =SUM(E5:E303) -> 2381 | F4: =SUM(F5:F303) -> 1084 | G4: =SUM(G5:G303) -> 3091 | H4: =SUM(H5:H334) -> 4332895
A5: 鹿屋 | B5: 1000GATCHA(2000) | C5: スイッチ本体 | D5: 39800 | G5: 1 | H5: =D5*(E5+F5+G5) -> 39800
C6: NIKEスニーカー | D6: 20000 | G6: 1 | H6: =D6*(E6+F6+G6) -> 20000
C7: ブランドコスメ | D7: 5000 | H7: =D7*(E7+F7+G7) -> 0
C8: シュプリームバッグ | D8: 29800 | G8: 3 | H8: =D8*(E8+F8+G8) -> 89400
C9: リファへアアイロン | D9: 25000 | H9: =D9*(E9+F9+G9) -> 0
C10: PSポータルリモートプレーヤー | D10: 38700 | G10: 1 | H10: =D10*(E10+F10+G10) -> 38700
C11: A景品 | D11: 1000 | G11: 3 | H11: =D11*(E11+F11+G11) -> 3000
C12: ラブブBOX
C13: 2000カプセル | D13: 450 | G13: 210 | H13: =D13*(E13+F13+G13) -> 94500
C14: bossヘッドホン | G14: 1
B15: 1000GATCHA | C15: スイッチライト | D15: 19800 | G15: 1 | H15: =D15*(E15+F15+G15) -> 19800
C16: ポケモンカードBOX | D16: 5500 | G16: 2 | H16: =D16*(E16+F16+G16) -> 11000
C17: ブランドコスメギフトセット | D17: 5500 | H17: =D17*(E17+F17+G17) -> 0
C18: スイッチソフト | D18: 5500 | H18: =D18*(E18+F18+G18) -> 0
C19: ブラウン5 シェーバー | D19: 12500
C20: 電動歯ブラシ | D20: 10000 | H20: =D20*(E20+F20+G20) -> 0
C21: A景品 | D21: 1050 | G21: 5 | H21: =D21*(E21+F21+G21) -> 5250
C22: ボンボンドロップシール | D22: 1500 | G22: 2 | H22: 3000
C23: 1000カプセル | D23: 150 | G23: 200 | H23: =D23*(E23+F23+G23) -> 30000
B25: 500GATCHA | C25: ゲームソフト | D25: 5000 | G25: 3 | H25: =D25*(E25+F25+G25) -> 15000
C26: ラブブ | D26: 4000 | G26: 2 | H26: =D26*(E26+F26+G26) -> 8000
H27: =D27*(E27+F27+G27) -> 0
C28: A景品 | D28: 1000 | G28: 9 | H28: =D28*(E28+F28+G28) -> 9000
H29: =D29*(E29+F29+G29) -> 0
C30: 500カプセル | D30: 55 | G30: 350 | H30: =D30*(E30+F30+G30) -> 19250
H31: =D31*(E31+F31+G31) -> 0
A33: 都城 | B33: 1000GATCHA(2000) | C33: スイッチ本体 | D33: 39800 | G33: 1 | H33: =D33*(E33+F33+G33) -> 39800
C34: NIKEスニーカー | D34: 25000 | G34: 1 | H34: =D34*(E34+F34+G34) -> 25000
H35: =D35*(E35+F35+G35) -> 0
H36: =D36*(E36+F36+G36) -> 0
C37: Appleウォッチ | D37: 26500 | G37: 1 | H37: =D37*(E37+F37+G37) -> 26500
H38: =D38*(E38+F38+G38) -> 0
C39: PS5 | D39: 59800 | G39: 1 | H39: =D39*(E39+F39+G39) -> 59800
C40: ポケモンカード | H40: =D40*(E40+F40+G40) -> 0
C41: A景品 | D41: 1050 | G41: 4 | H41: 4200
C42: 2000カプセル | D42: 450 | G42: 210 | H42: =D42*(E42+F42+G42) -> 94500
...

Sheet 塩川
A1: 46081
A2: 店舗 | B2: 機械名 | C2: 景品名 | D2: 単価 | E2: 在庫数 | H2: 金額
E3: 倉庫① | F3: 倉庫② | G3: 機械内
E4: =SUM(E5:E63) -> 0 | F4: =SUM(F5:F63) -> 0 | G4: =SUM(G5:G63) -> 0 | H4: =SUM(H5:H63) -> 181061
A5: 西新 | C5: 機械内景品 | H5: 53097 | I5: 詳細は別紙
H6: =D6*(E6+F6+G6) -> 0
H7: =D7*(E7+F7+G7) -> 0
A8: 浜の町 | C8: 機械内景品 | H8: 65742 | I8: 詳細は別紙
B9: 1000GACHA | H9: =D9*(E9+F9+G9) -> 0
H10: =D10*(E10+F10+G10) -> 0
H11: =D11*(E11+F11+G11) -> 0
H12: =D12*(E12+F12+G12) -> 0
H13: =D13*(E13+F13+G13) -> 0
H14: =D14*(E14+F14+G14) -> 0
H15: =D15*(E15+F15+G15) -> 0
H16: =D16*(E16+F16+G16) -> 0
H17: =D17*(E17+F17+G17) -> 0
H18: =D18*(E18+F18+G18) -> 0
H19: =D19*(E19+F19+G19) -> 0
H20: =D20*(E20+F20+G20) -> 0
A21: 時津 | C21: 機械内景品 | H21: 62222 | I21: 詳細は別紙
B22: ガチャコロ２ | H22: =D22*(E22+F22+G22) -> 0
H23: =D23*(E23+F23+G23) -> 0
H24: =D24*(E24+F24+G24) -> 0
H25: =D25*(E25+F25+G25) -> 0
H26: =D26*(E26+F26+G26) -> 0
H27: =D27*(E27+F27+G27) -> 0
H28: =D28*(E28+F28+G28) -> 0
H29: =D29*(E29+F29+G29) -> 0
H30: =D30*(E30+F30+G30) -> 0
H31: =D31*(E31+F31+G31) -> 0
H32: =D32*(E32+F32+G32) -> 0
H33: =D33*(E33+F33+G33) -> 0
H34: =D34*(E34+F34+G34) -> 0
A35: 手持ち景品 | H35: =D35*(E35+F35+G35) -> 0
H36: =D36*(E36+F36+G36) -> 0
H37: =D37*(E37+F37+G37) -> 0
H38: =D38*(E38+F38+G38) -> 0
H39: =D39*(E39+F39+G39) -> 0
H40: =D40*(E40+F40+G40) -> 0
...

Sheet 坂本
A1: 46081
A2: 店舗 | B2: 機械名 | C2: 景品名 | D2: 単価 | E2: 在庫数 | H2: 金額
E3: 倉庫① | F3: 倉庫② | G3: 機械内
H4: =SUM(H5:H122) -> 2510491
A5: 福重 | B5: BUZZクレーン他 | C5: クレーン景品 | H5: 688594 | I5: 詳細は別表
B6: 500GACHA | C6: カプセル景品 | D6: 55 | G6: 150 | H6: =D6*(E6+F6+G6) -> 8250
C7: A景品 | D7: 1050 | G7: 3 | H7: =D7*(E7+F7+G7) -> 3150
C8: スイッチソフト | D8: 5500 | H8: =D8*(E8+F8+G8) -> 0
C11: しなこ水筒 | D11: 6000 | G11: 1 | H11: =D11*(E11+F11+G11) -> 6000
H13: =D13*(E13+F13+G13) -> 0
B14: 1000GACHA | C14: カプセル景品 | D14: 450 | G14: 100 | H14: =D14*(E14+F14+G14) -> 45000
C15: A景品 | D15: 1050 | G15: 5 | H15: =D15*(E15+F15+G15) -> 5250
C16: PS5 | D16: 65000 | G16: 1 | H16: =D16*(E16+F16+G16) -> 65000
C17: echopop | D17: 5500 | G17: 1 | H17: =D17*(E17+F17+G17) -> 5500
C18: スイッチ本体 | D18: 38000 | H18: =D18*(E18+F18+G18) -> 0
C19: BOSEヘッドホン | D19: 36000 | H19: =D19*(E19+F19+G19) -> 0
C20: シュプリームニット帽 | D20: 16700 | H20: =D20*(E20+F20+G20) -> 0
C21: シュプリームウエストポーチ | D21: 15400 | H21: =D21*(E21+F21+G21) -> 0
C22: ディオール | D22: 8800 | H22: =D22*(E22+F22+G22) -> 0
C23: ティファニー | D23: 8800 | G23: 1 | H23: =D23*(E23+F23+G23) -> 8800
C24: 電動歯ブラシ | D24: 3300 | G24: 1 | H24: =D24*(E24+F24+G24) -> 3300
C25: スイッチソフト | D25: 5500 | G25: 2 | H25: =D25*(E25+F25+G25) -> 11000
C26: ナイキスニーカーシュプリーム | D26: 22000 | G26: 1 | H26: =D26*(E26+F26+G26) -> 22000
H27: =D27*(E27+F27+G27) -> 0
B28: ティアラ スニーカー | C28: カプセル景品 | D28: 450 | G28: 100 | H28: =D28*(E28+F28+G28) -> 45000
C29: A景品 | D29: 1050 | G29: 0 | H29: =D29*(E29+F29+G29) -> 0
C30: ナイキスニーカー | D30: 22000 | G30: 3 | H30: =D30*(E30+F30+G30) -> 66000
C31: シュプリームニット帽 | D31: 16700 | H31: =D31*(E31+F31+G31) -> 0
C32: シュプリームウエストポーチ | D32: 15400 | G32: 1 | H32: =D32*(E32+F32+G32) -> 15400
B34: ティアラ ゲーム | C34: カプセル景品 | D34: 450 | G34: 150 | H34: =D34*(E34+F34+G34) -> 67500
C35: switchライト | D35: 17000 | G35: 2 | H35: =D35*(E35+F35+G35) -> 34000
C36: switch本体 | D36: 39800 | G36: 1 | H36: =D36*(E36+F36+G36) -> 39800
C37: ジョイコン | D37: 8500 | G37: 2 | H37: =D37*(E37+F37+G37) -> 17000
C38: プロコン | D38: 8500 | G38: 1 | H38: =D38*(E38+F38+G38) -> 8500
B40: ティアラ ブランド | C40: カプセル景品 | D40: 450 | G40: 80 | H40: =D40*(E40+F40+G40) -> 36000
C41: リファドライヤー | D41: 40000 | G41: 0 | H41: =D41*(E41+F41+G41) -> 0
C42: GUESSバッグ | D42: 20000 | G42: 1 | H42: =D42*(E42+F42+G42) -> 20000
C43: coach財布 | D43: 20000 | G43: 1 | H43: =D43*(E43+F43+G43) -> 20000
C44: トミーヒルフィガーショルダーバッグ | D44: 6000 | H44: =D44*(E44+F44+G44) -> 0
C45: ディーゼルカードケース | D45: 10000 | H45: =D45*(E45+F45+G45) -> 0
...

Sheet 合計
A1: 45930 | D1: 45961 | I1: 45991 | N1: 46022 | S1: 46053 | X1: 46081 | AC1: 46112
B2: 棚卸額 | E2: 棚卸額 | F2: 前月差 | G2: 前月比 | J2: 棚卸額 | K2: 前月差 | L2: 前月比 | O2: 棚卸額 | P2: 前月差 | Q2: 前月比 | T2: 棚卸額 | U2: 前月差 | V2: 前月比 | Y2: 棚卸額 | Z2: 前月差 | AA2: 前月比 | AD2: 棚卸額 | AE2: 前月差 | AF2: 前月比
A3: 本田 | B3: 3993973 | D3: 本田 | F3: =E3-B3 -> -3993973 | G3: =E3/B3 -> 0 | I3: 本田 | K3: =J3-E3 -> 0 | L3: =J3/E3 -> #DIV/0! | N3: 本田 | P3: =O3-J3 -> 0 | Q3: =O3/J3 -> #DIV/0! | S3: 本田 | U3: =T3-O3 -> 0 | V3: =T3/O3 -> #DIV/0! | X3: 本田 | Z3: =Y3-T3 -> 0 | AA3: =Y3/T3 -> #DIV/0! | AC3: 本田 | AD3: =本田!D4 -> 0 | AE3: =AD3-Y3 -> 0 | AF3: =AD3/Y3 -> #DIV/0!
A4: 吉井 | B4: 2540534 | D4: 吉井 | F4: =E4-B4 -> -2540534 | G4: =E4/B4 -> 0 | I4: 吉井 | K4: =J4-E4 -> 0 | L4: =J4/E4 -> #DIV/0! | N4: 吉井 | P4: =O4-J4 -> 0 | Q4: =O4/J4 -> #DIV/0! | S4: 吉井 | U4: =T4-O4 -> 0 | V4: =T4/O4 -> #DIV/0! | X4: 吉井 | Z4: =Y4-T4 -> 0 | AA4: =Y4/T4 -> #DIV/0! | AC4: 吉井 | AD4: =吉井!D4 -> 0 | AE4: =AD4-Y4 -> 0 | AF4: =AD4/Y4 -> #DIV/0!
A5: 中島 | B5: 1619867 | D5: 中島 | F5: =E5-B5 -> -1619867 | G5: =E5/B5 -> 0 | I5: 中島 | K5: =J5-E5 -> 0 | L5: =J5/E5 -> #DIV/0! | N5: 中島 | P5: =O5-J5 -> 0 | Q5: =O5/J5 -> #DIV/0! | S5: 中島 | U5: =T5-O5 -> 0 | V5: =T5/O5 -> #DIV/0! | X5: 中島 | Z5: =Y5-T5 -> 0 | AA5: =Y5/T5 -> #DIV/0! | AC5: 中島 | AD5: =中島!D4 | AE5: =AD5-Y5 -> #VALUE! | AF5: =AD5/Y5 -> #VALUE!
A6: 堤 | B6: 1923889 | D6: 堤 | I6: 堤 | K6: =J6-E6 -> 0 | N6: 堤 | P6: =O6-J6 -> 0 | S6: 堤 | U6: =T6-O6 -> 0 | V6: =T6/O6 -> #DIV/0! | X6: 堤 | Z6: =Y6-T6 -> 0 | AA6: =Y6/T6 -> #DIV/0! | AC6: 堤 | AD6: =堤!D3 -> 0 | AE6: =AD6-Y6 -> 0 | AF6: =AD6/Y6 -> #DIV/0!
A7: 塩川 | B7: 181061 | D7: 塩川 | I7: 塩川 | N7: 塩川 | S7: 塩川 | X7: 塩川 | Z7: =Y7-T7 -> 0 | AA7: =Y7/T7 -> #DIV/0! | AC7: 塩川
A8: 坂本 | B8: 3555420 | D8: 坂本 | F8: =E8-B8 -> -3555420 | G8: =E8/B8 -> 0 | I8: 坂本 | K8: =J8-E8 -> 0 | L8: =J8/E8 -> #DIV/0! | N8: 坂本 | P8: =O8-J8 -> 0 | Q8: =O8/J8 -> #DIV/0! | S8: 坂本 | U8: =T8-O8 -> 0 | V8: =T8/O8 -> #DIV/0! | X8: 坂本 | Z8: =Y8-T8 -> 0 | AA8: =Y8/T8 -> #DIV/0! | AC8: 坂本 | AD8: =坂本!D4 -> 0 | AE8: =AD8-Y8 -> 0 | AF8: =AD8/Y8 -> #DIV/0!
A9: 久留米 | B9: 6363213 | D9: 久留米 | F9: =E9-B9 -> -6363213 | G9: =E9/B9 -> 0 | I9: 久留米 | K9: =J9-E9 -> 0 | L9: =J9/E9 -> #DIV/0! | N9: 久留米 | P9: =O9-J9 -> 0 | Q9: =O9/J9 -> #DIV/0! | S9: 久留米 | U9: =T9-O9 -> 0 | V9: =T9/O9 -> #DIV/0! | X9: 久留米 | Z9: =Y9-T9 -> 0 | AA9: =Y9/T9 -> #DIV/0! | AC9: 久留米 | AD9: ='久留米 '!#REF! -> #REF! | AE9: =AD9-Y9 -> #REF! | AF9: =AD9/Y9 -> #REF!
A10: 久留米(ドンキ) | B10: 335467 | D10: 久留米(ドンキ) | F10: =E10-B10 -> -335467 | G10: =E10/B10 -> 0 | I10: 久留米(ドンキ) | K10: =J10-E10 -> 0 | L10: =J10/E10 -> #DIV/0! | N10: 久留米(ドンキ) | P10: =O10-J10 -> 0 | Q10: =O10/J10 -> #DIV/0! | S10: 久留米(ドンキ) | U10: =T10-O10 -> 0 | V10: =T10/O10 -> #DIV/0! | X10: 久留米(ドンキ) | Z10: =Y10-T10 -> 0 | AA10: =Y10/T10 -> #DIV/0! | AC10: 久留米(ドンキ) | AD10: ='久留米(ドンキ景品)'!D3 -> 0 | AE10: =AD10-Y10 -> 0 | AF10: =AD10/Y10 -> #DIV/0!
A11: 飯塚 | B11: 3437686 | D11: 飯塚 | F11: =E11-B11 -> -3437686 | G11: =E11/B11 -> 0 | I11: 飯塚 | K11: =J11-E11 -> 0 | L11: =J11/E11 -> #DIV/0! | N11: 飯塚 | P11: =O11-J11 -> 0 | Q11: =O11/J11 -> #DIV/0! | S11: 飯塚 | U11: =T11-O11 -> 0 | V11: =T11/O11 -> #DIV/0! | X11: 飯塚 | Z11: =Y11-T11 -> 0 | AA11: =Y11/T11 -> #DIV/0! | AC11: 飯塚 | AD11: =飯塚!D4 -> 0 | AE11: =AD11-Y11 -> 0 | AF11: =AD11/Y11 -> #DIV/0!
A12: 鹿児島 | D12: 鹿児島 | I12: 鹿児島 | N12: 鹿児島 | S12: 鹿児島 | X12: 鹿児島 | Z12: =Y12-T12 -> 0 | AA12: =Y12/T12 -> #DIV/0! | AC12: 鹿児島
B13: 23951110 | E13: =SUM(E3:E12) -> 0 | F13: =E13-B13 -> -23951110 | G13: =E13/B13 -> 0 | J13: =SUM(J3:J12) -> 0 | K13: =J13-E13 -> 0 | L13: =J13/E13 -> #DIV/0! | O13: =SUM(O3:O12) -> 0 | P13: =O13-J13 -> 0 | Q13: =O13/J13 -> #DIV/0! | T13: =SUM(T3:T12) -> 0 | U13: =T13-O13 -> 0 | V13: =T13/O13 -> #DIV/0! | Y13: =SUM(Y3:Y12) -> 0 | Z13: =Y13-T13 -> 0 | AA13: =Y13/T13 -> #DIV/0! | AD13: =SUM(AD3:AD12) -> #REF! | AE13: =AD13-Y13 -> #REF! | AF13: =AD13/Y13 -> #REF!
